Workbook

Sheet 工程資料表
A1: 工程名稱 | B1: 橋頭國小暨許厝分校114-116年公立國民中小學老舊廁所整修工程
A2: 業主名稱 | B2: 雲林縣麥寮鄉橋頭國民小學
A3: 監造單位 | B3: 呂罡銘建築師事務所
A4: 承包廠商 | B4: 寶嶸營造有限公司
A5: 工程編號
A6: 契約編號 | B6: A1150507
A7: 開工日期 | B7: 46218
A8: 預定完工日期 | B8: =B7+B9-1 -> 46397
A9: 契約期限 | B9: 180 | C9: 日曆天
A10: 工期展延(第1次) | C10: 日曆天
A11: 不計工期(第2次) | C11: 日曆天
A12: 契約金額 | B12: 4349520
A13: 工程地點 | B13: 雲林縣麥寮鄉

Sheet 原契約
A1: =工程資料表!B1 -> 橋頭國小暨許厝分校114-116年公立國民中小學老舊廁所整修工程
A2: =工程資料表!B13 -> 雲林縣麥寮鄉
A3: 項次 | B3: 項目及說明 | C3: 單位 | D3: 數量 | E3: 單價 | F3: 複價 | G3: 備註
A4: 壹 | B4: 直接工程費
A5: 一 | B5: 分項工程 | F5: =SUM(F6:F33) -> 1454389
A6: 1 | B6: 工程告示牌與職安衛告示牌(租用)、施工圍籬、警示帶、安全警示燈等安全措施(租用) | C6: 式 | D6: 1 | E6: 9750 | F6: =ROUND(D6*E6,2) -> 9750
A7: 2 | B7: 施工動線開闢與損壞復原，既有設備管線遷移與復原；測量與放樣 | C7: 式 | D7: 1 | E7: 9000 | F7: =ROUND(D7*E7,2) -> 9000
A8: 3 | B8: 拆除(含切割)集中廁所既有牆面、地坪、磁磚、牆面小便斗與隔板、所有衛生設備、給排水設施、導擺及天花板等;廢棄物清運處理(含合法證明)與環境清潔 | C8: 式 | D8: 1 | E8: 182446 | F8: =ROUND(D8*E8,2) -> 182446
A9: 4 | B9: 既有污水處理設施抽水肥(含清潔孔開挖與復原) | C9: 式 | D9: 1 | E9: 9500 | F9: =ROUND(D9*E9,2) -> 9500
A10: 5 | B10: 地坪與台階增築 | C10: 式 | D10: 1 | E10: 35400 | F10: =ROUND(D10*E10,2) -> 35400
A11: 6 | B11: 砌1/2B磚牆 | C11: M2 | D11: 26 | E11: 1150 | F11: =ROUND(D11*E11,2) -> 29900
A12: 7 | B12: 施工範圍內樓板穿管處與既有無用穿管及孔洞需以水泥砂漿封閉並刷彈性防水材；樓板防水層試水 | C12: 式 | D12: 1 | E12: 6000 | F12: =ROUND(D12*E12,2) -> 6000
A13: 8 | B13: 地坪、牆面1:3水泥砂漿粉刷 | C13: M2 | D13: 230 | E13: 550 | F13: =ROUND(D13*E13,2) -> 126500
A14: 9 | B14: 地坪及牆面(H=1.5m)防水層粉刷 | C14: M2 | D14: 148 | E14: 500 | F14: =ROUND(D14*E14,2) -> 74000
A15: 10 | B15: 不銹鋼方形地板落水頭(10*10cm,連工帶料) | C15: 組 | D15: 13 | E15: 600 | F15: =ROUND(D15*E15,2) -> 7800
A16: 11 | B16: 地坪貼止滑石英磚30*30cm，本色水泥抹縫(連工帶料) | C16: M2 | D16: 54 | E16: 1100 | F16: =ROUND(D16*E16,2) -> 59400
A17: 12 | B17: 地坪貼止滑石英磚60*60cm，本色水泥抹縫(連工帶料) | C17: M2 | D17: 6 | E17: 1400 | F17: =ROUND(D17*E17,2) -> 8400
... A38: 六 | B38: 營業稅((壹~伍)*5%) | C38: 式 | D38: 1 | E38: 79542 | F38: =ROUND(D38*E38,2) -> 79542
B39: 合計 | F39: =SUM(F5+F34+F35+F36+F37+F38) -> 1670374

Sheet 工程進度表
E1: 數值輸入 | J1: 總計天數 | L1: 78 | M1: 1 | N1: 2 | O1: 3 | P1: 4 | Q1: 5 | R1: 6 | S1: 7 | T1: 8 | U1: 9 | V1: 10 | W1: 11 | X1: 12 | Y1: 13 | Z1: 14 | AA1: 15 | AB1: 16 | AC1: 17 | AD1: 18 | AE1: 19 | AF1: 20 | AG1: 21 | AH1: 22 | AI1: 23 | AJ1: 24 | AK1: 25 | AL1: 26 | AM1: 27 | AN1: 28 | AO1: 29 | AP1: 30 | AQ1: 31 | AR1: 32 | AS1: 33 | AT1: 34 | AU1: 35 | AV1: 36 | AW1: 37 | AX1: 38 | AY1: 39 | AZ1: 40 | BA1: 41 | BB1: 42 | BC1: 43 | BD1: 44 | BE1: 45 | BF1: 46 | BG1: 47 | BH1: 48 | BI1: 49 | BJ1: 50 | BK1: 51 | BL1: 52 | BM1: 53 | BN1: 54 | BO1: 55 | BP1: 56 | BQ1: 57 | BR1: 58 | BS1: 59 | BT1: 60 | BU1: 61 | BV1: 62 | BW1: 63 | BX1: 64 | BY1: 65 | BZ1: 66 | CA1: 67 | CB1: 68 | CC1: 69 | CD1: 70 | CE1: 71 | CF1: 72 | CG1: 73 | CH1: 74 | CI1: 75 | CJ1: 76 | CK1: 77 | CL1: 78 | CM1: 79 | CN1: 80 | CO1: 81 | CP1: 82 | CQ1: 83 | CR1: 84 | CS1: 85 | CT1: 86 | CU1: 87 | CV1: 88 | CW1: 89 | CX1: 90 | CY1: 91 | CZ1: 92 | DA1: 93 | DB1: 94 | DC1: 95 | DD1: 96 | DE1: 97 | DF1: 98 | DG1: 99 | DH1: 100 | DI1: 101 | DJ1: 102 | DK1: 103 | DL1: 104 | DM1: 105 | DN1: 106 | DO1: 107 | DP1: 108 | DQ1: 109 | DR1: 110 | DS1: 111 | DT1: 112 | DU1: 113 | DV1: 114 | DW1: 115 | DX1: 116 | DY1: 117 | DZ1: 118 | EA1: 119 | EB1: 120 | EC1: 121 | ED1: 122 | EE1: 123 | EF1: 124 | EG1: 125 | EH1: 126 | EI1: 127 | EJ1: 128 | EK1: 129 | EL1: 130 | EM1: 131 | EN1: 132 | EO1: 133 | EP1: 134 | EQ1: 135 | ER1: 136 | ES1: 137 | ET1: 138 | EU1: 139 | EV1: 140 | EW1: 141 | EX1: 142 | EY1: 143 | EZ1: 144 | FA1: 145 | FB1: 146 | FC1: 147 | FD1: 148 | FE1: 149 | FF1: 150 | FG1: 151 | FH1: 152 | FI1: 153 | FJ1: 154 | FK1: 155 | FL1: 156 | FM1: 157 | FN1: 158 | FO1: 159 | FP1: 160 | FQ1: 161 | FR1: 162 | FS1: 163 | FT1: 164 | FU1: 165 | FV1: 166 | FW1: 167 | FX1: 168 | FY1: 169 | FZ1: 170 | GA1: 171 | GB1: 172 | GC1: 173 | GD1: 174 | GE1: 175 | GF1: 176 | GG1: 177 | GH1: 178 | GI1: 179 | GJ1: 180
J2: 施工累計天數 | L2: =L1-L3 -> 78 | M2: 1 | N2: 2 | O2: 3 | P2: 4 | Q2: 5 | R2: 6 | S2: 7 | T2: 8 | U2: 9 | V2: 10 | W2: 11 | X2: 12 | Y2: 13 | Z2: 14 | AA2: 15 | AB2: 16 | AC2: 17 | AD2: 18 | AE2: 19 | AF2: 20 | AG2: 21 | AH2: 22 | AI2: 23 | AJ2: 24 | AK2: 25 | AL2: 26 | AM2: 27 | AN2: 28 | AO2: 29 | AP2: 30 | AQ2: 31 | AR2: 32 | AS2: 33 | AT2: 34 | AU2: 35 | AV2: 36 | AW2: 37 | AX2: 38 | AY2: 39 | AZ2: 40 | BA2: 41 | BB2: 42 | BC2: 43 | BD2: 44 | BE2: 45 | BF2: 46 | BG2: 47 | BH2: 48 | BI2: 49 | BJ2: 50 | BK2: 51 | BL2: 52 | BM2: 53 | BN2: 54 | BO2: 55 | BP2: 56 | BQ2: 57 | BR2: 58 | BS2: 59 | BT2: 60 | BU2: 61 | BV2: 62 | BW2: 63 | BX2: 64 | BY2: 65 | BZ2: 66 | CA2: 67 | CB2: 68 | CC2: 69 | CD2: 70 | CE2: 71 | CF2: 72 | CG2: 73 | CH2: 74 | CI2: 75 | CJ2: 76 | CK2: 77 | CL2: 78
J3: 不計工期 | L3: 0
J4: 展延工期 | L4: =SUMIF($M$1:$XFD$1,TEXT($L$1,"<=0"),M4:XFD4) -> 0
J5: 日期 | L5: =HLOOKUP($L$1,$M$1:$XFD$5,5) -> 46295 | M5: 46218 | N5: 46219 | O5: 46220 | P5: 46221 | Q5: 46222 | R5: 46223 | S5: 46224 | T5: 46225 | U5: 46226 | V5: 46227 | W5: 46228 | X5: 46229 | Y5: 46230 | Z5: 46231 | AA5: 46232 | AB5: 46233 | AC5: 46234 | AD5: 46235 | AE5: 46236 | AF5: 46237 | AG5: 46238 | AH5: 46239 | AI5: 46240 | AJ5: 46241 | AK5: 46242 | AL5: 46243 | AM5: 46244 | AN5: 46245 | AO5: 46246 | AP5: 46247 | AQ5: 46248 | AR5: 46249 | AS5: 46250 | AT5: 46251 | AU5: 46252 | AV5: 46253 | AW5: 46254 | AX5: 46255 | AY5: 46256 | AZ5: 46257 | BA5: 46258 | BB5: 46259 | BC5: 46260 | BD5: 46261 | BE5: 46262 | BF5: 46263 | BG5: 46264 | BH5: 46265 | BI5: 46266 | BJ5: 46267 | BK5: 46268 | BL5: 46269 | BM5: 46270 | BN5: 46271 | BO5: 46272 | BP5: 46273 | BQ5: 46274 | BR5: 46275 | BS5: 46276 | BT5: 46277 | BU5: 46278 | BV5: 46279 | BW5: 46280 | BX5: 46281 | BY5: 46282 | BZ5: 46283 | CA5: 46284 | CB5: 46285 | CC5: 46286 | CD5: 46287 | CE5: 46288 | CF5: 46289 | CG5: 46290 | CH5: 46291 | CI5: 46292 | CJ5: 46293 | CK5: 46294 | CL5: 46295 | CM5: 46296 | CN5: 46297 | CO5: 46298 | CP5: 46299 | CQ5: 46300 | CR5: 46301 | CS5: 46302 | CT5: 46303 | CU5: 46304 | CV5: 46305 | CW5: 46306 | CX5: 46307 | CY5: 46308 | CZ5: 46309 | DA5: 46310 | DB5: 46311 | DC5: 46312 | DD5: 46313 | DE5: 46314 | DF5: 46315 | DG5: 46316 | DH5: 46317 | DI5: 46318 | DJ5: 46319 | DK5: 46320 | DL5: 46321 | DM5: 46322 | DN5: 46323 | DO5: 46324 | DP5: 46325 | DQ5: 46326 | DR5: 46327 | DS5: 46328 | DT5: 46329 | DU5: 46330 | DV5: 46331 | DW5: 46332 | DX5: 46333 | DY5: 46334 | DZ5: 46335 | EA5: 46336 | EB5: 46337 | EC5: 46338 | ED5: 46339 | EE5: 46340 | EF5: 46341 | EG5: 46342 | EH5: 46343 | EI5: 46344 | EJ5: 46345 | EK5: 46346 | EL5: 46347 | EM5: 46348 | EN5: 46349 | EO5: 46350 | EP5: 46351 | EQ5: 46352 | ER5: 46353 | ES5: 46354 | ET5: 46355 | EU5: 46356 | EV5: 46357 | EW5: 46358 | EX5: 46359 | EY5: 46360 | EZ5: 46361 | FA5: 46362 | FB5: 46363 | FC5: 46364 | FD5: 46365 | FE5: 46366 | FF5: 46367 | FG5: 46368 | FH5: 46369 | FI5: 46370 | FJ5: 46371 | FK5: 46372 | FL5: 46373 | FM5: 46374 | FN5: 46375 | FO5: 46376 | FP5: 46377 | FQ5: 46378 | FR5: 46379 | FS5: 46380 | FT5: 46381 | FU5: 46382 | FV5: 46383 | FW5: 46384 | FX5: 46385 | FY5: 46386 | FZ5: 46387 | GA5: 46388 | GB5: 46389 | GC5: 46390 | GD5: 46391 | GE5: 46392 | GF5: 46393 | GG5: 46394 | GH5: 46395 | GI5: 46396 | GJ5: 46397
J6: 星期 | L6: =HLOOKUP($L$1,$M$1:$XFD$6,6) -> 46295 | M6: =M5 -> 46218 | N6: =N5 -> 46219 | O6: =O5 -> 46220 | P6: =P5 -> 46221 | Q6: =Q5 -> 46222 | R6: =R5 -> 46223 | S6: =S5 -> 46224 | T6: =T5 -> 46225 | ... GJ6: =GJ5 -> 46397
J7: 上午天氣 | L7: =HLOOKUP($L$1,$M$1:$XFD$7,7) -> 晴 | M7: 晴 | N7: 晴 | O7: 晴 | P7: 晴 | Q7: 晴 | R7: 晴 | S7: 晴 | T7: 晴 | U7: 晴 | V7: 晴 | W7: 晴 | X7: 晴 | Y7: 晴 | Z7: 陰 | AA7: 雨 | AB7: 雨 | AC7: 雨 | AD7: 雨 | AE7: 雨 | AF7: 雨 | AG7: 晴 | AH7: 晴 | AI7: 晴 | AJ7: 晴 | AK7: 晴 | AL7: 晴 | AM7: 晴 | AN7: 晴 | AO7: 晴 | AP7: 晴 | AQ7: 晴 | AR7: 晴 | AS7: 晴 | AT7: 晴 | AU7: 晴 | AV7: 晴 | AW7: 晴 | AX7: 晴 | AY7: 晴 | AZ7: 晴 | BA7: 晴 | BB7: 晴 | BC7: 晴 | BD7: 晴 | BE7: 晴 | BF7: 晴 | BG7: 晴 | BH7: 晴 | BI7: 晴 | BJ7: 晴 | BK7: 晴 | BL7: 晴 | BM7: 晴 | BN7: 晴 | BO7: 晴 | BP7: 晴 | BQ7: 晴 | BR7: 晴 | BS7: 晴 | BT7: 晴 | BU7: 晴 | BV7: 晴 | BW7: 晴 | BX7: 晴 | BY7: 晴 | BZ7: 晴 | CA7: 晴 | CB7: 晴 | CC7: 晴 | CD7: 晴 | CE7: 晴 | CF7: 晴 | CG7: 晴 | CH7: 晴 | CI7: 晴 | CJ7: 晴 | CK7: 晴 | CL7: 晴 | CM7: 晴 | CN7: 晴 | CO7: 晴 | CP7: 晴 | CQ7: 晴 | CR7: 晴 | CS7: 晴 | CT7: 晴 | CU7: 晴 | CV7: 晴 | CW7: 晴 | CX7: 晴 | CY7: 晴 | CZ7: 晴 | DA7: 晴 | DB7: 晴 | DC7: 晴 | DD7: 晴 | DE7: 晴 | DF7: 晴 | DG7: 晴 | DH7: 晴 | DI7: 晴 | DJ7: 晴 | DK7: 晴 | DL7: 晴 | DM7: 晴 | DN7: 晴 | DO7: 晴 | DP7: 晴 | DQ7: 晴 | DR7: 晴 | DS7: 晴 | DT7: 晴 | DU7: 晴 | DV7: 晴 | DW7: 晴 | DX7: 晴 | DY7: 晴 | DZ7: 晴 | EA7: 晴 | EB7: 晴 | EC7: 晴 | ED7: 晴 | EE7: 晴 | EF7: 晴 | EG7: 晴 | EH7: 晴 | EI7: 晴 | EJ7: 晴 | EK7: 晴 | EL7: 晴 | EM7: 晴 | EN7: 晴 | EO7: 晴 | EP7: 晴 | EQ7: 晴 | ER7: 晴 | ES7: 晴 | ET7: 晴 | EU7: 晴 | EV7: 晴 | EW7: 晴 | EX7: 晴 | EY7: 晴 | EZ7: 晴 | FA7: 晴 | FB7: 晴 | FC7: 晴 | FD7: 晴 | FE7: 晴 | FF7: 晴 | FG7: 晴 | FH7: 晴 | FI7: 晴 | FJ7: 晴 | FK7: 晴 | FL7: 晴 | FM7: 晴 | FN7: 晴 | FO7: 晴 | FP7: 晴 | FQ7: 晴 | FR7: 晴 | FS7: 晴 | FT7: 晴 | FU7: 晴 | FV7: 晴 | FW7: 晴 | FX7: 晴 | FY7: 晴 | FZ7: 晴 | GA7: 晴 | GB7: 晴 | GC7: 晴 | GD7: 晴 | GE7: 晴 | GF7: 晴 | GG7: 晴 | GH7: 晴 | GI7: 晴 | GJ7: 晴
J8: 下午天氣 | L8: =HLOOKUP($L$1,$M$1:$XFD$8,8) -> 晴 | M8: 晴 | N8: 晴 | O8: 晴 | P8: 晴 | Q8: 晴 | R8: 晴 | S8: 晴 | T8: 晴 | U8: 晴 | V8: 晴 | W8: 陰 | X8: 晴 | Y8: 雨 | Z8: 陰 | AA8: 雨 | AB8: 雨 | AC8: 雨 | AD8: 雨 | AE8: 雨 | AF8: 雨 | AG8: 陰 | AH8: 晴 | AI8: 晴 | AJ8: 晴 | AK8: 晴 | AL8: 晴 | AM8: 晴 | AN8: 晴 | AO8: 晴 | AP8: 晴 | AQ8: 晴 | AR8: 晴 | AS8: 晴 | AT8: 晴 | AU8: 晴 | AV8: 晴 | AW8: 晴 | AX8: 晴 | AY8: 晴 | AZ8: 晴 | BA8: 晴 | BB8: 晴 | BC8: 晴 | BD8: 晴 | BE8: 晴 | BF8: 晴 | BG8: 晴 | BH8: 晴 | BI8: 晴 | BJ8: 晴 | BK8: 晴 | BL8: 晴 | BM8: 晴 | BN8: 晴 | BO8: 晴 | BP8: 晴 | BQ8: 晴 | BR8: 晴 | BS8: 晴 | BT8: 晴 | BU8: 晴 | BV8: 晴 | BW8: 晴 | BX8: 晴 | BY8: 晴 | BZ8: 晴 | CA8: 晴 | CB8: 晴 | CC8: 晴 | CD8: 晴 | CE8: 晴 | CF8: 晴 | CG8: 晴 | CH8: 晴 | CI8: 晴 | CJ8: 晴 | CK8: 晴 | CL8: 晴 | CM8: 晴 | CN8: 晴 | CO8: 晴 | CP8: 晴 | CQ8: 晴 | CR8: 晴 | CS8: 晴 | CT8: 晴 | CU8: 晴 | CV8: 晴 | CW8: 晴 | CX8: 晴 | CY8: 晴 | CZ8: 晴 | DA8: 晴 | DB8: 晴 | DC8: 晴 | DD8: 晴 | DE8: 晴 | DF8: 晴 | DG8: 晴 | DH8: 晴 | DI8: 晴 | DJ8: 晴 | DK8: 晴 | DL8: 晴 | DM8: 晴 | DN8: 晴 | DO8: 晴 | DP8: 晴 | DQ8: 晴 | DR8: 晴 | DS8: 晴 | DT8: 晴 | DU8: 晴 | DV8: 晴 | DW8: 晴 | DX8: 晴 | DY8: 晴 | DZ8: 晴 | EA8: 晴 | EB8: 晴 | EC8: 晴 | ED8: 晴 | EE8: 晴 | EF8: 晴 | EG8: 晴 | EH8: 晴 | EI8: 晴 | EJ8: 晴 | EK8: 晴 | EL8: 晴 | EM8: 晴 | EN8: 晴 | EO8: 晴 | EP8: 晴 | EQ8: 晴 | ER8: 晴 | ES8: 晴 | ET8: 晴 | EU8: 晴 | EV8: 晴 | EW8: 晴 | EX8: 晴 | EY8: 晴 | EZ8: 晴 | FA8: 晴 | FB8: 晴 | FC8: 晴 | FD8: 晴 | FE8: 晴 | FF8: 晴 | FG8: 晴 | FH8: 晴 | FI8: 晴 | FJ8: 晴 | FK8: 晴 | FL8: 晴 | FM8: 晴 | FN8: 晴 | FO8: 晴 | FP8: 晴 | FQ8: 晴 | FR8: 晴 | FS8: 晴 | FT8: 晴 | FU8: 晴 | FV8: 晴 | FW8: 晴 | FX8: 晴 | FY8: 晴 | FZ8: 晴 | GA8: 晴 | GB8: 晴 | GC8: 晴 | GD8: 晴 | GE8: 晴 | GF8: 晴 | GG8: 晴 | GH8: 晴 | GI8: 晴 | GJ8: 晴
J9: 預定進度 | L9: =ROUND(SUMIF($M$1:$GJ$1,TEXT($L$1,"<=0"),M9:GJ9),4) -> 0.2711 | M9: =進度百分比!B5 -> 0.002243 | N9: =進度百分比!C5 -> 0.002243 | O9: =進度百分比!D5 -> 0.002243 | P9: =進度百分比!E5 -> 0.002243 | Q9: =進度百分比!F5 -> 0.002243 | R9: =進度百分比!G5 -> 0.002243 | S9: =進度百分比!H5 -> 0.002243 | T9: =進度百分比!I5 -> 0.002243 | ... GJ9: =進度百分比!FY5 -> 0.00426
A10: 本日完成 數量 | B10: 累計完成 數量 | C10: 項 | D10: 工程項目 | E10: 單位 | F10: 數量 | G10: 單價 | H10: 合計 | I10: 施作金額 | J10: 權重 | K10: 今日完成 進度 | L10: 累計完成 進度
C11: 次
A12: =SUMIF($M$1:$XFD$1,TEXT($L$1,"=0"),M12:XFD12) -> 0 | B12: =SUMIF($M$1:$XFD$1,TEXT($L$1,"<=0"),M12:XFD12) -> 0 | C12: =原契約!A4 -> 壹 | D12: =原契約!B4 -> 直接工程費
A13: =SUMIF($M$1:$XFD$1,TEXT($L$1,"=0"),M13:XFD13) -> 0 | B13: =SUMIF($M$1:$XFD$1,TEXT($L$1,"<=0"),M13:XFD13) -> 0 | C13: =原契約!A5 -> 一 | D13: =原契約!B5 -> 分項工程
A14: =SUMIF($M$1:$XFD$1,TEXT($L$1,"=0"),M14:XFD14) -> 0 | B14: =SUMIF($M$1:$XFD$1,TEXT($L$1,"<=0"),M14:XFD14) -> 1 | C14: =原契約!A6 -> 1 | D14: =原契約!B6 -> 工程告示牌與職安衛告示牌(租用)、施工圍籬、警示帶、安全警示燈等安全措施(租用) | E14: =原契約!C6 -> 式 | F14: =原契約!D6 -> 1 | G14: =原契約!E6 -> 9750 | H14: =原契約!F6 -> 9750 | J14: =H14/$H$47 -> 0.0058370161 | K14: =A14*G14/$H$47 -> 0 | L14: =B14*G14/$H$47 -> 0.0058370161 | P14: 1
A15: =SUMIF($M$1:$XFD$1,TEXT($L$1,"=0"),M15:XFD15) -> 0 | B15: =SUMIF($M$1:$XFD$1,TEXT($L$1,"<=0"),M15:XFD15) -> 0.5 | C15: =原契約!A7 -> 2 | D15: =原契約!B7 -> 施工動線開闢與損壞復原，既有設備管線遷移與復原；測量與放樣 | E15: =原契約!C7 -> 式 | F15: =原契約!D7 -> 1 | G15: =原契約!E7 -> 9000 | H15: =原契約!F7 -> 9000 | J15: =H15/$H$47 -> 0.0053880149 | K15: =A15*G15/$H$47 -> 0 | L15: =B15*G15/$H$47 -> 0.0026940074 | AD15: 0.25 | AM15: 0.25
A16: =SUMIF($M$1:$XFD$1,TEXT($L$1,"=0"),M16:XFD16) -> 0 | B16: =SUMIF($M$1:$XFD$1,TEXT($L$1,"<=0"),M16:XFD16) -> 1 | C16: =原契約!A8 -> 3 | D16: =原契約!B8 -> 拆除(含切割)集中廁所既有牆面、地坪、磁磚、牆面小便斗與隔板、所有衛生設備、給排水設施、導擺及天花板等;廢棄物清運處理(含合法證明)與環境清潔 | E16: =原契約!C8 -> 式 | F16: =原契約!D8 -> 1 | G16: =原契約!E8 -> 182446 | H16: =原契約!F8 -> 182446 | J16: =H16/$H$47 -> 0.10922464 | K16: =A16*G16/$H$47 -> 0 | L16: =B16*G16/$H$47 -> 0.10922464 | W16: 0.15 | Y16: 0.15 | Z16: 0.15 | AA16: 0.15 | AB16: 0.15 | AC16: 0.25
A17: =SUMIF($M$1:$XFD$1,TEXT($L$1,"=0"),M17:XFD17) -> 0 | B17: =SUMIF($M$1:$XFD$1,TEXT($L$1,"<=0"),M17:XFD17) -> 0 | C17: =原契約!A9 -> 4 | D17: =原契約!B9 -> 既有污水處理設施抽水肥(含清潔孔開挖與復原) | E17: =原契約!C9 -> 式 | F17: =原契約!D9 -> 1 | G17: =原契約!E9 -> 9500 | H17: =原契約!F9 -> 9500 | I17: =B17*G17 -> 0 | J17: =H17/$H$47 -> 0.0056873491 | K17: =A17*G17/$H$47 -> 0 | L17: =B17*G17/$H$47 -> 0
A18: =SUMIF($M$1:$XFD$1,TEXT($L$1,"=0"),M18:XFD18) -> 0 | B18: =SUMIF($M$1:$XFD$1,TEXT($L$1,"<=0"),M18:XFD18) -> 0 | C18: =原契約!A10 -> 5 | D18: =原契約!B10 -> 地坪與台階增築 | E18: =原契約!C10 -> 式 | F18: =原契約!D10 -> 1 | G18: =原契約!E10 -> 35400 | H18: =原契約!F10 -> 35400 | J18: =H18/$H$47 -> 0.021192859 | K18: =A18*G18/$H$47 -> 0 | L18: =B18*G18/$H$47 -> 0
A19: =SUMIF($M$1:$XFD$1,TEXT($L$1,"=0"),M19:XFD19) -> 0 | B19: =SUMIF($M$1:$XFD$1,TEXT($L$1,"<=0"),M19:XFD19) -> 0 | C19: =原契約!A11 -> 6 | D19: =原契約!B11 -> 砌1/2B磚牆 | E19: =原契約!C11 -> M2 | F19: =原契約!D11 -> 26 | G19: =原契約!E11 -> 1150 | H19: =原契約!F11 -> 29900 | I19: =B19*G19 -> 0 | J19: =H19/$H$47 -> 0.017900183 | K19: =A19*G19/$H$47 -> 0 | L19: =B19*G19/$H$47 -> 0
A20: =SUMIF($M$1:$XFD$1,TEXT($L$1,"=0"),M20:XFD20) -> 0 | B20: =SUMIF($M$1:$XFD$1,TEXT($L$1,"<=0"),M20:XFD20) -> 0.7 | C20: =原契約!A12 -> 7 | D20: =原契約!B12 -> 施工範圍內樓板穿管處與既有無用穿管及孔洞需以水泥砂漿封閉並刷彈性防水材；樓板防水層試水 | E20: =原契約!C12 -> 式 | F20: =原契約!D12 -> 1 | G20: =原契約!E12 -> 6000 | H20: =原契約!F12 -> 6000 | J20: =H20/$H$47 -> 0.0035920099 | K20: =A20*G20/$H$47 -> 0 | L20: =B20*G20/$H$47 -> 0.002514407 | AG20: 0.15 | AH20: 0.15 | BI20: 0.1 | BJ20: 0.1 | BK20: 0.1 | BL20: 0.1
A21: =SUMIF($M$1:$XFD$1,TEXT($L$1,"=0"),M21:XFD21) -> 0 | B21: =SUMIF($M$1:$XFD$1,TEXT($L$1,"<=0"),M21:XFD21) -> 40 | C21: =原契約!A13 -> 8 | D21: =原契約!B13 -> 地坪、牆面1:3水泥砂漿粉刷 | E21: =原契約!C13 -> M2 | F21: =原契約!D13 -> 230 | G21: =原契約!E13 -> 550 | H21: =原契約!F13 -> 126500 | I21: =B21*G21 -> 22000 | J21: =H21/$H$47 -> 0.075731543 | K21: =A21*G21/$H$47 -> 0 | L21: =B21*G21/$H$47 -> 0.013170703 | CH21: 10 | CI21: 10 | CK21: 20
A22: =SUMIF($M$1:$XFD$1,TEXT($L$1,"=0"),M22:XFD22) -> 0 | B22: =SUMIF($M$1:$XFD$1,TEXT($L$1,"<=0"),M22:XFD22) -> 0 | C22: =原契約!A14 -> 9 | D22: =原契約!B14 -> 地坪及牆面(H=1.5m)防水層粉刷 | E22: =原契約!C14 -> M2 | F22: =原契約!D14 -> 148 | G22: =原契約!E14 -> 500 | H22: =原契約!F14 -> 74000 | J22: =H22/$H$47 -> 0.044301456 | K22: =A22*G22/$H$47 -> 0 | L22: =B22*G22/$H$47 -> 0
A23: =SUMIF($M$1:$XFD$1,TEXT($L$1,"=0"),M23:XFD23) -> 0 | B23: =SUMIF($M$1:$XFD$1,TEXT($L$1,"<=0"),M23:XFD23) -> 0 | C23: =原契約!A15 -> 10 | D23: =原契約!B15 -> 不銹鋼方形地板落水頭(10*10cm,連工帶料) | E23: =原契約!C15 -> 組 | F23: =原契約!D15 -> 13 | G23: =原契約!E15 -> 600 | H23: =原契約!F15 -> 7800 | J23: =H23/$H$47 -> 0.0046696129 | K23: =A23*G23/$H$47 -> 0 | L23: =B23*G23/$H$47 -> 0
A24: =SUMIF($M$1:$XFD$1,TEXT($L$1,"=0"),M24:XFD24) -> 0 | B24: =SUMIF($M$1:$XFD$1,TEXT($L$1,"<=0"),M24:XFD24) -> 0 | C24: =原契約!A16 -> 11 | D24: =原契約!B16 -> 地坪貼止滑石英磚30*30cm，本色水泥抹縫(連工帶料) | E24: =原契約!C16 -> M2 | F24: =原契約!D16 -> 54 | G24: =原契約!E16 -> 1100 | H24: =原契約!F16 -> 59400 | J24: =H24/$H$47 -> 0.035560898 | K24: =A24*G24/$H$47 -> 0 | L24: =B24*G24/$H$47 -> 0
A25: =SUMIF($M$1:$XFD$1,TEXT($L$1,"=0"),M25:XFD25) -> 0 | B25: =SUMIF($M$1:$XFD$1,TEXT($L$1,"<=0"),M25:XFD25) -> 0 | C25: =原契約!A17 -> 12 | D25: =原契約!B17 -> 地坪貼止滑石英磚60*60cm，本色水泥抹縫(連工帶料) | E25: =原契約!C17 -> M2 | F25: =原契約!D17 -> 6 | G25: =原契約!E17 -> 1400 | H25: =原契約!F17 -> 8400 | I25: =B25*G25 -> 0 | J25: =H25/$H$47 -> 0.0050288139 | K25: =A25*G25/$H$47 -> 0 | L25: =B25*G25/$H$47 -> 0
A26: =SUMIF($M$1:$XFD$1,TEXT($L$1,"=0"),M26:XFD26) -> 0 | B26: =SUMIF($M$1:$XFD$1,TEXT($L$1,"<=0"),M26:XFD26) -> 0 | C26: =原契約!A18 -> 13 | D26: =原契約!B18 -> 牆面貼石英磚30*60cm，白色水泥抹縫(連工帶料) | E26: =原契約!C18 -> M2 | F26: =原契約!D18 -> 138 | G26: =原契約!E18 -> 1300 | H26: =原契約!F18 -> 179400 | I26: =B26*G26 -> 0 | J26: =H26/$H$47 -> 0.1074011 | K26: =A26*G26/$H$47 -> 0 | L26: =B26*G26/$H$47 -> 0
A27: =SUMIF($M$1:$XFD$1,TEXT($L$1,"=0"),M27:XFD27) -> 0 | B27: =SUMIF($M$1:$XFD$1,TEXT($L$1,"<=0"),M27:XFD27) -> 0 | C27: =原契約!A19 -> 14 | D27: =原契約!B19 -> 安裝鋁合金陽角收邊條 | E27: =原契約!C19 -> M | F27: =原契約!D19 -> 27 | G27: =原契約!E19 -> 400 | H27: =原契約!F19 -> 10800 | I27: =B27*G27 -> 0 | J27: =H27/$H$47 -> 0.0064656179 | K27: =A27*G27/$H$47 -> 0 | L27: =B27*G27/$H$47 -> 0
A28: =SUMIF($M$1:$XFD$1,TEXT($L$1,"=0"),M28:XFD28) -> 0 | B28: =SUMIF($M$1:$XFD$1,TEXT($L$1,"<=0"),M28:XFD28) -> 0 | C28: =原契約!A20 -> 15 | D28: =原契約!B20 -> 施做抿石子(1~2分霓虹石，抿石子專用泥) | E28: =原契約!C20 -> M2 | F28: =原契約!D20 -> 13 | G28: =原契約!E20 -> 1100 | H28: =原契約!F20 -> 14300 | I28: =B28*G28 -> 0 | J28: =H28/$H$47 -> 0.008560957 | K28: =A28*G28/$H$47 -> 0 | L28: =B28*G28/$H$47 -> 0
A29: =SUMIF($M$1:$XFD$1,TEXT($L$1,"=0"),M29:XFD29) -> 0 | B29: =SUMIF($M$1:$XFD$1,TEXT($L$1,"<=0"),M29:XFD29) -> 110 | C29: =原契約!A21 -> 16 | D29: =原契約!B21 -> 牆面與平頂塗刷水泥漆(含清潔，批土整平，一底漆二度面漆) | E29: =原契約!C21 -> M2 | F29: =原契約!D21 -> 117 | G29: =原契約!E21 -> 200 | H29: =原契約!F21 -> 23400 | I29: =B29*G29 -> 22000 | J29: =H29/$H$47 -> 0.014008839 | K29: =A29*G29/$H$47 -> 0 | L29: =B29*G29/$H$47 -> 0.013170703 | BP29: 10 | BQ29: 10 | BR29: 10 | BX29: 10 | BY29: 10 | CH29: 20 | CI29: 20 | CK29: 20
A30: =SUMIF($M$1:$XFD$1,TEXT($L$1,"=0"),M30:XFD30) -> 0 | B30: =SUMIF($M$1:$XFD$1,TEXT($L$1,"<=0"),M30:XFD30) -> 0 | C30: =原契約!A22 -> 17 | D30: =原契約!B22 -> 新建砌磚洗手台與拖布盆、既有洗手台拉皮工程(連工帶料，責任施工) | E30: =原契約!C22 -> 式 | F30: =原契約!D22 -> 1 | G30: =原契約!E22 -> 73453 | H30: =原契約!F22 -> 73453 | I30: =B30*G30 -> 0 | J30: =H30/$H$47 -> 0.043973984 | K30: =A30*G30/$H$47 -> 0 | L30: =B30*G30/$H$47 -> 0
A31: =SUMIF($M$1:$XFD$1,TEXT($L$1,"=0"),M31:XFD31) -> 0 | B31: =SUMIF($M$1:$XFD$1,TEXT($L$1,"<=0"),M31:XFD31) -> 0 | C31: =原契約!A23 -> 18 | D31: =原契約!B23 -> 貼深色石材檯面(石材t=2cm，倒圓角) | E31: =原契約!C23 -> 才 | F31: =原契約!D23 -> 19 | G31: =原契約!E23 -> 600 | H31: =原契約!F23 -> 11400 | I31: =B31*G31 -> 0 | J31: =H31/$H$47 -> 0.0068248189 | K31: =A31*G31/$H$47 -> 0 | L31: =B31*G31/$H$47 -> 0
A32: =SUMIF($M$1:$XFD$1,TEXT($L$1,"=0"),M32:XFD32) -> 0 | B32: =SUMIF($M$1:$XFD$1,TEXT($L$1,"<=0"),M32:XFD32) -> 0 | C32: =原契約!A24 -> 19 | D32: =原契約!B24 -> 安裝13mm熱固性樹脂板隔間含門片(頂面H=200cm以上) | E32: =原契約!C24 -> M2 | F32: =原契約!D24 -> 84 | G32: =原契約!E24 -> 2700 | H32: =原契約!F24 -> 226800 | I32: =B32*G32 -> 0 | J32: =H32/$H$47 -> 0.13577798 | K32: =A32*G32/$H$47 -> 0 | L32: =B32*G32/$H$47 -> 0
A33: =SUMIF($M$1:$XFD$1,TEXT($L$1,"=0"),M33:XFD33) -> 0 | B33: =SUMIF($M$1:$XFD$1,TEXT($L$1,"<=0"),M33:XFD33) -> 0 | C33: =原契約!A25 -> 20 | D33: =原契約!B25 -> 廁間安裝不鏽鋼掛鈎與13mm熱固性樹脂板置物板 | E33: =原契約!C25 -> 間 | F33: =原契約!D25 -> 8 | G33: =原契約!E25 -> 800 | H33: =原契約!F25 -> 6400 | I33: =B33*G33 -> 0 | J33: =H33/$H$47 -> 0.0038314773 | K33: =A33*G33/$H$47 -> 0 | L33: =B33*G33/$H$47 -> 0
A34: =SUMIF($M$1:$XFD$1,TEXT($L$1,"=0"),M34:XFD34) -> 0 | B34: =SUMIF($M$1:$XFD$1,TEXT($L$1,"<=0"),M34:XFD34) -> 0 | C34: =原契約!A26 -> 21 | D34: =原契約!B26 -> 安裝輕鋼架、金屬烤漆透空網與耐燃一級貼皮天花板(含必要之側封板與窗簾盒批土刷漆) | E34: =原契約!C26 -> 式 | F34: =原契約!D26 -> 1 | G34: =原契約!E26 -> 54200 | H34: =原契約!F26 -> 54200 | I34: =B34*G34 -> 0 | J34: =H34/$H$47 -> 0.032447823 | K34: =A34*G34/$H$47 -> 0 | L34: =B34*G34/$H$47 -> 0
A35: =SUMIF($M$1:$XFD$1,TEXT($L$1,"=0"),M35:XFD35) -> 0 | B35: =SUMIF($M$1:$XFD$1,TEXT($L$1,"<=0"),M35:XFD35) -> 0.75 | C35: =原契約!A27 -> 22 | D35: =原契約!B27 -> 廁所安裝衛生設備(連工帶料) | E35: =原契約!C27 -> 式 | F35: =原契約!D27 -> 1 | G35: =原契約!E27 -> 112700 | H35: =原契約!F27 -> 112700 | J35: =H35/$H$47 -> 0.06746992 | K35: =A35*G35/$H$47 -> 0 | L35: =B35*G35/$H$47 -> 0.05060244 | BD35: 0.5 | CH35: 0.25
A36: =SUMIF($M$1:$XFD$1,TEXT($L$1,"=0"),M36:XFD36) -> 0 | B36: =SUMIF($M$1:$XFD$1,TEXT($L$1,"<=0"),M36:XFD36) -> 0 | C36: =原契約!A28 -> 23 | D36: =原契約!B28 -> 安裝開關、插座與燈具(連工帶料) | E36: =原契約!C28 -> 式 | F36: =原契約!D28 -> 1 | G36: =原契約!E28 -> 27000 | H36: =原契約!F28 -> 27000 | J36: =H36/$H$47 -> 0.016164045 | K36: =A36*G36/$H$47 -> 0 | L36: =B36*G36/$H$47 -> 0
A37: =SUMIF($M$1:$XFD$1,TEXT($L$1,"=0"),M37:XFD37) -> 0 | B37: =SUMIF($M$1:$XFD$1,TEXT($L$1,"<=0"),M37:XFD37) -> 1 | C37: =原契約!A29 -> 24 | D37: =原契約!B29 -> 給排水系統配管與安裝(連工帶料) | E37: =原契約!C29 -> 式 | F37: =原契約!D29 -> 1 | G37: =原契約!E29 -> 59100 | H37: =原契約!F29 -> 59100 | J37: =H37/$H$47 -> 0.035381298 | K37: =A37*G37/$H$47 -> 0 | L37: =B37*G37/$H$47 -> 0.035381298 | AN37: 0.25 | BH37: 0.25 | BK37: 0.1 | BL37: 0.1 | BP37: 0.1 | BQ37: 0.1 | BR37: 0.1
A38: =SUMIF($M$1:$XFD$1,TEXT($L$1,"=0"),M38:XFD38) -> 0 | B38: =SUMIF($M$1:$XFD$1,TEXT($L$1,"<=0"),M38:XFD38) -> 0 | C38: =原契約!A30 -> 25 | D38: =原契約!B30 -> 施做緊急求救按鈕(含閃光與蜂嗚警報器、線材、五金配件, 各層樓每間廁所皆有求救鈕，連工帶料，責任施工) | E38: =原契約!C30 -> 式 | F38: =原契約!D30 -> 1 | G38: =原契約!E30 -> 16400 | H38: =原契約!F30 -> 16400 | I38: =B38*G38 -> 0 | J38: =H38/$H$47 -> 0.0098181605 | K38: =A38*G38/$H$47 -> 0 | L38: =B38*G38/$H$47 -> 0
A39: =SUMIF($M$1:$XFD$1,TEXT($L$1,"=0"),M39:XFD39) -> 0 | B39: =SUMIF($M$1:$XFD$1,TEXT($L$1,"<=0"),M39:XFD39) -> 0 | C39: =原契約!A31 -> 26 | D39: =原契約!B31 -> 安裝廁所指標系統、拖把夾(連工帶料，責任施工) | E39: =原契約!C31 -> 式 | F39: =原契約!D31 -> 1 | G39: =原契約!E31 -> 30000 | H39: =原契約!F31 -> 30000 | J39: =H39/$H$47 -> 0.01796005 | K39: =A39*G39/$H$47 -> 0 | L39: =B39*G39/$H$47 -> 0
A40: =SUMIF($M$1:$XFD$1,TEXT($L$1,"=0"),M40:XFD40) -> 0 | B40: =SUMIF($M$1:$XFD$1,TEXT($L$1,"<=0"),M40:XFD40) -> 0 | C40: =原契約!A32 -> 27 | D40: =原契約!B32 -> 牆面貼彩色花磚磁磚20*20cm，白色水泥勾縫(連工帶料) | E40: =原契約!C32 -> 片 | F40: =原契約!D32 -> 104 | G40: =原契約!E32 -> 110 | H40: =原契約!F32 -> 11440 | J40: =H40/$H$47 -> 0.0068487656 | K40: =A40*G40/$H$47 -> 0 | L40: =B40*G40/$H$47 -> 0
...

Sheet 施工日誌
A1: 建築物施工日誌 | Z1: 1
Z2: 2
A3: 報表編號： | C3: =工程進度表!L1 -> 78 | Z3: 3
A4: 本日天氣： | C4: 上午： | D4: =工程進度表!L7 -> 晴 | E4: 下午： | G4: =工程進度表!L8 -> 晴 | I4: 填表日期： | K4: =工程進度表!L5 -> 46295 | N4: =K4 -> 46295 | Z4: 4
A5: 工程名稱： | C5: =工程資料表!B1 -> 橋頭國小暨許厝分校114-116年公立國民中小學老舊廁所整修工程 | I5: 施工廠商 | J5: =工程資料表!B4 -> 寶嶸營造有限公司 | Z5: 5
A6: 核定工期： | C6: =工程資料表!B9 -> 180 | E6: 累計工期 | G6: =工程進度表!L2 -> 78 | H6: 天 | I6: 剩餘工期 | J6: =C6-G6 -> 102 | K6: 天 | L6: 不計工期天數 | Z6: 6
A7: 開工日期： | E7: =工程資料表!B7 -> 46218 | J7: 完工日期： | L7: =E7+C6-1 -> 46397 | Z7: 7
A8: 預定進度(%) | C8: =工程進度表!L9 -> 0.2711 | H8: 實際進度(%) | J8: =工程進度表!L48 -> 0.277 | Z8: 8
Z9: 9
A10: =[1]進度表!A246 -> 一、依施工計畫書執行按圖施工概況（含約定之重要施工、材料項目及完成數量等）： | Z10: 10
A11: 項次 | B11: 施工項目 | H11: 單位 | I11: 契約數量 | K11: 本日完成數量 | M11: 累計完成數量 | O11: 備註 | Z11: 11
Z12: 12
A13: =工程進度表!C12 -> 壹 | B13: =工程進度表!D12 -> 直接工程費 | H13: =工程進度表!E12 -> 0 | I13: =工程進度表!F12 -> 0 | K13: =工程進度表!A12 -> 0 | M13: =工程進度表!B12 -> 0 | Z13: 14
A14: =工程進度表!C13 -> 一 | B14: =工程進度表!D13 -> 分項工程 | H14: =工程進度表!E13 -> 0 | I14: =工程進度表!F13 -> 0 | K14: =工程進度表!A13 -> 0 | M14: =工程進度表!B13 -> 0 | Q14: 一式一份 | U14: =C6+210 -> 390 | Z14: 15
A15: =工程進度表!C14 -> 1 | B15: =工程進度表!D14 -> 工程告示牌與職安衛告示牌(租用)、施工圍籬、警示帶、安全警示燈等安全措施(租用) | H15: =工程進度表!E14 -> 式 | I15: =工程進度表!F14 -> 1 | K15: =工程進度表!A14 -> 0 | M15: =工程進度表!B14 -> 1
A16: =工程進度表!C15 -> 2 | B16: =工程進度表!D15 -> 施工動線開闢與損壞復原，既有設備管線遷移與復原；測量與放樣 | H16: =工程進度表!E15 -> 式 | I16: =工程進度表!F15 -> 1 | K16: =工程進度表!A15 -> 0 | M16: =工程進度表!B15 -> 0.5
A17: =工程進度表!C16 -> 3 | B17: =工程進度表!D16 -> 拆除(含切割)集中廁所既有牆面、地坪、磁磚、牆面小便斗與隔板、所有衛生設備、給排水設施、導擺及天花板等;廢棄物清運處理(含合法證明)與環境清潔 | H17: =工程進度表!E16 -> 式 | I17: =工程進度表!F16 -> 1 | K17: =工程進度表!A16 -> 0 | M17: =工程進度表!B16 -> 1 | Z17: 17
A18: =工程進度表!C17 -> 4 | B18: =工程進度表!D17 -> 既有污水處理設施抽水肥(含清潔孔開挖與復原) | H18: =工程進度表!E17 -> 式 | I18: =工程進度表!F17 -> 1 | K18: =工程進度表!A17 -> 0 | M18: =工程進度表!B17 -> 0 | U18: =#REF!+210 -> #REF! | Z18: 18
A19: =工程進度表!C18 -> 5 | B19: =工程進度表!D18 -> 地坪與台階增築 | H19: =工程進度表!E18 -> 式 | I19: =工程進度表!F18 -> 1 | K19: =工程進度表!A18 -> 0 | M19: =工程進度表!B18 -> 0 | Z19: 19
A20: =工程進度表!C19 -> 6 | B20: =工程進度表!D19 -> 砌1/2B磚牆 | H20: =工程進度表!E19 -> M2 | I20: =工程進度表!F19 -> 26 | K20: =工程進度表!A19 -> 0 | M20: =工程進度表!B19 -> 0 | Z20: 17
A21: =工程進度表!C20 -> 7 | B21: =工程進度表!D20 -> 施工範圍內樓板穿管處與既有無用穿管及孔洞需以水泥砂漿封閉並刷彈性防水材；樓板防水層試水 | H21: =工程進度表!E20 -> 式 | I21: =工程進度表!F20 -> 1 | K21: =工程進度表!A20 -> 0 | M21: =工程進度表!B20 -> 0.7 | U21: =#REF!+210 -> #REF! | Z21: 18
A22: =工程進度表!C21 -> 8 | B22: =工程進度表!D21 -> 地坪、牆面1:3水泥砂漿粉刷 | H22: =工程進度表!E21 -> M2 | I22: =工程進度表!F21 -> 230 | K22: =工程進度表!A21 -> 0 | M22: =工程進度表!B21 -> 40 | Z22: 19
A23: =工程進度表!C22 -> 9 | B23: =工程進度表!D22 -> 地坪及牆面(H=1.5m)防水層粉刷 | H23: =工程進度表!E22 -> M2 | I23: =工程進度表!F22 -> 148 | K23: =工程進度表!A22 -> 0 | M23: =工程進度表!B22 -> 0 | Z23: 17
A24: =工程進度表!C23 -> 10 | B24: =工程進度表!D23 -> 不銹鋼方形地板落水頭(10*10cm,連工帶料) | H24: =工程進度表!E23 -> 組 | I24: =工程進度表!F23 -> 13 | K24: =工程進度表!A23 -> 0 | M24: =工程進度表!B23 -> 0 | U24: =L1+210 -> 210 | Z24: 18
A25: =工程進度表!C24 -> 11 | B25: =工程進度表!D24 -> 地坪貼止滑石英磚30*30cm，本色水泥抹縫(連工帶料) | H25: =工程進度表!E24 -> M2 | I25: =工程進度表!F24 -> 54 | K25: =工程進度表!A24 -> 0 | M25: =工程進度表!B24 -> 0 | Z25: 17
A26: =工程進度表!C25 -> 12 | B26: =工程進度表!D25 -> 地坪貼止滑石英磚60*60cm，本色水泥抹縫(連工帶料) | H26: =工程進度表!E25 -> M2 | I26: =工程進度表!F25 -> 6 | K26: =工程進度表!A25 -> 0 | M26: =工程進度表!B25 -> 0 | U26: =#REF!+210 -> #REF! | Z26: 18
A27: =工程進度表!C26 -> 13 | B27: =工程進度表!D26 -> 牆面貼石英磚30*60cm，白色水泥抹縫(連工帶料) | H27: =工程進度表!E26 -> M2 | I27: =工程進度表!F26 -> 138 | K27: =工程進度表!A26 -> 0 | M27: =工程進度表!B26 -> 0 | Z27: 19
A28: =工程進度表!C27 -> 14 | B28: =工程進度表!D27 -> 安裝鋁合金陽角收邊條 | H28: =工程進度表!E27 -> M | I28: =工程進度表!F27 -> 27 | K28: =工程進度表!A27 -> 0 | M28: =工程進度表!B27 -> 0 | Z28: 17
A29: =工程進度表!C28 -> 15 | B29: =工程進度表!D28 -> 施做抿石子(1~2分霓虹石，抿石子專用泥) | H29: =工程進度表!E28 -> M2 | I29: =工程進度表!F28 -> 13 | K29: =工程進度表!A28 -> 0 | M29: =工程進度表!B28 -> 0 | U29: =L1+210 -> 210 | Z29: 18
A30: =工程進度表!C29 -> 16 | B30: =工程進度表!D29 -> 牆面與平頂塗刷水泥漆(含清潔，批土整平，一底漆二度面漆) | H30: =工程進度表!E29 -> M2 | I30: =工程進度表!F29 -> 117 | K30: =工程進度表!A29 -> 0 | M30: =工程進度表!B29 -> 110 | Z30: 16
A31: =工程進度表!C30 -> 17 | B31: =工程進度表!D30 -> 新建砌磚洗手台與拖布盆、既有洗手台拉皮工程(連工帶料，責任施工) | H31: =工程進度表!E30 -> 式 | I31: =工程進度表!F30 -> 1 | K31: =工程進度表!A30 -> 0 | M31: =工程進度表!B30 -> 0 | Z31: 17
A32: =工程進度表!C31 -> 18 | B32: =工程進度表!D31 -> 貼深色石材檯面(石材t=2cm，倒圓角) | H32: =工程進度表!E31 -> 才 | I32: =工程進度表!F31 -> 19 | K32: =工程進度表!A31 -> 0 | M32: =工程進度表!B31 -> 0 | U32: =L4+210 -> 210 | Z32: 18
A33: =工程進度表!C32 -> 19 | B33: =工程進度表!D32 -> 安裝13mm熱固性樹脂板隔間含門片(頂面H=200cm以上) | H33: =工程進度表!E32 -> M2 | I33: =工程進度表!F32 -> 84 | K33: =工程進度表!A32 -> 0 | M33: =工程進度表!B32 -> 0 | Z33: 19
A34: =工程進度表!C33 -> 20 | B34: =工程進度表!D33 -> 廁間安裝不鏽鋼掛鈎與13mm熱固性樹脂板置物板 | H34: =工程進度表!E33 -> 間 | I34: =工程進度表!F33 -> 8 | K34: =工程進度表!A33 -> 0 | M34: =工程進度表!B33 -> 0 | Z34: 17
A35: =工程進度表!C34 -> 21 | B35: =工程進度表!D34 -> 安裝輕鋼架、金屬烤漆透空網與耐燃一級貼皮天花板(含必要之側封板與窗簾盒批土刷漆) | H35: =工程進度表!E34 -> 式 | I35: =工程進度表!F34 -> 1 | K35: =工程進度表!A34 -> 0 | M35: =工程進度表!B34 -> 0 | U35: =L7+210 -> 46607 | Z35: 18
A36: =工程進度表!C35 -> 22 | B36: =工程進度表!D35 -> 廁所安裝衛生設備(連工帶料) | H36: =工程進度表!E35 -> 式 | I36: =工程進度表!F35 -> 1 | K36: =工程進度表!A35 -> 0 | M36: =工程進度表!B35 -> 0.75 | Z36: 16
A37: =工程進度表!C36 -> 23 | B37: =工程進度表!D36 -> 安裝開關、插座與燈具(連工帶料) | H37: =工程進度表!E36 -> 式 | I37: =工程進度表!F36 -> 1 | K37: =工程進度表!A36 -> 0 | M37: =工程進度表!B36 -> 0 | Z37: 17
A38: =工程進度表!C37 -> 24 | B38: =工程進度表!D37 -> 給排水系統配管與安裝(連工帶料) | H38: =工程進度表!E37 -> 式 | I38: =工程進度表!F37 -> 1 | K38: =工程進度表!A37 -> 0 | M38: =工程進度表!B37 -> 1 | U38: =L10+210 -> 210 | Z38: 18
A39: =工程進度表!C38 -> 25 | B39: =工程進度表!D38 -> 施做緊急求救按鈕(含閃光與蜂嗚警報器、線材、五金配件, 各層樓每間廁所皆有求救鈕，連工帶料，責任施工) | H39: =工程進度表!E38 -> 式 | I39: =工程進度表!F38 -> 1 | K39: =工程進度表!A38 -> 0 | M39: =工程進度表!B38 -> 0 | Z39: 19
A40: =工程進度表!C39 -> 26 | B40: =工程進度表!D39 -> 安裝廁所指標系統、拖把夾(連工帶料，責任施工) | H40: =工程進度表!E39 -> 式 | I40: =工程進度表!F39 -> 1 | K40: =工程進度表!A39 -> 0 | M40: =工程進度表!B39 -> 0 | U40: =L12+210 -> 210 | Z40: 18
...

Sheet 監造報表
A1: 公共工程監造報表
A2: 表報編號：
A3: 本日天氣： | B3: 上午: | D3: 下午: | H3: 填報日期： | K3: =I3 -> 0
A4: 工程名稱
A5: 契約工期 | C5: 開工日期 | G5: 預定完工 日期 | K5: 實際完工日期
A7: 契約變更次數 | E7: 次 | F7: 工期展延天數 | H7: 432 | I7: 天 | J7: 契約金額 | K7: 原契約： 228,349,097元整
A8: 預定進度(%) | F8: 實際進度(%) | K8: ="變更後契約："&" 元整" -> 變更後契約： 元整
A9: 一、工程進行情況（含約定之重要施工項目及數量）：
A16: 二、監督依照設計圖說及核定施工圖說施工（含約定之檢驗停留點及施工抽查等情形）：
A23: 三、查核材料規格及品質（含約定之檢驗停留點、材料設備管制及檢（試）驗等抽驗情形）：
A30: 四、督導工地職業安全衛生事項：
A31: （一）施工廠商施工前檢查事項辦理情形﹕□完成□未完成 (二)其他工地安全衛生督導事項﹕
A32: （二）其他工地安全衛生督導事項：
A33: 五、其他約定監造事項(含重要事項記錄、主辦機關指示及通知廠商辦理事項等)：
A35: 監造單位簽章：
A37: 註：1.監造報告表原則應包含上述欄位；惟若上述欄位之內容業詳載於廠商填報之施工日誌，並按時陳報監造單位核備者，則監造報表之該等欄位 可載明參詳施工日誌。 2.本表原則應按日填寫，機關另有規定者，從其規定；若屬委外監造之工程，則一律按日填寫。未達查核金額或工期為九十日曆天以下之工程 ，得由機關統一訂定內部稽查程序及監造報告表之填報方式與周期。 3.本監造報告表格式僅供參考，各機關亦得依契約約定事項，自行增訂之。 4.契約工期如有修正，應填修正後之契約工期，含展延工期及不計工期天數；如有依契約變更設計，預定進度及實際進度應填變更設計後計算 之進度。 5.公共工程屬建築物者，仍應依本表辦理。惟該工程之監造人（建築師），應另依內政部九十六年六月六日台內營字第○九六○八○二九五○ 號令頒之「建築物（監督、查核）報告表」填報（頻率按該表註2辦理）。

Sheet 進度百分比
C1: 當日權重 | D1: 累積預計
B2: 10 | L2: 20 | V2: 30 | AF2: 40 | AP2: 50 | AZ2: 60 | BJ2: 70 | BT2: 80 | CD2: 90 | CN2: 100 | CX2: 110 | DH2: 120 | DR2: 130 | EB2: 140 | EL2: 150 | EV2: 160 | FF2: 170 | FP2: 180
B3: 115/7/15 | C3: 115/7/16 | D3: 115/7/17 | E3: 115/7/18 | F3: 115/7/19 | G3: 115/7/20 | H3: 115/7/21 | I3: 115/7/22 | J3: 115/7/23 | K3: 115/7/24 | L3: 115/7/25 | M3: 115/7/26 | N3: 115/7/27 | O3: 115/7/28 | P3: 115/7/29 | Q3: 115/7/30 | R3: 115/7/31 | S3: 115/8/1 | T3: 115/8/2 | U3: 115/8/3 | V3: 115/8/4 | W3: 115/8/5 | X3: 115/8/6 | Y3: 115/8/7 | Z3: 115/8/8 | AA3: 115/8/9 | AB3: 115/8/10 | AC3: 115/8/11 | AD3: 115/8/12 | AE3: 115/8/13 | AF3: 115/8/14 | AG3: 115/8/15 | AH3: 115/8/16 | AI3: 115/8/17 | AJ3: 115/8/18 | AK3: 115/8/19 | AL3: 115/8/20 | AM3: 115/8/21 | AN3: 115/8/22 | AO3: 115/8/23 | AP3: 115/8/24 | AQ3: 115/8/25 | AR3: 115/8/26 | AS3: 115/8/27 | AT3: 115/8/28 | AU3: 115/8/29 | AV3: 115/8/30 | AW3: 115/8/31 | AX3: 115/9/1 | AY3: 115/9/2 | AZ3: 115/9/3 | BA3: 115/9/4 | BB3: 115/9/5 | BC3: 115/9/6 | BD3: 115/9/7 | BE3: 115/9/8 | BF3: 115/9/9 | BG3: 115/9/10 | BH3: 115/9/11 | BI3: 115/9/12 | BJ3: 115/9/13 | BK3: 115/9/14 | BL3: 115/9/15 | BM3: 115/9/16 | BN3: 115/9/17 | BO3: 115/9/18 | BP3: 115/9/19 | BQ3: 115/9/20 | BR3: 115/9/21 | BS3: 115/9/22 | BT3: 115/9/23 | BU3: 115/9/24 | BV3: 115/9/25 | BW3: 115/9/26 | BX3: 115/9/27 | BY3: 115/9/28 | BZ3: 115/9/29 | CA3: 115/9/30 | CB3: 115/10/1 | CC3: 115/10/2 | CD3: 115/10/3 | CE3: 115/10/4 | CF3: 115/10/5 | CG3: 115/10/6 | CH3: 115/10/7 | CI3: 115/10/8 | CJ3: 115/10/9 | CK3: 115/10/10 | CL3: 115/10/11 | CM3: 115/10/12 | CN3: 115/10/13 | CO3: 115/10/14 | CP3: 115/10/15 | CQ3: 115/10/16 | CR3: 115/10/17 | CS3: 115/10/18 | CT3: 115/10/19 | CU3: 115/10/20 | CV3: 115/10/21 | CW3: 115/10/22 | CX3: 115/10/23 | CY3: 115/10/24 | CZ3: 115/10/25 | DA3: 115/10/26 | DB3: 115/10/27 | DC3: 115/10/28 | DD3: 115/10/29 | DE3: 115/10/30 | DF3: 115/10/31 | DG3: 115/11/1 | DH3: 115/11/2 | DI3: 115/11/3 | DJ3: 115/11/4 | DK3: 115/11/5 | DL3: 115/11/6 | DM3: 115/11/7 | DN3: 115/11/8 | DO3: 115/11/9 | DP3: 115/11/10 | DQ3: 115/11/11 | DR3: 115/11/12 | DS3: 115/11/13 | DT3: 115/11/14 | DU3: 115/11/15 | DV3: 115/11/16 | DW3: 115/11/17 | DX3: 115/11/18 | DY3: 115/11/19 | DZ3: 115/11/20 | EA3: 115/11/21 | EB3: 115/11/22 | EC3: 115/11/23 | ED3: 115/11/24 | EE3: 115/11/25 | EF3: 115/11/26 | EG3: 115/11/27 | EH3: 115/11/28 | EI3: 115/11/29 | EJ3: 115/11/30 | EK3: 115/12/1 | EL3: 115/12/2 | EM3: 115/12/3 | EN3: 115/12/4 | EO3: 115/12/5 | EP3: 115/12/6 | EQ3: 115/12/7 | ER3: 115/12/8 | ES3: 115/12/9 | ET3: 115/12/10 | EU3: 115/12/11 | EV3: 115/12/12 | EW3: 115/12/13 | EX3: 115/12/14 | EY3: 115/12/15 | EZ3: 115/12/16 | FA3: 115/12/17 | FB3: 115/12/18 | FC3: 115/12/19 | FD3: 115/12/20 | FE3: 115/12/21 | FF3: 115/12/22 | FG3: 115/12/23 | FH3: 115/12/24 | FI3: 115/12/25 | FJ3: 115/12/26 | FK3: 115/12/27 | FL3: 115/12/28 | FM3: 115/12/29 | FN3: 115/12/30 | FO3: 115/12/31 | FP3: 116/1/1 | FQ3: 116/1/2 | FR3: 116/1/3 | FS3: 116/1/4 | FT3: 116/1/5 | FU3: 116/1/6 | FV3: 116/1/7 | FW3: 116/1/8 | FX3: 116/1/9 | FY3: 116/1/10
B4: 0.02243 | L4: 0.03823 | V4: 0.03741 | AF4: 0.08397 | AP4: 0.07507 | AZ4: 0.005 | BJ4: 0.005 | BT4: 0.005 | CD4: 0.04479 | CN4: 0.15823 | CX4: 0.02564 | DH4: 0.02421 | DR4: 0.02612 | EB4: 0.10923 | EL4: 0.11171 | EV4: 0.08535 | FF4: 0.085 | FP4: 0.0426
A5: 當日權重 | B5: =$B$4/10*1 -> 0.002243 | C5: =$B$4/10*1 -> 0.002243 | D5: =$B$4/10*1 -> 0.002243 | E5: =$B$4/10*1 -> 0.002243 | F5: =$B$4/10*1 -> 0.002243 | G5: =$B$4/10*1 -> 0.002243 | H5: =$B$4/10*1 -> 0.002243 | I5: =$B$4/10*1 -> 0.002243 | ... K5: =$B$4/10*1 -> 0.002243 | L5: =$L$4/10*1 -> 0.003823 | M5: =$L$4/10*1 -> 0.003823 | N5: =$L$4/10*1 -> 0.003823 | O5: =$L$4/10*1 -> 0.003823 | P5: =$L$4/10*1 -> 0.003823 | Q5: =$L$4/10*1 -> 0.003823 | R5: =$L$4/10*1 -> 0.003823 | S5: =$L$4/10*1 -> 0.003823 | ... U5: =$L$4/10*1 -> 0.003823 | V5: =$V$4/10*1 -> 0.003741 | W5: =$V$4/10*1 -> 0.003741 | X5: =$V$4/10*1 -> 0.003741 | Y5: =$V$4/10*1 -> 0.003741 | Z5: =$V$4/10*1 -> 0.003741 | AA5: =$V$4/10*1 -> 0.003741 | AB5: =$V$4/10*1 -> 0.003741 | AC5: =$V$4/10*1 -> 0.003741 | ... AE5: =$V$4/10*1 -> 0.003741 | AF5: =$AF$4/10*1 -> 0.008397 | AG5: =$AF$4/10*1 -> 0.008397 | AH5: =$AF$4/10*1 -> 0.008397 | AI5: =$AF$4/10*1 -> 0.008397 | AJ5: =$AF$4/10*1 -> 0.008397 | AK5: =$AF$4/10*1 -> 0.008397 | AL5: =$AF$4/10*1 -> 0.008397 | AM5: =$AF$4/10*1 -> 0.008397 | ... AO5: =$AF$4/10*1 -> 0.008397 | AP5: =$AP$4/10*1 -> 0.007507 | AQ5: =$AP$4/10*1 -> 0.007507 | AR5: =$AP$4/10*1 -> 0.007507 | AS5: =$AP$4/10*1 -> 0.007507 | AT5: =$AP$4/10*1 -> 0.007507 | AU5: =$AP$4/10*1 -> 0.007507 | AV5: =$AP$4/10*1 -> 0.007507 | AW5: =$AP$4/10*1 -> 0.007507 | ... AY5: =$AP$4/10*1 -> 0.007507 | AZ5: =$AZ$4/10*1 -> 0.0005 | BA5: =$AZ$4/10*1 -> 0.0005 | BB5: =$AZ$4/10*1 -> 0.0005 | BC5: =$AZ$4/10*1 -> 0.0005 | BD5: =$AZ$4/10*1 -> 0.0005 | BE5: =$AZ$4/10*1 -> 0.0005 | BF5: =$AZ$4/10*1 -> 0.0005 | BG5: =$AZ$4/10*1 -> 0.0005 | ... BI5: =$AZ$4/10*1 -> 0.0005 | BJ5: =$BJ$4/10*1 -> 0.0005 | BK5: =$BJ$4/10*1 -> 0.0005 | BL5: =$BJ$4/10*1 -> 0.0005 | BM5: =$BJ$4/10*1 -> 0.0005 | BN5: =$BJ$4/10*1 -> 0.0005 | BO5: =$BJ$4/10*1 -> 0.0005 | BP5: =$BJ$4/10*1 -> 0.0005 | BQ5: =$BJ$4/10*1 -> 0.0005 | ... BS5: =$BJ$4/10*1 -> 0.0005 | BT5: =$BT$4/10*1 -> 0.0005 | BU5: =$BT$4/10*1 -> 0.0005 | BV5: =$BT$4/10*1 -> 0.0005 | BW5: =$BT$4/10*1 -> 0.0005 | BX5: =$BT$4/10*1 -> 0.0005 | BY5: =$BT$4/10*1 -> 0.0005 | BZ5: =$BT$4/10*1 -> 0.0005 | CA5: =$BT$4/10*1 -> 0.0005 | ... CC5: =$BT$4/10*1 -> 0.0005 | CD5: =$CD$4/10*1 -> 0.004479 | CE5: =$CD$4/10*1 -> 0.004479 | CF5: =$CD$4/10*1 -> 0.004479 | CG5: =$CD$4/10*1 -> 0.004479 | CH5: =$CD$4/10*1 -> 0.004479 | CI5: =$CD$4/10*1 -> 0.004479 | CJ5: =$CD$4/10*1 -> 0.004479 | CK5: =$CD$4/10*1 -> 0.004479 | ... CM5: =$CD$4/10*1 -> 0.004479 | CN5: =$CN$4/10*1 -> 0.015823 | CO5: =$CN$4/10*1 -> 0.015823 | CP5: =$CN$4/10*1 -> 0.015823 | CQ5: =$CN$4/10*1 -> 0.015823 | CR5: =$CN$4/10*1 -> 0.015823 | CS5: =$CN$4/10*1 -> 0.015823 | CT5: =$CN$4/10*1 -> 0.015823 | CU5: =$CN$4/10*1 -> 0.015823 | ... CW5: =$CN$4/10*1 -> 0.015823 | CX5: =$CX$4/10*1 -> 0.002564 | CY5: =$CX$4/10*1 -> 0.002564 | CZ5: =$CX$4/10*1 -> 0.002564 | DA5: =$CX$4/10*1 -> 0.002564 | DB5: =$CX$4/10*1 -> 0.002564 | DC5: =$CX$4/10*1 -> 0.002564 | DD5: =$CX$4/10*1 -> 0.002564 | DE5: =$CX$4/10*1 -> 0.002564 | ... DG5: =$CX$4/10*1 -> 0.002564 | DH5: =$DH$4/10*1 -> 0.002421 | DI5: =$DH$4/10*1 -> 0.002421 | DJ5: =$DH$4/10*1 -> 0.002421 | DK5: =$DH$4/10*1 -> 0.002421 | DL5: =$DH$4/10*1 -> 0.002421 | DM5: =$DH$4/10*1 -> 0.002421 | DN5: =$DH$4/10*1 -> 0.002421 | DO5: =$DH$4/10*1 -> 0.002421 | ... DQ5: =$DH$4/10*1 -> 0.002421 | DR5: =$DR$4/10*1 -> 0.002612 | DS5: =$DR$4/10*1 -> 0.002612 | DT5: =$DR$4/10*1 -> 0.002612 | DU5: =$DR$4/10*1 -> 0.002612 | DV5: =$DR$4/10*1 -> 0.002612 | DW5: =$DR$4/10*1 -> 0.002612 | DX5: =$DR$4/10*1 -> 0.002612 | DY5: =$DR$4/10*1 -> 0.002612 | ... EA5: =$DR$4/10*1 -> 0.002612 | EB5: =$EB$4/10*1 -> 0.010923 | EC5: =$EB$4/10*1 -> 0.010923 | ED5: =$EB$4/10*1 -> 0.010923 | EE5: =$EB$4/10*1 -> 0.010923 | EF5: =$EB$4/10*1 -> 0.010923 | EG5: =$EB$4/10*1 -> 0.010923 | EH5: =$EB$4/10*1 -> 0.010923 | EI5: =$EB$4/10*1 -> 0.010923 | ... EK5: =$EB$4/10*1 -> 0.010923 | EL5: =$EL$4/10*1 -> 0.011171 | EM5: =$EL$4/10*1 -> 0.011171 | EN5: =$EL$4/10*1 -> 0.011171 | EO5: =$EL$4/10*1 -> 0.011171 | EP5: =$EL$4/10*1 -> 0.011171 | EQ5: =$EL$4/10*1 -> 0.011171 | ER5: =$EL$4/10*1 -> 0.011171 | ES5: =$EL$4/10*1 -> 0.011171 | ... EU5: =$EL$4/10*1 -> 0.011171 | EV5: =$EV$4/10*1 -> 0.008535 | EW5: =$EV$4/10*1 -> 0.008535 | EX5: =$EV$4/10*1 -> 0.008535 | EY5: =$EV$4/10*1 -> 0.008535 | EZ5: =$EV$4/10*1 -> 0.008535 | FA5: =$EV$4/10*1 -> 0.008535 | FB5: =$EV$4/10*1 -> 0.008535 | FC5: =$EV$4/10*1 -> 0.008535 | ... FE5: =$EV$4/10*1 -> 0.008535 | FF5: =$FF$4/10*1 -> 0.0085 | FG5: =$FF$4/10*1 -> 0.0085 | FH5: =$FF$4/10*1 -> 0.0085 | FI5: =$FF$4/10*1 -> 0.0085 | FJ5: =$FF$4/10*1 -> 0.0085 | FK5: =$FF$4/10*1 -> 0.0085 | FL5: =$FF$4/10*1 -> 0.0085 | FM5: =$FF$4/10*1 -> 0.0085 | ... FO5: =$FF$4/10*1 -> 0.0085 | FP5: =$FP$4/10*1 -> 0.00426 | FQ5: =$FP$4/10*1 -> 0.00426 | FR5: =$FP$4/10*1 -> 0.00426 | FS5: =$FP$4/10*1 -> 0.00426 | FT5: =$FP$4/10*1 -> 0.00426 | FU5: =$FP$4/10*1 -> 0.00426 | FV5: =$FP$4/10*1 -> 0.00426 | FW5: =$FP$4/10*1 -> 0.00426 | ... FY5: =$FP$4/10*1 -> 0.00426
A6: 累積預計 | B6: =B5 -> 0.002243 | C6: =C5+B6 -> 0.004486 | D6: =D5+C6 -> 0.006729 | E6: =E5+D6 -> 0.008972 | F6: =F5+E6 -> 0.011215 | G6: =G5+F6 -> 0.013458 | H6: =H5+G6 -> 0.015701 | I6: =I5+H6 -> 0.017944 | J6: =J5+I6 -> 0.020187 | ... FY6: =FY5+FX6 -> 0.98499
A7: 修正後
