Workbook

Sheet 封面
A4: 雲林縣東勢鄉明倫國民小學
A7: 雲林縣明倫國民小學114-116年公立國民中小學老舊廁所整修工程計畫
A12: 施工日誌
A24: 施工廠商：承昇營造有限公司
A25: 施工日期：115年05月13日~115年05月31日

Sheet 日報
A1: 公共工程施工日誌
A2: 表報編號： | B2: 1
A3: 本日天氣： | B3: 上午： | C3: 晴 | D3: 下午： 晴 | F3: 填表日期： | H3: 46155 | K3: =H3 -> 46155
A4: 工程名稱 | D4: 雲林縣明倫國民小學114-116年公立國民中小學老舊廁所整修工程計畫 | H4: 承攬廠商名稱 | K4: 承昇營造有限公司
A6: 核定工期 | B6: 120日曆天 | D6: 累計工期 | G6: 1 | H6: 剩餘工期 | I6: 119 | K6: 工期展延天數 | M6: 0
A7: 開工日期 | D7: 115年5月13日 | H7: 完工日期 | K7: 115年9月9日
A8: 預定進度(%) | D8: 0.003 | H8: 實際進度(%) | K8: =施工項目!AQ44 -> 0.007658505
A9: 一、依施工計畫書執行按圖施工概況（含約定之重要施工項目及完成數量等）：
A10: 施工項目 | E10: 單位 | F10: 契約數量 | H10: 本日完成數量 | J10: 累計完成數量 | L10: 備註
A11: 設立工程告示牌 | E11: 式 | F11: 1 | H11: 1 | J11: 1
A12: 工程保險 | E12: 式 | F12: 1 | H12: 1 | J12: 1
A13: 申報開工
A20: 營造業專業工程特定施工項目
A21: A.
A22: B.
A23: 二、工地材料管理概況（含約定之重要材料使用狀況及數量等）：
A24: 材料名稱 | E24: 單位 | F24: 設計數量 | H24: 本日使用數量 | J24: 累計使用數量 | L24: 備註
A27: 三、工地人員及機具管理（含約定之出工人數及機具使用情形及數量）：
A28: 工別 | C28: 本日人數 | E28: 累計人數 | H28: 機具名稱 | J28: 本日使用數量 | L28: 累計使用數量
A29: 大工
A30: 小工 | C30: 2 | E30: 2
A31: 四、本日施工項目是否有須依「營造業專業工程特定施工項目應置之技術士種類、比率或人數標準表」規定應設置技術士之專業工程：□有 □無（此項如勾選”有”，則應填寫後附「公共工程施工日誌之技術士簽章表」）
A32: 五、工地職業安全衛生事項之督導、公共環境與安全之維護及其他工地行政事務：
A33: (ㄧ)施工前檢查事項：
A34: 1.實施勤前教育(含工地預防災變及危害告知)：□有 □無
A35: 2.確認新進勞工是否提報勞工保險(或其他商業保險)資料及安全衛生教育訓練紀錄：□有 □無 □無新進勞工
A36: 3.檢查勞工個人防護具：□有 □無
A37: (二)其他事項：
A38: 六、施工取樣試驗紀錄：
A39: 七、通知協力廠商辦理事項：
A40: 八、重要事項記錄：
A41: 簽章：【工地主任】（註3）：
A42: 註：1.依營造業法第32條第1項第2款規定，工地主任應按日填報施工日誌
... A48: 公共工程施工日誌
A49: 表報編號： | B49: =B2+1 -> 2
A50: 本日天氣： | B50: 上午： | C50: 晴 | D50: 下午： 晴 | F50: 填表日期： | H50: =H3+1 -> 46156 | K50: =H50 -> 46156
A51: 工程名稱 | D51: =D4 -> 雲林縣明倫國民小學114-116年公立國民中小學老舊廁所整修工程計畫 | H51: 承攬廠商名稱 | K51: 承昇營造有限公司
A53: 核定工期 | B53: =B6 -> 120日曆天 | D53: 累計工期 | G53: =G6+1 -> 2 | H53: 剩餘工期 | I53: =I6-1 -> 118 | K53: 工期展延天數 | M53: 0
A54: 開工日期 | D54: =D7 -> 115年5月13日 | H54: 完工日期 | K54: =K7 -> 115年9月9日
A55: 預定進度(%) | D55: 0.006 | H55: 實際進度(%) | K55: =施工項目!AQ92 -> 0.008792694
...

Sheet 施工項目
A1: 承昇營造有限公司
A2: 第二聯 | J2: 公共工程施工日誌
A3: 工程名稱： | I3: 雲林縣明倫國民小學114-116年公立國民中小學老舊廁所整修工程計畫 | AO3: 日期： | AW3: 46155
A4: 項次 | E4: 工程項目 | U4: 單位 | Y4: 契約數量 | AE4: 契約單價 | AK4: 本日 完成數量 | AQ4: 本日 完成金額 | AW4: 累計 完成數量 | BC4: 累計 完成金額
A5: =[1]詳細價目表!A2 -> 壹 | E5: =[1]詳細價目表!B2 -> 直接工程費 | BI5: =Y5*AE5 -> 0
A6: =[1]詳細價目表!A3 -> 1 | E6: =[1]詳細價目表!B3 -> 乙種施工圍籬、警示帶、安全警示燈等安全措施(租用) | U6: =[1]詳細價目表!C3 -> 式 | Y6: =[1]詳細價目表!D3 -> 1 | AE6: =[1]詳細價目表!E3 -> 2200 | AK6: 0 | AQ6: =AK6*AE6 -> 0 | AW6: 0 | BC6: =AE6*AW6 -> 0 | BI6: =Y6*AE6 -> 2200
A7: =[1]詳細價目表!A4 -> 2 | E7: =[1]詳細價目表!B4 -> 工程告示牌與職安衛告示牌(租用) | U7: =[1]詳細價目表!C4 -> 式 | Y7: =[1]詳細價目表!D4 -> 1 | AE7: =[1]詳細價目表!E4 -> 6000 | AK7: 1 | AQ7: =AK7*AE7 -> 6000 | AW7: 1 | BC7: =AE7*AW7 -> 6000 | BI7: =Y7*AE7 -> 6000
A8: =[1]詳細價目表!A5 -> 3 | E8: =[1]詳細價目表!B5 -> 施工動線開闢與損壞復原，既有設備管線遷移與復原；測量與放樣 | U8: =[1]詳細價目表!C5 -> 式 | Y8: =[1]詳細價目表!D5 -> 1 | AE8: =[1]詳細價目表!E5 -> 9000 | AK8: 0 | AQ8: =AK8*AE8 -> 0 | AW8: 0 | BC8: =AE8*AW8 -> 0 | BI8: =Y8*AE8 -> 9000
A9: =[1]詳細價目表!A6 -> 4 | E9: =[1]詳細價目表!B6 -> 既有牆面、地坪、磁磚、衛生設備、給排水設施、搗擺及天花板等拆除(含切割)及運棄(含合法證明);環境保護與清潔 | U9: =[1]詳細價目表!C6 -> 式 | Y9: =[1]詳細價目表!D6 -> 1 | AE9: =[1]詳細價目表!E6 -> 214844 | AK9: 0 | AQ9: =AK9*AE9 -> 0 | AW9: =AK9 -> 0 | BC9: =AE9*AW9 -> 0 | BI9: =Y9*AE9 -> 214844
A10: =[1]詳細價目表!A7 -> 5 | E10: =[1]詳細價目表!B7 -> 既有污水處理設施抽水肥(含清潔孔開挖與復原) | U10: =[1]詳細價目表!C7 -> 式 | Y10: =[1]詳細價目表!D7 -> 1 | AE10: =[1]詳細價目表!E7 -> 10000 | AK10: 0 | AQ10: =AK10*AE10 -> 0 | AW10: 0 | BC10: =AE10*AW10 -> 0 | BI10: =Y10*AE10 -> 10000
A11: =[1]詳細價目表!A8 -> 6 | E11: =[1]詳細價目表!B8 -> 地坪與蹲便台階增築 | U11: =[1]詳細價目表!C8 -> 式 | Y11: =[1]詳細價目表!D8 -> 1 | AE11: =[1]詳細價目表!E8 -> 35000 | AK11: 0 | AQ11: =AK11*AE11 -> 0 | AW11: =AK11 -> 0 | BC11: =AE11*AW11 -> 0 | BI11: =Y11*AE11 -> 35000
A12: =[1]詳細價目表!A9 -> 7 | E12: =[1]詳細價目表!B9 -> 砌1/2B磚牆 | U12: =[1]詳細價目表!C9 -> M2 | Y12: =[1]詳細價目表!D9 -> 13 | AE12: =[1]詳細價目表!E9 -> 1500 | AK12: 0 | AQ12: =AK12*AE12 -> 0 | AW12: 0 | BC12: =AE12*AW12 -> 0 | BI12: =Y12*AE12 -> 19500
A13: =[1]詳細價目表!A10 -> 8 | E13: =[1]詳細價目表!B10 -> 施工範圍內樓板穿管處與既有無用穿管及孔洞需以水泥砂漿封閉並刷防水層；樓板防水層試水 | U13: =[1]詳細價目表!C10 -> 式 | Y13: =[1]詳細價目表!D10 -> 1 | AE13: =[1]詳細價目表!E10 -> 9000 | AK13: 0 | AQ13: =AK13*AE13 -> 0 | AW13: 0 | BC13: =AE13*AW13 -> 0 | BI13: =Y13*AE13 -> 9000
A14: =[1]詳細價目表!A11 -> 9 | E14: =[1]詳細價目表!B11 -> 地坪、牆面1:3水泥砂漿粉刷 | U14: =[1]詳細價目表!C11 -> M2 | Y14: =[1]詳細價目表!D11 -> 207 | AE14: =[1]詳細價目表!E11 -> 800 | AK14: 0 | AQ14: =AK14*AE14 -> 0 | AW14: =AK14 -> 0 | BC14: =AE14*AW14 -> 0 | BI14: =Y14*AE14 -> 165600
A15: =[1]詳細價目表!A12 -> 10 | E15: =[1]詳細價目表!B12 -> 地坪及牆面(H=1.5m)塗刷防水層 | U15: =[1]詳細價目表!C12 -> M2 | Y15: =[1]詳細價目表!D12 -> 113 | AE15: =[1]詳細價目表!E12 -> 700 | AK15: 0 | AQ15: =AK15*AE15 -> 0 | AW15: =AK15 -> 0 | BC15: =AE15*AW15 -> 0 | BI15: =Y15*AE15 -> 79100
A16: =[1]詳細價目表!A13 -> 11 | E16: =[1]詳細價目表!B13 -> 安裝不銹鋼方形地板落水頭(10cm*10cm,連工帶料) | U16: =[1]詳細價目表!C13 -> 組 | Y16: =[1]詳細價目表!D13 -> 9 | AE16: =[1]詳細價目表!E13 -> 750 | AK16: 0 | AQ16: =AK16*AE16 -> 0 | AW16: 0 | BC16: =AE16*AW16 -> 0 | BI16: =Y16*AE16 -> 6750
A17: =[1]詳細價目表!A14 -> 12 | E17: =[1]詳細價目表!B14 -> 地坪貼止滑石英磚30cm*30cm，本色水泥勾縫(連工帶料) | U17: =[1]詳細價目表!C14 -> M2 | Y17: =[1]詳細價目表!D14 -> 48 | AE17: =[1]詳細價目表!E14 -> 1300 | AK17: 0 | AQ17: =AK17*AE17 -> 0 | AW17: 0 | BC17: =AE17*AW17 -> 0 | BI17: =Y17*AE17 -> 62400
A18: =[1]詳細價目表!A15 -> 13 | E18: =[1]詳細價目表!B15 -> 地坪貼60cm*60cm止滑石英磚，本色水泥勾縫(連工帶料) | U18: =[1]詳細價目表!C15 -> M2 | Y18: =[1]詳細價目表!D15 -> 2 | AE18: =[1]詳細價目表!E15 -> 1700 | AK18: 0 | AQ18: =AK18*AE18 -> 0 | AW18: 0 | BC18: =AE18*AW18 -> 0 | BI18: =Y18*AE18 -> 3400
A19: =[1]詳細價目表!A16 -> 14 | E19: =[1]詳細價目表!B16 -> 牆面貼數位噴印石英磚30*60cm，白色水泥抹縫(連工帶料) | U19: =[1]詳細價目表!C16 -> M2 | Y19: =[1]詳細價目表!D16 -> 85 | AE19: =[1]詳細價目表!E16 -> 1700 | AK19: 0 | AQ19: =AK19*AE19 -> 0 | AW19: 0 | BC19: =AE19*AW19 -> 0 | BI19: =Y19*AE19 -> 144500
A20: =[1]詳細價目表!A17 -> 15 | E20: =[1]詳細價目表!B17 -> 牆面貼地鐵磚10cm*20cm，白色水泥勾縫(連工帶料) | U20: =[1]詳細價目表!C17 -> M2 | Y20: =[1]詳細價目表!D17 -> 13 | AE20: =[1]詳細價目表!E17 -> 1500 | AK20: 0 | AQ20: =AK20*AE20 -> 0 | AW20: =AK20 -> 0 | BC20: =AE20*AW20 -> 0 | BI20: =Y20*AE20 -> 19500
A21: =[1]詳細價目表!A18 -> 16 | E21: =[1]詳細價目表!B18 -> 安裝鋁合金陽角收邊條 | U21: =[1]詳細價目表!C18 -> M | Y21: =[1]詳細價目表!D18 -> 30 | AE21: =[1]詳細價目表!E18 -> 550 | AK21: 0 | AQ21: =AK21*AE21 -> 0 | AW21: 0 | BC21: =AE21*AW21 -> 0 | BI21: =Y21*AE21 -> 16500
A22: =[1]詳細價目表!A19 -> 17 | E22: =[1]詳細價目表!B19 -> 施做抿石子(1~2分霓虹石，抿石子專用泥) | U22: =[1]詳細價目表!C19 -> M2 | Y22: =[1]詳細價目表!D19 -> 9 | AE22: =[1]詳細價目表!E19 -> 1200 | AK22: 0 | AQ22: =AK22*AE22 -> 0 | AW22: =AK22 -> 0 | BC22: =AE22*AW22 -> 0 | BI22: =Y22*AE22 -> 10800
A23: =[1]詳細價目表!A20 -> 18 | E23: =[1]詳細價目表!B20 -> 牆壁面貼圖案排版釉面馬賽克(方型馬賽克寬1.8cm，12色以上排版，含排版費，白色抺縫，連工帶料) | U23: =[1]詳細價目表!C20 -> 才 | Y23: =[1]詳細價目表!D20 -> 58 | AE23: =[1]詳細價目表!E20 -> 750 | AK23: 0 | AQ23: =AK23*AE23 -> 0 | AW23: =AK23 -> 0 | BC23: =AE23*AW23 -> 0 | BI23: =Y23*AE23 -> 43500
A24: =[1]詳細價目表!A21 -> 19 | E24: =[1]詳細價目表!B21 -> 牆面與平頂塗刷水泥漆(含清潔，批土整平，一底漆二度面漆) | U24: =[1]詳細價目表!C21 -> M2 | Y24: =[1]詳細價目表!D21 -> 82 | AE24: =[1]詳細價目表!E21 -> 200 | AK24: 0 | AQ24: =AK24*AE24 -> 0 | AW24: 0 | BC24: =AE24*AW24 -> 0 | BI24: =Y24*AE24 -> 16400
A25: =[1]詳細價目表!A22 -> 20 | E25: =[1]詳細價目表!B22 -> 安裝13mm熱固性樹脂板隔間含門片(頂面H=200cm以上) | U25: =[1]詳細價目表!C22 -> M2 | Y25: =[1]詳細價目表!D22 -> 38 | AE25: =[1]詳細價目表!E22 -> 3500 | AK25: 0 | AQ25: =AK25*AE25 -> 0 | AW25: =AK25 -> 0 | BC25: =AE25*AW25 -> 0 | BI25: =Y25*AE25 -> 133000
A26: =[1]詳細價目表!A23 -> 21 | E26: =[1]詳細價目表!B23 -> 廁間安裝不鏽鋼掛鈎與置物板 | U26: =[1]詳細價目表!C23 -> 間 | Y26: =[1]詳細價目表!D23 -> 6 | AE26: =[1]詳細價目表!E23 -> 1200 | AK26: 0 | AQ26: =AK26*AE26 -> 0 | AW26: 0 | BC26: =AE26*AW26 -> 0 | BI26: =Y26*AE26 -> 7200
A27: =[1]詳細價目表!A24 -> 22 | E27: =[1]詳細價目表!B24 -> 新設砌磚洗手台 | U27: =[1]詳細價目表!C24 -> 式 | Y27: =[1]詳細價目表!D24 -> 1 | AE27: =[1]詳細價目表!E24 -> 54000 | AK27: 0 | AQ27: =AK27*AE27 -> 0 | AW27: 0 | BC27: =AE27*AW27 -> 0 | BI27: =Y27*AE27 -> 54000
A28: =[1]詳細價目表!A25 -> 23 | E28: =[1]詳細價目表!B25 -> 貼深色石材檯面(t=2cm，倒圓角) | U28: =[1]詳細價目表!C25 -> 才 | Y28: =[1]詳細價目表!D25 -> 4 | AE28: =[1]詳細價目表!E25 -> 750 | AK28: 0 | AQ28: =AK28*AE28 -> 0 | AW28: =AK28 -> 0 | BC28: =AE28*AW28 -> 0 | BI28: =Y28*AE28 -> 3000
A29: =[1]詳細價目表!A26 -> 24 | E29: =[1]詳細價目表!B26 -> 安裝輕鋼架、金屬烤漆透空網與耐燃一級貼皮天花板(含必要之側封板與窗簾盒批土刷漆) | U29: =[1]詳細價目表!C26 -> 式 | Y29: =[1]詳細價目表!D26 -> 1 | AE29: =[1]詳細價目表!E26 -> 53000 | AK29: 0 | AQ29: =AK29*AE29 -> 0 | AW29: 0 | BC29: =AE29*AW29 -> 0 | BI29: =Y29*AE29 -> 53000
A30: =[1]詳細價目表!A27 -> 25 | E30: =[1]詳細價目表!B27 -> 廁所安裝衛生設備(連工帶料) | U30: =[1]詳細價目表!C27 -> 式 | Y30: =[1]詳細價目表!D27 -> 1 | AE30: =[1]詳細價目表!E27 -> 90400 | AK30: 0 | AQ30: =AK30*AE30 -> 0 | AW30: =AK30 -> 0 | BC30: =AE30*AW30 -> 0 | BI30: =Y30*AE30 -> 90400
A31: =[1]詳細價目表!A28 -> 26 | E31: =[1]詳細價目表!B28 -> 安裝開關、插座與燈具(連工帶料) | U31: =[1]詳細價目表!C28 -> 式 | Y31: =[1]詳細價目表!D28 -> 1 | AE31: =[1]詳細價目表!E28 -> 28500 | AK31: 0 | AQ31: =AK31*AE31 -> 0 | AW31: =AK31 -> 0 | BC31: =AE31*AW31 -> 0 | BI31: =Y31*AE31 -> 28500
A32: =[1]詳細價目表!A29 -> 27 | E32: =[1]詳細價目表!B29 -> 給排水系統配管與安裝(連工帶料) | U32: =[1]詳細價目表!C29 -> 式 | Y32: =[1]詳細價目表!D29 -> 1 | AE32: =[1]詳細價目表!E29 -> 80500 | AK32: 0 | AQ32: =AK32*AE32 -> 0 | AW32: 0 | BC32: =AE32*AW32 -> 0 | BI32: =Y32*AE32 -> 80500
A33: =[1]詳細價目表!A30 -> 28 | E33: =[1]詳細價目表!B30 -> 施做緊急求救按鈕(含閃光與蜂嗚警報器、線材、五金配件, 各層樓每間廁所皆有求救鈕，連工帶料，責任施工) | U33: =[1]詳細價目表!C30 -> 式 | Y33: =[1]詳細價目表!D30 -> 1 | AE33: =[1]詳細價目表!E30 -> 12500 | AK33: 0 | AQ33: =AK33*AE33 -> 0 | AW33: =AK33 -> 0 | BC33: =AE33*AW33 -> 0 | BI33: =Y33*AE33 -> 12500
A34: =[1]詳細價目表!A31 -> 29 | E34: =[1]詳細價目表!B31 -> 施做拖布盆(砌磚粉刷貼磁磚，H=30cm) | U34: =[1]詳細價目表!C31 -> 式 | Y34: =[1]詳細價目表!D31 -> 1 | AE34: =[1]詳細價目表!E31 -> 6000 | AK34: 0 | AQ34: =AK34*AE34 -> 0 | AW34: 0 | BC34: =AE34*AW34 -> 0 | BI34: =Y34*AE34 -> 6000
A35: =[1]詳細價目表!A32 -> 30 | E35: =[1]詳細價目表!B32 -> 安裝廁所指標系統、拖把夾(連工帶料，責任施工) | U35: =[1]詳細價目表!C32 -> 式 | Y35: =[1]詳細價目表!D32 -> 1 | AE35: =[1]詳細價目表!E32 -> 16500 | AK35: 0 | AQ35: =AK35*AE35 -> 0 | AW35: =AK35 -> 0 | BC35: =AE35*AW35 -> 0 | BI35: =Y35*AE35 -> 16500
A36: =[1]詳細價目表!A33 -> 31 | E36: =[1]詳細價目表!B33 -> 門窗與雜項工程 | U36: =[1]詳細價目表!C33 -> 式 | Y36: =[1]詳細價目表!D33 -> 1 | AE36: =[1]詳細價目表!E33 -> 63400 | AK36: 0 | AQ36: =AK36*AE36 -> 0 | AW36: 0 | BC36: =AE36*AW36 -> 0 | BI36: =Y36*AE36 -> 63400
A37: =[1]詳細價目表!A35 -> 貳 | E37: =[1]詳細價目表!B35 -> 職業安全衛生管理費(壹*1%) | U37: =[1]詳細價目表!C35 -> 式 | Y37: 1 | AE37: =[1]詳細價目表!E35 -> 14220 | AK37: 0.009 | AQ37: =AK37*AE37 -> 127.98 | AW37: =AK37 -> 0.009 | BC37: =AE37*AW37 -> 127.98 | BI37: =Y37*AE37 -> 14220
A38: =[1]詳細價目表!A36 -> 參 | E38: =[1]詳細價目表!B36 -> 公共工程品質管制作業費(壹*1%) | U38: =[1]詳細價目表!C36 -> 式 | Y38: 1 | AE38: =[1]詳細價目表!E36 -> 14220 | AK38: 0.009 | AQ38: =AK38*AE38 -> 127.98 | AW38: =AK38 -> 0.009 | BC38: =AE38*AW38 -> 127.98 | BI38: =Y38*AE38 -> 14220
A39: =[1]詳細價目表!A37 -> 肆 | E39: =[1]詳細價目表!B37 -> 包商利潤及管理費(約壹*7%) | U39: =[1]詳細價目表!C37 -> 式 | Y39: 1 | AE39: =[1]詳細價目表!E37 -> 99540 | AK39: 0.009 | AQ39: =AK39*AE39 -> 895.86 | AW39: =AK39 -> 0.009 | BC39: =AE39*AW39 -> 895.86 | BI39: =Y39*AE39 -> 99540
A40: =[1]詳細價目表!A38 -> 伍 | E40: =[1]詳細價目表!B38 -> 營造綜合保險費 | U40: =[1]詳細價目表!C38 -> 式 | Y40: 1 | AE40: =[1]詳細價目表!E38 -> 4650 | AK40: 1 | AQ40: =AK40*AE40 -> 4650 | AW40: =AK40 -> 1 | BC40: =AE40*AW40 -> 4650 | BI40: =Y40*AE40 -> 4650
...
