Workbook

Sheet 封面
A1: 雲林縣立林內國民中學
A5: 114-Danas-E-05-01-011-雲林縣林內鄉林內國中射箭場側網毀損修復災後復建工程
A10: 施工日誌
A17: 主辦機關：雲林縣立林內國民中學 監造單位：呂罡銘建築師事務所 承攬廠商：國謙營造有限公司

Sheet 預定進度表
A1: 天數 | B1: 1~10 | C1: 11~20 | D1: 21~30 | E1: 31~40 | F1: 41~50
A2: 天數 | B2: 10 | C2: 10 | D2: 10 | E2: 10 | F2: 10
A3: 單日進度 | B3: =B11/B2 -> 0.5 | C3: =C11/C2 -> 1 | D3: =D11/D2 -> 1.7 | E3: =E11/E2 -> 3.5 | F3: =F11/F2 -> 3.3
A4: 該期進度 | B4: =B2*B3 -> 5 | C4: =C2*C3 -> 10 | D4: =D2*D3 -> 17 | E4: =E2*E3 -> 35 | F4: =F2*F3 -> 33
A5: 累計 | B5: 5 | C5: =B5+C4 -> 15 | D5: =C5+D4 -> 32 | E5: =D5+E4 -> 67 | F5: =E5+F4 -> 100
B11: 5 | C11: 10 | D11: 17 | E11: 35 | F11: 33
B12: 5 | C12: 15 | D12: 32 | E12: 67 | F12: 100

Sheet 日誌
A1: 國謙營造有限公司 | Q1: 國謙營造有限公司 | AG1: 國謙營造有限公司 | AW1: 國謙營造有限公司 | BM1: 國謙營造有限公司 | CC1: 國謙營造有限公司 | CS1: 國謙營造有限公司 | DI1: 國謙營造有限公司 | DY1: 國謙營造有限公司 | EO1: 國謙營造有限公司 | FE1: 國謙營造有限公司 | FU1: 國謙營造有限公司 | GK1: 國謙營造有限公司 | HA1: 國謙營造有限公司 | HQ1: 國謙營造有限公司 | IG1: 國謙營造有限公司 | IW1: 國謙營造有限公司 | JM1: 國謙營造有限公司 | KC1: 國謙營造有限公司 | KS1: 國謙營造有限公司 | LI1: 國謙營造有限公司 | LY1: 國謙營造有限公司
A2: 公共工程施工日誌 | Q2: 公共工程施工日誌 | AG2: 公共工程施工日誌 | AW2: 公共工程施工日誌 | BM2: 公共工程施工日誌 | CC2: 公共工程施工日誌 | CS2: 公共工程施工日誌 | DI2: 公共工程施工日誌 | DY2: 公共工程施工日誌 | EO2: 公共工程施工日誌 | FE2: 公共工程施工日誌 | FU2: 公共工程施工日誌 | GK2: 公共工程施工日誌 | HA2: 公共工程施工日誌 | HQ2: 公共工程施工日誌 | IG2: 公共工程施工日誌 | IW2: 公共工程施工日誌 | JM2: 公共工程施工日誌 | KC2: 公共工程施工日誌 | KS2: 公共工程施工日誌 | LI2: 公共工程施工日誌 | LY2: 公共工程施工日誌
A3: 第一聯 | K3: 編號： | L3: 1 | Q3: 第一聯 | AA3: 編號： | AB3: 2 | AG3: 第一聯 | AQ3: 編號： | AR3: 3 | AW3: 第一聯 | BG3: 編號： | BH3: 4 | BM3: 第一聯 | BW3: 編號： | BX3: 5 | CC3: 第一聯 | CM3: 編號： | CN3: 6 | CS3: 第一聯 | DC3: 編號： | DD3: 7 | DI3: 第一聯 | DS3: 編號： | DT3: 8 | DY3: 第一聯 | EI3: 編號： | EJ3: 9 | EO3: 第一聯 | EY3: 編號： | EZ3: 10 | FE3: 第一聯 | FO3: 編號： | FP3: 11 | FU3: 第一聯 | GE3: 編號： | GF3: 12 | GK3: 第一聯 | GU3: 編號： | GV3: 13 | HA3: 第一聯 | HK3: 編號： | HL3: 14 | HQ3: 第一聯 | IA3: 編號： | IB3: 15 | IG3: 第一聯 | IQ3: 編號： | IR3: 16 | IW3: 第一聯 | JG3: 編號： | JH3: 17 | JM3: 第一聯 | JW3: 編號： | JX3: 18 | KC3: 第一聯 | KM3: 編號： | KN3: 19 | KS3: 第一聯 | LC3: 編號： | LD3: 20 | LI3: 第一聯 | LS3: 編號： | LT3: 21 | LY3: 第一聯 | MI3: 編號： | MJ3: 22
A4: 本日天氣 | B4: 上午：晴 下午：晴 | H4: 填報日期：115年3月11日(星期三) | Q4: 本日天氣 | R4: 上午：晴 下午：晴 | X4: 填報日期：115年3月12日(星期四) | AG4: 本日天氣 | AH4: 上午：晴 下午：晴 | AN4: 填報日期：115年3月13日(星期五) | AW4: 本日天氣 | AX4: 上午：晴 下午：晴 | BD4: 填報日期：115年3月14日(星期六) | BM4: 本日天氣 | BN4: 上午：晴 下午：晴 | BT4: 填報日期：115年3月15日(星期日) | CC4: 本日天氣 | CD4: 上午：晴 下午：晴 | CJ4: 填報日期：115年3月16日(星期一) | CS4: 本日天氣 | CT4: 上午：晴 下午：晴 | CZ4: 填報日期：115年3月17日(星期二) | DI4: 本日天氣 | DJ4: 上午：晴 下午：晴 | DP4: 填報日期：115年3月18日(星期三) | DY4: 本日天氣 | DZ4: 上午：晴 下午：晴 | EF4: 填報日期：115年3月19日(星期四) | EO4: 本日天氣 | EP4: 上午：晴 下午：晴 | EV4: 填報日期：115年3月20日(星期五) | FE4: 本日天氣 | FF4: 上午：晴 下午：晴 | FL4: 填報日期：115年3月21日(星期六) | FU4: 本日天氣 | FV4: 上午：晴 下午：晴 | GB4: 填報日期：115年3月22日(星期日) | GK4: 本日天氣 | GL4: 上午：晴 下午：晴 | GR4: 填報日期：115年3月23日(星期一) | HA4: 本日天氣 | HB4: 上午：晴 下午：晴 | HH4: 填報日期：115年3月24日(星期二) | HQ4: 本日天氣 | HR4: 上午：晴 下午：晴 | HX4: 填報日期：115年3月25日(星期三) | IG4: 本日天氣 | IH4: 上午：晴 下午：晴 | IN4: 填報日期：115年3月26日(星期四) | IW4: 本日天氣 | IX4: 上午：晴 下午：晴 | JD4: 填報日期：115年3月27日(星期五) | JM4: 本日天氣 | JN4: 上午：晴 下午：晴 | JT4: 填報日期：115年3月28日(星期六) | KC4: 本日天氣 | KD4: 上午：晴 下午：晴 | KJ4: 填報日期：115年3月29日(星期日) | KS4: 本日天氣 | KT4: 上午：晴 下午：晴 | KZ4: 填報日期：115年3月30日(星期一) | LI4: 本日天氣 | LJ4: 上午：晴 下午：晴 | LP4: 填報日期：115年3月31日(星期二) | LY4: 本日天氣 | LZ4: 上午：晴 下午：晴 | MF4: 填報日期：115年4月1日(星期三 )
A5: 工程名稱：114-Danas-E-05-01-011-雲林縣林內鄉林內國中射箭場側網毀損修復災後復建工程 | G5: 承攬廠商名稱 | J5: =A1 -> 國謙營造有限公司 | Q5: 工程名稱：114-Danas-E-05-01-011-雲林縣林內鄉林內國中射箭場側網毀損修復災後復建工程 | W5: 承攬廠商名稱 | Z5: =Q1 -> 國謙營造有限公司 | AG5: 工程名稱：114-Danas-E-05-01-011-雲林縣林內鄉林內國中射箭場側網毀損修復災後復建工程 | AM5: 承攬廠商名稱 | AP5: =AG1 -> 國謙營造有限公司 | AW5: 工程名稱：114-Danas-E-05-01-011-雲林縣林內鄉林內國中射箭場側網毀損修復災後復建工程 | BC5: 承攬廠商名稱 | BF5: =AW1 -> 國謙營造有限公司 | BM5: 工程名稱：114-Danas-E-05-01-011-雲林縣林內鄉林內國中射箭場側網毀損修復災後復建工程 | BS5: 承攬廠商名稱 | BV5: =BM1 -> 國謙營造有限公司 | CC5: 工程名稱：114-Danas-E-05-01-011-雲林縣林內鄉林內國中射箭場側網毀損修復災後復建工程 | CI5: 承攬廠商名稱 | CL5: =CC1 -> 國謙營造有限公司 | CS5: 工程名稱：114-Danas-E-05-01-011-雲林縣林內鄉林內國中射箭場側網毀損修復災後復建工程 | CY5: 承攬廠商名稱 | DB5: =CS1 -> 國謙營造有限公司 | DI5: 工程名稱：114-Danas-E-05-01-011-雲林縣林內鄉林內國中射箭場側網毀損修復災後復建工程 | DO5: 承攬廠商名稱 | DR5: =DI1 -> 國謙營造有限公司 | DY5: 工程名稱：114-Danas-E-05-01-011-雲林縣林內鄉林內國中射箭場側網毀損修復災後復建工程 | EE5: 承攬廠商名稱 | EH5: =DY1 -> 國謙營造有限公司 | EO5: 工程名稱：114-Danas-E-05-01-011-雲林縣林內鄉林內國中射箭場側網毀損修復災後復建工程 | EU5: 承攬廠商名稱 | EX5: =EO1 -> 國謙營造有限公司 | FE5: 工程名稱：114-Danas-E-05-01-011-雲林縣林內鄉林內國中射箭場側網毀損修復災後復建工程 | FK5: 承攬廠商名稱 | FN5: =FE1 -> 國謙營造有限公司 | FU5: 工程名稱：114-Danas-E-05-01-011-雲林縣林內鄉林內國中射箭場側網毀損修復災後復建工程 | GA5: 承攬廠商名稱 | GD5: =FU1 -> 國謙營造有限公司 | GK5: 工程名稱：114-Danas-E-05-01-011-雲林縣林內鄉林內國中射箭場側網毀損修復災後復建工程 | GQ5: 承攬廠商名稱 | GT5: =GK1 -> 國謙營造有限公司 | HA5: 工程名稱：114-Danas-E-05-01-011-雲林縣林內鄉林內國中射箭場側網毀損修復災後復建工程 | HG5: 承攬廠商名稱 | HJ5: =HA1 -> 國謙營造有限公司 | HQ5: 工程名稱：114-Danas-E-05-01-011-雲林縣林內鄉林內國中射箭場側網毀損修復災後復建工程 | HW5: 承攬廠商名稱 | HZ5: =HQ1 -> 國謙營造有限公司 | IG5: 工程名稱：114-Danas-E-05-01-011-雲林縣林內鄉林內國中射箭場側網毀損修復災後復建工程 | IM5: 承攬廠商名稱 | IP5: =IG1 -> 國謙營造有限公司 | IW5: 工程名稱：114-Danas-E-05-01-011-雲林縣林內鄉林內國中射箭場側網毀損修復災後復建工程 | JC5: 承攬廠商名稱 | JF5: =IW1 -> 國謙營造有限公司 | JM5: 工程名稱：114-Danas-E-05-01-011-雲林縣林內鄉林內國中射箭場側網毀損修復災後復建工程 | JS5: 承攬廠商名稱 | JV5: =JM1 -> 國謙營造有限公司 | KC5: 工程名稱：114-Danas-E-05-01-011-雲林縣林內鄉林內國中射箭場側網毀損修復災後復建工程 | KI5: 承攬廠商名稱 | KL5: =KC1 -> 國謙營造有限公司 | KS5: 工程名稱：114-Danas-E-05-01-011-雲林縣林內鄉林內國中射箭場側網毀損修復災後復建工程 | KY5: 承攬廠商名稱 | LB5: =KS1 -> 國謙營造有限公司 | LI5: 工程名稱：114-Danas-E-05-01-011-雲林縣林內鄉林內國中射箭場側網毀損修復災後復建工程 | LO5: 承攬廠商名稱 | LR5: =LI1 -> 國謙營造有限公司 | LY5: 工程名稱：114-Danas-E-05-01-011-雲林縣林內鄉林內國中射箭場側網毀損修復災後復建工程 | ME5: 承攬廠商名稱 | MH5: =LY1 -> 國謙營造有限公司
A6: 核定工期 | B6: 50 | C6: 工作天 | D6: 累計工期 | E6: 1 | F6: 天 | G6: 剩餘工期 | H6: =B6-E6 -> 49 | I6: 天 | J6: 工期展延天數 | K6: 0 | L6: 天 | Q6: 核定工期 | R6: 50 | S6: 工作天 | T6: 累計工期 | U6: =AB3 -> 2 | V6: 天 | W6: 剩餘工期 | X6: =R6-U6 -> 48 | Y6: 天 | Z6: 工期展延天數 | AA6: 0 | AB6: 天 | AG6: 核定工期 | AH6: 50 | AI6: 工作天 | AJ6: 累計工期 | AK6: =AR3 -> 3 | AL6: 天 | AM6: 剩餘工期 | AN6: =AH6-AK6 -> 47 | AO6: 天 | AP6: 工期展延天數 | AQ6: 0 | AR6: 天 | AW6: 核定工期 | AX6: 50 | AY6: 工作天 | AZ6: 累計工期 | BA6: =BH3 -> 4 | BB6: 天 | BC6: 剩餘工期 | BD6: =AX6-BA6 -> 46 | BE6: 天 | BF6: 工期展延天數 | BG6: 0 | BH6: 天 | BM6: 核定工期 | BN6: 50 | BO6: 工作天 | BP6: 累計工期 | BQ6: =BX3 -> 5 | BR6: 天 | BS6: 剩餘工期 | BT6: =BN6-BQ6 -> 45 | BU6: 天 | BV6: 工期展延天數 | BW6: 0 | BX6: 天 | CC6: 核定工期 | CD6: 50 | CE6: 工作天 | CF6: 累計工期 | CG6: =CN3 -> 6 | CH6: 天 | CI6: 剩餘工期 | CJ6: =CD6-CG6 -> 44 | CK6: 天 | CL6: 工期展延天數 | CM6: 0 | CN6: 天 | CS6: 核定工期 | CT6: 50 | CU6: 工作天 | CV6: 累計工期 | CW6: =DD3 -> 7 | CX6: 天 | CY6: 剩餘工期 | CZ6: =CT6-CW6 -> 43 | DA6: 天 | DB6: 工期展延天數 | DC6: 0 | DD6: 天 | DI6: 核定工期 | DJ6: 50 | DK6: 工作天 | DL6: 累計工期 | DM6: =DT3 -> 8 | DN6: 天 | DO6: 剩餘工期 | DP6: =DJ6-DM6 -> 42 | DQ6: 天 | DR6: 工期展延天數 | DS6: 0 | DT6: 天 | DY6: 核定工期 | DZ6: 50 | EA6: 工作天 | EB6: 累計工期 | EC6: =EJ3 -> 9 | ED6: 天 | EE6: 剩餘工期 | EF6: =DZ6-EC6 -> 41 | EG6: 天 | EH6: 工期展延天數 | EI6: 0 | EJ6: 天 | EO6: 核定工期 | EP6: 50 | EQ6: 工作天 | ER6: 累計工期 | ES6: =EZ3 -> 10 | ET6: 天 | EU6: 剩餘工期 | EV6: =EP6-ES6 -> 40 | EW6: 天 | EX6: 工期展延天數 | EY6: 0 | EZ6: 天 | FE6: 核定工期 | FF6: 50 | FG6: 工作天 | FH6: 累計工期 | FI6: =FP3 -> 11 | FJ6: 天 | FK6: 剩餘工期 | FL6: =FF6-FI6 -> 39 | FM6: 天 | FN6: 工期展延天數 | FO6: 0 | FP6: 天 | FU6: 核定工期 | FV6: 50 | FW6: 工作天 | FX6: 累計工期 | FY6: =GF3 -> 12 | FZ6: 天 | GA6: 剩餘工期 | GB6: =FV6-FY6 -> 38 | GC6: 天 | GD6: 工期展延天數 | GE6: 0 | GF6: 天 | GK6: 核定工期 | GL6: 50 | GM6: 工作天 | GN6: 累計工期 | GO6: =GV3 -> 13 | GP6: 天 | GQ6: 剩餘工期 | GR6: =GL6-GO6 -> 37 | GS6: 天 | GT6: 工期展延天數 | GU6: 0 | GV6: 天 | HA6: 核定工期 | HB6: 50 | HC6: 工作天 | HD6: 累計工期 | HE6: =HL3 -> 14 | HF6: 天 | HG6: 剩餘工期 | HH6: =HB6-HE6 -> 36 | HI6: 天 | HJ6: 工期展延天數 | HK6: 0 | HL6: 天 | HQ6: 核定工期 | HR6: 50 | HS6: 工作天 | HT6: 累計工期 | HU6: =IB3 -> 15 | HV6: 天 | HW6: 剩餘工期 | HX6: =HR6-HU6 -> 35 | HY6: 天 | HZ6: 工期展延天數 | IA6: 0 | IB6: 天 | IG6: 核定工期 | IH6: 50 | II6: 工作天 | IJ6: 累計工期 | IK6: =IR3 -> 16 | IL6: 天 | IM6: 剩餘工期 | IN6: =IH6-IK6 -> 34 | IO6: 天 | IP6: 工期展延天數 | IQ6: 0 | IR6: 天 | IW6: 核定工期 | IX6: 50 | IY6: 工作天 | IZ6: 累計工期 | JA6: =JH3 -> 17 | JB6: 天 | JC6: 剩餘工期 | JD6: =IX6-JA6 -> 33 | JE6: 天 | JF6: 工期展延天數 | JG6: 0 | JH6: 天 | JM6: 核定工期 | JN6: 50 | JO6: 工作天 | JP6: 累計工期 | JQ6: =JX3 -> 18 | JR6: 天 | JS6: 剩餘工期 | JT6: =JN6-JQ6 -> 32 | JU6: 天 | JV6: 工期展延天數 | JW6: 0 | JX6: 天 | KC6: 核定工期 | KD6: 50 | KE6: 工作天 | KF6: 累計工期 | KG6: =KN3 -> 19 | KH6: 天 | KI6: 剩餘工期 | KJ6: =KD6-KG6 -> 31 | KK6: 天 | KL6: 工期展延天數 | KM6: 0 | KN6: 天 | KS6: 核定工期 | KT6: 50 | KU6: 工作天 | KV6: 累計工期 | KW6: =LD3 -> 20 | KX6: 天 | KY6: 剩餘工期 | KZ6: =KT6-KW6 -> 30 | LA6: 天 | LB6: 工期展延天數 | LC6: 0 | LD6: 天 | LI6: 核定工期 | LJ6: 50 | LK6: 工作天 | LL6: 累計工期 | LM6: =LT3 -> 21 | LN6: 天 | LO6: 剩餘工期 | LP6: =LJ6-LM6 -> 29 | LQ6: 天 | LR6: 工期展延天數 | LS6: 0 | LT6: 天 | LY6: 核定工期 | LZ6: 50 | MA6: 工作天 | MB6: 累計工期 | MC6: =MJ3 -> 22 | MD6: 天 | ME6: 剩餘工期 | MF6: =LZ6-MC6 -> 28 | MG6: 天 | MH6: 工期展延天數 | MI6: 0 | MJ6: 天
A7: 開工日期 | D7: 115年3月11日 | G7: 預計完工日期 | J7: 115年4月29日 | Q7: 開工日期 | T7: 115年3月11日 | W7: 預計完工日期 | Z7: 115年4月29日 | AG7: 開工日期 | AJ7: 115年3月11日 | AM7: 預計完工日期 | AP7: 115年4月29日 | AW7: 開工日期 | AZ7: 115年3月11日 | BC7: 預計完工日期 | BF7: 115年4月29日 | BM7: 開工日期 | BP7: 115年3月11日 | BS7: 預計完工日期 | BV7: 115年4月29日 | CC7: 開工日期 | CF7: 115年3月11日 | CI7: 預計完工日期 | CL7: 115年4月29日 | CS7: 開工日期 | CV7: 115年3月11日 | CY7: 預計完工日期 | DB7: 115年4月29日 | DI7: 開工日期 | DL7: 115年3月11日 | DO7: 預計完工日期 | DR7: 115年4月29日 | DY7: 開工日期 | EB7: 115年3月11日 | EE7: 預計完工日期 | EH7: 115年4月29日 | EO7: 開工日期 | ER7: 115年3月11日 | EU7: 預計完工日期 | EX7: 115年4月29日 | FE7: 開工日期 | FH7: 115年3月11日 | FK7: 預計完工日期 | FN7: 115年4月29日 | FU7: 開工日期 | FX7: 115年3月11日 | GA7: 預計完工日期 | GD7: 115年4月29日 | GK7: 開工日期 | GN7: 115年3月11日 | GQ7: 預計完工日期 | GT7: 115年4月29日 | HA7: 開工日期 | HD7: 115年3月11日 | HG7: 預計完工日期 | HJ7: 115年4月29日 | HQ7: 開工日期 | HT7: 115年3月11日 | HW7: 預計完工日期 | HZ7: 115年4月29日 | IG7: 開工日期 | IJ7: 115年3月11日 | IM7: 預計完工日期 | IP7: 115年4月29日 | IW7: 開工日期 | IZ7: 115年3月11日 | JC7: 預計完工日期 | JF7: 115年4月29日 | JM7: 開工日期 | JP7: 115年3月11日 | JS7: 預計完工日期 | JV7: 115年4月29日 | KC7: 開工日期 | KF7: 115年3月11日 | KI7: 預計完工日期 | KL7: 115年4月29日 | KS7: 開工日期 | KV7: 115年3月11日 | KY7: 預計完工日期 | LB7: 115年4月29日 | LI7: 開工日期 | LL7: 115年3月11日 | LO7: 預計完工日期 | LR7: 115年4月29日 | LY7: 開工日期 | MB7: 115年3月11日 | ME7: 預計完工日期 | MH7: 115年4月29日
A8: 預定進度(%) | D8: =預定進度表!B3 -> 0.5 | G8: 實際進度(%) | J8: =O94 -> 0.001226716 | Q8: 預定進度(%) | T8: =預定進度表!B3+D8 -> 1 | W8: 實際進度(%) | Z8: =AE94 -> 0.014999332 | AG8: 預定進度(%) | AJ8: =預定進度表!B3+T8 -> 1.5 | AM8: 實際進度(%) | AP8: =AU94 -> 0.041317847 | AW8: 預定進度(%) | AZ8: =預定進度表!B3+AJ8 -> 2 | BC8: 實際進度(%) | BF8: =BK94 -> 0.067636362 | BM8: 預定進度(%) | BP8: =預定進度表!B3+AZ8 -> 2.5 | BS8: 實際進度(%) | BV8: =CA94 -> 0.068863078 | CC8: 預定進度(%) | CF8: =預定進度表!B3+BP8 -> 3 | CI8: 實際進度(%) | CL8: =CQ94 -> 0.070089794 | CS8: 預定進度(%) | CV8: =預定進度表!B3+CF8 -> 3.5 | CY8: 實際進度(%) | DB8: =DG94 -> 0.07131651 | DI8: 預定進度(%) | DL8: =預定進度表!B3+CV8 -> 4 | DO8: 實際進度(%) | DR8: =DW94 -> 0.072543226 | DY8: 預定進度(%) | EB8: =預定進度表!B3+DL8 -> 4.5 | EE8: 實際進度(%) | EH8: =EM94 -> 0.073769942 | EO8: 預定進度(%) | ER8: =預定進度表!B3+EB8 -> 5 | EU8: 實際進度(%) | EX8: =FC94 -> 0.074996658 | FE8: 預定進度(%) | FH8: =預定進度表!C3+ER8 -> 6 | FK8: 實際進度(%) | FN8: =FS94 -> 0.076223374 | FU8: 預定進度(%) | FX8: =預定進度表!C3+FH8 -> 7 | GA8: 實際進度(%) | GD8: =GI94 -> 0.07745009 | GK8: 預定進度(%) | GN8: =預定進度表!C3+FX8 -> 8 | GQ8: 實際進度(%) | GT8: =GY94 -> 0.078676806 | HA8: 預定進度(%) | HD8: =預定進度表!B3+GN8 -> 8.5 | HG8: 實際進度(%) | HJ8: =HO94 -> 0.079903522 | HQ8: 預定進度(%) | HT8: =預定進度表!C3+HD8 -> 9.5 | HW8: 實際進度(%) | HZ8: =IE94 -> 0.10738483 | IG8: 預定進度(%) | IJ8: =預定進度表!C3+HT8 -> 10.5 | IM8: 實際進度(%) | IP8: =IU94 -> 0.13486613 | IW8: 預定進度(%) | IZ8: =預定進度表!C3+IJ8 -> 11.5 | JC8: 實際進度(%) | JF8: =JK94 -> 0.16234744 | JM8: 預定進度(%) | JP8: =預定進度表!C3+IZ8 -> 12.5 | JS8: 實際進度(%) | JV8: =KA94 -> 0.18982875 | KC8: 預定進度(%) | KF8: =預定進度表!C3+JP8 -> 13.5 | KI8: 實際進度(%) | KL8: =KQ94 -> 0.21731005 | KS8: 預定進度(%) | KV8: =預定進度表!C3+KF8 -> 14.5 | KY8: 實際進度(%) | LB8: =LG94 -> 0.24479136 | LI8: 預定進度(%) | LL8: =預定進度表!D3+KV8 -> 16.2 | LO8: 實際進度(%) | LR8: =LW94 -> 0.27227266 | LY8: 預定進度(%) | MB8: =預定進度表!D3+LL8 -> 17.9 | ME8: 實際進度(%) | MH8: =MM94 -> 0.29975397
A9: 一、依施工計畫書執行按圖施工概況(含約定之重要施工項目及完成數量等)： | Q9: 一、依施工計畫書執行按圖施工概況(含約定之重要施工項目及完成數量等)： | AG9: 一、依施工計畫書執行按圖施工概況(含約定之重要施工項目及完成數量等)： | AW9: 一、依施工計畫書執行按圖施工概況(含約定之重要施工項目及完成數量等)： | BM9: 一、依施工計畫書執行按圖施工概況(含約定之重要施工項目及完成數量等)： | CC9: 一、依施工計畫書執行按圖施工概況(含約定之重要施工項目及完成數量等)： | CS9: 一、依施工計畫書執行按圖施工概況(含約定之重要施工項目及完成數量等)： | DI9: 一、依施工計畫書執行按圖施工概況(含約定之重要施工項目及完成數量等)： | DY9: 一、依施工計畫書執行按圖施工概況(含約定之重要施工項目及完成數量等)： | EO9: 一、依施工計畫書執行按圖施工概況(含約定之重要施工項目及完成數量等)： | FE9: 一、依施工計畫書執行按圖施工概況(含約定之重要施工項目及完成數量等)： | FU9: 一、依施工計畫書執行按圖施工概況(含約定之重要施工項目及完成數量等)： | GK9: 一、依施工計畫書執行按圖施工概況(含約定之重要施工項目及完成數量等)： | HA9: 一、依施工計畫書執行按圖施工概況(含約定之重要施工項目及完成數量等)： | HQ9: 一、依施工計畫書執行按圖施工概況(含約定之重要施工項目及完成數量等)： | IG9: 一、依施工計畫書執行按圖施工概況(含約定之重要施工項目及完成數量等)： | IW9: 一、依施工計畫書執行按圖施工概況(含約定之重要施工項目及完成數量等)： | JM9: 一、依施工計畫書執行按圖施工概況(含約定之重要施工項目及完成數量等)： | KC9: 一、依施工計畫書執行按圖施工概況(含約定之重要施工項目及完成數量等)： | KS9: 一、依施工計畫書執行按圖施工概況(含約定之重要施工項目及完成數量等)： | LI9: 一、依施工計畫書執行按圖施工概況(含約定之重要施工項目及完成數量等)： | LY9: 一、依施工計畫書執行按圖施工概況(含約定之重要施工項目及完成數量等)：
A10: 施工項目 | D10: 單位 | E10: 契約數量 | G10: 本日完成數量 | J10: 累計完成數量 | K10: 備註 | Q10: 施工項目 | T10: 單位 | U10: 契約數量 | W10: 本日完成數量 | Z10: 累計完成數量 | AA10: 備註 | AG10: 施工項目 | AJ10: 單位 | AK10: 契約數量 | AM10: 本日完成數量 | AP10: 累計完成數量 | AQ10: 備註 | AW10: 施工項目 | AZ10: 單位 | BA10: 契約數量 | BC10: 本日完成數量 | BF10: 累計完成數量 | BG10: 備註 | BM10: 施工項目 | BP10: 單位 | BQ10: 契約數量 | BS10: 本日完成數量 | BV10: 累計完成數量 | BW10: 備註 | CC10: 施工項目 | CF10: 單位 | CG10: 契約數量 | CI10: 本日完成數量 | CL10: 累計完成數量 | CM10: 備註 | CS10: 施工項目 | CV10: 單位 | CW10: 契約數量 | CY10: 本日完成數量 | DB10: 累計完成數量 | DC10: 備註 | DI10: 施工項目 | DL10: 單位 | DM10: 契約數量 | DO10: 本日完成數量 | DR10: 累計完成數量 | DS10: 備註 | DY10: 施工項目 | EB10: 單位 | EC10: 契約數量 | EE10: 本日完成數量 | EH10: 累計完成數量 | EI10: 備註 | EO10: 施工項目 | ER10: 單位 | ES10: 契約數量 | EU10: 本日完成數量 | EX10: 累計完成數量 | EY10: 備註 | FE10: 施工項目 | FH10: 單位 | FI10: 契約數量 | FK10: 本日完成數量 | FN10: 累計完成數量 | FO10: 備註 | FU10: 施工項目 | FX10: 單位 | FY10: 契約數量 | GA10: 本日完成數量 | GD10: 累計完成數量 | GE10: 備註 | GK10: 施工項目 | GN10: 單位 | GO10: 契約數量 | GQ10: 本日完成數量 | GT10: 累計完成數量 | GU10: 備註 | HA10: 施工項目 | HD10: 單位 | HE10: 契約數量 | HG10: 本日完成數量 | HJ10: 累計完成數量 | HK10: 備註 | HQ10: 施工項目 | HT10: 單位 | HU10: 契約數量 | HW10: 本日完成數量 | HZ10: 累計完成數量 | IA10: 備註 | IG10: 施工項目 | IJ10: 單位 | IK10: 契約數量 | IM10: 本日完成數量 | IP10: 累計完成數量 | IQ10: 備註 | IW10: 施工項目 | IZ10: 單位 | JA10: 契約數量 | JC10: 本日完成數量 | JF10: 累計完成數量 | JG10: 備註 | JM10: 施工項目 | JP10: 單位 | JQ10: 契約數量 | JS10: 本日完成數量 | JV10: 累計完成數量 | JW10: 備註 | KC10: 施工項目 | KF10: 單位 | KG10: 契約數量 | KI10: 本日完成數量 | KL10: 累計完成數量 | KM10: 備註 | KS10: 施工項目 | KV10: 單位 | KW10: 契約數量 | KY10: 本日完成數量 | LB10: 累計完成數量 | LC10: 備註 | LI10: 施工項目 | LL10: 單位 | LM10: 契約數量 | LO10: 本日完成數量 | LR10: 累計完成數量 | LS10: 備註 | LY10: 施工項目 | MB10: 單位 | MC10: 契約數量 | ME10: 本日完成數量 | MH10: 累計完成數量 | MI10: 備註
A11: 無施工 | Q11: 既有傾斜高網修復 | T11: M | U11: 30 | W11: =Y65 -> 5 | Z11: =AA65 -> 5 | AG11: 既有傾斜高網修復 | AJ11: M | AK11: 30 | AM11: =AO65 -> 10 | AP11: =AQ65 -> 15 | AW11: 既有傾斜高網修復 | AZ11: M | BA11: 30 | BC11: =BE65 -> 10 | BF11: =BG65 -> 25 | BM11: 廠內備料 | CC11: 廠內備料 | CS11: 廠內備料 | DI11: 廠內備料 | DY11: 廠內備料 | EO11: 廠內備料 | FE11: 廠內備料 | FU11: 廠內備料 | GK11: 廠內備料 | HA11: 廠內備料 | HQ11: 既有3吋鋼管增加斜撐補強 | HT11: 組 | HU11: 22 | HW11: =HY67 -> 1 | HZ11: =IA67 -> 1 | IG11: 既有3吋鋼管增加斜撐補強 | IJ11: 組 | IK11: 22 | IM11: =IO67 -> 1 | IP11: =IQ67 -> 2 | IW11: 既有3吋鋼管增加斜撐補強 | IZ11: 組 | JA11: 22 | JC11: 1 | JF11: =JG67 -> 3 | JM11: 既有3吋鋼管增加斜撐補強 | JP11: 組 | JQ11: 22 | JS11: 1 | JV11: =JW67 -> 4 | KC11: 既有3吋鋼管增加斜撐補強 | KF11: 組 | KG11: 22 | KI11: 1 | KL11: =KM67 -> 5 | KS11: 既有3吋鋼管增加斜撐補強 | KV11: 組 | KW11: 22 | KY11: 1 | LB11: =LC67 -> 6 | LI11: 既有3吋鋼管增加斜撐補強 | LL11: 組 | LM11: 22 | LO11: 1 | LR11: =LS67 -> 7 | LY11: 既有3吋鋼管增加斜撐補強 | MB11: 組 | MC11: 22 | ME11: 1 | MH11: =MI67 -> 8
HQ12: 既有10吋鋼管增加斜撐補強 | HT12: 組 | HU12: 6 | HW12: =HY68 -> 0.2 | HZ12: =IA68 -> 0.2 | IG12: 既有10吋鋼管增加斜撐補強 | IJ12: 組 | IK12: 6 | IM12: =IO68 -> 0.2 | IP12: =IQ68 -> 0.4 | IW12: 既有10吋鋼管增加斜撐補強 | IZ12: 組 | JA12: 6 | JC12: =JE68 -> 0.2 | JF12: =JG68 -> 0.6 | JM12: 既有10吋鋼管增加斜撐補強 | JP12: 組 | JQ12: 6 | JS12: =JU68 -> 0.2 | JV12: =JW68 -> 0.8 | KC12: 既有10吋鋼管增加斜撐補強 | KF12: 組 | KG12: 6 | KI12: =KK68 -> 0.2 | KL12: =KM68 -> 1 | KS12: 既有10吋鋼管增加斜撐補強 | KV12: 組 | KW12: 6 | KY12: =LA68 -> 0.2 | LB12: =LC68 -> 1.2 | LI12: 既有10吋鋼管增加斜撐補強 | LL12: 組 | LM12: 6 | LO12: =LQ68 -> 0.2 | LR12: =LS68 -> 1.4 | LY12: 既有10吋鋼管增加斜撐補強 | MB12: 組 | MC12: 6 | ME12: =MG68 -> 0.2 | MH12: =MI68 -> 1.6
A16: 營造業專業工程特定施工項目 | Q16: 營造業專業工程特定施工項目 | AG16: 營造業專業工程特定施工項目 | AW16: 營造業專業工程特定施工項目 | BM16: 營造業專業工程特定施工項目 | CC16: 營造業專業工程特定施工項目 | CS16: 營造業專業工程特定施工項目 | DI16: 營造業專業工程特定施工項目 | DY16: 營造業專業工程特定施工項目 | EO16: 營造業專業工程特定施工項目 | FE16: 營造業專業工程特定施工項目 | FU16: 營造業專業工程特定施工項目 | GK16: 營造業專業工程特定施工項目 | HA16: 營造業專業工程特定施工項目 | HQ16: 營造業專業工程特定施工項目 | IG16: 營造業專業工程特定施工項目 | IW16: 營造業專業工程特定施工項目 | JM16: 營造業專業工程特定施工項目 | KC16: 營造業專業工程特定施工項目 | KS16: 營造業專業工程特定施工項目 | LI16: 營造業專業工程特定施工項目 | LY16: 營造業專業工程特定施工項目
A17: A. | Q17: A. | AG17: A. | AW17: A. | BM17: A. | CC17: A. | CS17: A. | DI17: A. | DY17: A. | EO17: A. | FE17: A. | FU17: A. | GK17: A. | HA17: A. | HQ17: A. | IG17: A. | IW17: A. | JM17: A. | KC17: A. | KS17: A. | LI17: A. | LY17: A.
A18: B. | Q18: B. | AG18: B. | AW18: B. | BM18: B. | CC18: B. | CS18: B. | DI18: B. | DY18: B. | EO18: B. | FE18: B. | FU18: B. | GK18: B. | HA18: B. | HQ18: B. | IG18: B. | IW18: B. | JM18: B. | KC18: B. | KS18: B. | LI18: B. | LY18: B.
A19: 二、工地材料管理概況(含約定之重要材料使用狀況及數量等)： | Q19: 二、工地材料管理概況(含約定之重要材料使用狀況及數量等)： | AG19: 二、工地材料管理概況(含約定之重要材料使用狀況及數量等)： | AW19: 二、工地材料管理概況(含約定之重要材料使用狀況及數量等)： | BM19: 二、工地材料管理概況(含約定之重要材料使用狀況及數量等)： | CC19: 二、工地材料管理概況(含約定之重要材料使用狀況及數量等)： | CS19: 二、工地材料管理概況(含約定之重要材料使用狀況及數量等)： | DI19: 二、工地材料管理概況(含約定之重要材料使用狀況及數量等)： | DY19: 二、工地材料管理概況(含約定之重要材料使用狀況及數量等)： | EO19: 二、工地材料管理概況(含約定之重要材料使用狀況及數量等)： | FE19: 二、工地材料管理概況(含約定之重要材料使用狀況及數量等)： | FU19: 二、工地材料管理概況(含約定之重要材料使用狀況及數量等)： | GK19: 二、工地材料管理概況(含約定之重要材料使用狀況及數量等)： | HA19: 二、工地材料管理概況(含約定之重要材料使用狀況及數量等)： | HQ19: 二、工地材料管理概況(含約定之重要材料使用狀況及數量等)： | IG19: 二、工地材料管理概況(含約定之重要材料使用狀況及數量等)： | IW19: 二、工地材料管理概況(含約定之重要材料使用狀況及數量等)： | JM19: 二、工地材料管理概況(含約定之重要材料使用狀況及數量等)： | KC19: 二、工地材料管理概況(含約定之重要材料使用狀況及數量等)： | KS19: 二、工地材料管理概況(含約定之重要材料使用狀況及數量等)： | LI19: 二、工地材料管理概況(含約定之重要材料使用狀況及數量等)： | LY19: 二、工地材料管理概況(含約定之重要材料使用狀況及數量等)：
A20: 材料名稱 | D20: 單位 | E20: 設計數量 | G20: 本日使用數量 | J20: 累計使用數量 | K20: 備註 | Q20: 材料名稱 | T20: 單位 | U20: 設計數量 | W20: 本日使用數量 | Z20: 累計使用數量 | AA20: 備註 | AG20: 材料名稱 | AJ20: 單位 | AK20: 設計數量 | AM20: 本日使用數量 | AP20: 累計使用數量 | AQ20: 備註 | AW20: 材料名稱 | AZ20: 單位 | BA20: 設計數量 | BC20: 本日使用數量 | BF20: 累計使用數量 | BG20: 備註 | BM20: 材料名稱 | BP20: 單位 | BQ20: 設計數量 | BS20: 本日使用數量 | BV20: 累計使用數量 | BW20: 備註 | CC20: 材料名稱 | CF20: 單位 | CG20: 設計數量 | CI20: 本日使用數量 | CL20: 累計使用數量 | CM20: 備註 | CS20: 材料名稱 | CV20: 單位 | CW20: 設計數量 | CY20: 本日使用數量 | DB20: 累計使用數量 | DC20: 備註 | DI20: 材料名稱 | DL20: 單位 | DM20: 設計數量 | DO20: 本日使用數量 | DR20: 累計使用數量 | DS20: 備註 | DY20: 材料名稱 | EB20: 單位 | EC20: 設計數量 | EE20: 本日使用數量 | EH20: 累計使用數量 | EI20: 備註 | EO20: 材料名稱 | ER20: 單位 | ES20: 設計數量 | EU20: 本日使用數量 | EX20: 累計使用數量 | EY20: 備註 | FE20: 材料名稱 | FH20: 單位 | FI20: 設計數量 | FK20: 本日使用數量 | FN20: 累計使用數量 | FO20: 備註 | FU20: 材料名稱 | FX20: 單位 | FY20: 設計數量 | GA20: 本日使用數量 | GD20: 累計使用數量 | GE20: 備註 | GK20: 材料名稱 | GN20: 單位 | GO20: 設計數量 | GQ20: 本日使用數量 | GT20: 累計使用數量 | GU20: 備註 | HA20: 材料名稱 | HD20: 單位 | HE20: 設計數量 | HG20: 本日使用數量 | HJ20: 累計使用數量 | HK20: 備註 | HQ20: 材料名稱 | HT20: 單位 | HU20: 設計數量 | HW20: 本日使用數量 | HZ20: 累計使用數量 | IA20: 備註 | IG20: 材料名稱 | IJ20: 單位 | IK20: 設計數量 | IM20: 本日使用數量 | IP20: 累計使用數量 | IQ20: 備註 | IW20: 材料名稱 | IZ20: 單位 | JA20: 設計數量 | JC20: 本日使用數量 | JF20: 累計使用數量 | JG20: 備註 | JM20: 材料名稱 | JP20: 單位 | JQ20: 設計數量 | JS20: 本日使用數量 | JV20: 累計使用數量 | JW20: 備註 | KC20: 材料名稱 | KF20: 單位 | KG20: 設計數量 | KI20: 本日使用數量 | KL20: 累計使用數量 | KM20: 備註 | KS20: 材料名稱 | KV20: 單位 | KW20: 設計數量 | KY20: 本日使用數量 | LB20: 累計使用數量 | LC20: 備註 | LI20: 材料名稱 | LL20: 單位 | LM20: 設計數量 | LO20: 本日使用數量 | LR20: 累計使用數量 | LS20: 備註 | LY20: 材料名稱 | MB20: 單位 | MC20: 設計數量 | ME20: 本日使用數量 | MH20: 累計使用數量 | MI20: 備註
A25: 三、工地人員及機具管理(含約定之出工人數及機具使用情形及數量)： | Q25: 三、工地人員及機具管理(含約定之出工人數及機具使用情形及數量)： | AG25: 三、工地人員及機具管理(含約定之出工人數及機具使用情形及數量)： | AW25: 三、工地人員及機具管理(含約定之出工人數及機具使用情形及數量)： | BM25: 三、工地人員及機具管理(含約定之出工人數及機具使用情形及數量)： | CC25: 三、工地人員及機具管理(含約定之出工人數及機具使用情形及數量)： | CS25: 三、工地人員及機具管理(含約定之出工人數及機具使用情形及數量)： | DI25: 三、工地人員及機具管理(含約定之出工人數及機具使用情形及數量)： | DY25: 三、工地人員及機具管理(含約定之出工人數及機具使用情形及數量)： | EO25: 三、工地人員及機具管理(含約定之出工人數及機具使用情形及數量)： | FE25: 三、工地人員及機具管理(含約定之出工人數及機具使用情形及數量)： | FU25: 三、工地人員及機具管理(含約定之出工人數及機具使用情形及數量)： | GK25: 三、工地人員及機具管理(含約定之出工人數及機具使用情形及數量)： | HA25: 三、工地人員及機具管理(含約定之出工人數及機具使用情形及數量)： | HQ25: 三、工地人員及機具管理(含約定之出工人數及機具使用情形及數量)： | IG25: 三、工地人員及機具管理(含約定之出工人數及機具使用情形及數量)： | IW25: 三、工地人員及機具管理(含約定之出工人數及機具使用情形及數量)： | JM25: 三、工地人員及機具管理(含約定之出工人數及機具使用情形及數量)： | KC25: 三、工地人員及機具管理(含約定之出工人數及機具使用情形及數量)： | KS25: 三、工地人員及機具管理(含約定之出工人數及機具使用情形及數量)： | LI25: 三、工地人員及機具管理(含約定之出工人數及機具使用情形及數量)： | LY25: 三、工地人員及機具管理(含約定之出工人數及機具使用情形及數量)：
A26: 工別 | B26: 本日人數 | D26: 累計人數 | G26: 機具名稱 | J26: 本日使用數量 | K26: 累計使用數量 | Q26: 工別 | R26: 本日人數 | T26: 累計人數 | W26: 機具名稱 | Z26: 本日使用數量 | AA26: 累計使用數量 | AG26: 工別 | AH26: 本日人數 | AJ26: 累計人數 | AM26: 機具名稱 | AP26: 本日使用數量 | AQ26: 累計使用數量 | AW26: 工別 | AX26: 本日人數 | AZ26: 累計人數 | BC26: 機具名稱 | BF26: 本日使用數量 | BG26: 累計使用數量 | BM26: 工別 | BN26: 本日人數 | BP26: 累計人數 | BS26: 機具名稱 | BV26: 本日使用數量 | BW26: 累計使用數量 | CC26: 工別 | CD26: 本日人數 | CF26: 累計人數 | CI26: 機具名稱 | CL26: 本日使用數量 | CM26: 累計使用數量 | CS26: 工別 | CT26: 本日人數 | CV26: 累計人數 | CY26: 機具名稱 | DB26: 本日使用數量 | DC26: 累計使用數量 | DI26: 工別 | DJ26: 本日人數 | DL26: 累計人數 | DO26: 機具名稱 | DR26: 本日使用數量 | DS26: 累計使用數量 | DY26: 工別 | DZ26: 本日人數 | EB26: 累計人數 | EE26: 機具名稱 | EH26: 本日使用數量 | EI26: 累計使用數量 | EO26: 工別 | EP26: 本日人數 | ER26: 累計人數 | EU26: 機具名稱 | EX26: 本日使用數量 | EY26: 累計使用數量 | FE26: 工別 | FF26: 本日人數 | FH26: 累計人數 | FK26: 機具名稱 | FN26: 本日使用數量 | FO26: 累計使用數量 | FU26: 工別 | FV26: 本日人數 | FX26: 累計人數 | GA26: 機具名稱 | GD26: 本日使用數量 | GE26: 累計使用數量 | GK26: 工別 | GL26: 本日人數 | GN26: 累計人數 | GQ26: 機具名稱 | GT26: 本日使用數量 | GU26: 累計使用數量 | HA26: 工別 | HB26: 本日人數 | HD26: 累計人數 | HG26: 機具名稱 | HJ26: 本日使用數量 | HK26: 累計使用數量 | HQ26: 工別 | HR26: 本日人數 | HT26: 累計人數 | HW26: 機具名稱 | HZ26: 本日使用數量 | IA26: 累計使用數量 | IG26: 工別 | IH26: 本日人數 | IJ26: 累計人數 | IM26: 機具名稱 | IP26: 本日使用數量 | IQ26: 累計使用數量 | IW26: 工別 | IX26: 本日人數 | IZ26: 累計人數 | JC26: 機具名稱 | JF26: 本日使用數量 | JG26: 累計使用數量 | JM26: 工別 | JN26: 本日人數 | JP26: 累計人數 | JS26: 機具名稱 | JV26: 本日使用數量 | JW26: 累計使用數量 | KC26: 工別 | KD26: 本日人數 | KF26: 累計人數 | KI26: 機具名稱 | KL26: 本日使用數量 | KM26: 累計使用數量 | KS26: 工別 | KT26: 本日人數 | KV26: 累計人數 | KY26: 機具名稱 | LB26: 本日使用數量 | LC26: 累計使用數量 | LI26: 工別 | LJ26: 本日人數 | LL26: 累計人數 | LO26: 機具名稱 | LR26: 本日使用數量 | LS26: 累計使用數量 | LY26: 工別 | LZ26: 本日人數 | MB26: 累計人數 | ME26: 機具名稱 | MH26: 本日使用數量 | MI26: 累計使用數量
Q27: 鐵工 | R27: 2 | T27: =R27+D27 -> 2 | AG27: 鐵工 | AH27: 2 | AJ27: =AH27+T27 -> 4 | AW27: 鐵工 | AX27: 2 | AZ27: =AX27+AJ27 -> 6 | BM27: 鐵工 | BN27: 0 | BP27: =BN27+AZ27 -> 6 | CC27: 鐵工 | CD27: 0 | CF27: =CD27+BP27 -> 6 | CS27: 鐵工 | CT27: 0 | CV27: =CT27+CF27 -> 6 | DI27: 鐵工 | DJ27: 0 | DL27: =DJ27+CV27 -> 6 | DY27: 鐵工 | DZ27: 0 | EB27: =DZ27+DL27 -> 6 | EO27: 鐵工 | EP27: 0 | ER27: =EP27+EB27 -> 6 | FE27: 鐵工 | FF27: 0 | FH27: =FF27+ER27 -> 6 | FU27: 鐵工 | FV27: 0 | FX27: =FV27+FH27 -> 6 | GK27: 鐵工 | GL27: 0 | GN27: =GL27+FX27 -> 6 | HA27: 鐵工 | HB27: 0 | HD27: =HB27+GN27 -> 6 | HQ27: 鐵工 | HR27: 2 | HT27: =HR27+HD27 -> 8 | HW27: 怪手 | HZ27: 1 | IA27: =HZ27 -> 1 | IG27: 鐵工 | IH27: 2 | IJ27: =IH27+HT27 -> 10 | IM27: 怪手 | IP27: 1 | IQ27: =IP27+IA27 -> 2 | IW27: 鐵工 | IX27: 2 | IZ27: =IX27+IJ27 -> 12 | JC27: 怪手 | JF27: 0 | JG27: =JF27+IQ27 -> 2 | JM27: 鐵工 | JN27: 2 | JP27: =JN27+IZ27 -> 14 | JS27: 怪手 | JV27: 0 | JW27: =JV27+JG27 -> 2 | KC27: 鐵工 | KD27: 2 | KF27: =KD27+JP27 -> 16 | KI27: 怪手 | KL27: 0 | KM27: =KL27+JW27 -> 2 | KS27: 鐵工 | KT27: 2 | KV27: =KT27+KF27 -> 18 | KY27: 怪手 | LB27: 0 | LC27: =LB27+KM27 -> 2 | LI27: 鐵工 | LJ27: 2 | LL27: =LJ27+KV27 -> 20 | LO27: 怪手 | LR27: 0 | LS27: =LR27+LC27 -> 2 | LY27: 鐵工 | LZ27: 2 | MB27: =LZ27+LL27 -> 22 | ME27: 怪手 | MH27: 0 | MI27: =MH27+LS27 -> 2
A32: 四、本日施工項目是否有須依「營造業專業工程特定施工項目應置之技術士種類、比率或人數標準表」規定應設置技術士之專業工程：□有 □無（此項如勾選"有"，則應填寫後附「公共工程施工日誌之技術士簽章表」） | Q32: 四、本日施工項目是否有須依「營造業專業工程特定施工項目應置之技術士種類、比率或人數標準表」規定應設置技術士之專業工程：□有 □無（此項如勾選"有"，則應填寫後附「公共工程施工日誌之技術士簽章表」） | AG32: 四、本日施工項目是否有須依「營造業專業工程特定施工項目應置之技術士種類、比率或人數標準表」規定應設置技術士之專業工程：□有 □無（此項如勾選"有"，則應填寫後附「公共工程施工日誌之技術士簽章表」） | AW32: 四、本日施工項目是否有須依「營造業專業工程特定施工項目應置之技術士種類、比率或人數標準表」規定應設置技術士之專業工程：□有 □無（此項如勾選"有"，則應填寫後附「公共工程施工日誌之技術士簽章表」） | BM32: 四、本日施工項目是否有須依「營造業專業工程特定施工項目應置之技術士種類、比率或人數標準表」規定應設置技術士之專業工程：□有 □無（此項如勾選"有"，則應填寫後附「公共工程施工日誌之技術士簽章表」） | CC32: 四、本日施工項目是否有須依「營造業專業工程特定施工項目應置之技術士種類、比率或人數標準表」規定應設置技術士之專業工程：□有 □無（此項如勾選"有"，則應填寫後附「公共工程施工日誌之技術士簽章表」） | CS32: 四、本日施工項目是否有須依「營造業專業工程特定施工項目應置之技術士種類、比率或人數標準表」規定應設置技術士之專業工程：□有 □無（此項如勾選"有"，則應填寫後附「公共工程施工日誌之技術士簽章表」） | DI32: 四、本日施工項目是否有須依「營造業專業工程特定施工項目應置之技術士種類、比率或人數標準表」規定應設置技術士之專業工程：□有 □無（此項如勾選"有"，則應填寫後附「公共工程施工日誌之技術士簽章表」） | DY32: 四、本日施工項目是否有須依「營造業專業工程特定施工項目應置之技術士種類、比率或人數標準表」規定應設置技術士之專業工程：□有 □無（此項如勾選"有"，則應填寫後附「公共工程施工日誌之技術士簽章表」） | EO32: 四、本日施工項目是否有須依「營造業專業工程特定施工項目應置之技術士種類、比率或人數標準表」規定應設置技術士之專業工程：□有 □無（此項如勾選"有"，則應填寫後附「公共工程施工日誌之技術士簽章表」） | FE32: 四、本日施工項目是否有須依「營造業專業工程特定施工項目應置之技術士種類、比率或人數標準表」規定應設置技術士之專業工程：□有 □無（此項如勾選"有"，則應填寫後附「公共工程施工日誌之技術士簽章表」） | FU32: 四、本日施工項目是否有須依「營造業專業工程特定施工項目應置之技術士種類、比率或人數標準表」規定應設置技術士之專業工程：□有 □無（此項如勾選"有"，則應填寫後附「公共工程施工日誌之技術士簽章表」） | GK32: 四、本日施工項目是否有須依「營造業專業工程特定施工項目應置之技術士種類、比率或人數標準表」規定應設置技術士之專業工程：□有 □無（此項如勾選"有"，則應填寫後附「公共工程施工日誌之技術士簽章表」） | HA32: 四、本日施工項目是否有須依「營造業專業工程特定施工項目應置之技術士種類、比率或人數標準表」規定應設置技術士之專業工程：□有 □無（此項如勾選"有"，則應填寫後附「公共工程施工日誌之技術士簽章表」） | HQ32: 四、本日施工項目是否有須依「營造業專業工程特定施工項目應置之技術士種類、比率或人數標準表」規定應設置技術士之專業工程：□有 □無（此項如勾選"有"，則應填寫後附「公共工程施工日誌之技術士簽章表」） | IG32: 四、本日施工項目是否有須依「營造業專業工程特定施工項目應置之技術士種類、比率或人數標準表」規定應設置技術士之專業工程：□有 □無（此項如勾選"有"，則應填寫後附「公共工程施工日誌之技術士簽章表」） | IW32: 四、本日施工項目是否有須依「營造業專業工程特定施工項目應置之技術士種類、比率或人數標準表」規定應設置技術士之專業工程：□有 □無（此項如勾選"有"，則應填寫後附「公共工程施工日誌之技術士簽章表」） | JM32: 四、本日施工項目是否有須依「營造業專業工程特定施工項目應置之技術士種類、比率或人數標準表」規定應設置技術士之專業工程：□有 □無（此項如勾選"有"，則應填寫後附「公共工程施工日誌之技術士簽章表」） | KC32: 四、本日施工項目是否有須依「營造業專業工程特定施工項目應置之技術士種類、比率或人數標準表」規定應設置技術士之專業工程：□有 □無（此項如勾選"有"，則應填寫後附「公共工程施工日誌之技術士簽章表」） | KS32: 四、本日施工項目是否有須依「營造業專業工程特定施工項目應置之技術士種類、比率或人數標準表」規定應設置技術士之專業工程：□有 □無（此項如勾選"有"，則應填寫後附「公共工程施工日誌之技術士簽章表」） | LI32: 四、本日施工項目是否有須依「營造業專業工程特定施工項目應置之技術士種類、比率或人數標準表」規定應設置技術士之專業工程：□有 □無（此項如勾選"有"，則應填寫後附「公共工程施工日誌之技術士簽章表」） | LY32: 四、本日施工項目是否有須依「營造業專業工程特定施工項目應置之技術士種類、比率或人數標準表」規定應設置技術士之專業工程：□有 □無（此項如勾選"有"，則應填寫後附「公共工程施工日誌之技術士簽章表」）
A35: 五、工地職業安全衛生事項之督導、公共環境與安全之維護及其他工地行政事務： (一)施工前檢查事項: 1.實施勤前教育(含工地預防災變及危害告知)：□有 □無 2.確認新進勞工是否提報勞工保險(或其他商業保險)資料及安全衛生教育訓練紀錄： □有 □無 □無新進勞工 3.檢查勞工個人防護具：□有 □無 (二)其他事項： | Q35: 五、工地職業安全衛生事項之督導、公共環境與安全之維護及其他工地行政事務： (一)施工前檢查事項: 1.實施勤前教育(含工地預防災變及危害告知)：□有 □無 2.確認新進勞工是否提報勞工保險(或其他商業保險)資料及安全衛生教育訓練紀錄： □有 □無 □無新進勞工 3.檢查勞工個人防護具：□有 □無 (二)其他事項： | AG35: 五、工地職業安全衛生事項之督導、公共環境與安全之維護及其他工地行政事務： (一)施工前檢查事項: 1.實施勤前教育(含工地預防災變及危害告知)：□有 □無 2.確認新進勞工是否提報勞工保險(或其他商業保險)資料及安全衛生教育訓練紀錄： □有 □無 □無新進勞工 3.檢查勞工個人防護具：□有 □無 (二)其他事項： | AW35: 五、工地職業安全衛生事項之督導、公共環境與安全之維護及其他工地行政事務： (一)施工前檢查事項: 1.實施勤前教育(含工地預防災變及危害告知)：□有 □無 2.確認新進勞工是否提報勞工保險(或其他商業保險)資料及安全衛生教育訓練紀錄： □有 □無 □無新進勞工 3.檢查勞工個人防護具：□有 □無 (二)其他事項： | BM35: 五、工地職業安全衛生事項之督導、公共環境與安全之維護及其他工地行政事務： (一)施工前檢查事項: 1.實施勤前教育(含工地預防災變及危害告知)：□有 □無 2.確認新進勞工是否提報勞工保險(或其他商業保險)資料及安全衛生教育訓練紀錄： □有 □無 □無新進勞工 3.檢查勞工個人防護具：□有 □無 (二)其他事項： | CC35: 五、工地職業安全衛生事項之督導、公共環境與安全之維護及其他工地行政事務： (一)施工前檢查事項: 1.實施勤前教育(含工地預防災變及危害告知)：□有 □無 2.確認新進勞工是否提報勞工保險(或其他商業保險)資料及安全衛生教育訓練紀錄： □有 □無 □無新進勞工 3.檢查勞工個人防護具：□有 □無 (二)其他事項： | CS35: 五、工地職業安全衛生事項之督導、公共環境與安全之維護及其他工地行政事務： (一)施工前檢查事項: 1.實施勤前教育(含工地預防災變及危害告知)：□有 □無 2.確認新進勞工是否提報勞工保險(或其他商業保險)資料及安全衛生教育訓練紀錄： □有 □無 □無新進勞工 3.檢查勞工個人防護具：□有 □無 (二)其他事項： | DI35: 五、工地職業安全衛生事項之督導、公共環境與安全之維護及其他工地行政事務： (一)施工前檢查事項: 1.實施勤前教育(含工地預防災變及危害告知)：□有 □無 2.確認新進勞工是否提報勞工保險(或其他商業保險)資料及安全衛生教育訓練紀錄： □有 □無 □無新進勞工 3.檢查勞工個人防護具：□有 □無 (二)其他事項： | DY35: 五、工地職業安全衛生事項之督導、公共環境與安全之維護及其他工地行政事務： (一)施工前檢查事項: 1.實施勤前教育(含工地預防災變及危害告知)：□有 □無 2.確認新進勞工是否提報勞工保險(或其他商業保險)資料及安全衛生教育訓練紀錄： □有 □無 □無新進勞工 3.檢查勞工個人防護具：□有 □無 (二)其他事項： | EO35: 五、工地職業安全衛生事項之督導、公共環境與安全之維護及其他工地行政事務： (一)施工前檢查事項: 1.實施勤前教育(含工地預防災變及危害告知)：□有 □無 2.確認新進勞工是否提報勞工保險(或其他商業保險)資料及安全衛生教育訓練紀錄： □有 □無 □無新進勞工 3.檢查勞工個人防護具：□有 □無 (二)其他事項： | FE35: 五、工地職業安全衛生事項之督導、公共環境與安全之維護及其他工地行政事務： (一)施工前檢查事項: 1.實施勤前教育(含工地預防災變及危害告知)：□有 □無 2.確認新進勞工是否提報勞工保險(或其他商業保險)資料及安全衛生教育訓練紀錄： □有 □無 □無新進勞工 3.檢查勞工個人防護具：□有 □無 (二)其他事項： | FU35: 五、工地職業安全衛生事項之督導、公共環境與安全之維護及其他工地行政事務： (一)施工前檢查事項: 1.實施勤前教育(含工地預防災變及危害告知)：□有 □無 2.確認新進勞工是否提報勞工保險(或其他商業保險)資料及安全衛生教育訓練紀錄： □有 □無 □無新進勞工 3.檢查勞工個人防護具：□有 □無 (二)其他事項： | GK35: 五、工地職業安全衛生事項之督導、公共環境與安全之維護及其他工地行政事務： (一)施工前檢查事項: 1.實施勤前教育(含工地預防災變及危害告知)：□有 □無 2.確認新進勞工是否提報勞工保險(或其他商業保險)資料及安全衛生教育訓練紀錄： □有 □無 □無新進勞工 3.檢查勞工個人防護具：□有 □無 (二)其他事項： | HA35: 五、工地職業安全衛生事項之督導、公共環境與安全之維護及其他工地行政事務： (一)施工前檢查事項: 1.實施勤前教育(含工地預防災變及危害告知)：□有 □無 2.確認新進勞工是否提報勞工保險(或其他商業保險)資料及安全衛生教育訓練紀錄： □有 □無 □無新進勞工 3.檢查勞工個人防護具：□有 □無 (二)其他事項： | HQ35: 五、工地職業安全衛生事項之督導、公共環境與安全之維護及其他工地行政事務： (一)施工前檢查事項: 1.實施勤前教育(含工地預防災變及危害告知)：□有 □無 2.確認新進勞工是否提報勞工保險(或其他商業保險)資料及安全衛生教育訓練紀錄： □有 □無 □無新進勞工 3.檢查勞工個人防護具：□有 □無 (二)其他事項： | IG35: 五、工地職業安全衛生事項之督導、公共環境與安全之維護及其他工地行政事務： (一)施工前檢查事項: 1.實施勤前教育(含工地預防災變及危害告知)：□有 □無 2.確認新進勞工是否提報勞工保險(或其他商業保險)資料及安全衛生教育訓練紀錄： □有 □無 □無新進勞工 3.檢查勞工個人防護具：□有 □無 (二)其他事項： | IW35: 五、工地職業安全衛生事項之督導、公共環境與安全之維護及其他工地行政事務： (一)施工前檢查事項: 1.實施勤前教育(含工地預防災變及危害告知)：□有 □無 2.確認新進勞工是否提報勞工保險(或其他商業保險)資料及安全衛生教育訓練紀錄： □有 □無 □無新進勞工 3.檢查勞工個人防護具：□有 □無 (二)其他事項： | JM35: 五、工地職業安全衛生事項之督導、公共環境與安全之維護及其他工地行政事務： (一)施工前檢查事項: 1.實施勤前教育(含工地預防災變及危害告知)：□有 □無 2.確認新進勞工是否提報勞工保險(或其他商業保險)資料及安全衛生教育訓練紀錄： □有 □無 □無新進勞工 3.檢查勞工個人防護具：□有 □無 (二)其他事項： | KC35: 五、工地職業安全衛生事項之督導、公共環境與安全之維護及其他工地行政事務： (一)施工前檢查事項: 1.實施勤前教育(含工地預防災變及危害告知)：□有 □無 2.確認新進勞工是否提報勞工保險(或其他商業保險)資料及安全衛生教育訓練紀錄： □有 □無 □無新進勞工 3.檢查勞工個人防護具：□有 □無 (二)其他事項： | KS35: 五、工地職業安全衛生事項之督導、公共環境與安全之維護及其他工地行政事務： (一)施工前檢查事項: 1.實施勤前教育(含工地預防災變及危害告知)：□有 □無 2.確認新進勞工是否提報勞工保險(或其他商業保險)資料及安全衛生教育訓練紀錄： □有 □無 □無新進勞工 3.檢查勞工個人防護具：□有 □無 (二)其他事項： | LI35: 五、工地職業安全衛生事項之督導、公共環境與安全之維護及其他工地行政事務： (一)施工前檢查事項: 1.實施勤前教育(含工地預防災變及危害告知)：□有 □無 2.確認新進勞工是否提報勞工保險(或其他商業保險)資料及安全衛生教育訓練紀錄： □有 □無 □無新進勞工 3.檢查勞工個人防護具：□有 □無 (二)其他事項： | LY35: 五、工地職業安全衛生事項之督導、公共環境與安全之維護及其他工地行政事務： (一)施工前檢查事項: 1.實施勤前教育(含工地預防災變及危害告知)：□有 □無 2.確認新進勞工是否提報勞工保險(或其他商業保險)資料及安全衛生教育訓練紀錄： □有 □無 □無新進勞工 3.檢查勞工個人防護具：□有 □無 (二)其他事項：
A42: 六、施工取樣試驗紀錄： | Q42: 六、施工取樣試驗紀錄： | AG42: 六、施工取樣試驗紀錄： | AW42: 六、施工取樣試驗紀錄： | BM42: 六、施工取樣試驗紀錄： | CC42: 六、施工取樣試驗紀錄： | CS42: 六、施工取樣試驗紀錄： | DI42: 六、施工取樣試驗紀錄： | DY42: 六、施工取樣試驗紀錄： | EO42: 六、施工取樣試驗紀錄： | FE42: 六、施工取樣試驗紀錄： | FU42: 六、施工取樣試驗紀錄： | GK42: 六、施工取樣試驗紀錄： | HA42: 六、施工取樣試驗紀錄： | HQ42: 六、施工取樣試驗紀錄： | IG42: 六、施工取樣試驗紀錄： | IW42: 六、施工取樣試驗紀錄： | JM42: 六、施工取樣試驗紀錄： | KC42: 六、施工取樣試驗紀錄： | KS42: 六、施工取樣試驗紀錄： | LI42: 六、施工取樣試驗紀錄： | LY42: 六、施工取樣試驗紀錄：
A43: 七、通知協力廠商辦理事項： | Q43: 七、通知協力廠商辦理事項： | AG43: 七、通知協力廠商辦理事項： | AW43: 七、通知協力廠商辦理事項： | BM43: 七、通知協力廠商辦理事項： | CC43: 七、通知協力廠商辦理事項： | CS43: 七、通知協力廠商辦理事項： | DI43: 七、通知協力廠商辦理事項： | DY43: 七、通知協力廠商辦理事項： | EO43: 七、通知協力廠商辦理事項： | FE43: 七、通知協力廠商辦理事項： | FU43: 七、通知協力廠商辦理事項： | GK43: 七、通知協力廠商辦理事項： | HA43: 七、通知協力廠商辦理事項： | HQ43: 七、通知協力廠商辦理事項： | IG43: 七、通知協力廠商辦理事項： | IW43: 七、通知協力廠商辦理事項： | JM43: 七、通知協力廠商辦理事項： | KC43: 七、通知協力廠商辦理事項： | KS43: 七、通知協力廠商辦理事項： | LI43: 七、通知協力廠商辦理事項： | LY43: 七、通知協力廠商辦理事項：
A44: 八、重要事項紀錄：配合校方訓練需求延後一日進場施工 | Q44: 八、重要事項紀錄： | AG44: 八、重要事項紀錄： | AW44: 八、重要事項紀錄： | BM44: 八、重要事項紀錄：本日無施工 | CC44: 八、重要事項紀錄：本日無施工 | CS44: 八、重要事項紀錄：本日無施工 | DI44: 八、重要事項紀錄：本日無施工 | DY44: 八、重要事項紀錄：本日無施工 | EO44: 八、重要事項紀錄：本日無施工 | FE44: 八、重要事項紀錄：本日無施工 | FU44: 八、重要事項紀錄：本日無施工 | GK44: 八、重要事項紀錄：本日無施工 | HA44: 八、重要事項紀錄：本日無施工 | HQ44: 八、重要事項紀錄： | IG44: 八、重要事項紀錄： | IW44: 八、重要事項紀錄： | JM44: 八、重要事項紀錄： | KC44: 八、重要事項紀錄： | KS44: 八、重要事項紀錄：本日無施工 | LI44: 八、重要事項紀錄： | LY44: 八、重要事項紀錄：
A45: 填表人（簽名，註5）： | Q45: 填表人（簽名，註5）： | AG45: 填表人（簽名，註5）： | AW45: 填表人（簽名，註5）： | BM45: 填表人（簽名，註5）： | CC45: 填表人（簽名，註5）： | CS45: 填表人（簽名，註5）： | DI45: 填表人（簽名，註5）： | DY45: 填表人（簽名，註5）： | EO45: 填表人（簽名，註5）： | FE45: 填表人（簽名，註5）： | FU45: 填表人（簽名，註5）： | GK45: 填表人（簽名，註5）： | HA45: 填表人（簽名，註5）： | HQ45: 填表人（簽名，註5）： | IG45: 填表人（簽名，註5）： | IW45: 填表人（簽名，註5）： | JM45: 填表人（簽名，註5）： | KC45: 填表人（簽名，註5）： | KS45: 填表人（簽名，註5）： | LI45: 填表人（簽名，註5）： | LY45: 填表人（簽名，註5）：
A46: 註：1.本施工日誌應按日提報，材料名稱應與契約書內單價分析表一致，並依核定之施工計畫書規定填報。本施工日誌分為二聯，填寫一式三份 | Q46: 註：1.本施工日誌應按日提報，材料名稱應與契約書內單價分析表一致，並依核定之施工計畫書規定填報。本施工日誌分為二聯，填寫一式三份 | AG46: 註：1.本施工日誌應按日提報，材料名稱應與契約書內單價分析表一致，並依核定之施工計畫書規定填報。本施工日誌分為二聯，填寫一式三份 | AW46: 註：1.本施工日誌應按日提報，材料名稱應與契約書內單價分析表一致，並依核定之施工計畫書規定填報。本施工日誌分為二聯，填寫一式三份 | BM46: 註：1.本施工日誌應按日提報，材料名稱應與契約書內單價分析表一致，並依核定之施工計畫書規定填報。本施工日誌分為二聯，填寫一式三份 | CC46: 註：1.本施工日誌應按日提報，材料名稱應與契約書內單價分析表一致，並依核定之施工計畫書規定填報。本施工日誌分為二聯，填寫一式三份 | CS46: 註：1.本施工日誌應按日提報，材料名稱應與契約書內單價分析表一致，並依核定之施工計畫書規定填報。本施工日誌分為二聯，填寫一式三份 | DI46: 註：1.本施工日誌應按日提報，材料名稱應與契約書內單價分析表一致，並依核定之施工計畫書規定填報。本施工日誌分為二聯，填寫一式三份 | DY46: 註：1.本施工日誌應按日提報，材料名稱應與契約書內單價分析表一致，並依核定之施工計畫書規定填報。本施工日誌分為二聯，填寫一式三份 | EO46: 註：1.本施工日誌應按日提報，材料名稱應與契約書內單價分析表一致，並依核定之施工計畫書規定填報。本施工日誌分為二聯，填寫一式三份 | FE46: 註：1.本施工日誌應按日提報，材料名稱應與契約書內單價分析表一致，並依核定之施工計畫書規定填報。本施工日誌分為二聯，填寫一式三份 | FU46: 註：1.本施工日誌應按日提報，材料名稱應與契約書內單價分析表一致，並依核定之施工計畫書規定填報。本施工日誌分為二聯，填寫一式三份 | GK46: 註：1.本施工日誌應按日提報，材料名稱應與契約書內單價分析表一致，並依核定之施工計畫書規定填報。本施工日誌分為二聯，填寫一式三份 | HA46: 註：1.本施工日誌應按日提報，材料名稱應與契約書內單價分析表一致，並依核定之施工計畫書規定填報。本施工日誌分為二聯，填寫一式三份 | HQ46: 註：1.本施工日誌應按日提報，材料名稱應與契約書內單價分析表一致，並依核定之施工計畫書規定填報。本施工日誌分為二聯，填寫一式三份 | IG46: 註：1.本施工日誌應按日提報，材料名稱應與契約書內單價分析表一致，並依核定之施工計畫書規定填報。本施工日誌分為二聯，填寫一式三份 | IW46: 註：1.本施工日誌應按日提報，材料名稱應與契約書內單價分析表一致，並依核定之施工計畫書規定填報。本施工日誌分為二聯，填寫一式三份 | JM46: 註：1.本施工日誌應按日提報，材料名稱應與契約書內單價分析表一致，並依核定之施工計畫書規定填報。本施工日誌分為二聯，填寫一式三份 | KC46: 註：1.本施工日誌應按日提報，材料名稱應與契約書內單價分析表一致，並依核定之施工計畫書規定填報。本施工日誌分為二聯，填寫一式三份 | KS46: 註：1.本施工日誌應按日提報，材料名稱應與契約書內單價分析表一致，並依核定之施工計畫書規定填報。本施工日誌分為二聯，填寫一式三份 | LI46: 註：1.本施工日誌應按日提報，材料名稱應與契約書內單價分析表一致，並依核定之施工計畫書規定填報。本施工日誌分為二聯，填寫一式三份 | LY46: 註：1.本施工日誌應按日提報，材料名稱應與契約書內單價分析表一致，並依核定之施工計畫書規定填報。本施工日誌分為二聯，填寫一式三份
A47: ，廠商及監造單位各留存一份隨時備查，一份送主辦機關。 | Q47: ，廠商及監造單位各留存一份隨時備查，一份送主辦機關。 | AG47: ，廠商及監造單位各留存一份隨時備查，一份送主辦機關。 | AW47: ，廠商及監造單位各留存一份隨時備查，一份送主辦機關。 | BM47: ，廠商及監造單位各留存一份隨時備查，一份送主辦機關。 | CC47: ，廠商及監造單位各留存一份隨時備查，一份送主辦機關。 | CS47: ，廠商及監造單位各留存一份隨時備查，一份送主辦機關。 | DI47: ，廠商及監造單位各留存一份隨時備查，一份送主辦機關。 | DY47: ，廠商及監造單位各留存一份隨時備查，一份送主辦機關。 | EO47: ，廠商及監造單位各留存一份隨時備查，一份送主辦機關。 | FE47: ，廠商及監造單位各留存一份隨時備查，一份送主辦機關。 | FU47: ，廠商及監造單位各留存一份隨時備查，一份送主辦機關。 | GK47: ，廠商及監造單位各留存一份隨時備查，一份送主辦機關。 | HA47: ，廠商及監造單位各留存一份隨時備查，一份送主辦機關。 | HQ47: ，廠商及監造單位各留存一份隨時備查，一份送主辦機關。 | IG47: ，廠商及監造單位各留存一份隨時備查，一份送主辦機關。 | IW47: ，廠商及監造單位各留存一份隨時備查，一份送主辦機關。 | JM47: ，廠商及監造單位各留存一份隨時備查，一份送主辦機關。 | KC47: ，廠商及監造單位各留存一份隨時備查，一份送主辦機關。 | KS47: ，廠商及監造單位各留存一份隨時備查，一份送主辦機關。 | LI47: ，廠商及監造單位各留存一份隨時備查，一份送主辦機關。 | LY47: ，廠商及監造單位各留存一份隨時備查，一份送主辦機關。
A48: 2.如辦理契約變更或工期展延，應填寫修正核定後之契約工期與預定完工日期，且應依修正核定後進度網圖計算累計預定進度及累計實際進 | Q48: 2.如辦理契約變更或工期展延，應填寫修正核定後之契約工期與預定完工日期，且應依修正核定後進度網圖計算累計預定進度及累計實際進 | AG48: 2.如辦理契約變更或工期展延，應填寫修正核定後之契約工期與預定完工日期，且應依修正核定後進度網圖計算累計預定進度及累計實際進 | AW48: 2.如辦理契約變更或工期展延，應填寫修正核定後之契約工期與預定完工日期，且應依修正核定後進度網圖計算累計預定進度及累計實際進 | BM48: 2.如辦理契約變更或工期展延，應填寫修正核定後之契約工期與預定完工日期，且應依修正核定後進度網圖計算累計預定進度及累計實際進 | CC48: 2.如辦理契約變更或工期展延，應填寫修正核定後之契約工期與預定完工日期，且應依修正核定後進度網圖計算累計預定進度及累計實際進 | CS48: 2.如辦理契約變更或工期展延，應填寫修正核定後之契約工期與預定完工日期，且應依修正核定後進度網圖計算累計預定進度及累計實際進 | DI48: 2.如辦理契約變更或工期展延，應填寫修正核定後之契約工期與預定完工日期，且應依修正核定後進度網圖計算累計預定進度及累計實際進 | DY48: 2.如辦理契約變更或工期展延，應填寫修正核定後之契約工期與預定完工日期，且應依修正核定後進度網圖計算累計預定進度及累計實際進 | EO48: 2.如辦理契約變更或工期展延，應填寫修正核定後之契約工期與預定完工日期，且應依修正核定後進度網圖計算累計預定進度及累計實際進 | FE48: 2.如辦理契約變更或工期展延，應填寫修正核定後之契約工期與預定完工日期，且應依修正核定後進度網圖計算累計預定進度及累計實際進 | FU48: 2.如辦理契約變更或工期展延，應填寫修正核定後之契約工期與預定完工日期，且應依修正核定後進度網圖計算累計預定進度及累計實際進 | GK48: 2.如辦理契約變更或工期展延，應填寫修正核定後之契約工期與預定完工日期，且應依修正核定後進度網圖計算累計預定進度及累計實際進 | HA48: 2.如辦理契約變更或工期展延，應填寫修正核定後之契約工期與預定完工日期，且應依修正核定後進度網圖計算累計預定進度及累計實際進 | HQ48: 2.如辦理契約變更或工期展延，應填寫修正核定後之契約工期與預定完工日期，且應依修正核定後進度網圖計算累計預定進度及累計實際進 | IG48: 2.如辦理契約變更或工期展延，應填寫修正核定後之契約工期與預定完工日期，且應依修正核定後進度網圖計算累計預定進度及累計實際進 | IW48: 2.如辦理契約變更或工期展延，應填寫修正核定後之契約工期與預定完工日期，且應依修正核定後進度網圖計算累計預定進度及累計實際進 | JM48: 2.如辦理契約變更或工期展延，應填寫修正核定後之契約工期與預定完工日期，且應依修正核定後進度網圖計算累計預定進度及累計實際進 | KC48: 2.如辦理契約變更或工期展延，應填寫修正核定後之契約工期與預定完工日期，且應依修正核定後進度網圖計算累計預定進度及累計實際進 | KS48: 2.如辦理契約變更或工期展延，應填寫修正核定後之契約工期與預定完工日期，且應依修正核定後進度網圖計算累計預定進度及累計實際進 | LI48: 2.如辦理契約變更或工期展延，應填寫修正核定後之契約工期與預定完工日期，且應依修正核定後進度網圖計算累計預定進度及累計實際進 | LY48: 2.如辦理契約變更或工期展延，應填寫修正核定後之契約工期與預定完工日期，且應依修正核定後進度網圖計算累計預定進度及累計實際進
A49: 度；工程項目依照契約詳細表選擇重要項目填入。 | Q49: 度；工程項目依照契約詳細表選擇重要項目填入。 | AG49: 度；工程項目依照契約詳細表選擇重要項目填入。 | AW49: 度；工程項目依照契約詳細表選擇重要項目填入。 | BM49: 度；工程項目依照契約詳細表選擇重要項目填入。 | CC49: 度；工程項目依照契約詳細表選擇重要項目填入。 | CS49: 度；工程項目依照契約詳細表選擇重要項目填入。 | DI49: 度；工程項目依照契約詳細表選擇重要項目填入。 | DY49: 度；工程項目依照契約詳細表選擇重要項目填入。 | EO49: 度；工程項目依照契約詳細表選擇重要項目填入。 | FE49: 度；工程項目依照契約詳細表選擇重要項目填入。 | FU49: 度；工程項目依照契約詳細表選擇重要項目填入。 | GK49: 度；工程項目依照契約詳細表選擇重要項目填入。 | HA49: 度；工程項目依照契約詳細表選擇重要項目填入。 | HQ49: 度；工程項目依照契約詳細表選擇重要項目填入。 | IG49: 度；工程項目依照契約詳細表選擇重要項目填入。 | IW49: 度；工程項目依照契約詳細表選擇重要項目填入。 | JM49: 度；工程項目依照契約詳細表選擇重要項目填入。 | KC49: 度；工程項目依照契約詳細表選擇重要項目填入。 | KS49: 度；工程項目依照契約詳細表選擇重要項目填入。 | LI49: 度；工程項目依照契約詳細表選擇重要項目填入。 | LY49: 度；工程項目依照契約詳細表選擇重要項目填入。
A50: 3.契約變更次數應依「修正契約總價表」內容填寫。 | Q50: 3.契約變更次數應依「修正契約總價表」內容填寫。 | AG50: 3.契約變更次數應依「修正契約總價表」內容填寫。 | AW50: 3.契約變更次數應依「修正契約總價表」內容填寫。 | BM50: 3.契約變更次數應依「修正契約總價表」內容填寫。 | CC50: 3.契約變更次數應依「修正契約總價表」內容填寫。 | CS50: 3.契約變更次數應依「修正契約總價表」內容填寫。 | DI50: 3.契約變更次數應依「修正契約總價表」內容填寫。 | DY50: 3.契約變更次數應依「修正契約總價表」內容填寫。 | EO50: 3.契約變更次數應依「修正契約總價表」內容填寫。 | FE50: 3.契約變更次數應依「修正契約總價表」內容填寫。 | FU50: 3.契約變更次數應依「修正契約總價表」內容填寫。 | GK50: 3.契約變更次數應依「修正契約總價表」內容填寫。 | HA50: 3.契約變更次數應依「修正契約總價表」內容填寫。 | HQ50: 3.契約變更次數應依「修正契約總價表」內容填寫。 | IG50: 3.契約變更次數應依「修正契約總價表」內容填寫。 | IW50: 3.契約變更次數應依「修正契約總價表」內容填寫。 | JM50: 3.契約變更次數應依「修正契約總價表」內容填寫。 | KC50: 3.契約變更次數應依「修正契約總價表」內容填寫。 | KS50: 3.契約變更次數應依「修正契約總價表」內容填寫。 | LI50: 3.契約變更次數應依「修正契約總價表」內容填寫。 | LY50: 3.契約變更次數應依「修正契約總價表」內容填寫。
A51: 4.累計預定進度與累計實際進度應於每週六及月底估計填寫一次。 | Q51: 4.累計預定進度與累計實際進度應於每週六及月底估計填寫一次。 | AG51: 4.累計預定進度與累計實際進度應於每週六及月底估計填寫一次。 | AW51: 4.累計預定進度與累計實際進度應於每週六及月底估計填寫一次。 | BM51: 4.累計預定進度與累計實際進度應於每週六及月底估計填寫一次。 | CC51: 4.累計預定進度與累計實際進度應於每週六及月底估計填寫一次。 | CS51: 4.累計預定進度與累計實際進度應於每週六及月底估計填寫一次。 | DI51: 4.累計預定進度與累計實際進度應於每週六及月底估計填寫一次。 | DY51: 4.累計預定進度與累計實際進度應於每週六及月底估計填寫一次。 | EO51: 4.累計預定進度與累計實際進度應於每週六及月底估計填寫一次。 | FE51: 4.累計預定進度與累計實際進度應於每週六及月底估計填寫一次。 | FU51: 4.累計預定進度與累計實際進度應於每週六及月底估計填寫一次。 | GK51: 4.累計預定進度與累計實際進度應於每週六及月底估計填寫一次。 | HA51: 4.累計預定進度與累計實際進度應於每週六及月底估計填寫一次。 | HQ51: 4.累計預定進度與累計實際進度應於每週六及月底估計填寫一次。 | IG51: 4.累計預定進度與累計實際進度應於每週六及月底估計填寫一次。 | IW51: 4.累計預定進度與累計實際進度應於每週六及月底估計填寫一次。 | JM51: 4.累計預定進度與累計實際進度應於每週六及月底估計填寫一次。 | KC51: 4.累計預定進度與累計實際進度應於每週六及月底估計填寫一次。 | KS51: 4.累計預定進度與累計實際進度應於每週六及月底估計填寫一次。 | LI51: 4.累計預定進度與累計實際進度應於每週六及月底估計填寫一次。 | LY51: 4.累計預定進度與累計實際進度應於每週六及月底估計填寫一次。
... A60: 第二聯 完成工程詳細表 | Q60: 第二聯 完成工程詳細表 | AG60: 第二聯 完成工程詳細表 | AW60: 第二聯 完成工程詳細表 | BM60: 第二聯 完成工程詳細表 | CC60: 第二聯 完成工程詳細表 | CS60: 第二聯 完成工程詳細表 | DI60: 第二聯 完成工程詳細表 | DY60: 第二聯 完成工程詳細表 | EO60: 第二聯 完成工程詳細表 | FE60: 第二聯 完成工程詳細表 | FU60: 第二聯 完成工程詳細表 | GK60: 第二聯 完成工程詳細表 | HA60: 第二聯 完成工程詳細表 | HQ60: 第二聯 完成工程詳細表 | IG60: 第二聯 完成工程詳細表 | IW60: 第二聯 完成工程詳細表 | JM60: 第二聯 完成工程詳細表 | KC60: 第二聯 完成工程詳細表 | KS60: 第二聯 完成工程詳細表 | LI60: 第二聯 完成工程詳細表 | LY60: 第二聯 完成工程詳細表
A61: =A5 -> 工程名稱：114-Danas-E-05-01-011-雲林縣林內鄉林內國中射箭場側網毀損修復災後復建工程 | H61: =H4 -> 填報日期：115年3月11日(星期三) | Q61: =Q5 -> 工程名稱：114-Danas-E-05-01-011-雲林縣林內鄉林內國中射箭場側網毀損修復災後復建工程 | X61: =X4 -> 填報日期：115年3月12日(星期四) | AG61: =AG5 -> 工程名稱：114-Danas-E-05-01-011-雲林縣林內鄉林內國中射箭場側網毀損修復災後復建工程 | AN61: =AN4 -> 填報日期：115年3月13日(星期五) | AW61: =AW5 -> 工程名稱：114-Danas-E-05-01-011-雲林縣林內鄉林內國中射箭場側網毀損修復災後復建工程 | BD61: =BD4 -> 填報日期：115年3月14日(星期六) | BM61: =BM5 -> 工程名稱：114-Danas-E-05-01-011-雲林縣林內鄉林內國中射箭場側網毀損修復災後復建工程 | BT61: =BT4 -> 填報日期：115年3月15日(星期日) | CC61: =CC5 -> 工程名稱：114-Danas-E-05-01-011-雲林縣林內鄉林內國中射箭場側網毀損修復災後復建工程 | CJ61: =CJ4 -> 填報日期：115年3月16日(星期一) | CS61: =CS5 -> 工程名稱：114-Danas-E-05-01-011-雲林縣林內鄉林內國中射箭場側網毀損修復災後復建工程 | CZ61: =CZ4 -> 填報日期：115年3月17日(星期二) | DI61: =DI5 -> 工程名稱：114-Danas-E-05-01-011-雲林縣林內鄉林內國中射箭場側網毀損修復災後復建工程 | DP61: =DP4 -> 填報日期：115年3月18日(星期三) | DY61: =DY5 -> 工程名稱：114-Danas-E-05-01-011-雲林縣林內鄉林內國中射箭場側網毀損修復災後復建工程 | EF61: =EF4 -> 填報日期：115年3月19日(星期四) | EO61: =EO5 -> 工程名稱：114-Danas-E-05-01-011-雲林縣林內鄉林內國中射箭場側網毀損修復災後復建工程 | EV61: =EV4 -> 填報日期：115年3月20日(星期五) | FE61: =FE5 -> 工程名稱：114-Danas-E-05-01-011-雲林縣林內鄉林內國中射箭場側網毀損修復災後復建工程 | FL61: =FL4 -> 填報日期：115年3月21日(星期六) | FU61: =FU5 -> 工程名稱：114-Danas-E-05-01-011-雲林縣林內鄉林內國中射箭場側網毀損修復災後復建工程 | GB61: =GB4 -> 填報日期：115年3月22日(星期日) | GK61: =GK5 -> 工程名稱：114-Danas-E-05-01-011-雲林縣林內鄉林內國中射箭場側網毀損修復災後復建工程 | GR61: =GR4 -> 填報日期：115年3月23日(星期一) | HA61: =HA5 -> 工程名稱：114-Danas-E-05-01-011-雲林縣林內鄉林內國中射箭場側網毀損修復災後復建工程 | HH61: =HH4 -> 填報日期：115年3月24日(星期二) | HQ61: =HQ5 -> 工程名稱：114-Danas-E-05-01-011-雲林縣林內鄉林內國中射箭場側網毀損修復災後復建工程 | HX61: =HX4 -> 填報日期：115年3月25日(星期三) | IG61: =IG5 -> 工程名稱：114-Danas-E-05-01-011-雲林縣林內鄉林內國中射箭場側網毀損修復災後復建工程 | IN61: =IN4 -> 填報日期：115年3月26日(星期四) | IW61: =IW5 -> 工程名稱：114-Danas-E-05-01-011-雲林縣林內鄉林內國中射箭場側網毀損修復災後復建工程 | JD61: =JD4 -> 填報日期：115年3月27日(星期五) | JM61: =JM5 -> 工程名稱：114-Danas-E-05-01-011-雲林縣林內鄉林內國中射箭場側網毀損修復災後復建工程 | JT61: =JT4 -> 填報日期：115年3月28日(星期六) | KC61: =KC5 -> 工程名稱：114-Danas-E-05-01-011-雲林縣林內鄉林內國中射箭場側網毀損修復災後復建工程 | KJ61: =KJ4 -> 填報日期：115年3月29日(星期日) | KS61: =KS5 -> 工程名稱：114-Danas-E-05-01-011-雲林縣林內鄉林內國中射箭場側網毀損修復災後復建工程 | KZ61: =KZ4 -> 填報日期：115年3月30日(星期一) | LI61: =LI5 -> 工程名稱：114-Danas-E-05-01-011-雲林縣林內鄉林內國中射箭場側網毀損修復災後復建工程 | LP61: =LP4 -> 填報日期：115年3月31日(星期二) | LY61: =LY5 -> 工程名稱：114-Danas-E-05-01-011-雲林縣林內鄉林內國中射箭場側網毀損修復災後復建工程 | MF61: =MF4 -> 填報日期：115年4月1日(星期三 )
K62: 第1共1頁 | AA62: 第1共1頁 | AQ62: 第1共1頁 | BG62: 第1共1頁 | BW62: 第1共1頁 | CM62: 第1共1頁 | DC62: 第1共1頁 | DS62: 第1共1頁 | EI62: 第1共1頁 | EY62: 第1共1頁 | FO62: 第1共1頁 | GE62: 第1共1頁 | GU62: 第1共1頁 | HK62: 第1共1頁 | IA62: 第1共1頁 | IQ62: 第1共1頁 | JG62: 第1共1頁 | JW62: 第1共1頁 | KM62: 第1共1頁 | LC62: 第1共1頁 | LS62: 第1共1頁 | MI62: 第1共1頁
A63: 項次 | B63: 工程項目 | F63: 單位 | G63: 契約數量 | I63: 本日完成數量 | K63: 累計完成數量 | L63: 備註 | N63: 契約單價 | O63: 完成金額 | Q63: 項次 | R63: 工程項目 | V63: 單位 | W63: 契約數量 | Y63: 本日完成數量 | AA63: 累計完成數量 | AB63: 備註 | AD63: 契約單價 | AE63: 完成金額 | AG63: 項次 | AH63: 工程項目 | AL63: 單位 | AM63: 契約數量 | AO63: 本日完成數量 | AQ63: 累計完成數量 | AR63: 備註 | AT63: 契約單價 | AU63: 完成金額 | AW63: 項次 | AX63: 工程項目 | BB63: 單位 | BC63: 契約數量 | BE63: 本日完成數量 | BG63: 累計完成數量 | BH63: 備註 | BJ63: 契約單價 | BK63: 完成金額 | BM63: 項次 | BN63: 工程項目 | BR63: 單位 | BS63: 契約數量 | BU63: 本日完成數量 | BW63: 累計完成數量 | BX63: 備註 | BZ63: 契約單價 | CA63: 完成金額 | CC63: 項次 | CD63: 工程項目 | CH63: 單位 | CI63: 契約數量 | CK63: 本日完成數量 | CM63: 累計完成數量 | CN63: 備註 | CP63: 契約單價 | CQ63: 完成金額 | CS63: 項次 | CT63: 工程項目 | CX63: 單位 | CY63: 契約數量 | DA63: 本日完成數量 | DC63: 累計完成數量 | DD63: 備註 | DF63: 契約單價 | DG63: 完成金額 | DI63: 項次 | DJ63: 工程項目 | DN63: 單位 | DO63: 契約數量 | DQ63: 本日完成數量 | DS63: 累計完成數量 | DT63: 備註 | DV63: 契約單價 | DW63: 完成金額 | DY63: 項次 | DZ63: 工程項目 | ED63: 單位 | EE63: 契約數量 | EG63: 本日完成數量 | EI63: 累計完成數量 | EJ63: 備註 | EL63: 契約單價 | EM63: 完成金額 | EO63: 項次 | EP63: 工程項目 | ET63: 單位 | EU63: 契約數量 | EW63: 本日完成數量 | EY63: 累計完成數量 | EZ63: 備註 | FB63: 契約單價 | FC63: 完成金額 | FE63: 項次 | FF63: 工程項目 | FJ63: 單位 | FK63: 契約數量 | FM63: 本日完成數量 | FO63: 累計完成數量 | FP63: 備註 | FR63: 契約單價 | FS63: 完成金額 | FU63: 項次 | FV63: 工程項目 | FZ63: 單位 | GA63: 契約數量 | GC63: 本日完成數量 | GE63: 累計完成數量 | GF63: 備註 | GH63: 契約單價 | GI63: 完成金額 | GK63: 項次 | GL63: 工程項目 | GP63: 單位 | GQ63: 契約數量 | GS63: 本日完成數量 | GU63: 累計完成數量 | GV63: 備註 | GX63: 契約單價 | GY63: 完成金額 | HA63: 項次 | HB63: 工程項目 | HF63: 單位 | HG63: 契約數量 | HI63: 本日完成數量 | HK63: 累計完成數量 | HL63: 備註 | HN63: 契約單價 | HO63: 完成金額 | HQ63: 項次 | HR63: 工程項目 | HV63: 單位 | HW63: 契約數量 | HY63: 本日完成數量 | IA63: 累計完成數量 | IB63: 備註 | ID63: 契約單價 | IE63: 完成金額 | IG63: 項次 | IH63: 工程項目 | IL63: 單位 | IM63: 契約數量 | IO63: 本日完成數量 | IQ63: 累計完成數量 | IR63: 備註 | IT63: 契約單價 | IU63: 完成金額 | IW63: 項次 | IX63: 工程項目 | JB63: 單位 | JC63: 契約數量 | JE63: 本日完成數量 | JG63: 累計完成數量 | JH63: 備註 | JJ63: 契約單價 | JK63: 完成金額 | JM63: 項次 | JN63: 工程項目 | JR63: 單位 | JS63: 契約數量 | JU63: 本日完成數量 | JW63: 累計完成數量 | JX63: 備註 | JZ63: 契約單價 | KA63: 完成金額 | KC63: 項次 | KD63: 工程項目 | KH63: 單位 | KI63: 契約數量 | KK63: 本日完成數量 | KM63: 累計完成數量 | KN63: 備註 | KP63: 契約單價 | KQ63: 完成金額 | KS63: 項次 | KT63: 工程項目 | KX63: 單位 | KY63: 契約數量 | LA63: 本日完成數量 | LC63: 累計完成數量 | LD63: 備註 | LF63: 契約單價 | LG63: 完成金額 | LI63: 項次 | LJ63: 工程項目 | LN63: 單位 | LO63: 契約數量 | LQ63: 本日完成數量 | LS63: 累計完成數量 | LT63: 備註 | LV63: 契約單價 | LW63: 完成金額 | LY63: 項次 | LZ63: 工程項目 | MD63: 單位 | ME63: 契約數量 | MG63: 本日完成數量 | MI63: 累計完成數量 | MJ63: 備註 | ML63: 契約單價 | MM63: 完成金額
A64: 壹 | B64: 直接工程 | Q64: 壹 | R64: 直接工程 | AG64: 壹 | AH64: 直接工程 | AW64: 壹 | AX64: 直接工程 | BM64: 壹 | BN64: 直接工程 | CC64: 壹 | CD64: 直接工程 | CS64: 壹 | CT64: 直接工程 | DI64: 壹 | DJ64: 直接工程 | DY64: 壹 | DZ64: 直接工程 | EO64: 壹 | EP64: 直接工程 | FE64: 壹 | FF64: 直接工程 | FU64: 壹 | FV64: 直接工程 | GK64: 壹 | GL64: 直接工程 | HA64: 壹 | HB64: 直接工程 | HQ64: 壹 | HR64: 直接工程 | IG64: 壹 | IH64: 直接工程 | IW64: 壹 | IX64: 直接工程 | JM64: 壹 | JN64: 直接工程 | KC64: 壹 | KD64: 直接工程 | KS64: 壹 | KT64: 直接工程 | LI64: 壹 | LJ64: 直接工程 | LY64: 壹 | LZ64: 直接工程
A65: 1 | B65: 既有傾斜高網修復 | F65: M | G65: 30 | K65: =I65 -> 0 | N65: 2050 | O65: =I65*N65 -> 0 | Q65: 1 | R65: 既有傾斜高網修復 | V65: M | W65: 30 | Y65: 5 | AA65: =Y65+K65 -> 5 | AD65: 2050 | AE65: =Y65*AD65 -> 10250 | AG65: 1 | AH65: 既有傾斜高網修復 | AL65: M | AM65: 30 | AO65: 10 | AQ65: =AO65+AA65 -> 15 | AT65: 2050 | AU65: =AO65*AT65 -> 20500 | AW65: 1 | AX65: 既有傾斜高網修復 | BB65: M | BC65: 30 | BE65: 10 | BG65: =BE65+AQ65 -> 25 | BJ65: 2050 | BK65: =BE65*BJ65 -> 20500 | BM65: 1 | BN65: 既有傾斜高網修復 | BR65: M | BS65: 30 | BW65: =BU65+BG65 -> 25 | BZ65: 2050 | CA65: =BU65*BZ65 -> 0 | CC65: 1 | CD65: 既有傾斜高網修復 | CH65: M | CI65: 30 | CM65: =CK65+BW65 -> 25 | CP65: 2050 | CQ65: =CK65*CP65 -> 0 | CS65: 1 | CT65: 既有傾斜高網修復 | CX65: M | CY65: 30 | DC65: =DA65+CM65 -> 25 | DF65: 2050 | DG65: =DA65*DF65 -> 0 | DI65: 1 | DJ65: 既有傾斜高網修復 | DN65: M | DO65: 30 | DS65: =DQ65+DC65 -> 25 | DV65: 2050 | DW65: =DQ65*DV65 -> 0 | DY65: 1 | DZ65: 既有傾斜高網修復 | ED65: M | EE65: 30 | EI65: =EG65+DS65 -> 25 | EL65: 2050 | EM65: =EG65*EL65 -> 0 | EO65: 1 | EP65: 既有傾斜高網修復 | ET65: M | EU65: 30 | EY65: =EW65+EI65 -> 25 | FB65: 2050 | FC65: =EW65*FB65 -> 0 | FE65: 1 | FF65: 既有傾斜高網修復 | FJ65: M | FK65: 30 | FO65: =FM65+EY65 -> 25 | FR65: 2050 | FS65: =FM65*FR65 -> 0 | FU65: 1 | FV65: 既有傾斜高網修復 | FZ65: M | GA65: 30 | GE65: =GC65+FO65 -> 25 | GH65: 2050 | GI65: =GC65*GH65 -> 0 | GK65: 1 | GL65: 既有傾斜高網修復 | GP65: M | GQ65: 30 | GU65: =GS65+GE65 -> 25 | GX65: 2050 | GY65: =GS65*GX65 -> 0 | HA65: 1 | HB65: 既有傾斜高網修復 | HF65: M | HG65: 30 | HK65: =HI65+GU65 -> 25 | HN65: 2050 | HO65: =HI65*HN65 -> 0 | HQ65: 1 | HR65: 既有傾斜高網修復 | HV65: M | HW65: 30 | IA65: =HY65+HK65 -> 25 | ID65: 2050 | IE65: =HY65*ID65 -> 0 | IG65: 1 | IH65: 既有傾斜高網修復 | IL65: M | IM65: 30 | IQ65: =IO65+IA65 -> 25 | IT65: 2050 | IU65: =IO65*IT65 -> 0 | IW65: 1 | IX65: 既有傾斜高網修復 | JB65: M | JC65: 30 | JG65: =JE65+IQ65 -> 25 | JJ65: 2050 | JK65: =JE65*JJ65 -> 0 | JM65: 1 | JN65: 既有傾斜高網修復 | JR65: M | JS65: 30 | JW65: =JU65+JG65 -> 25 | JZ65: 2050 | KA65: =JU65*JZ65 -> 0 | KC65: 1 | KD65: 既有傾斜高網修復 | KH65: M | KI65: 30 | KM65: =KK65+JW65 -> 25 | KP65: 2050 | KQ65: =KK65*KP65 -> 0 | KS65: 1 | KT65: 既有傾斜高網修復 | KX65: M | KY65: 30 | LC65: =LA65+KM65 -> 25 | LF65: 2050 | LG65: =LA65*LF65 -> 0 | LI65: 1 | LJ65: 既有傾斜高網修復 | LN65: M | LO65: 30 | LS65: =LQ65+LC65 -> 25 | LV65: 2050 | LW65: =LQ65*LV65 -> 0 | LY65: 1 | LZ65: 既有傾斜高網修復 | MD65: M | ME65: 30 | MI65: =MG65+LS65 -> 25 | ML65: 2050 | MM65: =MG65*ML65 -> 0
A66: 2 | B66: 10吋鋼管與3吋鋼管焊接補強 | F66: 處 | G66: 12 | K66: =I66 -> 0 | N66: 4250 | O66: =I66*N66 -> 0 | Q66: 2 | R66: 10吋鋼管與3吋鋼管焊接補強 | V66: 處 | W66: 12 | AA66: =Y66+K66 -> 0 | AD66: 4250 | AE66: =Y66*AD66 -> 0 | AG66: 2 | AH66: 10吋鋼管與3吋鋼管焊接補強 | AL66: 處 | AM66: 12 | AQ66: =AO66+AA66 -> 0 | AT66: 4250 | AU66: =AO66*AT66 -> 0 | AW66: 2 | AX66: 10吋鋼管與3吋鋼管焊接補強 | BB66: 處 | BC66: 12 | BG66: =BE66+AQ66 -> 0 | BJ66: 4250 | BK66: =BE66*BJ66 -> 0 | BM66: 2 | BN66: 10吋鋼管與3吋鋼管焊接補強 | BR66: 處 | BS66: 12 | BW66: =BU66+BG66 -> 0 | BZ66: 4250 | CA66: =BU66*BZ66 -> 0 | CC66: 2 | CD66: 10吋鋼管與3吋鋼管焊接補強 | CH66: 處 | CI66: 12 | CM66: =CK66+BW66 -> 0 | CP66: 4250 | CQ66: =CK66*CP66 -> 0 | CS66: 2 | CT66: 10吋鋼管與3吋鋼管焊接補強 | CX66: 處 | CY66: 12 | DC66: =DA66+CM66 -> 0 | DF66: 4250 | DG66: =DA66*DF66 -> 0 | DI66: 2 | DJ66: 10吋鋼管與3吋鋼管焊接補強 | DN66: 處 | DO66: 12 | DS66: =DQ66+DC66 -> 0 | DV66: 4250 | DW66: =DQ66*DV66 -> 0 | DY66: 2 | DZ66: 10吋鋼管與3吋鋼管焊接補強 | ED66: 處 | EE66: 12 | EI66: =EG66+DS66 -> 0 | EL66: 4250 | EM66: =EG66*EL66 -> 0 | EO66: 2 | EP66: 10吋鋼管與3吋鋼管焊接補強 | ET66: 處 | EU66: 12 | EY66: =EW66+EI66 -> 0 | FB66: 4250 | FC66: =EW66*FB66 -> 0 | FE66: 2 | FF66: 10吋鋼管與3吋鋼管焊接補強 | FJ66: 處 | FK66: 12 | FO66: =FM66+EY66 -> 0 | FR66: 4250 | FS66: =FM66*FR66 -> 0 | FU66: 2 | FV66: 10吋鋼管與3吋鋼管焊接補強 | FZ66: 處 | GA66: 12 | GE66: =GC66+FO66 -> 0 | GH66: 4250 | GI66: =GC66*GH66 -> 0 | GK66: 2 | GL66: 10吋鋼管與3吋鋼管焊接補強 | GP66: 處 | GQ66: 12 | GU66: =GS66+GE66 -> 0 | GX66: 4250 | GY66: =GS66*GX66 -> 0 | HA66: 2 | HB66: 10吋鋼管與3吋鋼管焊接補強 | HF66: 處 | HG66: 12 | HK66: =HI66+GU66 -> 0 | HN66: 4250 | HO66: =HI66*HN66 -> 0 | HQ66: 2 | HR66: 10吋鋼管與3吋鋼管焊接補強 | HV66: 處 | HW66: 12 | IA66: =HY66+HK66 -> 0 | ID66: 4250 | IE66: =HY66*ID66 -> 0 | IG66: 2 | IH66: 10吋鋼管與3吋鋼管焊接補強 | IL66: 處 | IM66: 12 | IQ66: =IO66+IA66 -> 0 | IT66: 4250 | IU66: =IO66*IT66 -> 0 | IW66: 2 | IX66: 10吋鋼管與3吋鋼管焊接補強 | JB66: 處 | JC66: 12 | JG66: =JE66+IQ66 -> 0 | JJ66: 4250 | JK66: =JE66*JJ66 -> 0 | JM66: 2 | JN66: 10吋鋼管與3吋鋼管焊接補強 | JR66: 處 | JS66: 12 | JW66: =JU66+JG66 -> 0 | JZ66: 4250 | KA66: =JU66*JZ66 -> 0 | KC66: 2 | KD66: 10吋鋼管與3吋鋼管焊接補強 | KH66: 處 | KI66: 12 | KM66: =KK66+JW66 -> 0 | KP66: 4250 | KQ66: =KK66*KP66 -> 0 | KS66: 2 | KT66: 10吋鋼管與3吋鋼管焊接補強 | KX66: 處 | KY66: 12 | LC66: =LA66+KM66 -> 0 | LF66: 4250 | LG66: =LA66*LF66 -> 0 | LI66: 2 | LJ66: 10吋鋼管與3吋鋼管焊接補強 | LN66: 處 | LO66: 12 | LS66: =LQ66+LC66 -> 0 | LV66: 4250 | LW66: =LQ66*LV66 -> 0 | LY66: 2 | LZ66: 10吋鋼管與3吋鋼管焊接補強 | MD66: 處 | ME66: 12 | MI66: =MG66+LS66 -> 0 | ML66: 4250 | MM66: =MG66*ML66 -> 0
A67: 3 | B67: 既有3吋鋼管增加斜撐補強 | F67: 組 | G67: 22 | K67: =I67 -> 0 | N67: 7150 | O67: =I67*N67 -> 0 | Q67: 3 | R67: 既有3吋鋼管增加斜撐補強 | V67: 組 | W67: 22 | AA67: =Y67+K67 -> 0 | AD67: 7150 | AE67: =Y67*AD67 -> 0 | AG67: 3 | AH67: 既有3吋鋼管增加斜撐補強 | AL67: 組 | AM67: 22 | AQ67: =AO67+AA67 -> 0 | AT67: 7150 | AU67: =AO67*AT67 -> 0 | AW67: 3 | AX67: 既有3吋鋼管增加斜撐補強 | BB67: 組 | BC67: 22 | BG67: =BE67+AQ67 -> 0 | BJ67: 7150 | BK67: =BE67*BJ67 -> 0 | BM67: 3 | BN67: 既有3吋鋼管增加斜撐補強 | BR67: 組 | BS67: 22 | BW67: =BU67+BG67 -> 0 | BZ67: 7150 | CA67: =BU67*BZ67 -> 0 | CC67: 3 | CD67: 既有3吋鋼管增加斜撐補強 | CH67: 組 | CI67: 22 | CM67: =CK67+BW67 -> 0 | CP67: 7150 | CQ67: =CK67*CP67 -> 0 | CS67: 3 | CT67: 既有3吋鋼管增加斜撐補強 | CX67: 組 | CY67: 22 | DC67: =DA67+CM67 -> 0 | DF67: 7150 | DG67: =DA67*DF67 -> 0 | DI67: 3 | DJ67: 既有3吋鋼管增加斜撐補強 | DN67: 組 | DO67: 22 | DS67: =DQ67+DC67 -> 0 | DV67: 7150 | DW67: =DQ67*DV67 -> 0 | DY67: 3 | DZ67: 既有3吋鋼管增加斜撐補強 | ED67: 組 | EE67: 22 | EI67: =EG67+DS67 -> 0 | EL67: 7150 | EM67: =EG67*EL67 -> 0 | EO67: 3 | EP67: 既有3吋鋼管增加斜撐補強 | ET67: 組 | EU67: 22 | EY67: =EW67+EI67 -> 0 | FB67: 7150 | FC67: =EW67*FB67 -> 0 | FE67: 3 | FF67: 既有3吋鋼管增加斜撐補強 | FJ67: 組 | FK67: 22 | FO67: =FM67+EY67 -> 0 | FR67: 7150 | FS67: =FM67*FR67 -> 0 | FU67: 3 | FV67: 既有3吋鋼管增加斜撐補強 | FZ67: 組 | GA67: 22 | GE67: =GC67+FO67 -> 0 | GH67: 7150 | GI67: =GC67*GH67 -> 0 | GK67: 3 | GL67: 既有3吋鋼管增加斜撐補強 | GP67: 組 | GQ67: 22 | GU67: =GS67+GE67 -> 0 | GX67: 7150 | GY67: =GS67*GX67 -> 0 | HA67: 3 | HB67: 既有3吋鋼管增加斜撐補強 | HF67: 組 | HG67: 22 | HK67: =HI67+GU67 -> 0 | HN67: 7150 | HO67: =HI67*HN67 -> 0 | HQ67: 3 | HR67: 既有3吋鋼管增加斜撐補強 | HV67: 組 | HW67: 22 | HY67: 1 | IA67: =HY67+HK67 -> 1 | ID67: 7150 | IE67: =HY67*ID67 -> 7150 | IG67: 3 | IH67: 既有3吋鋼管增加斜撐補強 | IL67: 組 | IM67: 22 | IO67: 1 | IQ67: =IO67+IA67 -> 2 | IT67: 7150 | IU67: =IO67*IT67 -> 7150 | IW67: 3 | IX67: 既有3吋鋼管增加斜撐補強 | JB67: 組 | JC67: 22 | JE67: 1 | JG67: =JE67+IQ67 -> 3 | JJ67: 7150 | JK67: =JE67*JJ67 -> 7150 | JM67: 3 | JN67: 既有3吋鋼管增加斜撐補強 | JR67: 組 | JS67: 22 | JU67: 1 | JW67: =JU67+JG67 -> 4 | JZ67: 7150 | KA67: =JU67*JZ67 -> 7150 | KC67: 3 | KD67: 既有3吋鋼管增加斜撐補強 | KH67: 組 | KI67: 22 | KK67: 1 | KM67: =KK67+JW67 -> 5 | KP67: 7150 | KQ67: =KK67*KP67 -> 7150 | KS67: 3 | KT67: 既有3吋鋼管增加斜撐補強 | KX67: 組 | KY67: 22 | LA67: 1 | LC67: =LA67+KM67 -> 6 | LF67: 7150 | LG67: =LA67*LF67 -> 7150 | LI67: 3 | LJ67: 既有3吋鋼管增加斜撐補強 | LN67: 組 | LO67: 22 | LQ67: 1 | LS67: =LQ67+LC67 -> 7 | LV67: 7150 | LW67: =LQ67*LV67 -> 7150 | LY67: 3 | LZ67: 既有3吋鋼管增加斜撐補強 | MD67: 組 | ME67: 22 | MG67: 1 | MI67: =MG67+LS67 -> 8 | ML67: 7150 | MM67: =MG67*ML67 -> 7150
...
