Workbook

Sheet 封面
A4: 雲林縣二崙鄉永定國民小學
A7: 雲林縣永定國小114年度改善無障礙校園環境工程
A12: 施工日誌
A24: 施工廠商：和穩土木包工業
A25: 施工日期：114年09月10日~114年09月30日

Sheet 日報
A1: 公共工程施工日誌
A2: 表報編號： | B2: 1
A3: 本日天氣： | B3: 上午： | C3: 晴 | D3: 下午： 晴 | F3: 填表日期： | H3: 45910 | K3: =H3 -> 45910
A4: 工程名稱 | D4: 雲林縣永定國小114年度改善無障礙校園環境工程 | H4: 承攬廠商名稱 | K4: 和穩土木包工業
A6: 核定工期 | B6: 60日曆天 | D6: 累計工期 | G6: 1 | H6: 剩餘工期 | I6: 59 | K6: 工期展延天數 | M6: 0
A7: 開工日期 | D7: 114年09年10日 | H7: 完工日期 | K7: 114年11月08日
A8: 預定進度(%) | D8: 0.002 | H8: 實際進度(%) | K8: =施工項目!AQ24 -> 0.0048686275
A9: 一、依施工計畫書執行按圖施工概況（含約定之重要施工項目及完成數量等）：
A10: 施工項目 | E10: 單位 | F10: 契約數量 | H10: 本日完成數量 | J10: 累計完成數量 | L10: 備註
A11: 設立工程告示牌 | E11: 式 | F11: 1 | H11: 1 | J11: 1
A12: 工程保險 | E12: 式 | F12: 1 | H12: 1 | J12: 1
A13: 申報開工
A20: 營造業專業工程特定施工項目
A21: A.
A22: B.
A23: 二、工地材料管理概況（含約定之重要材料使用狀況及數量等）：
A24: 材料名稱 | E24: 單位 | F24: 設計數量 | H24: 本日使用數量 | J24: 累計使用數量 | L24: 備註
A27: 三、工地人員及機具管理（含約定之出工人數及機具使用情形及數量）：
A28: 工別 | C28: 本日人數 | E28: 累計人數 | H28: 機具名稱 | J28: 本日使用數量 | L28: 累計使用數量
A29: 大工
A30: 小工 | C30: 2 | E30: 2
A31: 四、本日施工項目是否有須依「營造業專業工程特定施工項目應置之技術士種類、比率或人數標準表」規定應設置技術士之專業工程：□有 □無（此項如勾選”有”，則應填寫後附「公共工程施工日誌之技術士簽章表」）
A32: 五、工地職業安全衛生事項之督導、公共環境與安全之維護及其他工地行政事務：
A33: (ㄧ)施工前檢查事項：
A34: 1.實施勤前教育(含工地預防災變及危害告知)：□有 □無
A35: 2.確認新進勞工是否提報勞工保險(或其他商業保險)資料及安全衛生教育訓練紀錄：□有 □無 □無新進勞工
A36: 3.檢查勞工個人防護具：□有 □無
A37: (二)其他事項：
A38: 六、施工取樣試驗紀錄：
A39: 七、通知協力廠商辦理事項：
A40: 八、重要事項記錄：
A41: 簽章：【工地主任】（註3）：
A42: 註：1.依營造業法第32條第1項第2款規定，工地主任應按日填報施工日誌
... A48: 公共工程施工日誌
A49: 表報編號： | B49: =B2+1 -> 2
A50: 本日天氣： | B50: 上午： | C50: 晴 | D50: 下午： 晴 | F50: 填表日期： | H50: =H3+1 -> 45911 | K50: =H50 -> 45911
A51: 工程名稱 | D51: 雲林縣永定國小114年度改善無障礙校園環境工程 | H51: 承攬廠商名稱 | K51: 和穩土木包工業
A53: 核定工期 | B53: 60日曆天 | D53: 累計工期 | G53: =G6+1 -> 2 | H53: 剩餘工期 | I53: =I6-1 -> 58 | K53: 工期展延天數 | M53: 0
A54: 開工日期 | D54: 114年09年10日 | H54: 完工日期 | K54: 114年11月08日
A55: 預定進度(%) | D55: 0.004 | H55: 實際進度(%) | K55: =施工項目!AQ52 -> 0.011066667
...

Sheet 施工項目
A1: 和穩土木包工業
A2: 第二聯 | J2: 公共工程施工日誌
A3: 工程名稱： | I3: 雲林縣永定國小114年度改善無障礙校園環境工程 | AO3: 日期： | AW3: 45910
A4: 項次 | E4: 工程項目 | U4: 單位 | Y4: 契約數量 | AE4: 契約單價 | AK4: 本日 完成數量 | AQ4: 本日 完成金額 | AW4: 累計 完成數量 | BC4: 累計 完成金額
A5: ='[1](標單)詳細價目表'!A2 -> 壹 | E5: ='[1](標單)詳細價目表'!B2 -> 直接工程費 | BI5: =Y5*AE5 -> 0
A6: 1 | E6: ='[1](標單)詳細價目表'!B3 -> 工程告示牌與職安衛告示牌(租用) | U6: ='[1](標單)詳細價目表'!C3 -> 式 | Y6: 1 | Z6: 1 | AA6: 1 | AB6: 1 | AC6: 1 | AD6: 1 | AE6: ='[1](標單)詳細價目表'!E3 -> 5000 | AK6: 1 | AQ6: =AK6*AE6 -> 5000 | AW6: =AK6 -> 1 | BC6: =ROUND(AW6*AE6,0) -> 5000 | BI6: =Y6*AE6 -> 5000
A7: ='[1](標單)詳細價目表'!A4 -> 2 | E7: ='[1](標單)詳細價目表'!B4 -> 三角錐與連桿(租用) | U7: ='[1](標單)詳細價目表'!C4 -> M | Y7: 86 | Z7: 86 | AA7: 86 | AB7: 86 | AC7: 86 | AD7: 86 | AE7: ='[1](標單)詳細價目表'!E4 -> 60 | AK7: 0 | AQ7: =AK7*AE7 -> 0 | AW7: =AK7 -> 0 | BC7: =ROUND(AW7*AE7,0) -> 0 | BI7: =Y7*AE7 -> 5160
A8: ='[1](標單)詳細價目表'!A5 -> 3 | E8: ='[1](標單)詳細價目表'!B5 -> 施工動線開闢及損害復原；測量與放樣 | U8: ='[1](標單)詳細價目表'!C5 -> 式 | Y8: 1 | Z8: 1 | AA8: 1 | AB8: 1 | AC8: 1 | AD8: 1 | AE8: ='[1](標單)詳細價目表'!E5 -> 4000 | AK8: 0 | AQ8: =AK8*AE8 -> 0 | AW8: =AK8 -> 0 | BC8: =ROUND(AW8*AE8,0) -> 0 | BI8: =Y8*AE8 -> 4000
A9: ='[1](標單)詳細價目表'!A6 -> 4 | E9: ='[1](標單)詳細價目表'!B6 -> 切割打除清運校舍與教室出入口地坪以及司令台階梯平台(含合法清運證明) | U9: ='[1](標單)詳細價目表'!C6 -> 式 | Y9: 1 | Z9: 1 | AA9: 1 | AB9: 1 | AC9: 1 | AD9: 1 | AE9: ='[1](標單)詳細價目表'!E6 -> 52817 | AK9: 0 | AQ9: =AK9*AE9 -> 0 | AW9: =AK9 -> 0 | BC9: =ROUND(AW9*AE9,0) -> 0 | BI9: =Y9*AE9 -> 52817
A10: ='[1](標單)詳細價目表'!A7 -> 5 | E10: ='[1](標單)詳細價目表'!B7 -> 校舍出入口施做斜坡順平高差 | U10: ='[1](標單)詳細價目表'!C7 -> M2 | Y10: 15 | Z10: 15 | AA10: 15 | AB10: 15 | AC10: 15 | AD10: 15 | AE10: ='[1](標單)詳細價目表'!E7 -> 600 | AK10: 0 | AQ10: =AK10*AE10 -> 0 | AW10: =AK10 -> 0 | BC10: =ROUND(AW10*AE10,0) -> 0 | BI10: =Y10*AE10 -> 9000
A11: ='[1](標單)詳細價目表'!A8 -> 6 | E11: ='[1](標單)詳細價目表'!B8 -> 開挖整地，新設無障礙RC坡道，牆面與地坪粉刷整平(連工帶料，責任施工) | U11: ='[1](標單)詳細價目表'!C8 -> 式 | Y11: 1 | Z11: 1 | AA11: 1 | AB11: 1 | AC11: 1 | AD11: 1 | AE11: ='[1](標單)詳細價目表'!E8 -> 153000 | AK11: 0 | AQ11: =AK11*AE11 -> 0 | AW11: =AK11 -> 0 | BC11: =ROUND(AW11*AE11,0) -> 0 | BI11: =Y11*AE11 -> 153000
A12: ='[1](標單)詳細價目表'!A9 -> 7 | E12: ='[1](標單)詳細價目表'!B9 -> 施做抿石子(1~2分AK石，抿石子專用泥) | U12: ='[1](標單)詳細價目表'!C9 -> M2 | Y12: 38 | Z12: 38 | AA12: 38 | AB12: 38 | AC12: 38 | AD12: 38 | AE12: ='[1](標單)詳細價目表'!E9 -> 1460 | AK12: 0 | AQ12: =AK12*AE12 -> 0 | AW12: =AK12 -> 0 | BC12: =ROUND(AW12*AE12,0) -> 0 | BI12: =Y12*AE12 -> 55480
A13: ='[1](標單)詳細價目表'!A10 -> 8 | E13: ='[1](標單)詳細價目表'!B10 -> 無障礙坡道地坪拉毛 | U13: ='[1](標單)詳細價目表'!C10 -> M2 | Y13: 33 | Z13: 33 | AA13: 33 | AB13: 33 | AC13: 33 | AD13: 33 | AE13: ='[1](標單)詳細價目表'!E10 -> 100 | BI13: =Y13*AE13 -> 3300
A14: ='[1](標單)詳細價目表'!A11 -> 9 | E14: ='[1](標單)詳細價目表'!B11 -> 司令台既有樓梯面清潔，刷止滑漆(一底二度) | U14: ='[1](標單)詳細價目表'!C11 -> 式 | Y14: 1 | Z14: 1 | AA14: 1 | AB14: 1 | AC14: 1 | AD14: 1 | AE14: ='[1](標單)詳細價目表'!E11 -> 3000 | AK14: 0 | AQ14: =AK14*AE14 -> 0 | AW14: =AK14 -> 0 | BC14: =ROUND(AW14*AE14,0) -> 0 | BI14: =Y14*AE14 -> 3000
A15: ='[1](標單)詳細價目表'!A12 -> 10 | E15: ='[1](標單)詳細價目表'!B12 -> 校舍、教室及司令台坡道出入口配置無線押扣與插電式緊急求救鈴 | U15: ='[1](標單)詳細價目表'!C12 -> 組 | Y15: 8 | Z15: 8 | AA15: 8 | AB15: 8 | AC15: 8 | AD15: 8 | AE15: ='[1](標單)詳細價目表'!E12 -> 700 | AK15: 0 | AQ15: =AK15*AE15 -> 0 | AW15: =AK15 -> 0 | BC15: =ROUND(AW15*AE15,0) -> 0 | BI15: =Y15*AE15 -> 5600
A16: ='[1](標單)詳細價目表'!A13 -> 11 | E16: ='[1](標單)詳細價目表'!B13 -> 司令台周圍及無障礙坡道安裝不鏽鋼扶手(連工帶料) | U16: ='[1](標單)詳細價目表'!C13 -> M | Y16: 48 | Z16: 48 | AA16: 48 | AB16: 48 | AC16: 48 | AD16: 48 | AE16: ='[1](標單)詳細價目表'!E13 -> 3000 | AK16: 0 | AQ16: =AK16*AE16 -> 0 | AW16: =AK16 -> 0 | BC16: =ROUND(AW16*AE16,0) -> 0 | BI16: =Y16*AE16 -> 144000
A17: ='[1](標單)詳細價目表'!A15 -> 貳 | E17: ='[1](標單)詳細價目表'!B15 -> 職業安全衛生管理費與施工環境保護與清潔（壹*2%） | U17: ='[1](標單)詳細價目表'!C15 -> 式 | Y17: ='[1](標單)詳細價目表'!D15 -> 1 | AE17: ='[1](標單)詳細價目表'!E15 -> 8807 | AK17: 0.017 | AQ17: =AK17*AE17 -> 149.719 | AW17: =AK17 -> 0.017 | BC17: =ROUND(AW17*AE17,0) -> 150 | BI17: =Y17*AE17 -> 8807
A18: ='[1](標單)詳細價目表'!A16 -> 參 | E18: ='[1](標單)詳細價目表'!B16 -> 公共工程品質管制作業費（壹*1%） | U18: ='[1](標單)詳細價目表'!C16 -> 式 | Y18: ='[1](標單)詳細價目表'!D16 -> 1 | AE18: ='[1](標單)詳細價目表'!E16 -> 4404 | AK18: 0.017 | AQ18: =AK18*AE18 -> 74.868 | AW18: =AK18 -> 0.017 | BC18: =ROUND(AW18*AE18,0) -> 75 | BI18: =Y18*AE18 -> 4404
A19: ='[1](標單)詳細價目表'!A17 -> 肆 | E19: ='[1](標單)詳細價目表'!B17 -> 包商管理及利潤費（約壹*7%） | U19: ='[1](標單)詳細價目表'!C17 -> 式 | Y19: ='[1](標單)詳細價目表'!D17 -> 1 | AE19: ='[1](標單)詳細價目表'!E17 -> 30825 | AK19: 0.017 | AQ19: =AK19*AE19 -> 524.025 | AW19: =AK19 -> 0.017 | BC19: =ROUND(AW19*AE19,0) -> 524 | BI19: =Y19*AE19 -> 30825
A20: ='[1](標單)詳細價目表'!A18 -> 伍 | E20: ='[1](標單)詳細價目表'!B18 -> 營造綜合保險費 | U20: ='[1](標單)詳細價目表'!C18 -> 式 | Y20: ='[1](標單)詳細價目表'!D18 -> 1 | AE20: ='[1](標單)詳細價目表'!E18 -> 1321 | AK20: 1 | AQ20: =AK20*AE20 -> 1321 | AW20: =AK20 -> 1 | BC20: =ROUND(AW20*AE20,0) -> 1321 | BI20: =Y20*AE20 -> 1321
A21: ='[1](標單)詳細價目表'!A19 -> 陸 | E21: ='[1](標單)詳細價目表'!B19 -> 營業稅（(壹~伍)*5％） | U21: ='[1](標單)詳細價目表'!C19 -> 式 | Y21: ='[1](標單)詳細價目表'!D19 -> 1 | AE21: ='[1](標單)詳細價目表'!E19 -> 24286 | AK21: 0.017 | AQ21: =AK21*AE21 -> 412.862 | AW21: =AK21 -> 0.017 | BC21: =ROUND(AW21*AE21,0) -> 413 | BI21: =Y21*AE21 -> 24286
E22: 計 | AQ22: =SUM(AQ8:AQ21) -> 2482.474 | BC22: =SUM(BC8:BC21) -> 2483 | BI22: =SUM(BI6:BI21) -> 510000
BI23: =Y23*AE23 -> 0
A24: 累計完成進度=(累計完成金額÷契約金額)%= | AQ24: =BC22/BI22 -> 0.0048686275 | BI24: =AQ24 -> 0.0048686275
A25: 承 包 廠 商 | AE25: 負 責 人
A29: 和穩土木包工業
A30: 第二聯 | J30: 公共工程施工日誌
A31: 工程名稱： | I31: 雲林縣永定國小114年度改善無障礙校園環境工程 | AO31: 日期： | AW31: =AW3+1 -> 45911
A32: 項次 | E32: 工程項目 | U32: 單位 | Y32: 契約數量 | AE32: 契約單價 | AK32: 本日 完成數量 | AQ32: 本日 完成金額 | AW32: 累計 完成數量 | BC32: 累計 完成金額
A33: =A5 -> 壹 | E33: =E5 -> 直接工程費 | BI33: =Y33*AE33 -> 0
A34: =A6 -> 1 | E34: =E6 -> 工程告示牌與職安衛告示牌(租用) | U34: =U6 -> 式 | Y34: =Y6 -> 1 | AE34: =AE6 -> 5000 | AK34: 0 | AQ34: =AK34*AE34 -> 0 | AW34: =AW6+AK34 -> 1 | BC34: =ROUND(AW34*AE34,0) -> 5000 | BI34: =Y34*AE34 -> 5000
A35: =A7 -> 2 | E35: =E7 -> 三角錐與連桿(租用) | U35: =U7 -> M | Y35: =Y7 -> 86 | AE35: =AE7 -> 60 | AK35: 86 | AQ35: =AK35*AE35 -> 5160 | AW35: =AW7+AK35 -> 86 | BC35: =ROUND(AW35*AE35,0) -> 5160 | BI35: =Y35*AE35 -> 5160
A36: =A8 -> 3 | E36: =E8 -> 施工動線開闢及損害復原；測量與放樣 | U36: =U8 -> 式 | Y36: =Y8 -> 1 | AE36: =AE8 -> 4000 | AK36: 0.5 | AQ36: =AK36*AE36 -> 2000 | AW36: =AW8+AK36 -> 0.5 | BC36: =ROUND(AW36*AE36,0) -> 2000 | BI36: =Y36*AE36 -> 4000
A37: =A9 -> 4 | E37: =E9 -> 切割打除清運校舍與教室出入口地坪以及司令台階梯平台(含合法清運證明) | U37: =U9 -> 式 | Y37: =Y9 -> 1 | AE37: =AE9 -> 52817 | AK37: 0 | AQ37: =AK37*AE37 -> 0 | AW37: =AW9+AK37 -> 0 | BC37: =ROUND(AW37*AE37,0) -> 0 | BI37: =Y37*AE37 -> 52817
A38: =A10 -> 5 | E38: =E10 -> 校舍出入口施做斜坡順平高差 | U38: =U10 -> M2 | Y38: =Y10 -> 15 | AE38: =AE10 -> 600 | AK38: 0 | AQ38: =AK38*AE38 -> 0 | AW38: =AW10+AK38 -> 0 | BC38: =ROUND(AW38*AE38,0) -> 0 | BI38: =Y38*AE38 -> 9000
A39: =A11 -> 6 | E39: =E11 -> 開挖整地，新設無障礙RC坡道，牆面與地坪粉刷整平(連工帶料，責任施工) | U39: =U11 -> 式 | Y39: =Y11 -> 1 | AE39: =AE11 -> 153000 | AK39: 0 | AQ39: =AK39*AE39 -> 0 | AW39: =AW11+AK39 -> 0 | BC39: =ROUND(AW39*AE39,0) -> 0 | BI39: =Y39*AE39 -> 153000
A40: =A12 -> 7 | E40: =E12 -> 施做抿石子(1~2分AK石，抿石子專用泥) | U40: =U12 -> M2 | Y40: =Y12 -> 38 | AE40: =AE12 -> 1460 | AK40: 0 | AQ40: =AK40*AE40 -> 0 | AW40: =AW12+AK40 -> 0 | BC40: =ROUND(AW40*AE40,0) -> 0 | BI40: =Y40*AE40 -> 55480
A41: =A13 -> 8 | E41: =E13 -> 無障礙坡道地坪拉毛 | U41: =U13 -> M2 | Y41: =Y13 -> 33 | AE41: =AE13 -> 100 | AW41: =AW13+AK41 -> 0 | BI41: =Y41*AE41 -> 3300
A42: =A14 -> 9 | E42: =E14 -> 司令台既有樓梯面清潔，刷止滑漆(一底二度) | U42: =U14 -> 式 | Y42: =Y14 -> 1 | AE42: =AE14 -> 3000 | AK42: 0 | AQ42: =AK42*AE42 -> 0 | AW42: =AW14+AK42 -> 0 | BC42: =ROUND(AW42*AE42,0) -> 0 | BI42: =Y42*AE42 -> 3000
A43: =A15 -> 10 | E43: =E15 -> 校舍、教室及司令台坡道出入口配置無線押扣與插電式緊急求救鈴 | U43: =U15 -> 組 | Y43: =Y15 -> 8 | AE43: =AE15 -> 700 | AK43: 0 | AQ43: =AK43*AE43 -> 0 | AW43: =AW15+AK43 -> 0 | BC43: =ROUND(AW43*AE43,0) -> 0 | BI43: =Y43*AE43 -> 5600
...
