Workbook

Sheet 進度表
A1: 施 工 預 定 進 度 表 | Q1: =F3-$F3+1&"天-"&F3&"天" -> 1天-12天 | R1: =G3-$F3+1&"天-"&G3&"天" -> 13天-24天 | S1: =H3-$F3+1&"天-"&H3&"天" -> 25天-36天 | T1: =I3-$F3+1&"天-"&I3&"天" -> 37天-48天 | U1: =J3-$F3+1&"天-"&J3&"天" -> 49天-60天 | V1: =K3-$F3+1&"天-"&K3&"天" -> 61天-72天 | W1: =L3-$F3+1&"天-"&L3&"天" -> 73天-84天 | X1: =M3-$F3+1&"天-"&M3&"天" -> 85天-96天 | ... Z1: =O3-$F3+1&"天-"&O3&"天" -> 109天-120天
A2: 工程名稱：台西國中教學大樓西側廁所整修工程 | Q2: =F3-$F3+1 -> 1 | R2: =G3-$F3+1 -> 13 | S2: =H3-$F3+1 -> 25 | T2: =I3-$F3+1 -> 37 | U2: =J3-$F3+1 -> 49 | V2: =K3-$F3+1 -> 61 | W2: =L3-$F3+1 -> 73 | X2: =M3-$F3+1 -> 85 | ... Z2: =O3-$F3+1 -> 109
A3: 項 目 | C3: 金 額 | D3: 比 例 | E3: 日 | F3: 12 | G3: =F3+12 -> 24 | H3: =G3+12 -> 36 | I3: =H3+12 -> 48 | J3: =I3+12 -> 60 | K3: =J3+12 -> 72 | L3: =K3+12 -> 84 | M3: =L3+12 -> 96 | N3: =M3+12 -> 108 | O3: =N3+12 -> 120 | Q3: =F21/$F3 -> 0.0039800845 | R3: =G21/$F3 -> 0.0045638928 | S3: =H21/$F3 -> 0.0055316673 | T3: =I21/$F3 -> 0.0075267271 | U3: =J21/$F3 -> 0.0085842223 | V3: =K21/$F3 -> 0.0085842223 | W3: =L21/$F3 -> 0.01185291 | X3: =M21/$F3 -> 0.01185291 | ... Z3: =O21/$F3 -> 0.010041049
E4: 期
A5: 壹 | B5: 直接工程費
A6: 1 | B6: 假設及拆除 | C6: 342603 | D6: =C6/$C$20 -> 0.13949634 | F6: =$D6/4 -> 0.034874084 | G6: =$D6/4 -> 0.034874084 | H6: =$D6/4 -> 0.034874084 | I6: =$D6/4 -> 0.034874084
A7: 2 | B7: 地坪增築工程 | C7: 51618 | D7: =C7/$C$20 -> 0.021017101 | G7: =$D7/3 -> 0.0070057003 | H7: =$D7/3 -> 0.0070057003 | I7: =$D7/3 -> 0.0070057003
A8: 3 | B8: 砌磚工程 | C8: 114089 | D8: =C8/$C$20 -> 0.046453176 | H8: =$D8/4 -> 0.011613294 | I8: =$D8/4 -> 0.011613294 | J8: =$D8/4 -> 0.011613294 | K8: =$D8/4 -> 0.011613294
A9: 4 | B9: 水泥砂漿粉刷工程 | C9: 293992 | D9: =C9/$C$20 -> 0.11970358 | I9: =$D9/5 -> 0.023940717 | J9: =$D9/5 -> 0.023940717 | K9: =$D9/5 -> 0.023940717 | L9: =$D9/5 -> 0.023940717 | M9: =$D9/5 -> 0.023940717 | P9: =P10+0.1 -> 1
A10: 5 | B10: 防水工程 | C10: 114145 | D10: =C10/$C$20 -> 0.046475977 | J10: =$D10/5 -> 0.0092951954 | K10: =$D10/5 -> 0.0092951954 | L10: =$D10/5 -> 0.0092951954 | M10: =$D10/5 -> 0.0092951954 | N10: =$D10/5 -> 0.0092951954 | P10: =P11+0.1 -> 0.9
A11: 6 | B11: 磁磚工程 | C11: 444777 | D11: =C11/$C$20 -> 0.18109813 | J11: =$D11/4 -> 0.045274532 | K11: =$D11/4 -> 0.045274532 | L11: =$D11/4 -> 0.045274532 | M11: =$D11/4 -> 0.045274532 | P11: =P12+0.1 -> 0.8
A12: 7 | B12: 水泥漆工程 | C12: 58090 | D12: =C12/$C$20 -> 0.02365228 | L12: =$D12/2 -> 0.01182614 | M12: =$D12/2 -> 0.01182614 | P12: =P13+0.1 -> 0.7
A13: 8 | B13: 熱固性樹脂板工程 | C13: 336935 | D13: =C13/$C$20 -> 0.13718852 | N13: =$D$13/2 -> 0.068594259 | O13: =$D$13/2 -> 0.068594259 | P13: =P14+0.1 -> 0.6
A14: 9 | B14: 雜項工程 | C14: 383248 | D14: =C14/$C$20 -> 0.1560456 | L14: =$D$14/4 -> 0.039011401 | M14: =$D$14/4 -> 0.039011401 | N14: =$D$14/4 -> 0.039011401 | O14: =$D$14/4 -> 0.039011401 | P14: =P15+0.1 -> 0.5
A15: 貳 | B15: 職業安全衛生管理費(壹*1%) | C15: 21395 | D15: =C15/$C$20 -> 0.0087113192 | F15: =$D15/10 -> 0.00087113192 | G15: =$D15/10 -> 0.00087113192 | H15: =$D15/10 -> 0.00087113192 | I15: =$D15/10 -> 0.00087113192 | J15: =$D15/10 -> 0.00087113192 | K15: =$D15/10 -> 0.00087113192 | L15: =$D15/10 -> 0.00087113192 | M15: =$D15/10 -> 0.00087113192 | ... O15: =$D15/10 -> 0.00087113192 | P15: =P16+0.1 -> 0.4
A16: 參 | B16: 公共工程品質管制作業費(壹*1%) | C16: 21395 | D16: =C16/$C$20 -> 0.0087113192 | F16: =$D16/10 -> 0.00087113192 | G16: =$D16/10 -> 0.00087113192 | H16: =$D16/10 -> 0.00087113192 | I16: =$D16/10 -> 0.00087113192 | J16: =$D16/10 -> 0.00087113192 | K16: =$D16/10 -> 0.00087113192 | L16: =$D16/10 -> 0.00087113192 | M16: =$D16/10 -> 0.00087113192 | ... O16: =$D16/10 -> 0.00087113192 | P16: =P17+0.1 -> 0.3
A17: 肆 | B17: 包商利潤及管理費(約壹*7%) | C17: 149765 | D17: =C17/$C$20 -> 0.060979235 | F17: =$D17/10 -> 0.0060979235 | G17: =$D17/10 -> 0.0060979235 | H17: =$D17/10 -> 0.0060979235 | I17: =$D17/10 -> 0.0060979235 | J17: =$D17/10 -> 0.0060979235 | K17: =$D17/10 -> 0.0060979235 | L17: =$D17/10 -> 0.0060979235 | M17: =$D17/10 -> 0.0060979235 | ... O17: =$D17/10 -> 0.0060979235 | P17: =P18+0.1 -> 0.2
A18: 伍 | B18: 營造綜合保險費 | C18: 6996 | D18: =C18/$C$20 -> 0.0028485342 | F18: =$D18/10 -> 0.00028485342 | G18: =$D18/10 -> 0.00028485342 | H18: =$D18/10 -> 0.00028485342 | I18: =$D18/10 -> 0.00028485342 | J18: =$D18/10 -> 0.00028485342 | K18: =$D18/10 -> 0.00028485342 | L18: =$D18/10 -> 0.00028485342 | M18: =$D18/10 -> 0.00028485342 | ... O18: =$D18/10 -> 0.00028485342 | P18: =P19+0.1 -> 0.1
A19: 陸 | B19: 營業稅((壹~伍)*5%) | C19: 116952 | D19: =C19/$C$20 -> 0.047618893 | F19: =$D19/10 -> 0.0047618893 | G19: =$D19/10 -> 0.0047618893 | H19: =$D19/10 -> 0.0047618893 | I19: =$D19/10 -> 0.0047618893 | J19: =$D19/10 -> 0.0047618893 | K19: =$D19/10 -> 0.0047618893 | L19: =$D19/10 -> 0.0047618893 | M19: =$D19/10 -> 0.0047618893 | ... O19: =$D19/10 -> 0.0047618893 | P19: 0
C20: =SUM(C5:C19) -> 2456000 | D20: =SUM(D5:D19) -> 1
D21: 每月預訂進度 | F21: =SUM(F5:F19) -> 0.047761014 | G21: =SUM(G5:G19) -> 0.054766714 | H21: =SUM(H5:H19) -> 0.066380008 | I21: =SUM(I5:I19) -> 0.090320725 | J21: =SUM(J5:J19) -> 0.10301067 | K21: =SUM(K5:K19) -> 0.10301067 | L21: =SUM(L5:L19) -> 0.14223491 | M21: =SUM(M5:M19) -> 0.14223491 | ... O21: =SUM(O5:O19) -> 0.12049259
D22: 每月累計進度 | F22: =F21 -> 0.047761014 | G22: =F22+G21 -> 0.10252773 | H22: =G22+H21 -> 0.16890774 | I22: =H22+I21 -> 0.25922846 | J22: =I22+J21 -> 0.36223913 | K22: =J22+K21 -> 0.4652498 | L22: =K22+L21 -> 0.60748471 | M22: =L22+M21 -> 0.74971963 | N22: =M22+N21 -> 0.87950741 | O22: =N22+O21 -> 1
C23: 預定進度 | J23: 實際進度
A24: 承覽廠商：坤曜土木工程有限公司 | F24: 監造單位:呂罡銘建築師事務所 | K24: 主辦機關：雲林縣台西國民中學
Q27: =#REF!/10 -> #REF!

Sheet 日報表(7)
A1: 公 共 工 程 施 工 日 誌 | J1: 1
A2: 表報編號： | B2: 1 | J2: 1
A3: 本日天氣： | B3: 上午：晴 下午:晴 | E3: 46204 | J3: 1
A4: 工程名稱 | B4: 台西國中教學大樓西側廁所整修工程 | C4: 承攬廠商名稱 | E4: 坤曜土木工程有限公司 | J4: 1
A5: 核定工期 | B5: 120 | C5: 工期展延天數 | J5: 1
A6: 累計工期 | B6: =B2 -> 1 | C6: 剩餘工期 | E6: =B5-B6 -> 119 | J6: 1
A7: 開工日期 | B7: 46204 | C7: 完工日期 | E7: =B7+B5-1 -> 46323 | J7: 1
A8: 預定進度(%) | B8: =HLOOKUP(B2,進度表!$Q$2:$Z$3,2,1) -> 0.0039800845 | C8: 實際進度(%) | E8: =I46/I8 -> 0.0053524125 | H8: 契約金額 | I8: 2456000 | J8: 1
A9: 一、依施工計畫書執行按圖施工概況（含約定之重要施工項目及完成數量等）： | J9: 1
A10: 項 次 | B10: 施工項目 | C10: 單位 | D10: 契約數量 | E10: 本日完成數量 | F10: 累計完成數量 | G10: 備註 | H10: 單價 | I10: 本日完成金額 | J10: 1
A11: 壹 | B11: 直接工程費 | J11: 1
A12: 1 | B12: 工程告示牌與職安衛告示牌(租用)、施工圍籬、警示帶、安全警示燈等安全措施(租用) | C12: 式 | D12: 1 | E12: 1 | F12: =E12 -> 1 | H12: 10508 | I12: =H12*E12 -> 10508 | J12: 1
A13: 2 | B13: 施工動線開闢與損壞復原，既有設備管線遷移與復原；測量與放樣 | C13: 式 | D13: 1 | F13: =E13 -> 0 | H13: 13223 | I13: =H13*E13 -> 0 | J13: 1
A14: 3 | B14: 拆除(含切割)集中廁所既有牆面、地坪、磁磚、牆面小便斗與隔板、所有衛生設備、給排水設施、導擺及天花板等;廢棄物清運處理(含合法證明)與環境清潔 | C14: 式 | D14: 1 | F14: =E14 -> 0 | H14: 310497 | I14: =H14*E14 -> 0 | J14: 1
A15: 4 | B15: 既有污水處理設施抽水肥(含清潔孔開挖與復原) | C15: 式 | D15: 1 | F15: =E15 -> 0 | H15: 8375 | I15: =H15*E15 -> 0 | J15: 1
A16: 5 | B16: 地坪與台階增築 | C16: 式 | D16: 1 | F16: =E16 -> 0 | H16: 51618 | I16: =H16*E16 -> 0 | J16: 1
A17: 6 | B17: 砌1/2B磚牆 | C17: M2 | D17: 11.55 | F17: =E17 -> 0 | H17: 1188 | I17: =H17*E17 -> 0 | J17: 1
A18: 7 | B18: 施工範圍內樓板穿管處與既有無用穿管及孔洞需以水泥砂漿封閉並刷彈性砂漿防水塗膜；樓板防水層試水 | C18: 式 | D18: 1 | F18: =E18 -> 0 | H18: 21157 | I18: =H18*E18 -> 0 | J18: 1
A19: 8 | B19: 地坪、牆面1:3水泥砂漿粉刷 | C19: M2 | D19: 387 | F19: =E19 -> 0 | H19: 705 | I19: =H19*E19 -> 0 | J19: 1
A20: 9 | B20: 地坪及牆面(H=1.2m)防水層粉刷 | C20: M2 | D20: 170 | F20: =E20 -> 0 | H20: 617 | I20: =H20*E20 -> 0 | J20: 1
A21: 10 | B21: 不銹鋼方形地板落水頭(10*10cm,連工帶料) | C21: 組 | D21: 15 | F21: =E21 -> 0 | H21: 617 | I21: =H21*E21 -> 0 | J21: 1
A22: 11 | B22: 地坪貼止滑石英磚30*30cm，本色水泥抹縫(連工帶料) | C22: M2 | D22: 75 | F22: =E22 -> 0 | H22: 1146 | I22: =H22*E22 -> 0 | J22: 1
A23: 12 | B23: 地坪貼止滑石英磚60*60cm，本色水泥抹縫(連工帶料) | C23: M2 | D23: 5 | F23: =E23 -> 0 | H23: 1455 | I23: =H23*E23 -> 0 | J23: 1
A24: 13 | B24: 牆面貼石英磚30*60cm，白色水泥抹縫(連工帶料) | C24: M2 | D24: 217 | F24: =E24 -> 0 | H24: 1410 | I24: =H24*E24 -> 0 | J24: 1
... A40: 29 | B40: 門窗工程與雜項工程 | C40: 式 | D40: 1 | F40: =E40 -> 0 | H40: 34381 | I40: =H40*E40 -> 0 | J40: 1
A41: 貳 | B41: 職業安全衛生管理費(壹*1%) | C41: 式 | D41: 1 | E41: =1/120 -> 0.0083333333 | F41: =E41 -> 0.0083333333 | H41: 21395 | I41: =H41*E41 -> 178.29167 | J41: 1
A42: 參 | B42: 公共工程品質管制作業費(壹*1%) | C42: 式 | D42: 1 | E42: =1/120 -> 0.0083333333 | F42: =E42 -> 0.0083333333 | H42: 21395 | I42: =H42*E42 -> 178.29167 | J42: 1
A43: 肆 | B43: 包商利潤及管理費(約壹*7%) | C43: 式 | D43: 1 | E43: =1/120 -> 0.0083333333 | F43: =E43 -> 0.0083333333 | H43: 149765 | I43: =H43*E43 -> 1248.0417 | J43: 1
A44: 伍 | B44: 營造綜合保險費 | C44: 式 | D44: 1 | E44: =1/120 -> 0.0083333333 | F44: =E44 -> 0.0083333333 | H44: 6996 | I44: =H44*E44 -> 58.3 | J44: 1
A45: 陸 | B45: 營業稅((壹~伍)*5%) | C45: 式 | D45: 1 | E45: =1/120 -> 0.0083333333 | F45: =E45 -> 0.0083333333 | H45: 116952 | I45: =H45*E45 -> 974.6 | J45: 1
A46: 營照專業工程特定施工項目 | H46: 本日完成總金額 | I46: =SUM(I11:I45) -> 13145.525 | J46: 1
A47: A. | J47: 1
A48: B. | J48: 1
A49: 二、工地材料管理概況（含約定之重要材料使用狀況及數量等）； | J49: 1
A50: 材料名稱 | C50: 單位 | D50: 設計數量 | E50: 本日完成數量 | F50: 累計完成數量 | G50: 備註 | J50: 1
J51: 1
J52: 1
A53: 三、工地人員及機具管理(含約定之出工人數及機具使用情形及數量)： | J53: 2
A54: 工別 | B54: 本日人數 | C54: 累計人數 | E54: 機具名稱 | F54: 本日使用數量 | G54: 累計使用數量 | J54: 2
A55: 大工 | C55: =B55 -> 0 | J55: 2
...

Sheet 日報表(8)
A1: 公 共 工 程 施 工 日 誌 | J1: 1
A2: 表報編號： | B2: 2 | J2: 1
A3: 本日天氣： | B3: 上午：晴 下午:晴 | E3: 46204 | J3: 1
A4: 工程名稱 | B4: 台西國中教學大樓西側廁所整修工程 | C4: 承攬廠商名稱 | E4: 坤曜土木工程有限公司 | J4: 1
A5: 核定工期 | B5: 120 | C5: 工期展延天數 | J5: 1
A6: 累計工期 | B6: =B2 -> 2 | C6: 剩餘工期 | E6: =B5-B6 -> 118 | J6: 1
A7: 開工日期 | B7: 46204 | C7: 完工日期 | E7: =B7+B5-1 -> 46323 | J7: 1
A8: 預定進度(%) | B8: =HLOOKUP(B2,進度表!$Q$2:$Z$3,2,1)+#REF! -> #REF! | C8: 實際進度(%) | E8: =I46/I8+#REF! -> #REF! | H8: 契約金額 | I8: 2456000 | J8: 1
A9: 一、依施工計畫書執行按圖施工概況（含約定之重要施工項目及完成數量等）： | J9: 1
A10: 項 次 | B10: 施工項目 | C10: 單位 | D10: 契約數量 | E10: 本日完成數量 | F10: 累計完成數量 | G10: 備註 | H10: 單價 | I10: 本日完成金額 | J10: 1
A11: 壹 | B11: 直接工程費 | J11: 1
A12: 1 | B12: 工程告示牌與職安衛告示牌(租用)、施工圍籬、警示帶、安全警示燈等安全措施(租用) | C12: 式 | D12: 1 | F12: =E12+#REF! -> #REF! | H12: 10508 | I12: =H12*E12 -> 0 | J12: 1
A13: 2 | B13: 施工動線開闢與損壞復原，既有設備管線遷移與復原；測量與放樣 | C13: 式 | D13: 1 | F13: =E13+#REF! -> #REF! | H13: 13223 | I13: =H13*E13 -> 0 | J13: 1
A14: 3 | B14: 拆除(含切割)集中廁所既有牆面、地坪、磁磚、牆面小便斗與隔板、所有衛生設備、給排水設施、導擺及天花板等;廢棄物清運處理(含合法證明)與環境清潔 | C14: 式 | D14: 1 | F14: =E14+#REF! -> #REF! | H14: 310497 | I14: =H14*E14 -> 0 | J14: 1
A15: 4 | B15: 既有污水處理設施抽水肥(含清潔孔開挖與復原) | C15: 式 | D15: 1 | F15: =E15+#REF! -> #REF! | H15: 8375 | I15: =H15*E15 -> 0 | J15: 1
A16: 5 | B16: 地坪與台階增築 | C16: 式 | D16: 1 | F16: =E16+#REF! -> #REF! | H16: 51618 | I16: =H16*E16 -> 0 | J16: 1
A17: 6 | B17: 砌1/2B磚牆 | C17: M2 | D17: 11.55 | F17: =E17+#REF! -> #REF! | H17: 1188 | I17: =H17*E17 -> 0 | J17: 1
A18: 7 | B18: 施工範圍內樓板穿管處與既有無用穿管及孔洞需以水泥砂漿封閉並刷彈性砂漿防水塗膜；樓板防水層試水 | C18: 式 | D18: 1 | F18: =E18+#REF! -> #REF! | H18: 21157 | I18: =H18*E18 -> 0 | J18: 1
A19: 8 | B19: 地坪、牆面1:3水泥砂漿粉刷 | C19: M2 | D19: 387 | F19: =E19+#REF! -> #REF! | H19: 705 | I19: =H19*E19 -> 0 | J19: 1
A20: 9 | B20: 地坪及牆面(H=1.2m)防水層粉刷 | C20: M2 | D20: 170 | F20: =E20+#REF! -> #REF! | H20: 617 | I20: =H20*E20 -> 0 | J20: 1
A21: 10 | B21: 不銹鋼方形地板落水頭(10*10cm,連工帶料) | C21: 組 | D21: 15 | F21: =E21+#REF! -> #REF! | H21: 617 | I21: =H21*E21 -> 0 | J21: 1
A22: 11 | B22: 地坪貼止滑石英磚30*30cm，本色水泥抹縫(連工帶料) | C22: M2 | D22: 75 | F22: =E22+#REF! -> #REF! | H22: 1146 | I22: =H22*E22 -> 0 | J22: 1
A23: 12 | B23: 地坪貼止滑石英磚60*60cm，本色水泥抹縫(連工帶料) | C23: M2 | D23: 5 | F23: =E23+#REF! -> #REF! | H23: 1455 | I23: =H23*E23 -> 0 | J23: 1
... A40: 29 | B40: 門窗工程與雜項工程 | C40: 式 | D40: 1 | F40: =E40+#REF! -> #REF! | H40: 34381 | I40: =H40*E40 -> 0 | J40: 1
A41: 貳 | B41: 職業安全衛生管理費(壹*1%) | C41: 式 | D41: 1 | E41: =1/120 -> 0.0083333333 | F41: =E41+#REF! -> #REF! | H41: 21395 | I41: =H41*E41 -> 178.29167 | J41: 1
A42: 參 | B42: 公共工程品質管制作業費(壹*1%) | C42: 式 | D42: 1 | E42: =1/120 -> 0.0083333333 | F42: =E42+#REF! -> #REF! | H42: 21395 | I42: =H42*E42 -> 178.29167 | J42: 1
A43: 肆 | B43: 包商利潤及管理費(約壹*7%) | C43: 式 | D43: 1 | E43: =1/120 -> 0.0083333333 | F43: =E43+#REF! -> #REF! | H43: 149765 | I43: =H43*E43 -> 1248.0417 | J43: 1
A44: 伍 | B44: 營造綜合保險費 | C44: 式 | D44: 1 | E44: =1/120 -> 0.0083333333 | F44: =E44+#REF! -> #REF! | H44: 6996 | I44: =H44*E44 -> 58.3 | J44: 1
A45: 陸 | B45: 營業稅((壹~伍)*5%) | C45: 式 | D45: 1 | E45: =1/120 -> 0.0083333333 | F45: =E45+#REF! -> #REF! | H45: 116952 | I45: =H45*E45 -> 974.6 | J45: 1
A46: 營照專業工程特定施工項目 | H46: 本日完成總金額 | I46: =SUM(I11:I45) -> 2637.525 | J46: 1
A47: A. | J47: 1
A48: B. | J48: 1
A49: 二、工地材料管理概況（含約定之重要材料使用狀況及數量等）； | J49: 1
A50: 材料名稱 | C50: 單位 | D50: 設計數量 | E50: 本日完成數量 | F50: 累計完成數量 | G50: 備註 | J50: 1
J51: 1
J52: 1
A53: 三、工地人員及機具管理(含約定之出工人數及機具使用情形及數量)： | J53: 2
A54: 工別 | B54: 本日人數 | C54: 累計人數 | E54: 機具名稱 | F54: 本日使用數量 | G54: 累計使用數量 | J54: 2
A55: 大工 | C55: =B55+#REF! -> #REF! | J55: 2
A56: 小工 | C56: =B56+#REF! -> #REF! | J56: 2
...

Sheet 日報表(9)
A1: 公 共 工 程 施 工 日 誌 | J1: 1
A2: 表報編號： | B2: 2 | J2: 1
A3: 本日天氣： | B3: 上午：晴 下午:晴 | E3: 46204 | J3: 1
A4: 工程名稱 | B4: 台西國中教學大樓西側廁所整修工程 | C4: 承攬廠商名稱 | E4: 坤曜土木工程有限公司 | J4: 1
A5: 核定工期 | B5: 120 | C5: 工期展延天數 | J5: 1
A6: 累計工期 | B6: =B2 -> 2 | C6: 剩餘工期 | E6: =B5-B6 -> 118 | J6: 1
A7: 開工日期 | B7: 46204 | C7: 完工日期 | E7: =B7+B5-1 -> 46323 | J7: 1
A8: 預定進度(%) | B8: =HLOOKUP(B2,進度表!$Q$2:$Z$3,2,1)+#REF! -> #REF! | C8: 實際進度(%) | E8: =I46/I8+#REF! -> #REF! | H8: 契約金額 | I8: 2456000 | J8: 1
A9: 一、依施工計畫書執行按圖施工概況（含約定之重要施工項目及完成數量等）： | J9: 1
A10: 項 次 | B10: 施工項目 | C10: 單位 | D10: 契約數量 | E10: 本日完成數量 | F10: 累計完成數量 | G10: 備註 | H10: 單價 | I10: 本日完成金額 | J10: 1
A11: 壹 | B11: 直接工程費 | J11: 1
A12: 1 | B12: 工程告示牌與職安衛告示牌(租用)、施工圍籬、警示帶、安全警示燈等安全措施(租用) | C12: 式 | D12: 1 | F12: =E12+#REF! -> #REF! | H12: 10508 | I12: =H12*E12 -> 0 | J12: 1
A13: 2 | B13: 施工動線開闢與損壞復原，既有設備管線遷移與復原；測量與放樣 | C13: 式 | D13: 1 | F13: =E13+#REF! -> #REF! | H13: 13223 | I13: =H13*E13 -> 0 | J13: 1
A14: 3 | B14: 拆除(含切割)集中廁所既有牆面、地坪、磁磚、牆面小便斗與隔板、所有衛生設備、給排水設施、導擺及天花板等;廢棄物清運處理(含合法證明)與環境清潔 | C14: 式 | D14: 1 | F14: =E14+#REF! -> #REF! | H14: 310497 | I14: =H14*E14 -> 0 | J14: 1
A15: 4 | B15: 既有污水處理設施抽水肥(含清潔孔開挖與復原) | C15: 式 | D15: 1 | F15: =E15+#REF! -> #REF! | H15: 8375 | I15: =H15*E15 -> 0 | J15: 1
A16: 5 | B16: 地坪與台階增築 | C16: 式 | D16: 1 | F16: =E16+#REF! -> #REF! | H16: 51618 | I16: =H16*E16 -> 0 | J16: 1
A17: 6 | B17: 砌1/2B磚牆 | C17: M2 | D17: 11.55 | F17: =E17+#REF! -> #REF! | H17: 1188 | I17: =H17*E17 -> 0 | J17: 1
A18: 7 | B18: 施工範圍內樓板穿管處與既有無用穿管及孔洞需以水泥砂漿封閉並刷彈性砂漿防水塗膜；樓板防水層試水 | C18: 式 | D18: 1 | F18: =E18+#REF! -> #REF! | H18: 21157 | I18: =H18*E18 -> 0 | J18: 1
A19: 8 | B19: 地坪、牆面1:3水泥砂漿粉刷 | C19: M2 | D19: 387 | F19: =E19+#REF! -> #REF! | H19: 705 | I19: =H19*E19 -> 0 | J19: 1
A20: 9 | B20: 地坪及牆面(H=1.2m)防水層粉刷 | C20: M2 | D20: 170 | F20: =E20+#REF! -> #REF! | H20: 617 | I20: =H20*E20 -> 0 | J20: 1
A21: 10 | B21: 不銹鋼方形地板落水頭(10*10cm,連工帶料) | C21: 組 | D21: 15 | F21: =E21+#REF! -> #REF! | H21: 617 | I21: =H21*E21 -> 0 | J21: 1
A22: 11 | B22: 地坪貼止滑石英磚30*30cm，本色水泥抹縫(連工帶料) | C22: M2 | D22: 75 | F22: =E22+#REF! -> #REF! | H22: 1146 | I22: =H22*E22 -> 0 | J22: 1
A23: 12 | B23: 地坪貼止滑石英磚60*60cm，本色水泥抹縫(連工帶料) | C23: M2 | D23: 5 | F23: =E23+#REF! -> #REF! | H23: 1455 | I23: =H23*E23 -> 0 | J23: 1
... A40: 29 | B40: 門窗工程與雜項工程 | C40: 式 | D40: 1 | F40: =E40+#REF! -> #REF! | H40: 34381 | I40: =H40*E40 -> 0 | J40: 1
A41: 貳 | B41: 職業安全衛生管理費(壹*1%) | C41: 式 | D41: 1 | E41: =1/120 -> 0.0083333333 | F41: =E41+#REF! -> #REF! | H41: 21395 | I41: =H41*E41 -> 178.29167 | J41: 1
A42: 參 | B42: 公共工程品質管制作業費(壹*1%) | C42: 式 | D42: 1 | E42: =1/120 -> 0.0083333333 | F42: =E42+#REF! -> #REF! | H42: 21395 | I42: =H42*E42 -> 178.29167 | J42: 1
A43: 肆 | B43: 包商利潤及管理費(約壹*7%) | C43: 式 | D43: 1 | E43: =1/120 -> 0.0083333333 | F43: =E43+#REF! -> #REF! | H43: 149765 | I43: =H43*E43 -> 1248.0417 | J43: 1
A44: 伍 | B44: 營造綜合保險費 | C44: 式 | D44: 1 | E44: =1/120 -> 0.0083333333 | F44: =E44+#REF! -> #REF! | H44: 6996 | I44: =H44*E44 -> 58.3 | J44: 1
A45: 陸 | B45: 營業稅((壹~伍)*5%) | C45: 式 | D45: 1 | E45: =1/120 -> 0.0083333333 | F45: =E45+#REF! -> #REF! | H45: 116952 | I45: =H45*E45 -> 974.6 | J45: 1
A46: 營照專業工程特定施工項目 | H46: 本日完成總金額 | I46: =SUM(I11:I45) -> 2637.525 | J46: 1
A47: A. | J47: 1
A48: B. | J48: 1
A49: 二、工地材料管理概況（含約定之重要材料使用狀況及數量等）； | J49: 1
A50: 材料名稱 | C50: 單位 | D50: 設計數量 | E50: 本日完成數量 | F50: 累計完成數量 | G50: 備註 | J50: 1
J51: 1
J52: 1
A53: 三、工地人員及機具管理(含約定之出工人數及機具使用情形及數量)： | J53: 2
A54: 工別 | B54: 本日人數 | C54: 累計人數 | E54: 機具名稱 | F54: 本日使用數量 | G54: 累計使用數量 | J54: 2
A55: 大工 | C55: =B55+#REF! -> #REF! | J55: 2
A56: 小工 | C56: =B56+#REF! -> #REF! | J56: 2
...

Sheet 日報表(10)
A1: 公 共 工 程 施 工 日 誌 | J1: 1
A2: 表報編號： | B2: 2 | J2: 1
A3: 本日天氣： | B3: 上午：晴 下午:晴 | E3: 46204 | J3: 1
A4: 工程名稱 | B4: 台西國中教學大樓西側廁所整修工程 | C4: 承攬廠商名稱 | E4: 坤曜土木工程有限公司 | J4: 1
A5: 核定工期 | B5: 120 | C5: 工期展延天數 | J5: 1
A6: 累計工期 | B6: =B2 -> 2 | C6: 剩餘工期 | E6: =B5-B6 -> 118 | J6: 1
A7: 開工日期 | B7: 46204 | C7: 完工日期 | E7: =B7+B5-1 -> 46323 | J7: 1
A8: 預定進度(%) | B8: =HLOOKUP(B2,進度表!$Q$2:$Z$3,2,1)+#REF! -> #REF! | C8: 實際進度(%) | E8: =I46/I8+#REF! -> #REF! | H8: 契約金額 | I8: 2456000 | J8: 1
A9: 一、依施工計畫書執行按圖施工概況（含約定之重要施工項目及完成數量等）： | J9: 1
A10: 項 次 | B10: 施工項目 | C10: 單位 | D10: 契約數量 | E10: 本日完成數量 | F10: 累計完成數量 | G10: 備註 | H10: 單價 | I10: 本日完成金額 | J10: 1
A11: 壹 | B11: 直接工程費 | J11: 1
A12: 1 | B12: 工程告示牌與職安衛告示牌(租用)、施工圍籬、警示帶、安全警示燈等安全措施(租用) | C12: 式 | D12: 1 | F12: =E12+#REF! -> #REF! | H12: 10508 | I12: =H12*E12 -> 0 | J12: 1
A13: 2 | B13: 施工動線開闢與損壞復原，既有設備管線遷移與復原；測量與放樣 | C13: 式 | D13: 1 | F13: =E13+#REF! -> #REF! | H13: 13223 | I13: =H13*E13 -> 0 | J13: 1
A14: 3 | B14: 拆除(含切割)集中廁所既有牆面、地坪、磁磚、牆面小便斗與隔板、所有衛生設備、給排水設施、導擺及天花板等;廢棄物清運處理(含合法證明)與環境清潔 | C14: 式 | D14: 1 | F14: =E14+#REF! -> #REF! | H14: 310497 | I14: =H14*E14 -> 0 | J14: 1
A15: 4 | B15: 既有污水處理設施抽水肥(含清潔孔開挖與復原) | C15: 式 | D15: 1 | F15: =E15+#REF! -> #REF! | H15: 8375 | I15: =H15*E15 -> 0 | J15: 1
A16: 5 | B16: 地坪與台階增築 | C16: 式 | D16: 1 | F16: =E16+#REF! -> #REF! | H16: 51618 | I16: =H16*E16 -> 0 | J16: 1
A17: 6 | B17: 砌1/2B磚牆 | C17: M2 | D17: 11.55 | F17: =E17+#REF! -> #REF! | H17: 1188 | I17: =H17*E17 -> 0 | J17: 1
A18: 7 | B18: 施工範圍內樓板穿管處與既有無用穿管及孔洞需以水泥砂漿封閉並刷彈性砂漿防水塗膜；樓板防水層試水 | C18: 式 | D18: 1 | F18: =E18+#REF! -> #REF! | H18: 21157 | I18: =H18*E18 -> 0 | J18: 1
A19: 8 | B19: 地坪、牆面1:3水泥砂漿粉刷 | C19: M2 | D19: 387 | F19: =E19+#REF! -> #REF! | H19: 705 | I19: =H19*E19 -> 0 | J19: 1
A20: 9 | B20: 地坪及牆面(H=1.2m)防水層粉刷 | C20: M2 | D20: 170 | F20: =E20+#REF! -> #REF! | H20: 617 | I20: =H20*E20 -> 0 | J20: 1
A21: 10 | B21: 不銹鋼方形地板落水頭(10*10cm,連工帶料) | C21: 組 | D21: 15 | F21: =E21+#REF! -> #REF! | H21: 617 | I21: =H21*E21 -> 0 | J21: 1
A22: 11 | B22: 地坪貼止滑石英磚30*30cm，本色水泥抹縫(連工帶料) | C22: M2 | D22: 75 | F22: =E22+#REF! -> #REF! | H22: 1146 | I22: =H22*E22 -> 0 | J22: 1
A23: 12 | B23: 地坪貼止滑石英磚60*60cm，本色水泥抹縫(連工帶料) | C23: M2 | D23: 5 | F23: =E23+#REF! -> #REF! | H23: 1455 | I23: =H23*E23 -> 0 | J23: 1
... A40: 29 | B40: 門窗工程與雜項工程 | C40: 式 | D40: 1 | F40: =E40+#REF! -> #REF! | H40: 34381 | I40: =H40*E40 -> 0 | J40: 1
A41: 貳 | B41: 職業安全衛生管理費(壹*1%) | C41: 式 | D41: 1 | E41: =1/120 -> 0.0083333333 | F41: =E41+#REF! -> #REF! | H41: 21395 | I41: =H41*E41 -> 178.29167 | J41: 1
A42: 參 | B42: 公共工程品質管制作業費(壹*1%) | C42: 式 | D42: 1 | E42: =1/120 -> 0.0083333333 | F42: =E42+#REF! -> #REF! | H42: 21395 | I42: =H42*E42 -> 178.29167 | J42: 1
A43: 肆 | B43: 包商利潤及管理費(約壹*7%) | C43: 式 | D43: 1 | E43: =1/120 -> 0.0083333333 | F43: =E43+#REF! -> #REF! | H43: 149765 | I43: =H43*E43 -> 1248.0417 | J43: 1
A44: 伍 | B44: 營造綜合保險費 | C44: 式 | D44: 1 | E44: =1/120 -> 0.0083333333 | F44: =E44+#REF! -> #REF! | H44: 6996 | I44: =H44*E44 -> 58.3 | J44: 1
A45: 陸 | B45: 營業稅((壹~伍)*5%) | C45: 式 | D45: 1 | E45: =1/120 -> 0.0083333333 | F45: =E45+#REF! -> #REF! | H45: 116952 | I45: =H45*E45 -> 974.6 | J45: 1
A46: 營照專業工程特定施工項目 | H46: 本日完成總金額 | I46: =SUM(I11:I45) -> 2637.525 | J46: 1
A47: A. | J47: 1
A48: B. | J48: 1
A49: 二、工地材料管理概況（含約定之重要材料使用狀況及數量等）； | J49: 1
A50: 材料名稱 | C50: 單位 | D50: 設計數量 | E50: 本日完成數量 | F50: 累計完成數量 | G50: 備註 | J50: 1
J51: 1
J52: 1
A53: 三、工地人員及機具管理(含約定之出工人數及機具使用情形及數量)： | J53: 2
A54: 工別 | B54: 本日人數 | C54: 累計人數 | E54: 機具名稱 | F54: 本日使用數量 | G54: 累計使用數量 | J54: 2
A55: 大工 | C55: =B55+#REF! -> #REF! | J55: 2
A56: 小工 | C56: =B56+#REF! -> #REF! | J56: 2
...
