Workbook

Sheet 9月
A1: 公共工程施工日誌
A2: 表報編號： | B2: 1
A3: 本日天氣：上午：晴 下午：晴 | H3: 填表日期： | K3: 45927
A4: 工程名稱 | D4: 光明國中B與C區5樓老舊廁所整修工程 | H4: 承攬廠商名稱 | K4: 利成營造有限公司
A5: 核定工期 | B5: 130 | C5: 天 | D5: 累計工期 | F5: 1 | G5: 天 | H5: 剩餘工期 | I5: =+B5-F5 -> 129 | J5: 天 | K5: 工期展延天數 | M5: 0
A6: 開工日期 | D6: 114.9.27 | H6: 完工日期 | K6: 115.2.3
A7: 預定進度(%) | D7: 0.01 | H7: 實際進度(%) | K7: =0.5%+0.5%+1.5% -> 0.025
A8: 一、依施工計畫書執行按圖施工概況（含約定之重要施工項目及完成數量等）：
A9: 施工項目 | E9: 單位 | F9: 契約數量 | H9: 本日完成數量 | J9: 累計完成數量 | L9: 備註
A10: 乙種施工圍籬、警示帶、安全警示燈等安全措施 | E10: 式 | F10: 1 | H10: 1 | J10: 1
A11: 工程告示牌與職安衛告示牌 | E11: 式 | F11: 1 | H11: 1 | J11: 1
A12: 既有地坪、磁磚、衛生設備、給排水設施、搗擺及天花板等拆除;工區下方廁所保護措施與清潔復原;環境保護與清潔 | E12: 式 | F12: 1 | H12: 0.1 | J12: 0.1
A15: 二、工地材料管理概況（含約定之重要材料使用狀況及數量等）：
A16: 材料名稱 | E16: 單位 | F16: 契約數量 | H16: 本日使用數量 | J16: 累計使用數量 | L16: 備註
A19: 三、工地人員及機具管理（含約定之出工人數及機具使用情形及數量）：
A20: 工別 | C20: 本日人數 | E20: 累計人數 | H20: 機具名稱 | J20: 本日使用數量 | L20: 累計使用數量
A21: 普通工 | C21: 2 | E21: 2
A22: 體力工 | C22: 6 | E22: 6
A23: 四、本日施工項目是否有須依「營造業專業工程特定施工項目應置之技術士種類、比率或人數標準表」規定應設置技術士之專業工程：□有 ■無（此項如勾選”有”，則應填寫後附「公共工程施工日誌之技術士簽章表」）
A24: 五、工地職業安全衛生事項之督導、公共環境與安全之維護及其他工地行政事務：
A25: (ㄧ)施工前檢查事項：
A26: 1.實施勤前教育(含工地預防災變及危害告知)：■有 □無
A27: 2.確認新進勞工是否提報勞工保險(或其他商業保險)資料及安全衛生教育訓練紀錄：□有 □無
A28: ■無新進勞工
A29: 3.檢查勞工個人防護具：■有 □無
A30: (二)其他事項：
A32: 六、施工取樣試驗紀錄：
A33: 七、通知協力廠商辦理事項：
A34: 八、重要事項記錄：1.申報本日開工 2.廁所舊有設備拆除
A35: 簽章：【工地負責人】（註3）：
... A45: 公共工程施工日誌
A46: 表報編號： | B46: =+B2+1 -> 2
A47: 本日天氣：上午：晴 下午：晴 | H47: 填表日期： | K47: =+K3+1 -> 45928
A48: 工程名稱 | D48: =+D4 -> 光明國中B與C區5樓老舊廁所整修工程 | H48: 承攬廠商名稱 | K48: 利成營造有限公司
A49: 核定工期 | B49: =+B5 -> 130 | C49: 天 | D49: 累計工期 | F49: =+F5+1 -> 2 | G49: 天 | H49: 剩餘工期 | I49: =+B49-F49 -> 128 | J49: 天 | K49: 工期展延天數 | M49: =+M5 -> 0
A50: 開工日期 | D50: =+D6 -> 114.9.27 | H50: 完工日期 | K50: =+K6 -> 115.2.3
A51: 預定進度(%) | D51: 0.012 | H51: 實際進度(%) | K51: =+K7+1.5% -> 0.04
A52: 一、依施工計畫書執行按圖施工概況（含約定之重要施工項目及完成數量等）：
A53: 施工項目 | E53: 單位 | F53: 契約數量 | H53: 本日完成數量 | J53: 累計完成數量 | L53: 備註
A54: 既有地坪、磁磚、衛生設備、給排水設施、搗擺及天花板等拆除;工區下方廁所保護措施與清潔復原;環境保護與清潔 | E54: 式 | F54: 1 | H54: 0.1 | J54: 0.2
...

Sheet 10月
A1: 公共工程施工日誌
A2: 表報編號： | B2: =+'9月'!B134+1 -> 5
A3: 本日天氣：上午：晴 下午：晴 | H3: 填表日期： | K3: 45931
A4: 工程名稱 | D4: 光明國中B與C區5樓老舊廁所整修工程 | H4: 承攬廠商名稱 | K4: 利成營造有限公司
A5: 核定工期 | B5: =+'9月'!B137+1 -> 132 | C5: 天 | D5: 累計工期 | F5: =+'9月'!F137+1 -> 5 | G5: 天 | H5: 剩餘工期 | I5: =+B5-F5 -> 127 | J5: 天 | K5: 工期展延天數 | M5: =+'9月'!M137+1 -> 2
A6: 開工日期 | D6: =+'9月'!D138:G138 -> 114.9.27 | H6: 完工日期 | K6: 114.2.5
A7: 預定進度(%) | D7: 0.018 | H7: 實際進度(%) | K7: =+'9月'!K139:M139 -> 0.058
A8: 一、依施工計畫書執行按圖施工概況（含約定之重要施工項目及完成數量等）：
A9: 施工項目 | E9: 單位 | F9: 契約數量 | H9: 本日完成數量 | J9: 累計完成數量 | L9: 備註
A12: 營造業專業工程特定施工項目
A13: A.
A14: B.
A15: 二、工地材料管理概況（含約定之重要材料使用狀況及數量等）：
A16: 材料名稱 | E16: 單位 | F16: 契約數量 | H16: 本日使用數量 | J16: 累計使用數量 | L16: 備註
A19: 三、工地人員及機具管理（含約定之出工人數及機具使用情形及數量）：
A20: 工別 | C20: 本日人數 | E20: 累計人數 | H20: 機具名稱 | J20: 本日使用數量 | L20: 累計使用數量
A23: 四、本日施工項目是否有須依「營造業專業工程特定施工項目應置之技術士種類、比率或人數標準表」規定應設置技術士之專業工程：□有 □無（此項如勾選”有”，則應填寫後附「公共工程施工日誌之技術士簽章表」）
A24: 五、工地職業安全衛生事項之督導、公共環境與安全之維護及其他工地行政事務：
A25: (ㄧ)施工前檢查事項：
A26: 1.實施勤前教育(含工地預防災變及危害告知)：□有 □無
A27: 2.確認新進勞工是否提報勞工保險(或其他商業保險)資料及安全衛生教育訓練紀錄：□有 □無
A28: □無新進勞工
A29: 3.檢查勞工個人防護具：□有 □無
A30: (二)其他事項：
A32: 六、施工取樣試驗紀錄：
A33: 七、通知協力廠商辦理事項：
A34: 八、重要事項記錄：1.本日無施工 2.依據9月22日施工協調會紀錄,校方同意開工日起前4周上班日予以不計工期。
A35: 簽章：【工地負責人】（註3）：
... A45: 公共工程施工日誌
A46: 表報編號： | B46: =+B2+1 -> 6
A47: 本日天氣：上午：晴 下午：晴 | H47: 填表日期： | K47: =+K3+1 -> 45932
A48: 工程名稱 | D48: =+D4 -> 光明國中B與C區5樓老舊廁所整修工程 | H48: 承攬廠商名稱 | K48: 利成營造有限公司
A49: 核定工期 | B49: =+B5+1 -> 133 | C49: 天 | D49: 累計工期 | F49: =+F5+1 -> 6 | G49: 天 | H49: 剩餘工期 | I49: =+B49-F49 -> 127 | J49: 天 | K49: 工期展延天數 | M49: =+M5+1 -> 3
A50: 開工日期 | D50: =+D6 -> 114.9.27 | H50: 完工日期 | K50: 115.2.6
A51: 預定進度(%) | D51: 0.02 | H51: 實際進度(%) | K51: =+K7 -> 0.058
A52: 一、依施工計畫書執行按圖施工概況（含約定之重要施工項目及完成數量等）：
A53: 施工項目 | E53: 單位 | F53: 契約數量 | H53: 本日完成數量 | J53: 累計完成數量 | L53: 備註
A56: 營造業專業工程特定施工項目
A57: A.
A58: B.
...

Sheet 11月
A1: 公共工程施工日誌
A2: 表報編號： | B2: =+'10月'!B1322+1 -> 36
A3: 本日天氣：上午：晴 下午：晴 | H3: 填表日期： | K3: 45962
A4: 工程名稱 | D4: 光明國中B與C區5樓老舊廁所整修工程 | H4: 承攬廠商名稱 | K4: 利成營造有限公司
A5: 核定工期 | B5: =+'10月'!B1325 -> 142 | C5: 天 | D5: 累計工期 | F5: =+'10月'!F1325+1 -> 36 | G5: 天 | H5: 剩餘工期 | I5: =+B5-F5 -> 106 | J5: 天 | K5: 工期展延天數 | M5: =+'10月'!M1325 -> 12
A6: 開工日期 | D6: =+'9月'!D138:G138 -> 114.9.27 | H6: 完工日期 | K6: =+'10月'!K1326:M1326 -> 115.2.15
A7: 預定進度(%) | D7: 0.12 | H7: 實際進度(%) | K7: =+'10月'!K1327:M1327+0.3% -> 0.177
A8: 一、依施工計畫書執行按圖施工概況（含約定之重要施工項目及完成數量等）：
A9: 施工項目 | E9: 單位 | F9: 契約數量 | H9: 本日完成數量 | J9: 累計完成數量 | L9: 備註
A10: 給排水系統配管與安裝 | E10: 式 | F10: 1 | H10: 0.05 | J10: 0.65
A12: 營造業專業工程特定施工項目
A13: A.
A14: B.
A15: 二、工地材料管理概況（含約定之重要材料使用狀況及數量等）：
A16: 材料名稱 | E16: 單位 | F16: 契約數量 | H16: 本日使用數量 | J16: 累計使用數量 | L16: 備註
A19: 三、工地人員及機具管理（含約定之出工人數及機具使用情形及數量）：
A20: 工別 | C20: 本日人數 | E20: 累計人數 | H20: 機具名稱 | J20: 本日使用數量 | L20: 累計使用數量
A21: 水電工 | C21: 1 | E21: 20
A23: 四、本日施工項目是否有須依「營造業專業工程特定施工項目應置之技術士種類、比率或人數標準表」規定應設置技術士之專業工程：□有 ■無（此項如勾選”有”，則應填寫後附「公共工程施工日誌之技術士簽章表」）
A24: 五、工地職業安全衛生事項之督導、公共環境與安全之維護及其他工地行政事務：
A25: (ㄧ)施工前檢查事項：
A26: 1.實施勤前教育(含工地預防災變及危害告知)：■有 □無
A27: 2.確認新進勞工是否提報勞工保險(或其他商業保險)資料及安全衛生教育訓練紀錄：□有 □無
A28: ■無新進勞工
A29: 3.檢查勞工個人防護具：■有 □無
A30: (二)其他事項：
A32: 六、施工取樣試驗紀錄：
A33: 七、通知協力廠商辦理事項：
A34: 八、重要事項記錄：1.給排水配管施工
A35: 簽章：【工地負責人】（註3）：
... A44: 公共工程施工日誌
A45: 表報編號： | B45: =+B2+1 -> 37
A46: 本日天氣：上午：晴 下午：晴 | H46: 填表日期： | K46: =+K3+1 -> 45963
A47: 工程名稱 | D47: =+D4 -> 光明國中B與C區5樓老舊廁所整修工程 | H47: 承攬廠商名稱 | K47: 利成營造有限公司
A48: 核定工期 | B48: =+B5 -> 142 | C48: 天 | D48: 累計工期 | F48: =+F5+1 -> 37 | G48: 天 | H48: 剩餘工期 | I48: =+B48-F48 -> 105 | J48: 天 | K48: 工期展延天數 | M48: =+M5 -> 12
A49: 開工日期 | D49: =+D6 -> 114.9.27 | H49: 完工日期 | K49: =+K6 -> 115.2.15
A50: 預定進度(%) | D50: 0.126 | H50: 實際進度(%) | K50: =+K7 -> 0.177
A51: 一、依施工計畫書執行按圖施工概況（含約定之重要施工項目及完成數量等）：
A52: 施工項目 | E52: 單位 | F52: 契約數量 | H52: 本日完成數量 | J52: 累計完成數量 | L52: 備註
A55: 營造業專業工程特定施工項目
...

Sheet 12月
A1: 公共工程施工日誌
A2: 表報編號： | B2: =+'11月'!B1272+1 -> 66
A3: 本日天氣：上午：晴 下午：晴 | H3: 填表日期： | K3: 45992
A4: 工程名稱 | D4: 光明國中B與C區5樓老舊廁所整修工程 | H4: 承攬廠商名稱 | K4: 利成營造有限公司
A5: 核定工期 | B5: =+'11月'!B1275 -> 143 | C5: 天 | D5: 累計工期 | F5: =+'11月'!F1275+1 -> 66 | G5: 天 | H5: 剩餘工期 | I5: =+B5-F5 -> 77 | J5: 天 | K5: 工期展延天數 | M5: =+'11月'!M1275 -> 13
A6: 開工日期 | D6: =+'9月'!D138:G138 -> 114.9.27 | H6: 完工日期 | K6: =+'11月'!K1276:M1276 -> 115.2.16
A7: 預定進度(%) | D7: 0.3 | H7: 實際進度(%) | K7: =+'11月'!K1277:M1277+2.5%+2% -> 0.393
A8: 一、依施工計畫書執行按圖施工概況（含約定之重要施工項目及完成數量等）：
A9: 施工項目 | E9: 單位 | F9: 契約數量 | H9: 本日完成數量 | J9: 累計完成數量 | L9: 備註
A10: 牆面貼石英磚30*60cm，白色水泥抹縫 | E10: M2 | F10: 190 | H10: 40 | J10: 60
A11: 地坪、牆面1:3水泥砂漿粉刷 | E11: M2 | F11: 313 | H11: 133 | J11: 313
A12: 地坪及牆面(H=1.2m)防水層粉刷 | E12: M2 | F12: 160 | H12: 60 | J12: 160
A15: 二、工地材料管理概況（含約定之重要材料使用狀況及數量等）：
A16: 材料名稱 | E16: 單位 | F16: 契約數量 | H16: 本日使用數量 | J16: 累計使用數量 | L16: 備註
A19: 三、工地人員及機具管理（含約定之出工人數及機具使用情形及數量）：
A20: 工別 | C20: 本日人數 | E20: 累計人數 | H20: 機具名稱 | J20: 本日使用數量 | L20: 累計使用數量
A21: 泥水工 | C21: 4 | E21: 42
A23: 四、本日施工項目是否有須依「營造業專業工程特定施工項目應置之技術士種類、比率或人數標準表」規定應設置技術士之專業工程：□有 ■無（此項如勾選”有”，則應填寫後附「公共工程施工日誌之技術士簽章表」）
A24: 五、工地職業安全衛生事項之督導、公共環境與安全之維護及其他工地行政事務：
A25: (ㄧ)施工前檢查事項：
A26: 1.實施勤前教育(含工地預防災變及危害告知)：■有 □無
A27: 2.確認新進勞工是否提報勞工保險(或其他商業保險)資料及安全衛生教育訓練紀錄：□有 □無
A28: ■無新進勞工
A29: 3.檢查勞工個人防護具：■有 □無
A30: (二)其他事項：
A32: 六、施工取樣試驗紀錄：
A33: 七、通知協力廠商辦理事項：
A34: 八、重要事項記錄：1.牆面貼石英磚30*60cm施工2.地坪、牆面1:3水泥砂漿粉刷3.地坪及牆面(H=1.2m)防水層粉刷4.防水粉刷施工自主檢查。
A35: 簽章：【工地負責人】（註3）：
... A45: 公共工程施工日誌
A46: 表報編號： | B46: =+B2+1 -> 67
A47: 本日天氣：上午：晴 下午：晴 | H47: 填表日期： | K47: =+K3+1 -> 45993
A48: 工程名稱 | D48: =+D4 -> 光明國中B與C區5樓老舊廁所整修工程 | H48: 承攬廠商名稱 | K48: 利成營造有限公司
A49: 核定工期 | B49: =+B5+1 -> 144 | C49: 天 | D49: 累計工期 | F49: =+F5+1 -> 67 | G49: 天 | H49: 剩餘工期 | I49: =+B49-F49 -> 77 | J49: 天 | K49: 工期展延天數 | M49: =+M5+1 -> 14
A50: 開工日期 | D50: =+D6 -> 114.9.27 | H50: 完工日期 | K50: 115.2.17
A51: 預定進度(%) | D51: 0.306 | H51: 實際進度(%) | K51: =+K7 -> 0.393
A52: 一、依施工計畫書執行按圖施工概況（含約定之重要施工項目及完成數量等）：
A53: 施工項目 | E53: 單位 | F53: 契約數量 | H53: 本日完成數量 | J53: 累計完成數量 | L53: 備註
A56: 營造業專業工程特定施工項目
A57: A.
...

Sheet 12月 (2)
A1: 公共工程施工日誌
A2: 表報編號： | B2: =+'10月'!B1322+1 -> 36
A3: 本日天氣：上午：晴 下午：晴 | H3: 填表日期： | K3: 45962
A4: 工程名稱 | D4: 光明國中B與C區5樓老舊廁所整修工程 | H4: 承攬廠商名稱 | K4: 利成營造有限公司
A5: 核定工期 | B5: =+'10月'!B1325 -> 142 | C5: 天 | D5: 累計工期 | F5: =+'10月'!F1325+1 -> 36 | G5: 天 | H5: 剩餘工期 | I5: =+B5-F5 -> 106 | J5: 天 | K5: 工期展延天數 | M5: =+'10月'!M1325 -> 12
A6: 開工日期 | D6: =+'9月'!D138:G138 -> 114.9.27 | H6: 完工日期 | K6: =+'10月'!K1326:M1326 -> 115.2.15
A7: 預定進度(%) | D7: 0.018 | H7: 實際進度(%) | K7: =+'9月'!K139:M139 -> 0.058
A8: 一、依施工計畫書執行按圖施工概況（含約定之重要施工項目及完成數量等）：
A9: 施工項目 | E9: 單位 | F9: 契約數量 | H9: 本日完成數量 | J9: 累計完成數量 | L9: 備註
A12: 營造業專業工程特定施工項目
A13: A.
A14: B.
A15: 二、工地材料管理概況（含約定之重要材料使用狀況及數量等）：
A16: 材料名稱 | E16: 單位 | F16: 契約數量 | H16: 本日使用數量 | J16: 累計使用數量 | L16: 備註
A19: 三、工地人員及機具管理（含約定之出工人數及機具使用情形及數量）：
A20: 工別 | C20: 本日人數 | E20: 累計人數 | H20: 機具名稱 | J20: 本日使用數量 | L20: 累計使用數量
A23: 四、本日施工項目是否有須依「營造業專業工程特定施工項目應置之技術士種類、比率或人數標準表」規定應設置技術士之專業工程：□有 □無（此項如勾選”有”，則應填寫後附「公共工程施工日誌之技術士簽章表」）
A24: 五、工地職業安全衛生事項之督導、公共環境與安全之維護及其他工地行政事務：
A25: (ㄧ)施工前檢查事項：
A26: 1.實施勤前教育(含工地預防災變及危害告知)：□有 □無
A27: 2.確認新進勞工是否提報勞工保險(或其他商業保險)資料及安全衛生教育訓練紀錄：□有 □無
A28: □無新進勞工
A29: 3.檢查勞工個人防護具：□有 □無
A30: (二)其他事項：
A32: 六、施工取樣試驗紀錄：
A33: 七、通知協力廠商辦理事項：
A34: 八、重要事項記錄：本日無施工,施工準備
A35: 簽章：【工地負責人】（註3）：
... A45: 公共工程施工日誌
A46: 表報編號： | B46: =+B2+1 -> 37
A47: 本日天氣：上午：晴 下午：晴 | H47: 填表日期： | K47: =+K3+1 -> 45963
A48: 工程名稱 | D48: =+D4 -> 光明國中B與C區5樓老舊廁所整修工程 | H48: 承攬廠商名稱 | K48: 利成營造有限公司
A49: 核定工期 | B49: =+B5 -> 142 | C49: 天 | D49: 累計工期 | F49: =+F5+1 -> 37 | G49: 天 | H49: 剩餘工期 | I49: =+B49-F49 -> 105 | J49: 天 | K49: 工期展延天數 | M49: =+M5 -> 12
A50: 開工日期 | D50: =+D6 -> 114.9.27 | H50: 完工日期 | K50: =+K6 -> 115.2.15
A51: 預定進度(%) | D51: 0.02 | H51: 實際進度(%) | K51: =+K7 -> 0.058
A52: 一、依施工計畫書執行按圖施工概況（含約定之重要施工項目及完成數量等）：
A53: 施工項目 | E53: 單位 | F53: 契約數量 | H53: 本日完成數量 | J53: 累計完成數量 | L53: 備註
A56: 營造業專業工程特定施工項目
A57: A.
A58: B.
...

Sheet Sheet3
