Workbook

Sheet 1215
A1: 公共工程施工日誌
A2: 表報編號： | H2: 1
A3: 本日天氣: | G3: 上午： | K3: 晴 | Q3: 下午: | U3: 晴 | AR3: 日期： | AW3: =SUM(R6+H2)-1 -> 45641 | BH3: =WEEKDAY(AW3) -> 1
A4: 工程名稱 | G4: 113年育英樓排水改善工程 | AN4: 承攬廠商名稱 | AV4: 齊全土木包工業
A5: 核定工期 | J5: 60 | O5: 天 | R5: 累計工期 | Z5: =H2 -> 1 | AE5: 天 | AH5: 剩餘工期 | AP5: =J5-Z5 -> 59 | AU5: 天 | AX5: 工期展廷天數 | BK5: 天
A6: 開 工 日 期 | R6: 45641 | AH6: 完 工 日 期 | AX6: =SUM(R6,J5)+31 -> 45732
A7: 本日預定進度(%) | R7: 0.00301 | AH7: 本日實際進度(%) | AX7: =SUM(AR33/BO7) -> 0.01579478 | BO7: 891687
A8: 累計預定進度(%) | R8: =R7 -> 0.00301 | AH8: 累計實際進度(%) | AX8: =AX7 -> 0.01579478
A9: 一、依施工計劃書執行按圖施工概況(含約定之重要施工項目及完成數量等)等：
A10: 項次 | D10: 施工項目 | AE10: 單位 | AI10: 契約數量 | AR10: 本日完成數量 | BA10: 累計完成數量 | BJ10: 備註 | BN10: 契約單價金額 | BO10: 本日完成金額 | BP10: 累計完成金額 | BR10: 契約總額
A11: 壹. | D11: 直接工程
A12: 1 | D12: 工程告示牌、職業安全衛生告示牌與交通管制設施(租用) | AE12: 式 | AI12: 1 | AR12: 1 | BA12: =AR12 -> 1 | BN12: 5000 | BO12: =SUM(AR12*BN12) -> 5000 | BP12: =BO12 -> 5000 | BQ12: =BP12 -> 5000 | BR12: 5000
A13: 2 | D13: 施工圍籬(租用) | AE13: M | AI13: 74 | AR13: 15 | BA13: =AR13 -> 15 | BN13: 400 | BO13: =SUM(AR13*BN13) -> 6000 | BP13: =BO13 -> 6000 | BQ13: =BP13 -> 6000 | BR13: 29600
A14: 3 | D14: 施工動線開闢及損壞復原 | AE14: 式 | AI14: 1 | BA14: =AR14 -> 0 | BN14: 5000 | BO14: =SUM(AR14*BN14) -> 0 | BP14: =BO14 -> 0 | BQ14: =BP14 -> 0 | BR14: 5000
A15: 4 | D15: 測量與放樣 | AE15: 式 | AI15: 1 | BA15: =AR15 -> 0 | BN15: 5000 | BO15: =SUM(AR15*BN15) -> 0 | BP15: =BO15 -> 0 | BQ15: =BP15 -> 0 | BR15: 5000
A16: 5 | D16: 既有水溝清淤(含移除水溝內樹木竄根)，破損處以樹脂水泥砂漿整平，外側溝壁以樹脂水泥砂漿打底至與鋪面齊平 | AE16: M | AI16: 81 | BA16: =AR16 -> 0 | BN16: 1000 | BO16: =SUM(AR16*BN16) -> 0 | BP16: =BO16 -> 0 | BQ16: =BP16 -> 0 | BR16: 81000
A17: 6 | D17: 既有水溝安裝鍍鋅鋼板 | AE17: M | AI17: 22 | BA17: =AR17 -> 0 | BN17: 4650 | BO17: =SUM(AR17*BN17) -> 0 | BP17: =BO17 -> 0 | BQ17: =BP17 -> 0 | BR17: 102300
A18: 7 | D18: 新設RC水溝 | AE18: M | AI18: 23 | BA18: =AR18 -> 0 | BN18: 3500 | BO18: =SUM(AR18*BN18) -> 0 | BP18: =BO18 -> 0 | BQ18: =BP18 -> 0 | BR18: 80500
A19: 8 | D19: 設置鍍鋅鋼材烤漆止滑細縫水溝蓋含框 | AE19: 組 | AI19: 8 | BA19: =AR19 -> 0 | BN19: 6250 | BO19: =SUM(AR19*BN19) -> 0 | BP19: =BO19 -> 0 | BQ19: =BP19 -> 0 | BR19: 50000
A20: 9 | D20: 切割打除既有地坪，整地，底土壓實 | AE20: M2 | AI20: 68 | BA20: =AR20 -> 0 | BN20: 1200 | BO20: =SUM(AR20*BN20) -> 0 | BP20: =BO20 -> 0 | BQ20: =BP20 -> 0 | BR20: 81600
A21: 10 | D21: 新設RC地坪與斜坡，面層抿石子 | AE21: M2 | AI21: 68 | BA21: =AR21 -> 0 | BN21: 3000 | BO21: =SUM(AR21*BN21) -> 0 | BP21: =BO21 -> 0 | BQ21: =BP21 -> 0 | BR21: 204000
A22: 11 | D22: 北側圍牆邊陰井新設不鏽鋼沉水馬達220V/110V 1HP以上(含工帶料，需配浮球開關)，抽水至圍牆外水溝 | AE22: 組 | AI22: 1 | BA22: =AR22 -> 0 | BN22: 20000 | BO22: =SUM(AR22*BN22) -> 0 | BP22: =BO22 -> 0 | BQ22: =BP22 -> 0 | BR22: 20000
A23: 12 | D23: 西側既有走廊上水溝格柵蓋板，設置化妝蓋板含框，周邊復原 | AE23: 式 | AI23: 1 | BA23: =AR23 -> 0 | BN23: 68000 | BO23: =SUM(AR23*BN23) -> 0 | BP23: =BO23 -> 0 | BQ23: =BP23 -> 0 | BR23: 68000
A24: 13 | D24: 營建廢棄物清除與環境清潔 | AE24: 式 | AI24: 1 | BA24: =AR24 -> 0 | BN24: 42839 | BO24: =SUM(AR24*BN24) -> 0 | BP24: =BO24 -> 0 | BQ24: =BP24 -> 0 | BR24: 42839
A25: 14 | D25: 材料檢驗費用 | AE25: 式 | AI25: 1 | BA25: =AR25 -> 0 | BN25: 1440 | BO25: =SUM(AR25*BN25) -> 0 | BP25: =BO25 -> 0 | BQ25: =BP25 -> 0 | BR25: 1440
D26: 合計(壹) | BO26: =SUM(BO12:BO25) -> 11000 | BP26: =SUM(BP12:BP25) -> 11000 | BQ26: =BP26 -> 11000 | BR26: =SUM(BR12:BR25) -> 776279
A27: 貳 | D27: 職業安全衛生管理費 (壹*1%) | AE27: 式 | AI27: 1 | AR27: =SUM(BO27/BN27) -> 0 | BA27: =AR27 -> 0 | BN27: 7762 | BO27: 0 | BP27: =BO27 -> 0 | BQ27: =BP27 -> 0 | BR27: 7762 | BT27: 0.01
A28: 參 | D28: 工程品質管制作業費 (壹*1%) | AE28: 式 | AI28: 1 | AR28: =SUM(BO28/BN28) -> 0 | BA28: =AR28 -> 0 | BN28: 7763 | BO28: 0 | BP28: =BO28 -> 0 | BQ28: =BP28 -> 0 | BR28: 7763 | BT28: 0.01
A29: 肆 | D29: 包商利潤及管理費 (約壹*7%) | AE29: 式 | AI29: 1 | AR29: =SUM(BO29/BN29) -> 0 | BA29: =AR29 -> 0 | BN29: 54338 | BO29: 0 | BP29: =BO29 -> 0 | BQ29: =BP29 -> 0 | BR29: 54338 | BT29: 0.07
A30: 伍 | D30: 保險費 | AE30: 式 | AI30: 1 | AR30: 1 | BA30: =AR30 -> 1 | BN30: 3084 | BO30: 3084 | BP30: =BO30 -> 3084 | BQ30: =BP30 -> 3084 | BR30: 3084 | BS30: =SUM(BO26:BO30) -> 14084 | BU30: =SUM(BR26:BR30) -> 849226
A31: 陸 | D31: 營業稅 ((壹~伍)*5%) | AE31: 式 | AI31: 1 | AR31: 0 | BA31: =AR31 -> 0 | BN31: 42461 | BO31: 0 | BP31: =BO31 -> 0 | BQ31: =BP31 -> 0 | BR31: 42461 | BT31: 0.05
D32: 發包工程費合計 (壹~陸) | BO32: =SUM(BO26:BO31) -> 14084 | BP32: =SUM(BP26:BP31) -> 14084 | BQ32: =SUM(BQ26:BQ31) -> 14084 | BR32: =SUM(BR26:BR31) -> 891687
D33: 本日合計金額 | AR33: =BO32 -> 14084
D34: 累計合計金額 | AR34: =BP32 -> 14084 | BN34: 契約單價金額 | BO34: 本日完成金額 | BP34: 累計完成金額
A35: 營造業專業工程特定施工項目
A36: A.
A37: B.
A38: 二、工地材料管理概況(含約定之重要材料使用情況及數量等)：
A39: 材料名稱 | V39: 單位 | Y39: 設計數量 | AI39: 本日使用數量 | AS39: 累計使用數量 | BC39: 備註
AS40: =AI40 -> 0
...

Sheet 1216
A1: 公共工程施工日誌
A2: 表報編號： | H2: 2
A3: 本日天氣: | G3: 上午： | K3: 晴 | Q3: 下午: | U3: 晴 | AR3: 日期： | AW3: =SUM(R6+H2)-1 -> 45642 | BH3: =WEEKDAY(AW3) -> 2
A4: 工程名稱 | G4: 113年育英樓排水改善工程 | AN4: 承攬廠商名稱 | AV4: 齊全土木包工業
A5: 核定工期 | J5: 60 | O5: 天 | R5: 累計工期 | Z5: =H2-1 -> 1 | AE5: 天 | AH5: 剩餘工期 | AP5: =J5-Z5 -> 59 | AU5: 天 | AX5: 工期展廷天數 | BK5: 天
A6: 開 工 日 期 | R6: 45641 | AH6: 完 工 日 期 | AX6: =SUM(R6,J5)+31 -> 45732
A7: 本日預定進度(%) | R7: 0 | AH7: 本日實際進度(%) | AX7: =SUM(AR33/BO7) -> 0 | BO7: 891687
A8: 累計預定進度(%) | R8: =R7+'1215'!R8 -> 0.00301 | AH8: 累計實際進度(%) | AX8: =AX7+'1215'!AX8 -> 0.01579478
A9: 一、依施工計劃書執行按圖施工概況(含約定之重要施工項目及完成數量等)等：
A10: 項次 | D10: 施工項目 | AE10: 單位 | AI10: 契約數量 | AR10: 本日完成數量 | BA10: 累計完成數量 | BJ10: 備註 | BN10: 契約單價金額 | BO10: 本日完成金額 | BP10: 累計完成金額 | BR10: 契約總額
A11: 壹. | D11: 直接工程
A12: 1 | D12: 工程告示牌、職業安全衛生告示牌與交通管制設施(租用) | AE12: 式 | AI12: 1 | BA12: =AR12+'1215'!BA12 -> 1 | BN12: 5000 | BO12: =SUM(AR12*BN12) -> 0 | BP12: =BO12+'1215'!BP12 -> 5000 | BQ12: =BP12 -> 5000 | BR12: 5000
A13: 2 | D13: 施工圍籬(租用) | AE13: M | AI13: 74 | BA13: =AR13+'1215'!BA13 -> 15 | BN13: 400 | BO13: =SUM(AR13*BN13) -> 0 | BP13: =BO13+'1215'!BP13 -> 6000 | BQ13: =BP13 -> 6000 | BR13: 29600
A14: 3 | D14: 施工動線開闢及損壞復原 | AE14: 式 | AI14: 1 | BA14: =AR14+'1215'!BA14 -> 0 | BN14: 5000 | BO14: =SUM(AR14*BN14) -> 0 | BP14: =BO14+'1215'!BP14 -> 0 | BQ14: =BP14 -> 0 | BR14: 5000
A15: 4 | D15: 測量與放樣 | AE15: 式 | AI15: 1 | BA15: =AR15+'1215'!BA15 -> 0 | BN15: 5000 | BO15: =SUM(AR15*BN15) -> 0 | BP15: =BO15+'1215'!BP15 -> 0 | BQ15: =BP15 -> 0 | BR15: 5000
A16: 5 | D16: 既有水溝清淤(含移除水溝內樹木竄根)，破損處以樹脂水泥砂漿整平，外側溝壁以樹脂水泥砂漿打底至與鋪面齊平 | AE16: M | AI16: 81 | BA16: =AR16+'1215'!BA16 -> 0 | BN16: 1000 | BO16: =SUM(AR16*BN16) -> 0 | BP16: =BO16+'1215'!BP16 -> 0 | BQ16: =BP16 -> 0 | BR16: 81000
A17: 6 | D17: 既有水溝安裝鍍鋅鋼板 | AE17: M | AI17: 22 | BA17: =AR17+'1215'!BA17 -> 0 | BN17: 4650 | BO17: =SUM(AR17*BN17) -> 0 | BP17: =BO17+'1215'!BP17 -> 0 | BQ17: =BP17 -> 0 | BR17: 102300
A18: 7 | D18: 新設RC水溝 | AE18: M | AI18: 23 | BA18: =AR18+'1215'!BA18 -> 0 | BN18: 3500 | BO18: =SUM(AR18*BN18) -> 0 | BP18: =BO18+'1215'!BP18 -> 0 | BQ18: =BP18 -> 0 | BR18: 80500
A19: 8 | D19: 設置鍍鋅鋼材烤漆止滑細縫水溝蓋含框 | AE19: 組 | AI19: 8 | BA19: =AR19+'1215'!BA19 -> 0 | BN19: 6250 | BO19: =SUM(AR19*BN19) -> 0 | BP19: =BO19+'1215'!BP19 -> 0 | BQ19: =BP19 -> 0 | BR19: 50000
A20: 9 | D20: 切割打除既有地坪，整地，底土壓實 | AE20: M2 | AI20: 68 | BA20: =AR20+'1215'!BA20 -> 0 | BN20: 1200 | BO20: =SUM(AR20*BN20) -> 0 | BP20: =BO20+'1215'!BP20 -> 0 | BQ20: =BP20 -> 0 | BR20: 81600
A21: 10 | D21: 新設RC地坪與斜坡，面層抿石子 | AE21: M2 | AI21: 68 | BA21: =AR21+'1215'!BA21 -> 0 | BN21: 3000 | BO21: =SUM(AR21*BN21) -> 0 | BP21: =BO21+'1215'!BP21 -> 0 | BQ21: =BP21 -> 0 | BR21: 204000
A22: 11 | D22: 北側圍牆邊陰井新設不鏽鋼沉水馬達220V/110V 1HP以上(含工帶料，需配浮球開關)，抽水至圍牆外水溝 | AE22: 組 | AI22: 1 | BA22: =AR22+'1215'!BA22 -> 0 | BN22: 20000 | BO22: =SUM(AR22*BN22) -> 0 | BP22: =BO22+'1215'!BP22 -> 0 | BQ22: =BP22 -> 0 | BR22: 20000
A23: 12 | D23: 西側既有走廊上水溝格柵蓋板，設置化妝蓋板含框，周邊復原 | AE23: 式 | AI23: 1 | BA23: =AR23+'1215'!BA23 -> 0 | BN23: 68000 | BO23: =SUM(AR23*BN23) -> 0 | BP23: =BO23+'1215'!BP23 -> 0 | BQ23: =BP23 -> 0 | BR23: 68000
... A25: 14 | D25: 材料檢驗費用 | AE25: 式 | AI25: 1 | BA25: =AR25+'1215'!BA25 -> 0 | BN25: 1440 | BO25: =SUM(AR25*BN25) -> 0 | BP25: =BO25+'1215'!BP25 -> 0 | BQ25: =BP25 -> 0 | BR25: 1440
D26: 合計(壹) | BO26: =SUM(BO12:BO25) -> 0 | BP26: =SUM(BP12:BP25) -> 11000 | BQ26: =BP26 -> 11000 | BR26: =SUM(BR12:BR25) -> 776279
A27: 貳 | D27: 職業安全衛生管理費 (壹*1%) | AE27: 式 | AI27: 1 | AR27: =SUM(BO26/BN27) -> 0 | BA27: =AR27+'1215'!BA27 -> 0 | BN27: 7762 | BO27: =SUM(AR27*BN27) -> 0 | BP27: =BO27+'1215'!BP27 -> 0 | BQ27: =BP27 -> 0 | BR27: 7762 | BS27: =SUM(BN27/BR26) -> 0.0099989823
A28: 參 | D28: 工程品質管制作業費 (壹*1%) | AE28: 式 | AI28: 1 | AR28: =SUM(BO26/BN28) -> 0 | BA28: =AR28+'1215'!BA28 -> 0 | BN28: 7763 | BO28: =SUM(AR28*BN28) -> 0 | BP28: =BO28+'1215'!BP28 -> 0 | BQ28: =BP28 -> 0 | BR28: 7763 | BS28: =SUM(BN28/BR26) -> 0.010000271
A29: 肆 | D29: 包商利潤及管理費 (約壹*7%) | AE29: 式 | AI29: 1 | AR29: =SUM(BO26/BN29) -> 0 | BA29: =AR29+'1215'!BA29 -> 0 | BN29: 54338 | BO29: =SUM(AR29*BN29) -> 0 | BP29: =BO29+'1215'!BP29 -> 0 | BQ29: =BP29 -> 0 | BR29: 54338 | BS29: =SUM(BN29/BR26) -> 0.069998029
A30: 伍 | D30: 保險費 | AE30: 式 | AI30: 1 | AR30: 0 | BA30: =AR30+'1215'!BA30 -> 1 | BN30: 3084 | BO30: =SUM(AR30*BN30) -> 0 | BP30: =BO30+'1215'!BP30 -> 3084 | BQ30: =BP30 -> 3084 | BR30: 3084 | BT30: =SUM(BR26:BR30) -> 849226
A31: 陸 | D31: 營業稅 ((壹~伍)*5%) | AE31: 式 | AI31: 1 | AR31: =SUM(BT31/BN31) -> 0 | BA31: =AR31+'1215'!BA31 -> 0 | BN31: 42461 | BO31: =SUM(AR31*BN31) -> 0 | BP31: =BO31+'1215'!BP31 -> 0 | BQ31: =BP31 -> 0 | BR31: 42461 | BS31: =SUM(BN31/BT30) -> 0.049999647 | BT31: =SUM(BO26:BO30) -> 0
D32: 發包工程費合計 (壹~陸) | BO32: =SUM(BO26:BO31) -> 0 | BP32: =SUM(BP26:BP31) -> 14084 | BQ32: =SUM(BQ26:BQ31) -> 14084 | BR32: =SUM(BR26:BR31) -> 891687
D33: 本日合計金額 | AR33: =BO32 -> 0
D34: 累計合計金額 | AR34: =BP32 -> 14084 | BN34: 契約單價金額 | BO34: 本日完成金額 | BP34: 累計完成金額
A35: 營造業專業工程特定施工項目
A36: A.
A37: B.
A38: 二、工地材料管理概況(含約定之重要材料使用情況及數量等)：
A39: 材料名稱 | V39: 單位 | Y39: 設計數量 | AI39: 本日使用數量 | AS39: 累計使用數量 | BC39: 備註
AS40: =AI40+'1215'!AS40 -> 0
AS41: =AI41+'1215'!AS41 -> 0
...

Sheet 1217
A1: 公共工程施工日誌
A2: 表報編號： | H2: 3
A3: 本日天氣: | G3: 上午： | K3: 晴 | Q3: 下午: | U3: 晴 | AR3: 日期： | AW3: =SUM(R6+H2)-1 -> 45643 | BH3: =WEEKDAY(AW3) -> 3
A4: 工程名稱 | G4: 113年育英樓排水改善工程 | AN4: 承攬廠商名稱 | AV4: 齊全土木包工業
A5: 核定工期 | J5: 60 | O5: 天 | R5: 累計工期 | Z5: =H2-2 -> 1 | AE5: 天 | AH5: 剩餘工期 | AP5: =J5-Z5 -> 59 | AU5: 天 | AX5: 工期展廷天數 | BK5: 天
A6: 開 工 日 期 | R6: 45641 | AH6: 完 工 日 期 | AX6: =SUM(R6,J5)+31 -> 45732
A7: 本日預定進度(%) | R7: 0 | AH7: 本日實際進度(%) | AX7: =SUM(AR33/BO7) -> 0 | BO7: 891687
A8: 累計預定進度(%) | R8: =R7+'1216'!R8 -> 0.00301 | AH8: 累計實際進度(%) | AX8: =AX7+'1216'!AX8 -> 0.01579478
A9: 一、依施工計劃書執行按圖施工概況(含約定之重要施工項目及完成數量等)等：
A10: 項次 | D10: 施工項目 | AE10: 單位 | AI10: 契約數量 | AR10: 本日完成數量 | BA10: 累計完成數量 | BJ10: 備註 | BN10: 契約單價金額 | BO10: 本日完成金額 | BP10: 累計完成金額 | BR10: 契約總額
A11: 壹. | D11: 直接工程
A12: 1 | D12: 工程告示牌、職業安全衛生告示牌與交通管制設施(租用) | AE12: 式 | AI12: 1 | BA12: =AR12+'1216'!BA12 -> 1 | BN12: 5000 | BO12: =SUM(AR12*BN12) -> 0 | BP12: =BO12+'1216'!BP12 -> 5000 | BQ12: =BP12 -> 5000 | BR12: 5000
A13: 2 | D13: 施工圍籬(租用) | AE13: M | AI13: 74 | BA13: =AR13+'1216'!BA13 -> 15 | BN13: 400 | BO13: =SUM(AR13*BN13) -> 0 | BP13: =BO13+'1216'!BP13 -> 6000 | BQ13: =BP13 -> 6000 | BR13: 29600
A14: 3 | D14: 施工動線開闢及損壞復原 | AE14: 式 | AI14: 1 | BA14: =AR14+'1216'!BA14 -> 0 | BN14: 5000 | BO14: =SUM(AR14*BN14) -> 0 | BP14: =BO14+'1216'!BP14 -> 0 | BQ14: =BP14 -> 0 | BR14: 5000
A15: 4 | D15: 測量與放樣 | AE15: 式 | AI15: 1 | BA15: =AR15+'1216'!BA15 -> 0 | BN15: 5000 | BO15: =SUM(AR15*BN15) -> 0 | BP15: =BO15+'1216'!BP15 -> 0 | BQ15: =BP15 -> 0 | BR15: 5000
A16: 5 | D16: 既有水溝清淤(含移除水溝內樹木竄根)，破損處以樹脂水泥砂漿整平，外側溝壁以樹脂水泥砂漿打底至與鋪面齊平 | AE16: M | AI16: 81 | BA16: =AR16+'1216'!BA16 -> 0 | BN16: 1000 | BO16: =SUM(AR16*BN16) -> 0 | BP16: =BO16+'1216'!BP16 -> 0 | BQ16: =BP16 -> 0 | BR16: 81000
A17: 6 | D17: 既有水溝安裝鍍鋅鋼板 | AE17: M | AI17: 22 | BA17: =AR17+'1216'!BA17 -> 0 | BN17: 4650 | BO17: =SUM(AR17*BN17) -> 0 | BP17: =BO17+'1216'!BP17 -> 0 | BQ17: =BP17 -> 0 | BR17: 102300
A18: 7 | D18: 新設RC水溝 | AE18: M | AI18: 23 | BA18: =AR18+'1216'!BA18 -> 0 | BN18: 3500 | BO18: =SUM(AR18*BN18) -> 0 | BP18: =BO18+'1216'!BP18 -> 0 | BQ18: =BP18 -> 0 | BR18: 80500
A19: 8 | D19: 設置鍍鋅鋼材烤漆止滑細縫水溝蓋含框 | AE19: 組 | AI19: 8 | BA19: =AR19+'1216'!BA19 -> 0 | BN19: 6250 | BO19: =SUM(AR19*BN19) -> 0 | BP19: =BO19+'1216'!BP19 -> 0 | BQ19: =BP19 -> 0 | BR19: 50000
A20: 9 | D20: 切割打除既有地坪，整地，底土壓實 | AE20: M2 | AI20: 68 | BA20: =AR20+'1216'!BA20 -> 0 | BN20: 1200 | BO20: =SUM(AR20*BN20) -> 0 | BP20: =BO20+'1216'!BP20 -> 0 | BQ20: =BP20 -> 0 | BR20: 81600
A21: 10 | D21: 新設RC地坪與斜坡，面層抿石子 | AE21: M2 | AI21: 68 | BA21: =AR21+'1216'!BA21 -> 0 | BN21: 3000 | BO21: =SUM(AR21*BN21) -> 0 | BP21: =BO21+'1216'!BP21 -> 0 | BQ21: =BP21 -> 0 | BR21: 204000
A22: 11 | D22: 北側圍牆邊陰井新設不鏽鋼沉水馬達220V/110V 1HP以上(含工帶料，需配浮球開關)，抽水至圍牆外水溝 | AE22: 組 | AI22: 1 | BA22: =AR22+'1216'!BA22 -> 0 | BN22: 20000 | BO22: =SUM(AR22*BN22) -> 0 | BP22: =BO22+'1216'!BP22 -> 0 | BQ22: =BP22 -> 0 | BR22: 20000
A23: 12 | D23: 西側既有走廊上水溝格柵蓋板，設置化妝蓋板含框，周邊復原 | AE23: 式 | AI23: 1 | BA23: =AR23+'1216'!BA23 -> 0 | BN23: 68000 | BO23: =SUM(AR23*BN23) -> 0 | BP23: =BO23+'1216'!BP23 -> 0 | BQ23: =BP23 -> 0 | BR23: 68000
... A25: 14 | D25: 材料檢驗費用 | AE25: 式 | AI25: 1 | BA25: =AR25+'1216'!BA25 -> 0 | BN25: 1440 | BO25: =SUM(AR25*BN25) -> 0 | BP25: =BO25+'1216'!BP25 -> 0 | BQ25: =BP25 -> 0 | BR25: 1440
D26: 合計(壹) | BO26: =SUM(BO12:BO25) -> 0 | BP26: =SUM(BP12:BP25) -> 11000 | BQ26: =BP26 -> 11000 | BR26: =SUM(BR12:BR25) -> 776279
A27: 貳 | D27: 職業安全衛生管理費 (壹*1%) | AE27: 式 | AI27: 1 | AR27: =SUM(BO26/BN27) -> 0 | BA27: =AR27+'1216'!BA27 -> 0 | BN27: 7762 | BO27: =SUM(AR27*BN27) -> 0 | BP27: =BO27+'1216'!BP27 -> 0 | BQ27: =BP27 -> 0 | BR27: 7762 | BS27: =SUM(BN27/BR26) -> 0.0099989823
A28: 參 | D28: 工程品質管制作業費 (壹*1%) | AE28: 式 | AI28: 1 | AR28: =SUM(BO26/BN28) -> 0 | BA28: =AR28+'1216'!BA28 -> 0 | BN28: 7763 | BO28: =SUM(AR28*BN28) -> 0 | BP28: =BO28+'1216'!BP28 -> 0 | BQ28: =BP28 -> 0 | BR28: 7763 | BS28: =SUM(BN28/BR26) -> 0.010000271
A29: 肆 | D29: 包商利潤及管理費 (約壹*7%) | AE29: 式 | AI29: 1 | AR29: =SUM(BO26/BN29) -> 0 | BA29: =AR29+'1216'!BA29 -> 0 | BN29: 54338 | BO29: =SUM(AR29*BN29) -> 0 | BP29: =BO29+'1216'!BP29 -> 0 | BQ29: =BP29 -> 0 | BR29: 54338 | BS29: =SUM(BN29/BR26) -> 0.069998029
A30: 伍 | D30: 保險費 | AE30: 式 | AI30: 1 | AR30: 0 | BA30: =AR30+'1216'!BA30 -> 1 | BN30: 3084 | BO30: =SUM(AR30*BN30) -> 0 | BP30: =BO30+'1216'!BP30 -> 3084 | BQ30: =BP30 -> 3084 | BR30: 3084 | BT30: =SUM(BR26:BR30) -> 849226
A31: 陸 | D31: 營業稅 ((壹~伍)*5%) | AE31: 式 | AI31: 1 | AR31: =SUM(BT31/BN31) -> 0 | BA31: =AR31+'1216'!BA31 -> 0 | BN31: 42461 | BO31: =SUM(AR31*BN31) -> 0 | BP31: =BO31+'1216'!BP31 -> 0 | BQ31: =BP31 -> 0 | BR31: 42461 | BS31: =SUM(BN31/BT30) -> 0.049999647 | BT31: =SUM(BO26:BO30) -> 0
D32: 發包工程費合計 (壹~陸) | BO32: =SUM(BO26:BO31) -> 0 | BP32: =SUM(BP26:BP31) -> 14084 | BQ32: =SUM(BQ26:BQ31) -> 14084 | BR32: =SUM(BR26:BR31) -> 891687
D33: 本日合計金額 | AR33: =BO32 -> 0
D34: 累計合計金額 | AR34: =BP32 -> 14084 | BN34: 契約單價金額 | BO34: 本日完成金額 | BP34: 累計完成金額
A35: 營造業專業工程特定施工項目
A36: A.
A37: B.
A38: 二、工地材料管理概況(含約定之重要材料使用情況及數量等)：
A39: 材料名稱 | V39: 單位 | Y39: 設計數量 | AI39: 本日使用數量 | AS39: 累計使用數量 | BC39: 備註
AS40: =AI40+'1216'!AS40 -> 0
AS41: =AI41+'1216'!AS41 -> 0
...

Sheet 1218
A1: 公共工程施工日誌
A2: 表報編號： | H2: 4
A3: 本日天氣: | G3: 上午： | K3: 晴 | Q3: 下午: | U3: 晴 | AR3: 日期： | AW3: =SUM(R6+H2)-1 -> 45644 | BH3: =WEEKDAY(AW3) -> 4
A4: 工程名稱 | G4: 113年育英樓排水改善工程 | AN4: 承攬廠商名稱 | AV4: 齊全土木包工業
A5: 核定工期 | J5: 60 | O5: 天 | R5: 累計工期 | Z5: =H2-3 -> 1 | AE5: 天 | AH5: 剩餘工期 | AP5: =J5-Z5 -> 59 | AU5: 天 | AX5: 工期展廷天數 | BK5: 天
A6: 開 工 日 期 | R6: 45641 | AH6: 完 工 日 期 | AX6: =SUM(R6,J5)+31 -> 45732
A7: 本日預定進度(%) | R7: 0 | AH7: 本日實際進度(%) | AX7: =SUM(AR33/BO7) -> 0 | BO7: 891687
A8: 累計預定進度(%) | R8: =R7+'1217'!R8 -> 0.00301 | AH8: 累計實際進度(%) | AX8: =AX7+'1217'!AX8 -> 0.01579478
A9: 一、依施工計劃書執行按圖施工概況(含約定之重要施工項目及完成數量等)等：
A10: 項次 | D10: 施工項目 | AE10: 單位 | AI10: 契約數量 | AR10: 本日完成數量 | BA10: 累計完成數量 | BJ10: 備註 | BN10: 契約單價金額 | BO10: 本日完成金額 | BP10: 累計完成金額 | BR10: 契約總額
A11: 壹. | D11: 直接工程
A12: 1 | D12: 工程告示牌、職業安全衛生告示牌與交通管制設施(租用) | AE12: 式 | AI12: 1 | BA12: =AR12+'1217'!BA12 -> 1 | BN12: 5000 | BO12: =SUM(AR12*BN12) -> 0 | BP12: =BO12+'1217'!BP12 -> 5000 | BQ12: =BP12 -> 5000 | BR12: 5000
A13: 2 | D13: 施工圍籬(租用) | AE13: M | AI13: 74 | BA13: =AR13+'1217'!BA13 -> 15 | BN13: 400 | BO13: =SUM(AR13*BN13) -> 0 | BP13: =BO13+'1217'!BP13 -> 6000 | BQ13: =BP13 -> 6000 | BR13: 29600
A14: 3 | D14: 施工動線開闢及損壞復原 | AE14: 式 | AI14: 1 | BA14: =AR14+'1217'!BA14 -> 0 | BN14: 5000 | BO14: =SUM(AR14*BN14) -> 0 | BP14: =BO14+'1217'!BP14 -> 0 | BQ14: =BP14 -> 0 | BR14: 5000
A15: 4 | D15: 測量與放樣 | AE15: 式 | AI15: 1 | BA15: =AR15+'1217'!BA15 -> 0 | BN15: 5000 | BO15: =SUM(AR15*BN15) -> 0 | BP15: =BO15+'1217'!BP15 -> 0 | BQ15: =BP15 -> 0 | BR15: 5000
A16: 5 | D16: 既有水溝清淤(含移除水溝內樹木竄根)，破損處以樹脂水泥砂漿整平，外側溝壁以樹脂水泥砂漿打底至與鋪面齊平 | AE16: M | AI16: 81 | BA16: =AR16+'1217'!BA16 -> 0 | BN16: 1000 | BO16: =SUM(AR16*BN16) -> 0 | BP16: =BO16+'1217'!BP16 -> 0 | BQ16: =BP16 -> 0 | BR16: 81000
A17: 6 | D17: 既有水溝安裝鍍鋅鋼板 | AE17: M | AI17: 22 | BA17: =AR17+'1217'!BA17 -> 0 | BN17: 4650 | BO17: =SUM(AR17*BN17) -> 0 | BP17: =BO17+'1217'!BP17 -> 0 | BQ17: =BP17 -> 0 | BR17: 102300
A18: 7 | D18: 新設RC水溝 | AE18: M | AI18: 23 | BA18: =AR18+'1217'!BA18 -> 0 | BN18: 3500 | BO18: =SUM(AR18*BN18) -> 0 | BP18: =BO18+'1217'!BP18 -> 0 | BQ18: =BP18 -> 0 | BR18: 80500
A19: 8 | D19: 設置鍍鋅鋼材烤漆止滑細縫水溝蓋含框 | AE19: 組 | AI19: 8 | BA19: =AR19+'1217'!BA19 -> 0 | BN19: 6250 | BO19: =SUM(AR19*BN19) -> 0 | BP19: =BO19+'1217'!BP19 -> 0 | BQ19: =BP19 -> 0 | BR19: 50000
A20: 9 | D20: 切割打除既有地坪，整地，底土壓實 | AE20: M2 | AI20: 68 | BA20: =AR20+'1217'!BA20 -> 0 | BN20: 1200 | BO20: =SUM(AR20*BN20) -> 0 | BP20: =BO20+'1217'!BP20 -> 0 | BQ20: =BP20 -> 0 | BR20: 81600
A21: 10 | D21: 新設RC地坪與斜坡，面層抿石子 | AE21: M2 | AI21: 68 | BA21: =AR21+'1217'!BA21 -> 0 | BN21: 3000 | BO21: =SUM(AR21*BN21) -> 0 | BP21: =BO21+'1217'!BP21 -> 0 | BQ21: =BP21 -> 0 | BR21: 204000
A22: 11 | D22: 北側圍牆邊陰井新設不鏽鋼沉水馬達220V/110V 1HP以上(含工帶料，需配浮球開關)，抽水至圍牆外水溝 | AE22: 組 | AI22: 1 | BA22: =AR22+'1217'!BA22 -> 0 | BN22: 20000 | BO22: =SUM(AR22*BN22) -> 0 | BP22: =BO22+'1217'!BP22 -> 0 | BQ22: =BP22 -> 0 | BR22: 20000
A23: 12 | D23: 西側既有走廊上水溝格柵蓋板，設置化妝蓋板含框，周邊復原 | AE23: 式 | AI23: 1 | BA23: =AR23+'1217'!BA23 -> 0 | BN23: 68000 | BO23: =SUM(AR23*BN23) -> 0 | BP23: =BO23+'1217'!BP23 -> 0 | BQ23: =BP23 -> 0 | BR23: 68000
... A25: 14 | D25: 材料檢驗費用 | AE25: 式 | AI25: 1 | BA25: =AR25+'1217'!BA25 -> 0 | BN25: 1440 | BO25: =SUM(AR25*BN25) -> 0 | BP25: =BO25+'1217'!BP25 -> 0 | BQ25: =BP25 -> 0 | BR25: 1440
D26: 合計(壹) | BO26: =SUM(BO12:BO25) -> 0 | BP26: =SUM(BP12:BP25) -> 11000 | BQ26: =BP26 -> 11000 | BR26: =SUM(BR12:BR25) -> 776279
A27: 貳 | D27: 職業安全衛生管理費 (壹*1%) | AE27: 式 | AI27: 1 | AR27: =SUM(BO26/BN27) -> 0 | BA27: =AR27+'1217'!BA27 -> 0 | BN27: 7762 | BO27: =SUM(AR27*BN27) -> 0 | BP27: =BO27+'1217'!BP27 -> 0 | BQ27: =BP27 -> 0 | BR27: 7762 | BS27: =SUM(BN27/BR26) -> 0.0099989823
A28: 參 | D28: 工程品質管制作業費 (壹*1%) | AE28: 式 | AI28: 1 | AR28: =SUM(BO26/BN28) -> 0 | BA28: =AR28+'1217'!BA28 -> 0 | BN28: 7763 | BO28: =SUM(AR28*BN28) -> 0 | BP28: =BO28+'1217'!BP28 -> 0 | BQ28: =BP28 -> 0 | BR28: 7763 | BS28: =SUM(BN28/BR26) -> 0.010000271
A29: 肆 | D29: 包商利潤及管理費 (約壹*7%) | AE29: 式 | AI29: 1 | AR29: =SUM(BO26/BN29) -> 0 | BA29: =AR29+'1217'!BA29 -> 0 | BN29: 54338 | BO29: =SUM(AR29*BN29) -> 0 | BP29: =BO29+'1217'!BP29 -> 0 | BQ29: =BP29 -> 0 | BR29: 54338 | BS29: =SUM(BN29/BR26) -> 0.069998029
A30: 伍 | D30: 保險費 | AE30: 式 | AI30: 1 | AR30: 0 | BA30: =AR30+'1217'!BA30 -> 1 | BN30: 3084 | BO30: =SUM(AR30*BN30) -> 0 | BP30: =BO30+'1217'!BP30 -> 3084 | BQ30: =BP30 -> 3084 | BR30: 3084 | BT30: =SUM(BR26:BR30) -> 849226
A31: 陸 | D31: 營業稅 ((壹~伍)*5%) | AE31: 式 | AI31: 1 | AR31: =SUM(BT31/BN31) -> 0 | BA31: =AR31+'1217'!BA31 -> 0 | BN31: 42461 | BO31: =SUM(AR31*BN31) -> 0 | BP31: =BO31+'1217'!BP31 -> 0 | BQ31: =BP31 -> 0 | BR31: 42461 | BS31: =SUM(BN31/BT30) -> 0.049999647 | BT31: =SUM(BO26:BO30) -> 0
D32: 發包工程費合計 (壹~陸) | BO32: =SUM(BO26:BO31) -> 0 | BP32: =SUM(BP26:BP31) -> 14084 | BQ32: =SUM(BQ26:BQ31) -> 14084 | BR32: =SUM(BR26:BR31) -> 891687
D33: 本日合計金額 | AR33: =BO32 -> 0
D34: 累計合計金額 | AR34: =BP32 -> 14084 | BN34: 契約單價金額 | BO34: 本日完成金額 | BP34: 累計完成金額
A35: 營造業專業工程特定施工項目
A36: A.
A37: B.
A38: 二、工地材料管理概況(含約定之重要材料使用情況及數量等)：
A39: 材料名稱 | V39: 單位 | Y39: 設計數量 | AI39: 本日使用數量 | AS39: 累計使用數量 | BC39: 備註
AS40: =AI40+'1217'!AS40 -> 0
AS41: =AI41+'1217'!AS41 -> 0
...

Sheet 1219
A1: 公共工程施工日誌
A2: 表報編號： | H2: 5
A3: 本日天氣: | G3: 上午： | K3: 晴 | Q3: 下午: | U3: 晴 | AR3: 日期： | AW3: =SUM(R6+H2)-1 -> 45645 | BH3: =WEEKDAY(AW3) -> 5
A4: 工程名稱 | G4: 113年育英樓排水改善工程 | AN4: 承攬廠商名稱 | AV4: 齊全土木包工業
A5: 核定工期 | J5: 60 | O5: 天 | R5: 累計工期 | Z5: =H2-4 -> 1 | AE5: 天 | AH5: 剩餘工期 | AP5: =J5-Z5 -> 59 | AU5: 天 | AX5: 工期展廷天數 | BK5: 天
A6: 開 工 日 期 | R6: 45641 | AH6: 完 工 日 期 | AX6: =SUM(R6,J5)+31 -> 45732
A7: 本日預定進度(%) | R7: 0 | AH7: 本日實際進度(%) | AX7: =SUM(AR33/BO7) -> 0 | BO7: 891687
A8: 累計預定進度(%) | R8: =R7+'1218'!R8 -> 0.00301 | AH8: 累計實際進度(%) | AX8: =AX7+'1218'!AX8 -> 0.01579478
A9: 一、依施工計劃書執行按圖施工概況(含約定之重要施工項目及完成數量等)等：
A10: 項次 | D10: 施工項目 | AE10: 單位 | AI10: 契約數量 | AR10: 本日完成數量 | BA10: 累計完成數量 | BJ10: 備註 | BN10: 契約單價金額 | BO10: 本日完成金額 | BP10: 累計完成金額 | BR10: 契約總額
A11: 壹. | D11: 直接工程
A12: 1 | D12: 工程告示牌、職業安全衛生告示牌與交通管制設施(租用) | AE12: 式 | AI12: 1 | BA12: =AR12+'1218'!BA12 -> 1 | BN12: 5000 | BO12: =SUM(AR12*BN12) -> 0 | BP12: =BO12+'1218'!BP12 -> 5000 | BQ12: =BP12 -> 5000 | BR12: 5000
A13: 2 | D13: 施工圍籬(租用) | AE13: M | AI13: 74 | BA13: =AR13+'1218'!BA13 -> 15 | BN13: 400 | BO13: =SUM(AR13*BN13) -> 0 | BP13: =BO13+'1218'!BP13 -> 6000 | BQ13: =BP13 -> 6000 | BR13: 29600
A14: 3 | D14: 施工動線開闢及損壞復原 | AE14: 式 | AI14: 1 | BA14: =AR14+'1218'!BA14 -> 0 | BN14: 5000 | BO14: =SUM(AR14*BN14) -> 0 | BP14: =BO14+'1218'!BP14 -> 0 | BQ14: =BP14 -> 0 | BR14: 5000
A15: 4 | D15: 測量與放樣 | AE15: 式 | AI15: 1 | BA15: =AR15+'1218'!BA15 -> 0 | BN15: 5000 | BO15: =SUM(AR15*BN15) -> 0 | BP15: =BO15+'1218'!BP15 -> 0 | BQ15: =BP15 -> 0 | BR15: 5000
A16: 5 | D16: 既有水溝清淤(含移除水溝內樹木竄根)，破損處以樹脂水泥砂漿整平，外側溝壁以樹脂水泥砂漿打底至與鋪面齊平 | AE16: M | AI16: 81 | BA16: =AR16+'1218'!BA16 -> 0 | BN16: 1000 | BO16: =SUM(AR16*BN16) -> 0 | BP16: =BO16+'1218'!BP16 -> 0 | BQ16: =BP16 -> 0 | BR16: 81000
A17: 6 | D17: 既有水溝安裝鍍鋅鋼板 | AE17: M | AI17: 22 | BA17: =AR17+'1218'!BA17 -> 0 | BN17: 4650 | BO17: =SUM(AR17*BN17) -> 0 | BP17: =BO17+'1218'!BP17 -> 0 | BQ17: =BP17 -> 0 | BR17: 102300
A18: 7 | D18: 新設RC水溝 | AE18: M | AI18: 23 | BA18: =AR18+'1218'!BA18 -> 0 | BN18: 3500 | BO18: =SUM(AR18*BN18) -> 0 | BP18: =BO18+'1218'!BP18 -> 0 | BQ18: =BP18 -> 0 | BR18: 80500
A19: 8 | D19: 設置鍍鋅鋼材烤漆止滑細縫水溝蓋含框 | AE19: 組 | AI19: 8 | BA19: =AR19+'1218'!BA19 -> 0 | BN19: 6250 | BO19: =SUM(AR19*BN19) -> 0 | BP19: =BO19+'1218'!BP19 -> 0 | BQ19: =BP19 -> 0 | BR19: 50000
A20: 9 | D20: 切割打除既有地坪，整地，底土壓實 | AE20: M2 | AI20: 68 | BA20: =AR20+'1218'!BA20 -> 0 | BN20: 1200 | BO20: =SUM(AR20*BN20) -> 0 | BP20: =BO20+'1218'!BP20 -> 0 | BQ20: =BP20 -> 0 | BR20: 81600
A21: 10 | D21: 新設RC地坪與斜坡，面層抿石子 | AE21: M2 | AI21: 68 | BA21: =AR21+'1218'!BA21 -> 0 | BN21: 3000 | BO21: =SUM(AR21*BN21) -> 0 | BP21: =BO21+'1218'!BP21 -> 0 | BQ21: =BP21 -> 0 | BR21: 204000
A22: 11 | D22: 北側圍牆邊陰井新設不鏽鋼沉水馬達220V/110V 1HP以上(含工帶料，需配浮球開關)，抽水至圍牆外水溝 | AE22: 組 | AI22: 1 | BA22: =AR22+'1218'!BA22 -> 0 | BN22: 20000 | BO22: =SUM(AR22*BN22) -> 0 | BP22: =BO22+'1218'!BP22 -> 0 | BQ22: =BP22 -> 0 | BR22: 20000
A23: 12 | D23: 西側既有走廊上水溝格柵蓋板，設置化妝蓋板含框，周邊復原 | AE23: 式 | AI23: 1 | BA23: =AR23+'1218'!BA23 -> 0 | BN23: 68000 | BO23: =SUM(AR23*BN23) -> 0 | BP23: =BO23+'1218'!BP23 -> 0 | BQ23: =BP23 -> 0 | BR23: 68000
... A25: 14 | D25: 材料檢驗費用 | AE25: 式 | AI25: 1 | BA25: =AR25+'1218'!BA25 -> 0 | BN25: 1440 | BO25: =SUM(AR25*BN25) -> 0 | BP25: =BO25+'1218'!BP25 -> 0 | BQ25: =BP25 -> 0 | BR25: 1440
D26: 合計(壹) | BO26: =SUM(BO12:BO25) -> 0 | BP26: =SUM(BP12:BP25) -> 11000 | BQ26: =BP26 -> 11000 | BR26: =SUM(BR12:BR25) -> 776279
A27: 貳 | D27: 職業安全衛生管理費 (壹*1%) | AE27: 式 | AI27: 1 | AR27: =SUM(BO26/BN27) -> 0 | BA27: =AR27+'1218'!BA27 -> 0 | BN27: 7762 | BO27: =SUM(AR27*BN27) -> 0 | BP27: =BO27+'1218'!BP27 -> 0 | BQ27: =BP27 -> 0 | BR27: 7762 | BS27: =SUM(BN27/BR26) -> 0.0099989823
A28: 參 | D28: 工程品質管制作業費 (壹*1%) | AE28: 式 | AI28: 1 | AR28: =SUM(BO26/BN28) -> 0 | BA28: =AR28+'1218'!BA28 -> 0 | BN28: 7763 | BO28: =SUM(AR28*BN28) -> 0 | BP28: =BO28+'1218'!BP28 -> 0 | BQ28: =BP28 -> 0 | BR28: 7763 | BS28: =SUM(BN28/BR26) -> 0.010000271
A29: 肆 | D29: 包商利潤及管理費 (約壹*7%) | AE29: 式 | AI29: 1 | AR29: =SUM(BO26/BN29) -> 0 | BA29: =AR29+'1218'!BA29 -> 0 | BN29: 54338 | BO29: =SUM(AR29*BN29) -> 0 | BP29: =BO29+'1218'!BP29 -> 0 | BQ29: =BP29 -> 0 | BR29: 54338 | BS29: =SUM(BN29/BR26) -> 0.069998029
A30: 伍 | D30: 保險費 | AE30: 式 | AI30: 1 | AR30: 0 | BA30: =AR30+'1218'!BA30 -> 1 | BN30: 3084 | BO30: =SUM(AR30*BN30) -> 0 | BP30: =BO30+'1218'!BP30 -> 3084 | BQ30: =BP30 -> 3084 | BR30: 3084 | BT30: =SUM(BR26:BR30) -> 849226
A31: 陸 | D31: 營業稅 ((壹~伍)*5%) | AE31: 式 | AI31: 1 | AR31: =SUM(BT31/BN31) -> 0 | BA31: =AR31+'1218'!BA31 -> 0 | BN31: 42461 | BO31: =SUM(AR31*BN31) -> 0 | BP31: =BO31+'1218'!BP31 -> 0 | BQ31: =BP31 -> 0 | BR31: 42461 | BS31: =SUM(BN31/BT30) -> 0.049999647 | BT31: =SUM(BO26:BO30) -> 0
D32: 發包工程費合計 (壹~陸) | BO32: =SUM(BO26:BO31) -> 0 | BP32: =SUM(BP26:BP31) -> 14084 | BQ32: =SUM(BQ26:BQ31) -> 14084 | BR32: =SUM(BR26:BR31) -> 891687
D33: 本日合計金額 | AR33: =BO32 -> 0
D34: 累計合計金額 | AR34: =BP32 -> 14084 | BN34: 契約單價金額 | BO34: 本日完成金額 | BP34: 累計完成金額
A35: 營造業專業工程特定施工項目
A36: A.
A37: B.
A38: 二、工地材料管理概況(含約定之重要材料使用情況及數量等)：
A39: 材料名稱 | V39: 單位 | Y39: 設計數量 | AI39: 本日使用數量 | AS39: 累計使用數量 | BC39: 備註
AS40: =AI40+'1218'!AS40 -> 0
AS41: =AI41+'1218'!AS41 -> 0
...

Sheet 1220
A1: 公共工程施工日誌
A2: 表報編號： | H2: 6
A3: 本日天氣: | G3: 上午： | K3: 晴 | Q3: 下午: | U3: 晴 | AR3: 日期： | AW3: =SUM(R6+H2)-1 -> 45646 | BH3: =WEEKDAY(AW3) -> 6
A4: 工程名稱 | G4: 113年育英樓排水改善工程 | AN4: 承攬廠商名稱 | AV4: 齊全土木包工業
A5: 核定工期 | J5: 60 | O5: 天 | R5: 累計工期 | Z5: =H2-5 -> 1 | AE5: 天 | AH5: 剩餘工期 | AP5: =J5-Z5 -> 59 | AU5: 天 | AX5: 工期展廷天數 | BK5: 天
A6: 開 工 日 期 | R6: 45641 | AH6: 完 工 日 期 | AX6: =SUM(R6,J5)+31 -> 45732
A7: 本日預定進度(%) | R7: 0 | AH7: 本日實際進度(%) | AX7: =SUM(AR33/BO7) -> 0 | BO7: 891687
A8: 累計預定進度(%) | R8: =R7+'1219'!R8 -> 0.00301 | AH8: 累計實際進度(%) | AX8: =AX7+'1219'!AX8 -> 0.01579478
A9: 一、依施工計劃書執行按圖施工概況(含約定之重要施工項目及完成數量等)等：
A10: 項次 | D10: 施工項目 | AE10: 單位 | AI10: 契約數量 | AR10: 本日完成數量 | BA10: 累計完成數量 | BJ10: 備註 | BN10: 契約單價金額 | BO10: 本日完成金額 | BP10: 累計完成金額 | BR10: 契約總額
A11: 壹. | D11: 直接工程
A12: 1 | D12: 工程告示牌、職業安全衛生告示牌與交通管制設施(租用) | AE12: 式 | AI12: 1 | BA12: =AR12+'1219'!BA12 -> 1 | BN12: 5000 | BO12: =SUM(AR12*BN12) -> 0 | BP12: =BO12+'1219'!BP12 -> 5000 | BQ12: =BP12 -> 5000 | BR12: 5000
A13: 2 | D13: 施工圍籬(租用) | AE13: M | AI13: 74 | BA13: =AR13+'1219'!BA13 -> 15 | BN13: 400 | BO13: =SUM(AR13*BN13) -> 0 | BP13: =BO13+'1219'!BP13 -> 6000 | BQ13: =BP13 -> 6000 | BR13: 29600
A14: 3 | D14: 施工動線開闢及損壞復原 | AE14: 式 | AI14: 1 | BA14: =AR14+'1219'!BA14 -> 0 | BN14: 5000 | BO14: =SUM(AR14*BN14) -> 0 | BP14: =BO14+'1219'!BP14 -> 0 | BQ14: =BP14 -> 0 | BR14: 5000
A15: 4 | D15: 測量與放樣 | AE15: 式 | AI15: 1 | BA15: =AR15+'1219'!BA15 -> 0 | BN15: 5000 | BO15: =SUM(AR15*BN15) -> 0 | BP15: =BO15+'1219'!BP15 -> 0 | BQ15: =BP15 -> 0 | BR15: 5000
A16: 5 | D16: 既有水溝清淤(含移除水溝內樹木竄根)，破損處以樹脂水泥砂漿整平，外側溝壁以樹脂水泥砂漿打底至與鋪面齊平 | AE16: M | AI16: 81 | BA16: =AR16+'1219'!BA16 -> 0 | BN16: 1000 | BO16: =SUM(AR16*BN16) -> 0 | BP16: =BO16+'1219'!BP16 -> 0 | BQ16: =BP16 -> 0 | BR16: 81000
A17: 6 | D17: 既有水溝安裝鍍鋅鋼板 | AE17: M | AI17: 22 | BA17: =AR17+'1219'!BA17 -> 0 | BN17: 4650 | BO17: =SUM(AR17*BN17) -> 0 | BP17: =BO17+'1219'!BP17 -> 0 | BQ17: =BP17 -> 0 | BR17: 102300
A18: 7 | D18: 新設RC水溝 | AE18: M | AI18: 23 | BA18: =AR18+'1219'!BA18 -> 0 | BN18: 3500 | BO18: =SUM(AR18*BN18) -> 0 | BP18: =BO18+'1219'!BP18 -> 0 | BQ18: =BP18 -> 0 | BR18: 80500
A19: 8 | D19: 設置鍍鋅鋼材烤漆止滑細縫水溝蓋含框 | AE19: 組 | AI19: 8 | BA19: =AR19+'1219'!BA19 -> 0 | BN19: 6250 | BO19: =SUM(AR19*BN19) -> 0 | BP19: =BO19+'1219'!BP19 -> 0 | BQ19: =BP19 -> 0 | BR19: 50000
A20: 9 | D20: 切割打除既有地坪，整地，底土壓實 | AE20: M2 | AI20: 68 | BA20: =AR20+'1219'!BA20 -> 0 | BN20: 1200 | BO20: =SUM(AR20*BN20) -> 0 | BP20: =BO20+'1219'!BP20 -> 0 | BQ20: =BP20 -> 0 | BR20: 81600
A21: 10 | D21: 新設RC地坪與斜坡，面層抿石子 | AE21: M2 | AI21: 68 | BA21: =AR21+'1219'!BA21 -> 0 | BN21: 3000 | BO21: =SUM(AR21*BN21) -> 0 | BP21: =BO21+'1219'!BP21 -> 0 | BQ21: =BP21 -> 0 | BR21: 204000
A22: 11 | D22: 北側圍牆邊陰井新設不鏽鋼沉水馬達220V/110V 1HP以上(含工帶料，需配浮球開關)，抽水至圍牆外水溝 | AE22: 組 | AI22: 1 | BA22: =AR22+'1219'!BA22 -> 0 | BN22: 20000 | BO22: =SUM(AR22*BN22) -> 0 | BP22: =BO22+'1219'!BP22 -> 0 | BQ22: =BP22 -> 0 | BR22: 20000
A23: 12 | D23: 西側既有走廊上水溝格柵蓋板，設置化妝蓋板含框，周邊復原 | AE23: 式 | AI23: 1 | BA23: =AR23+'1219'!BA23 -> 0 | BN23: 68000 | BO23: =SUM(AR23*BN23) -> 0 | BP23: =BO23+'1219'!BP23 -> 0 | BQ23: =BP23 -> 0 | BR23: 68000
... A25: 14 | D25: 材料檢驗費用 | AE25: 式 | AI25: 1 | BA25: =AR25+'1219'!BA25 -> 0 | BN25: 1440 | BO25: =SUM(AR25*BN25) -> 0 | BP25: =BO25+'1219'!BP25 -> 0 | BQ25: =BP25 -> 0 | BR25: 1440
D26: 合計(壹) | BO26: =SUM(BO12:BO25) -> 0 | BP26: =SUM(BP12:BP25) -> 11000 | BQ26: =BP26 -> 11000 | BR26: =SUM(BR12:BR25) -> 776279
A27: 貳 | D27: 職業安全衛生管理費 (壹*1%) | AE27: 式 | AI27: 1 | AR27: =SUM(BO26/BN27) -> 0 | BA27: =AR27+'1219'!BA27 -> 0 | BN27: 7762 | BO27: =SUM(AR27*BN27) -> 0 | BP27: =BO27+'1219'!BP27 -> 0 | BQ27: =BP27 -> 0 | BR27: 7762 | BS27: =SUM(BN27/BR26) -> 0.0099989823
A28: 參 | D28: 工程品質管制作業費 (壹*1%) | AE28: 式 | AI28: 1 | AR28: =SUM(BO26/BN28) -> 0 | BA28: =AR28+'1219'!BA28 -> 0 | BN28: 7763 | BO28: =SUM(AR28*BN28) -> 0 | BP28: =BO28+'1219'!BP28 -> 0 | BQ28: =BP28 -> 0 | BR28: 7763 | BS28: =SUM(BN28/BR26) -> 0.010000271
A29: 肆 | D29: 包商利潤及管理費 (約壹*7%) | AE29: 式 | AI29: 1 | AR29: =SUM(BO26/BN29) -> 0 | BA29: =AR29+'1219'!BA29 -> 0 | BN29: 54338 | BO29: =SUM(AR29*BN29) -> 0 | BP29: =BO29+'1219'!BP29 -> 0 | BQ29: =BP29 -> 0 | BR29: 54338 | BS29: =SUM(BN29/BR26) -> 0.069998029
A30: 伍 | D30: 保險費 | AE30: 式 | AI30: 1 | AR30: 0 | BA30: =AR30+'1219'!BA30 -> 1 | BN30: 3084 | BO30: =SUM(AR30*BN30) -> 0 | BP30: =BO30+'1219'!BP30 -> 3084 | BQ30: =BP30 -> 3084 | BR30: 3084 | BT30: =SUM(BR26:BR30) -> 849226
A31: 陸 | D31: 營業稅 ((壹~伍)*5%) | AE31: 式 | AI31: 1 | AR31: =SUM(BT31/BN31) -> 0 | BA31: =AR31+'1219'!BA31 -> 0 | BN31: 42461 | BO31: =SUM(AR31*BN31) -> 0 | BP31: =BO31+'1219'!BP31 -> 0 | BQ31: =BP31 -> 0 | BR31: 42461 | BS31: =SUM(BN31/BT30) -> 0.049999647 | BT31: =SUM(BO26:BO30) -> 0
D32: 發包工程費合計 (壹~陸) | BO32: =SUM(BO26:BO31) -> 0 | BP32: =SUM(BP26:BP31) -> 14084 | BQ32: =SUM(BQ26:BQ31) -> 14084 | BR32: =SUM(BR26:BR31) -> 891687
D33: 本日合計金額 | AR33: =BO32 -> 0
D34: 累計合計金額 | AR34: =BP32 -> 14084 | BN34: 契約單價金額 | BO34: 本日完成金額 | BP34: 累計完成金額
A35: 營造業專業工程特定施工項目
A36: A.
A37: B.
A38: 二、工地材料管理概況(含約定之重要材料使用情況及數量等)：
A39: 材料名稱 | V39: 單位 | Y39: 設計數量 | AI39: 本日使用數量 | AS39: 累計使用數量 | BC39: 備註
AS40: =AI40+'1219'!AS40 -> 0
AS41: =AI41+'1219'!AS41 -> 0
...

Sheet 1221
A1: 公共工程施工日誌
A2: 表報編號： | H2: 7
A3: 本日天氣: | G3: 上午： | K3: 晴 | Q3: 下午: | U3: 晴 | AR3: 日期： | AW3: =SUM(R6+H2)-1 -> 45647 | BH3: =WEEKDAY(AW3) -> 7
A4: 工程名稱 | G4: 113年育英樓排水改善工程 | AN4: 承攬廠商名稱 | AV4: 齊全土木包工業
A5: 核定工期 | J5: 60 | O5: 天 | R5: 累計工期 | Z5: =H2-5 -> 2 | AE5: 天 | AH5: 剩餘工期 | AP5: =J5-Z5 -> 58 | AU5: 天 | AX5: 工期展廷天數 | BK5: 天
A6: 開 工 日 期 | R6: 45641 | AH6: 完 工 日 期 | AX6: =SUM(R6,J5)+31 -> 45732
A7: 本日預定進度(%) | R7: 0.00301 | AH7: 本日實際進度(%) | AX7: =SUM(AR33/BO7) -> 0 | BO7: 891687
A8: 累計預定進度(%) | R8: =R7+'1220'!R8 -> 0.00602 | AH8: 累計實際進度(%) | AX8: =AX7+'1220'!AX8 -> 0.01579478
A9: 一、依施工計劃書執行按圖施工概況(含約定之重要施工項目及完成數量等)等：
A10: 項次 | D10: 施工項目 | AE10: 單位 | AI10: 契約數量 | AR10: 本日完成數量 | BA10: 累計完成數量 | BJ10: 備註 | BN10: 契約單價金額 | BO10: 本日完成金額 | BP10: 累計完成金額 | BR10: 契約總額
A11: 壹. | D11: 直接工程
A12: 1 | D12: 工程告示牌、職業安全衛生告示牌與交通管制設施(租用) | AE12: 式 | AI12: 1 | BA12: =AR12+'1220'!BA12 -> 1 | BN12: 5000 | BO12: =SUM(AR12*BN12) -> 0 | BP12: =BO12+'1220'!BP12 -> 5000 | BQ12: =BP12 -> 5000 | BR12: 5000
A13: 2 | D13: 施工圍籬(租用) | AE13: M | AI13: 74 | BA13: =AR13+'1220'!BA13 -> 15 | BN13: 400 | BO13: =SUM(AR13*BN13) -> 0 | BP13: =BO13+'1220'!BP13 -> 6000 | BQ13: =BP13 -> 6000 | BR13: 29600
A14: 3 | D14: 施工動線開闢及損壞復原 | AE14: 式 | AI14: 1 | BA14: =AR14+'1220'!BA14 -> 0 | BN14: 5000 | BO14: =SUM(AR14*BN14) -> 0 | BP14: =BO14+'1220'!BP14 -> 0 | BQ14: =BP14 -> 0 | BR14: 5000
A15: 4 | D15: 測量與放樣 | AE15: 式 | AI15: 1 | BA15: =AR15+'1220'!BA15 -> 0 | BN15: 5000 | BO15: =SUM(AR15*BN15) -> 0 | BP15: =BO15+'1220'!BP15 -> 0 | BQ15: =BP15 -> 0 | BR15: 5000
A16: 5 | D16: 既有水溝清淤(含移除水溝內樹木竄根)，破損處以樹脂水泥砂漿整平，外側溝壁以樹脂水泥砂漿打底至與鋪面齊平 | AE16: M | AI16: 81 | BA16: =AR16+'1220'!BA16 -> 0 | BN16: 1000 | BO16: =SUM(AR16*BN16) -> 0 | BP16: =BO16+'1220'!BP16 -> 0 | BQ16: =BP16 -> 0 | BR16: 81000
A17: 6 | D17: 既有水溝安裝鍍鋅鋼板 | AE17: M | AI17: 22 | BA17: =AR17+'1220'!BA17 -> 0 | BN17: 4650 | BO17: =SUM(AR17*BN17) -> 0 | BP17: =BO17+'1220'!BP17 -> 0 | BQ17: =BP17 -> 0 | BR17: 102300
A18: 7 | D18: 新設RC水溝 | AE18: M | AI18: 23 | BA18: =AR18+'1220'!BA18 -> 0 | BN18: 3500 | BO18: =SUM(AR18*BN18) -> 0 | BP18: =BO18+'1220'!BP18 -> 0 | BQ18: =BP18 -> 0 | BR18: 80500
A19: 8 | D19: 設置鍍鋅鋼材烤漆止滑細縫水溝蓋含框 | AE19: 組 | AI19: 8 | BA19: =AR19+'1220'!BA19 -> 0 | BN19: 6250 | BO19: =SUM(AR19*BN19) -> 0 | BP19: =BO19+'1220'!BP19 -> 0 | BQ19: =BP19 -> 0 | BR19: 50000
A20: 9 | D20: 切割打除既有地坪，整地，底土壓實 | AE20: M2 | AI20: 68 | BA20: =AR20+'1220'!BA20 -> 0 | BN20: 1200 | BO20: =SUM(AR20*BN20) -> 0 | BP20: =BO20+'1220'!BP20 -> 0 | BQ20: =BP20 -> 0 | BR20: 81600
A21: 10 | D21: 新設RC地坪與斜坡，面層抿石子 | AE21: M2 | AI21: 68 | BA21: =AR21+'1220'!BA21 -> 0 | BN21: 3000 | BO21: =SUM(AR21*BN21) -> 0 | BP21: =BO21+'1220'!BP21 -> 0 | BQ21: =BP21 -> 0 | BR21: 204000
A22: 11 | D22: 北側圍牆邊陰井新設不鏽鋼沉水馬達220V/110V 1HP以上(含工帶料，需配浮球開關)，抽水至圍牆外水溝 | AE22: 組 | AI22: 1 | BA22: =AR22+'1220'!BA22 -> 0 | BN22: 20000 | BO22: =SUM(AR22*BN22) -> 0 | BP22: =BO22+'1220'!BP22 -> 0 | BQ22: =BP22 -> 0 | BR22: 20000
A23: 12 | D23: 西側既有走廊上水溝格柵蓋板，設置化妝蓋板含框，周邊復原 | AE23: 式 | AI23: 1 | BA23: =AR23+'1220'!BA23 -> 0 | BN23: 68000 | BO23: =SUM(AR23*BN23) -> 0 | BP23: =BO23+'1220'!BP23 -> 0 | BQ23: =BP23 -> 0 | BR23: 68000
... A25: 14 | D25: 材料檢驗費用 | AE25: 式 | AI25: 1 | BA25: =AR25+'1220'!BA25 -> 0 | BN25: 1440 | BO25: =SUM(AR25*BN25) -> 0 | BP25: =BO25+'1220'!BP25 -> 0 | BQ25: =BP25 -> 0 | BR25: 1440
D26: 合計(壹) | BO26: =SUM(BO12:BO25) -> 0 | BP26: =SUM(BP12:BP25) -> 11000 | BQ26: =BP26 -> 11000 | BR26: =SUM(BR12:BR25) -> 776279
A27: 貳 | D27: 職業安全衛生管理費 (壹*1%) | AE27: 式 | AI27: 1 | AR27: =SUM(BO26/BN27) -> 0 | BA27: =AR27+'1220'!BA27 -> 0 | BN27: 7762 | BO27: =SUM(AR27*BN27) -> 0 | BP27: =BO27+'1220'!BP27 -> 0 | BQ27: =BP27 -> 0 | BR27: 7762 | BS27: =SUM(BN27/BR26) -> 0.0099989823
A28: 參 | D28: 工程品質管制作業費 (壹*1%) | AE28: 式 | AI28: 1 | AR28: =SUM(BO26/BN28) -> 0 | BA28: =AR28+'1220'!BA28 -> 0 | BN28: 7763 | BO28: =SUM(AR28*BN28) -> 0 | BP28: =BO28+'1220'!BP28 -> 0 | BQ28: =BP28 -> 0 | BR28: 7763 | BS28: =SUM(BN28/BR26) -> 0.010000271
A29: 肆 | D29: 包商利潤及管理費 (約壹*7%) | AE29: 式 | AI29: 1 | AR29: =SUM(BO26/BN29) -> 0 | BA29: =AR29+'1220'!BA29 -> 0 | BN29: 54338 | BO29: =SUM(AR29*BN29) -> 0 | BP29: =BO29+'1220'!BP29 -> 0 | BQ29: =BP29 -> 0 | BR29: 54338 | BS29: =SUM(BN29/BR26) -> 0.069998029
A30: 伍 | D30: 保險費 | AE30: 式 | AI30: 1 | AR30: 0 | BA30: =AR30+'1220'!BA30 -> 1 | BN30: 3084 | BO30: =SUM(AR30*BN30) -> 0 | BP30: =BO30+'1220'!BP30 -> 3084 | BQ30: =BP30 -> 3084 | BR30: 3084 | BT30: =SUM(BR26:BR30) -> 849226
A31: 陸 | D31: 營業稅 ((壹~伍)*5%) | AE31: 式 | AI31: 1 | AR31: =SUM(BT31/BN31) -> 0 | BA31: =AR31+'1220'!BA31 -> 0 | BN31: 42461 | BO31: =SUM(AR31*BN31) -> 0 | BP31: =BO31+'1220'!BP31 -> 0 | BQ31: =BP31 -> 0 | BR31: 42461 | BS31: =SUM(BN31/BT30) -> 0.049999647 | BT31: =SUM(BO26:BO30) -> 0
D32: 發包工程費合計 (壹~陸) | BO32: =SUM(BO26:BO31) -> 0 | BP32: =SUM(BP26:BP31) -> 14084 | BQ32: =SUM(BQ26:BQ31) -> 14084 | BR32: =SUM(BR26:BR31) -> 891687
D33: 本日合計金額 | AR33: =BO32 -> 0
D34: 累計合計金額 | AR34: =BP32 -> 14084 | BN34: 契約單價金額 | BO34: 本日完成金額 | BP34: 累計完成金額
A35: 營造業專業工程特定施工項目
A36: A.
A37: B.
A38: 二、工地材料管理概況(含約定之重要材料使用情況及數量等)：
A39: 材料名稱 | V39: 單位 | Y39: 設計數量 | AI39: 本日使用數量 | AS39: 累計使用數量 | BC39: 備註
AS40: =AI40+'1220'!AS40 -> 0
AS41: =AI41+'1220'!AS41 -> 0
...

Sheet 1222
A1: 公共工程施工日誌
A2: 表報編號： | H2: 8
A3: 本日天氣: | G3: 上午： | K3: 晴 | Q3: 下午: | U3: 晴 | AR3: 日期： | AW3: =SUM(R6+H2)-1 -> 45648 | BH3: =WEEKDAY(AW3) -> 1
A4: 工程名稱 | G4: 113年育英樓排水改善工程 | AN4: 承攬廠商名稱 | AV4: 齊全土木包工業
A5: 核定工期 | J5: 60 | O5: 天 | R5: 累計工期 | Z5: =H2-5 -> 3 | AE5: 天 | AH5: 剩餘工期 | AP5: =J5-Z5 -> 57 | AU5: 天 | AX5: 工期展廷天數 | BK5: 天
A6: 開 工 日 期 | R6: 45641 | AH6: 完 工 日 期 | AX6: =SUM(R6,J5)+31 -> 45732
A7: 本日預定進度(%) | R7: 0.00301 | AH7: 本日實際進度(%) | AX7: =SUM(AR33/BO7) -> 0 | BO7: 891687
A8: 累計預定進度(%) | R8: =R7+'1221'!R8 -> 0.00903 | AH8: 累計實際進度(%) | AX8: =AX7+'1221'!AX8 -> 0.01579478
A9: 一、依施工計劃書執行按圖施工概況(含約定之重要施工項目及完成數量等)等：
A10: 項次 | D10: 施工項目 | AE10: 單位 | AI10: 契約數量 | AR10: 本日完成數量 | BA10: 累計完成數量 | BJ10: 備註 | BN10: 契約單價金額 | BO10: 本日完成金額 | BP10: 累計完成金額 | BR10: 契約總額
A11: 壹. | D11: 直接工程
A12: 1 | D12: 工程告示牌、職業安全衛生告示牌與交通管制設施(租用) | AE12: 式 | AI12: 1 | BA12: =AR12+'1221'!BA12 -> 1 | BN12: 5000 | BO12: =SUM(AR12*BN12) -> 0 | BP12: =BO12+'1221'!BP12 -> 5000 | BQ12: =BP12 -> 5000 | BR12: 5000
A13: 2 | D13: 施工圍籬(租用) | AE13: M | AI13: 74 | BA13: =AR13+'1221'!BA13 -> 15 | BN13: 400 | BO13: =SUM(AR13*BN13) -> 0 | BP13: =BO13+'1221'!BP13 -> 6000 | BQ13: =BP13 -> 6000 | BR13: 29600
A14: 3 | D14: 施工動線開闢及損壞復原 | AE14: 式 | AI14: 1 | BA14: =AR14+'1221'!BA14 -> 0 | BN14: 5000 | BO14: =SUM(AR14*BN14) -> 0 | BP14: =BO14+'1221'!BP14 -> 0 | BQ14: =BP14 -> 0 | BR14: 5000
A15: 4 | D15: 測量與放樣 | AE15: 式 | AI15: 1 | BA15: =AR15+'1221'!BA15 -> 0 | BN15: 5000 | BO15: =SUM(AR15*BN15) -> 0 | BP15: =BO15+'1221'!BP15 -> 0 | BQ15: =BP15 -> 0 | BR15: 5000
A16: 5 | D16: 既有水溝清淤(含移除水溝內樹木竄根)，破損處以樹脂水泥砂漿整平，外側溝壁以樹脂水泥砂漿打底至與鋪面齊平 | AE16: M | AI16: 81 | BA16: =AR16+'1221'!BA16 -> 0 | BN16: 1000 | BO16: =SUM(AR16*BN16) -> 0 | BP16: =BO16+'1221'!BP16 -> 0 | BQ16: =BP16 -> 0 | BR16: 81000
A17: 6 | D17: 既有水溝安裝鍍鋅鋼板 | AE17: M | AI17: 22 | BA17: =AR17+'1221'!BA17 -> 0 | BN17: 4650 | BO17: =SUM(AR17*BN17) -> 0 | BP17: =BO17+'1221'!BP17 -> 0 | BQ17: =BP17 -> 0 | BR17: 102300
A18: 7 | D18: 新設RC水溝 | AE18: M | AI18: 23 | BA18: =AR18+'1221'!BA18 -> 0 | BN18: 3500 | BO18: =SUM(AR18*BN18) -> 0 | BP18: =BO18+'1221'!BP18 -> 0 | BQ18: =BP18 -> 0 | BR18: 80500
A19: 8 | D19: 設置鍍鋅鋼材烤漆止滑細縫水溝蓋含框 | AE19: 組 | AI19: 8 | BA19: =AR19+'1221'!BA19 -> 0 | BN19: 6250 | BO19: =SUM(AR19*BN19) -> 0 | BP19: =BO19+'1221'!BP19 -> 0 | BQ19: =BP19 -> 0 | BR19: 50000
A20: 9 | D20: 切割打除既有地坪，整地，底土壓實 | AE20: M2 | AI20: 68 | BA20: =AR20+'1221'!BA20 -> 0 | BN20: 1200 | BO20: =SUM(AR20*BN20) -> 0 | BP20: =BO20+'1221'!BP20 -> 0 | BQ20: =BP20 -> 0 | BR20: 81600
A21: 10 | D21: 新設RC地坪與斜坡，面層抿石子 | AE21: M2 | AI21: 68 | BA21: =AR21+'1221'!BA21 -> 0 | BN21: 3000 | BO21: =SUM(AR21*BN21) -> 0 | BP21: =BO21+'1221'!BP21 -> 0 | BQ21: =BP21 -> 0 | BR21: 204000
A22: 11 | D22: 北側圍牆邊陰井新設不鏽鋼沉水馬達220V/110V 1HP以上(含工帶料，需配浮球開關)，抽水至圍牆外水溝 | AE22: 組 | AI22: 1 | BA22: =AR22+'1221'!BA22 -> 0 | BN22: 20000 | BO22: =SUM(AR22*BN22) -> 0 | BP22: =BO22+'1221'!BP22 -> 0 | BQ22: =BP22 -> 0 | BR22: 20000
A23: 12 | D23: 西側既有走廊上水溝格柵蓋板，設置化妝蓋板含框，周邊復原 | AE23: 式 | AI23: 1 | BA23: =AR23+'1221'!BA23 -> 0 | BN23: 68000 | BO23: =SUM(AR23*BN23) -> 0 | BP23: =BO23+'1221'!BP23 -> 0 | BQ23: =BP23 -> 0 | BR23: 68000
... A25: 14 | D25: 材料檢驗費用 | AE25: 式 | AI25: 1 | BA25: =AR25+'1221'!BA25 -> 0 | BN25: 1440 | BO25: =SUM(AR25*BN25) -> 0 | BP25: =BO25+'1221'!BP25 -> 0 | BQ25: =BP25 -> 0 | BR25: 1440
D26: 合計(壹) | BO26: =SUM(BO12:BO25) -> 0 | BP26: =SUM(BP12:BP25) -> 11000 | BQ26: =BP26 -> 11000 | BR26: =SUM(BR12:BR25) -> 776279
A27: 貳 | D27: 職業安全衛生管理費 (壹*1%) | AE27: 式 | AI27: 1 | AR27: =SUM(BO26/BN27) -> 0 | BA27: =AR27+'1221'!BA27 -> 0 | BN27: 7762 | BO27: =SUM(AR27*BN27) -> 0 | BP27: =BO27+'1221'!BP27 -> 0 | BQ27: =BP27 -> 0 | BR27: 7762 | BS27: =SUM(BN27/BR26) -> 0.0099989823
A28: 參 | D28: 工程品質管制作業費 (壹*1%) | AE28: 式 | AI28: 1 | AR28: =SUM(BO26/BN28) -> 0 | BA28: =AR28+'1221'!BA28 -> 0 | BN28: 7763 | BO28: =SUM(AR28*BN28) -> 0 | BP28: =BO28+'1221'!BP28 -> 0 | BQ28: =BP28 -> 0 | BR28: 7763 | BS28: =SUM(BN28/BR26) -> 0.010000271
A29: 肆 | D29: 包商利潤及管理費 (約壹*7%) | AE29: 式 | AI29: 1 | AR29: =SUM(BO26/BN29) -> 0 | BA29: =AR29+'1221'!BA29 -> 0 | BN29: 54338 | BO29: =SUM(AR29*BN29) -> 0 | BP29: =BO29+'1221'!BP29 -> 0 | BQ29: =BP29 -> 0 | BR29: 54338 | BS29: =SUM(BN29/BR26) -> 0.069998029
A30: 伍 | D30: 保險費 | AE30: 式 | AI30: 1 | AR30: 0 | BA30: =AR30+'1221'!BA30 -> 1 | BN30: 3084 | BO30: =SUM(AR30*BN30) -> 0 | BP30: =BO30+'1221'!BP30 -> 3084 | BQ30: =BP30 -> 3084 | BR30: 3084 | BT30: =SUM(BR26:BR30) -> 849226
A31: 陸 | D31: 營業稅 ((壹~伍)*5%) | AE31: 式 | AI31: 1 | AR31: =SUM(BT31/BN31) -> 0 | BA31: =AR31+'1221'!BA31 -> 0 | BN31: 42461 | BO31: =SUM(AR31*BN31) -> 0 | BP31: =BO31+'1221'!BP31 -> 0 | BQ31: =BP31 -> 0 | BR31: 42461 | BS31: =SUM(BN31/BT30) -> 0.049999647 | BT31: =SUM(BO26:BO30) -> 0
D32: 發包工程費合計 (壹~陸) | BO32: =SUM(BO26:BO31) -> 0 | BP32: =SUM(BP26:BP31) -> 14084 | BQ32: =SUM(BQ26:BQ31) -> 14084 | BR32: =SUM(BR26:BR31) -> 891687
D33: 本日合計金額 | AR33: =BO32 -> 0
D34: 累計合計金額 | AR34: =BP32 -> 14084 | BN34: 契約單價金額 | BO34: 本日完成金額 | BP34: 累計完成金額
A35: 營造業專業工程特定施工項目
A36: A.
A37: B.
A38: 二、工地材料管理概況(含約定之重要材料使用情況及數量等)：
A39: 材料名稱 | V39: 單位 | Y39: 設計數量 | AI39: 本日使用數量 | AS39: 累計使用數量 | BC39: 備註
AS40: =AI40+'1221'!AS40 -> 0
AS41: =AI41+'1221'!AS41 -> 0
...

Sheet 1223
A1: 公共工程施工日誌
A2: 表報編號： | H2: 9
A3: 本日天氣: | G3: 上午： | K3: 晴 | Q3: 下午: | U3: 晴 | AR3: 日期： | AW3: =SUM(R6+H2)-1 -> 45649 | BH3: =WEEKDAY(AW3) -> 2
A4: 工程名稱 | G4: 113年育英樓排水改善工程 | AN4: 承攬廠商名稱 | AV4: 齊全土木包工業
A5: 核定工期 | J5: 60 | O5: 天 | R5: 累計工期 | Z5: =H2-6 -> 3 | AE5: 天 | AH5: 剩餘工期 | AP5: =J5-Z5 -> 57 | AU5: 天 | AX5: 工期展廷天數 | BK5: 天
A6: 開 工 日 期 | R6: 45641 | AH6: 完 工 日 期 | AX6: =SUM(R6,J5)+31 -> 45732
A7: 本日預定進度(%) | R7: 0 | AH7: 本日實際進度(%) | AX7: =SUM(AR33/BO7) -> 0 | BO7: 891687
A8: 累計預定進度(%) | R8: =R7+'1222'!R8 -> 0.00903 | AH8: 累計實際進度(%) | AX8: =AX7+'1222'!AX8 -> 0.01579478
A9: 一、依施工計劃書執行按圖施工概況(含約定之重要施工項目及完成數量等)等：
A10: 項次 | D10: 施工項目 | AE10: 單位 | AI10: 契約數量 | AR10: 本日完成數量 | BA10: 累計完成數量 | BJ10: 備註 | BN10: 契約單價金額 | BO10: 本日完成金額 | BP10: 累計完成金額 | BR10: 契約總額
A11: 壹. | D11: 直接工程
A12: 1 | D12: 工程告示牌、職業安全衛生告示牌與交通管制設施(租用) | AE12: 式 | AI12: 1 | BA12: =AR12+'1222'!BA12 -> 1 | BN12: 5000 | BO12: =SUM(AR12*BN12) -> 0 | BP12: =BO12+'1222'!BP12 -> 5000 | BQ12: =BP12 -> 5000 | BR12: 5000
A13: 2 | D13: 施工圍籬(租用) | AE13: M | AI13: 74 | BA13: =AR13+'1222'!BA13 -> 15 | BN13: 400 | BO13: =SUM(AR13*BN13) -> 0 | BP13: =BO13+'1222'!BP13 -> 6000 | BQ13: =BP13 -> 6000 | BR13: 29600
A14: 3 | D14: 施工動線開闢及損壞復原 | AE14: 式 | AI14: 1 | BA14: =AR14+'1222'!BA14 -> 0 | BN14: 5000 | BO14: =SUM(AR14*BN14) -> 0 | BP14: =BO14+'1222'!BP14 -> 0 | BQ14: =BP14 -> 0 | BR14: 5000
A15: 4 | D15: 測量與放樣 | AE15: 式 | AI15: 1 | BA15: =AR15+'1222'!BA15 -> 0 | BN15: 5000 | BO15: =SUM(AR15*BN15) -> 0 | BP15: =BO15+'1222'!BP15 -> 0 | BQ15: =BP15 -> 0 | BR15: 5000
A16: 5 | D16: 既有水溝清淤(含移除水溝內樹木竄根)，破損處以樹脂水泥砂漿整平，外側溝壁以樹脂水泥砂漿打底至與鋪面齊平 | AE16: M | AI16: 81 | BA16: =AR16+'1222'!BA16 -> 0 | BN16: 1000 | BO16: =SUM(AR16*BN16) -> 0 | BP16: =BO16+'1222'!BP16 -> 0 | BQ16: =BP16 -> 0 | BR16: 81000
A17: 6 | D17: 既有水溝安裝鍍鋅鋼板 | AE17: M | AI17: 22 | BA17: =AR17+'1222'!BA17 -> 0 | BN17: 4650 | BO17: =SUM(AR17*BN17) -> 0 | BP17: =BO17+'1222'!BP17 -> 0 | BQ17: =BP17 -> 0 | BR17: 102300
A18: 7 | D18: 新設RC水溝 | AE18: M | AI18: 23 | BA18: =AR18+'1222'!BA18 -> 0 | BN18: 3500 | BO18: =SUM(AR18*BN18) -> 0 | BP18: =BO18+'1222'!BP18 -> 0 | BQ18: =BP18 -> 0 | BR18: 80500
A19: 8 | D19: 設置鍍鋅鋼材烤漆止滑細縫水溝蓋含框 | AE19: 組 | AI19: 8 | BA19: =AR19+'1222'!BA19 -> 0 | BN19: 6250 | BO19: =SUM(AR19*BN19) -> 0 | BP19: =BO19+'1222'!BP19 -> 0 | BQ19: =BP19 -> 0 | BR19: 50000
A20: 9 | D20: 切割打除既有地坪，整地，底土壓實 | AE20: M2 | AI20: 68 | BA20: =AR20+'1222'!BA20 -> 0 | BN20: 1200 | BO20: =SUM(AR20*BN20) -> 0 | BP20: =BO20+'1222'!BP20 -> 0 | BQ20: =BP20 -> 0 | BR20: 81600
A21: 10 | D21: 新設RC地坪與斜坡，面層抿石子 | AE21: M2 | AI21: 68 | BA21: =AR21+'1222'!BA21 -> 0 | BN21: 3000 | BO21: =SUM(AR21*BN21) -> 0 | BP21: =BO21+'1222'!BP21 -> 0 | BQ21: =BP21 -> 0 | BR21: 204000
A22: 11 | D22: 北側圍牆邊陰井新設不鏽鋼沉水馬達220V/110V 1HP以上(含工帶料，需配浮球開關)，抽水至圍牆外水溝 | AE22: 組 | AI22: 1 | BA22: =AR22+'1222'!BA22 -> 0 | BN22: 20000 | BO22: =SUM(AR22*BN22) -> 0 | BP22: =BO22+'1222'!BP22 -> 0 | BQ22: =BP22 -> 0 | BR22: 20000
A23: 12 | D23: 西側既有走廊上水溝格柵蓋板，設置化妝蓋板含框，周邊復原 | AE23: 式 | AI23: 1 | BA23: =AR23+'1222'!BA23 -> 0 | BN23: 68000 | BO23: =SUM(AR23*BN23) -> 0 | BP23: =BO23+'1222'!BP23 -> 0 | BQ23: =BP23 -> 0 | BR23: 68000
... A25: 14 | D25: 材料檢驗費用 | AE25: 式 | AI25: 1 | BA25: =AR25+'1222'!BA25 -> 0 | BN25: 1440 | BO25: =SUM(AR25*BN25) -> 0 | BP25: =BO25+'1222'!BP25 -> 0 | BQ25: =BP25 -> 0 | BR25: 1440
D26: 合計(壹) | BO26: =SUM(BO12:BO25) -> 0 | BP26: =SUM(BP12:BP25) -> 11000 | BQ26: =BP26 -> 11000 | BR26: =SUM(BR12:BR25) -> 776279
A27: 貳 | D27: 職業安全衛生管理費 (壹*1%) | AE27: 式 | AI27: 1 | AR27: =SUM(BO26/BN27) -> 0 | BA27: =AR27+'1222'!BA27 -> 0 | BN27: 7762 | BO27: =SUM(AR27*BN27) -> 0 | BP27: =BO27+'1222'!BP27 -> 0 | BQ27: =BP27 -> 0 | BR27: 7762 | BS27: =SUM(BN27/BR26) -> 0.0099989823
A28: 參 | D28: 工程品質管制作業費 (壹*1%) | AE28: 式 | AI28: 1 | AR28: =SUM(BO26/BN28) -> 0 | BA28: =AR28+'1222'!BA28 -> 0 | BN28: 7763 | BO28: =SUM(AR28*BN28) -> 0 | BP28: =BO28+'1222'!BP28 -> 0 | BQ28: =BP28 -> 0 | BR28: 7763 | BS28: =SUM(BN28/BR26) -> 0.010000271
A29: 肆 | D29: 包商利潤及管理費 (約壹*7%) | AE29: 式 | AI29: 1 | AR29: =SUM(BO26/BN29) -> 0 | BA29: =AR29+'1222'!BA29 -> 0 | BN29: 54338 | BO29: =SUM(AR29*BN29) -> 0 | BP29: =BO29+'1222'!BP29 -> 0 | BQ29: =BP29 -> 0 | BR29: 54338 | BS29: =SUM(BN29/BR26) -> 0.069998029
A30: 伍 | D30: 保險費 | AE30: 式 | AI30: 1 | AR30: 0 | BA30: =AR30+'1222'!BA30 -> 1 | BN30: 3084 | BO30: =SUM(AR30*BN30) -> 0 | BP30: =BO30+'1222'!BP30 -> 3084 | BQ30: =BP30 -> 3084 | BR30: 3084 | BT30: =SUM(BR26:BR30) -> 849226
A31: 陸 | D31: 營業稅 ((壹~伍)*5%) | AE31: 式 | AI31: 1 | AR31: =SUM(BT31/BN31) -> 0 | BA31: =AR31+'1222'!BA31 -> 0 | BN31: 42461 | BO31: =SUM(AR31*BN31) -> 0 | BP31: =BO31+'1222'!BP31 -> 0 | BQ31: =BP31 -> 0 | BR31: 42461 | BS31: =SUM(BN31/BT30) -> 0.049999647 | BT31: =SUM(BO26:BO30) -> 0
D32: 發包工程費合計 (壹~陸) | BO32: =SUM(BO26:BO31) -> 0 | BP32: =SUM(BP26:BP31) -> 14084 | BQ32: =SUM(BQ26:BQ31) -> 14084 | BR32: =SUM(BR26:BR31) -> 891687
D33: 本日合計金額 | AR33: =BO32 -> 0
D34: 累計合計金額 | AR34: =BP32 -> 14084 | BN34: 契約單價金額 | BO34: 本日完成金額 | BP34: 累計完成金額
A35: 營造業專業工程特定施工項目
A36: A.
A37: B.
A38: 二、工地材料管理概況(含約定之重要材料使用情況及數量等)：
A39: 材料名稱 | V39: 單位 | Y39: 設計數量 | AI39: 本日使用數量 | AS39: 累計使用數量 | BC39: 備註
AS40: =AI40+'1222'!AS40 -> 0
AS41: =AI41+'1222'!AS41 -> 0
...

Sheet 1224
A1: 公共工程施工日誌
A2: 表報編號： | H2: 10
A3: 本日天氣: | G3: 上午： | K3: 晴 | Q3: 下午: | U3: 晴 | AR3: 日期： | AW3: =SUM(R6+H2)-1 -> 45650 | BH3: =WEEKDAY(AW3) -> 3
A4: 工程名稱 | G4: 113年育英樓排水改善工程 | AN4: 承攬廠商名稱 | AV4: 齊全土木包工業
A5: 核定工期 | J5: 60 | O5: 天 | R5: 累計工期 | Z5: =H2-7 -> 3 | AE5: 天 | AH5: 剩餘工期 | AP5: =J5-Z5 -> 57 | AU5: 天 | AX5: 工期展廷天數 | BK5: 天
A6: 開 工 日 期 | R6: 45641 | AH6: 完 工 日 期 | AX6: =SUM(R6,J5)+31 -> 45732
A7: 本日預定進度(%) | R7: 0 | AH7: 本日實際進度(%) | AX7: =SUM(AR33/BO7) -> 0 | BO7: 891687
A8: 累計預定進度(%) | R8: =R7+'1223'!R8 -> 0.00903 | AH8: 累計實際進度(%) | AX8: =AX7+'1223'!AX8 -> 0.01579478
A9: 一、依施工計劃書執行按圖施工概況(含約定之重要施工項目及完成數量等)等：
A10: 項次 | D10: 施工項目 | AE10: 單位 | AI10: 契約數量 | AR10: 本日完成數量 | BA10: 累計完成數量 | BJ10: 備註 | BN10: 契約單價金額 | BO10: 本日完成金額 | BP10: 累計完成金額 | BR10: 契約總額
A11: 壹. | D11: 直接工程
A12: 1 | D12: 工程告示牌、職業安全衛生告示牌與交通管制設施(租用) | AE12: 式 | AI12: 1 | BA12: =AR12+'1223'!BA12 -> 1 | BN12: 5000 | BO12: =SUM(AR12*BN12) -> 0 | BP12: =BO12+'1223'!BP12 -> 5000 | BQ12: =BP12 -> 5000 | BR12: 5000
A13: 2 | D13: 施工圍籬(租用) | AE13: M | AI13: 74 | BA13: =AR13+'1223'!BA13 -> 15 | BN13: 400 | BO13: =SUM(AR13*BN13) -> 0 | BP13: =BO13+'1223'!BP13 -> 6000 | BQ13: =BP13 -> 6000 | BR13: 29600
A14: 3 | D14: 施工動線開闢及損壞復原 | AE14: 式 | AI14: 1 | BA14: =AR14+'1223'!BA14 -> 0 | BN14: 5000 | BO14: =SUM(AR14*BN14) -> 0 | BP14: =BO14+'1223'!BP14 -> 0 | BQ14: =BP14 -> 0 | BR14: 5000
A15: 4 | D15: 測量與放樣 | AE15: 式 | AI15: 1 | BA15: =AR15+'1223'!BA15 -> 0 | BN15: 5000 | BO15: =SUM(AR15*BN15) -> 0 | BP15: =BO15+'1223'!BP15 -> 0 | BQ15: =BP15 -> 0 | BR15: 5000
A16: 5 | D16: 既有水溝清淤(含移除水溝內樹木竄根)，破損處以樹脂水泥砂漿整平，外側溝壁以樹脂水泥砂漿打底至與鋪面齊平 | AE16: M | AI16: 81 | BA16: =AR16+'1223'!BA16 -> 0 | BN16: 1000 | BO16: =SUM(AR16*BN16) -> 0 | BP16: =BO16+'1223'!BP16 -> 0 | BQ16: =BP16 -> 0 | BR16: 81000
A17: 6 | D17: 既有水溝安裝鍍鋅鋼板 | AE17: M | AI17: 22 | BA17: =AR17+'1223'!BA17 -> 0 | BN17: 4650 | BO17: =SUM(AR17*BN17) -> 0 | BP17: =BO17+'1223'!BP17 -> 0 | BQ17: =BP17 -> 0 | BR17: 102300
A18: 7 | D18: 新設RC水溝 | AE18: M | AI18: 23 | BA18: =AR18+'1223'!BA18 -> 0 | BN18: 3500 | BO18: =SUM(AR18*BN18) -> 0 | BP18: =BO18+'1223'!BP18 -> 0 | BQ18: =BP18 -> 0 | BR18: 80500
A19: 8 | D19: 設置鍍鋅鋼材烤漆止滑細縫水溝蓋含框 | AE19: 組 | AI19: 8 | BA19: =AR19+'1223'!BA19 -> 0 | BN19: 6250 | BO19: =SUM(AR19*BN19) -> 0 | BP19: =BO19+'1223'!BP19 -> 0 | BQ19: =BP19 -> 0 | BR19: 50000
A20: 9 | D20: 切割打除既有地坪，整地，底土壓實 | AE20: M2 | AI20: 68 | BA20: =AR20+'1223'!BA20 -> 0 | BN20: 1200 | BO20: =SUM(AR20*BN20) -> 0 | BP20: =BO20+'1223'!BP20 -> 0 | BQ20: =BP20 -> 0 | BR20: 81600
A21: 10 | D21: 新設RC地坪與斜坡，面層抿石子 | AE21: M2 | AI21: 68 | BA21: =AR21+'1223'!BA21 -> 0 | BN21: 3000 | BO21: =SUM(AR21*BN21) -> 0 | BP21: =BO21+'1223'!BP21 -> 0 | BQ21: =BP21 -> 0 | BR21: 204000
A22: 11 | D22: 北側圍牆邊陰井新設不鏽鋼沉水馬達220V/110V 1HP以上(含工帶料，需配浮球開關)，抽水至圍牆外水溝 | AE22: 組 | AI22: 1 | BA22: =AR22+'1223'!BA22 -> 0 | BN22: 20000 | BO22: =SUM(AR22*BN22) -> 0 | BP22: =BO22+'1223'!BP22 -> 0 | BQ22: =BP22 -> 0 | BR22: 20000
A23: 12 | D23: 西側既有走廊上水溝格柵蓋板，設置化妝蓋板含框，周邊復原 | AE23: 式 | AI23: 1 | BA23: =AR23+'1223'!BA23 -> 0 | BN23: 68000 | BO23: =SUM(AR23*BN23) -> 0 | BP23: =BO23+'1223'!BP23 -> 0 | BQ23: =BP23 -> 0 | BR23: 68000
... A25: 14 | D25: 材料檢驗費用 | AE25: 式 | AI25: 1 | BA25: =AR25+'1223'!BA25 -> 0 | BN25: 1440 | BO25: =SUM(AR25*BN25) -> 0 | BP25: =BO25+'1223'!BP25 -> 0 | BQ25: =BP25 -> 0 | BR25: 1440
D26: 合計(壹) | BO26: =SUM(BO12:BO25) -> 0 | BP26: =SUM(BP12:BP25) -> 11000 | BQ26: =BP26 -> 11000 | BR26: =SUM(BR12:BR25) -> 776279
A27: 貳 | D27: 職業安全衛生管理費 (壹*1%) | AE27: 式 | AI27: 1 | AR27: =SUM(BO26/BN27) -> 0 | BA27: =AR27+'1223'!BA27 -> 0 | BN27: 7762 | BO27: =SUM(AR27*BN27) -> 0 | BP27: =BO27+'1223'!BP27 -> 0 | BQ27: =BP27 -> 0 | BR27: 7762 | BS27: =SUM(BN27/BR26) -> 0.0099989823
A28: 參 | D28: 工程品質管制作業費 (壹*1%) | AE28: 式 | AI28: 1 | AR28: =SUM(BO26/BN28) -> 0 | BA28: =AR28+'1223'!BA28 -> 0 | BN28: 7763 | BO28: =SUM(AR28*BN28) -> 0 | BP28: =BO28+'1223'!BP28 -> 0 | BQ28: =BP28 -> 0 | BR28: 7763 | BS28: =SUM(BN28/BR26) -> 0.010000271
A29: 肆 | D29: 包商利潤及管理費 (約壹*7%) | AE29: 式 | AI29: 1 | AR29: =SUM(BO26/BN29) -> 0 | BA29: =AR29+'1223'!BA29 -> 0 | BN29: 54338 | BO29: =SUM(AR29*BN29) -> 0 | BP29: =BO29+'1223'!BP29 -> 0 | BQ29: =BP29 -> 0 | BR29: 54338 | BS29: =SUM(BN29/BR26) -> 0.069998029
A30: 伍 | D30: 保險費 | AE30: 式 | AI30: 1 | AR30: 0 | BA30: =AR30+'1223'!BA30 -> 1 | BN30: 3084 | BO30: =SUM(AR30*BN30) -> 0 | BP30: =BO30+'1223'!BP30 -> 3084 | BQ30: =BP30 -> 3084 | BR30: 3084 | BT30: =SUM(BR26:BR30) -> 849226
A31: 陸 | D31: 營業稅 ((壹~伍)*5%) | AE31: 式 | AI31: 1 | AR31: =SUM(BT31/BN31) -> 0 | BA31: =AR31+'1223'!BA31 -> 0 | BN31: 42461 | BO31: =SUM(AR31*BN31) -> 0 | BP31: =BO31+'1223'!BP31 -> 0 | BQ31: =BP31 -> 0 | BR31: 42461 | BS31: =SUM(BN31/BT30) -> 0.049999647 | BT31: =SUM(BO26:BO30) -> 0
D32: 發包工程費合計 (壹~陸) | BO32: =SUM(BO26:BO31) -> 0 | BP32: =SUM(BP26:BP31) -> 14084 | BQ32: =SUM(BQ26:BQ31) -> 14084 | BR32: =SUM(BR26:BR31) -> 891687
D33: 本日合計金額 | AR33: =BO32 -> 0
D34: 累計合計金額 | AR34: =BP32 -> 14084 | BN34: 契約單價金額 | BO34: 本日完成金額 | BP34: 累計完成金額
A35: 營造業專業工程特定施工項目
A36: A.
A37: B.
A38: 二、工地材料管理概況(含約定之重要材料使用情況及數量等)：
A39: 材料名稱 | V39: 單位 | Y39: 設計數量 | AI39: 本日使用數量 | AS39: 累計使用數量 | BC39: 備註
AS40: =AI40+'1223'!AS40 -> 0
AS41: =AI41+'1223'!AS41 -> 0
...

Sheet 1225
A1: 公共工程施工日誌
A2: 表報編號： | H2: 11
A3: 本日天氣: | G3: 上午： | K3: 晴 | Q3: 下午: | U3: 晴 | AR3: 日期： | AW3: =SUM(R6+H2)-1 -> 45651 | BH3: =WEEKDAY(AW3) -> 4
A4: 工程名稱 | G4: 113年育英樓排水改善工程 | AN4: 承攬廠商名稱 | AV4: 齊全土木包工業
A5: 核定工期 | J5: 60 | O5: 天 | R5: 累計工期 | Z5: =H2-8 -> 3 | AE5: 天 | AH5: 剩餘工期 | AP5: =J5-Z5 -> 57 | AU5: 天 | AX5: 工期展廷天數 | BK5: 天
A6: 開 工 日 期 | R6: 45641 | AH6: 完 工 日 期 | AX6: =SUM(R6,J5)+31 -> 45732
A7: 本日預定進度(%) | R7: 0 | AH7: 本日實際進度(%) | AX7: =SUM(AR33/BO7) -> 0 | BO7: 891687
A8: 累計預定進度(%) | R8: =R7+'1224'!R8 -> 0.00903 | AH8: 累計實際進度(%) | AX8: =AX7+'1224'!AX8 -> 0.01579478
A9: 一、依施工計劃書執行按圖施工概況(含約定之重要施工項目及完成數量等)等：
A10: 項次 | D10: 施工項目 | AE10: 單位 | AI10: 契約數量 | AR10: 本日完成數量 | BA10: 累計完成數量 | BJ10: 備註 | BN10: 契約單價金額 | BO10: 本日完成金額 | BP10: 累計完成金額 | BR10: 契約總額
A11: 壹. | D11: 直接工程
A12: 1 | D12: 工程告示牌、職業安全衛生告示牌與交通管制設施(租用) | AE12: 式 | AI12: 1 | BA12: =AR12+'1224'!BA12 -> 1 | BN12: 5000 | BO12: =SUM(AR12*BN12) -> 0 | BP12: =BO12+'1224'!BP12 -> 5000 | BQ12: =BP12 -> 5000 | BR12: 5000
A13: 2 | D13: 施工圍籬(租用) | AE13: M | AI13: 74 | BA13: =AR13+'1224'!BA13 -> 15 | BN13: 400 | BO13: =SUM(AR13*BN13) -> 0 | BP13: =BO13+'1224'!BP13 -> 6000 | BQ13: =BP13 -> 6000 | BR13: 29600
A14: 3 | D14: 施工動線開闢及損壞復原 | AE14: 式 | AI14: 1 | BA14: =AR14+'1224'!BA14 -> 0 | BN14: 5000 | BO14: =SUM(AR14*BN14) -> 0 | BP14: =BO14+'1224'!BP14 -> 0 | BQ14: =BP14 -> 0 | BR14: 5000
A15: 4 | D15: 測量與放樣 | AE15: 式 | AI15: 1 | BA15: =AR15+'1224'!BA15 -> 0 | BN15: 5000 | BO15: =SUM(AR15*BN15) -> 0 | BP15: =BO15+'1224'!BP15 -> 0 | BQ15: =BP15 -> 0 | BR15: 5000
A16: 5 | D16: 既有水溝清淤(含移除水溝內樹木竄根)，破損處以樹脂水泥砂漿整平，外側溝壁以樹脂水泥砂漿打底至與鋪面齊平 | AE16: M | AI16: 81 | BA16: =AR16+'1224'!BA16 -> 0 | BN16: 1000 | BO16: =SUM(AR16*BN16) -> 0 | BP16: =BO16+'1224'!BP16 -> 0 | BQ16: =BP16 -> 0 | BR16: 81000
A17: 6 | D17: 既有水溝安裝鍍鋅鋼板 | AE17: M | AI17: 22 | BA17: =AR17+'1224'!BA17 -> 0 | BN17: 4650 | BO17: =SUM(AR17*BN17) -> 0 | BP17: =BO17+'1224'!BP17 -> 0 | BQ17: =BP17 -> 0 | BR17: 102300
A18: 7 | D18: 新設RC水溝 | AE18: M | AI18: 23 | BA18: =AR18+'1224'!BA18 -> 0 | BN18: 3500 | BO18: =SUM(AR18*BN18) -> 0 | BP18: =BO18+'1224'!BP18 -> 0 | BQ18: =BP18 -> 0 | BR18: 80500
A19: 8 | D19: 設置鍍鋅鋼材烤漆止滑細縫水溝蓋含框 | AE19: 組 | AI19: 8 | BA19: =AR19+'1224'!BA19 -> 0 | BN19: 6250 | BO19: =SUM(AR19*BN19) -> 0 | BP19: =BO19+'1224'!BP19 -> 0 | BQ19: =BP19 -> 0 | BR19: 50000
A20: 9 | D20: 切割打除既有地坪，整地，底土壓實 | AE20: M2 | AI20: 68 | BA20: =AR20+'1224'!BA20 -> 0 | BN20: 1200 | BO20: =SUM(AR20*BN20) -> 0 | BP20: =BO20+'1224'!BP20 -> 0 | BQ20: =BP20 -> 0 | BR20: 81600
A21: 10 | D21: 新設RC地坪與斜坡，面層抿石子 | AE21: M2 | AI21: 68 | BA21: =AR21+'1224'!BA21 -> 0 | BN21: 3000 | BO21: =SUM(AR21*BN21) -> 0 | BP21: =BO21+'1224'!BP21 -> 0 | BQ21: =BP21 -> 0 | BR21: 204000
A22: 11 | D22: 北側圍牆邊陰井新設不鏽鋼沉水馬達220V/110V 1HP以上(含工帶料，需配浮球開關)，抽水至圍牆外水溝 | AE22: 組 | AI22: 1 | BA22: =AR22+'1224'!BA22 -> 0 | BN22: 20000 | BO22: =SUM(AR22*BN22) -> 0 | BP22: =BO22+'1224'!BP22 -> 0 | BQ22: =BP22 -> 0 | BR22: 20000
A23: 12 | D23: 西側既有走廊上水溝格柵蓋板，設置化妝蓋板含框，周邊復原 | AE23: 式 | AI23: 1 | BA23: =AR23+'1224'!BA23 -> 0 | BN23: 68000 | BO23: =SUM(AR23*BN23) -> 0 | BP23: =BO23+'1224'!BP23 -> 0 | BQ23: =BP23 -> 0 | BR23: 68000
... A25: 14 | D25: 材料檢驗費用 | AE25: 式 | AI25: 1 | BA25: =AR25+'1224'!BA25 -> 0 | BN25: 1440 | BO25: =SUM(AR25*BN25) -> 0 | BP25: =BO25+'1224'!BP25 -> 0 | BQ25: =BP25 -> 0 | BR25: 1440
D26: 合計(壹) | BO26: =SUM(BO12:BO25) -> 0 | BP26: =SUM(BP12:BP25) -> 11000 | BQ26: =BP26 -> 11000 | BR26: =SUM(BR12:BR25) -> 776279
A27: 貳 | D27: 職業安全衛生管理費 (壹*1%) | AE27: 式 | AI27: 1 | AR27: =SUM(BO26/BN27) -> 0 | BA27: =AR27+'1224'!BA27 -> 0 | BN27: 7762 | BO27: =SUM(AR27*BN27) -> 0 | BP27: =BO27+'1224'!BP27 -> 0 | BQ27: =BP27 -> 0 | BR27: 7762 | BS27: =SUM(BN27/BR26) -> 0.0099989823
A28: 參 | D28: 工程品質管制作業費 (壹*1%) | AE28: 式 | AI28: 1 | AR28: =SUM(BO26/BN28) -> 0 | BA28: =AR28+'1224'!BA28 -> 0 | BN28: 7763 | BO28: =SUM(AR28*BN28) -> 0 | BP28: =BO28+'1224'!BP28 -> 0 | BQ28: =BP28 -> 0 | BR28: 7763 | BS28: =SUM(BN28/BR26) -> 0.010000271
A29: 肆 | D29: 包商利潤及管理費 (約壹*7%) | AE29: 式 | AI29: 1 | AR29: =SUM(BO26/BN29) -> 0 | BA29: =AR29+'1224'!BA29 -> 0 | BN29: 54338 | BO29: =SUM(AR29*BN29) -> 0 | BP29: =BO29+'1224'!BP29 -> 0 | BQ29: =BP29 -> 0 | BR29: 54338 | BS29: =SUM(BN29/BR26) -> 0.069998029
A30: 伍 | D30: 保險費 | AE30: 式 | AI30: 1 | AR30: 0 | BA30: =AR30+'1224'!BA30 -> 1 | BN30: 3084 | BO30: =SUM(AR30*BN30) -> 0 | BP30: =BO30+'1224'!BP30 -> 3084 | BQ30: =BP30 -> 3084 | BR30: 3084 | BT30: =SUM(BR26:BR30) -> 849226
A31: 陸 | D31: 營業稅 ((壹~伍)*5%) | AE31: 式 | AI31: 1 | AR31: =SUM(BT31/BN31) -> 0 | BA31: =AR31+'1224'!BA31 -> 0 | BN31: 42461 | BO31: =SUM(AR31*BN31) -> 0 | BP31: =BO31+'1224'!BP31 -> 0 | BQ31: =BP31 -> 0 | BR31: 42461 | BS31: =SUM(BN31/BT30) -> 0.049999647 | BT31: =SUM(BO26:BO30) -> 0
D32: 發包工程費合計 (壹~陸) | BO32: =SUM(BO26:BO31) -> 0 | BP32: =SUM(BP26:BP31) -> 14084 | BQ32: =SUM(BQ26:BQ31) -> 14084 | BR32: =SUM(BR26:BR31) -> 891687
D33: 本日合計金額 | AR33: =BO32 -> 0
D34: 累計合計金額 | AR34: =BP32 -> 14084 | BN34: 契約單價金額 | BO34: 本日完成金額 | BP34: 累計完成金額
A35: 營造業專業工程特定施工項目
A36: A.
A37: B.
A38: 二、工地材料管理概況(含約定之重要材料使用情況及數量等)：
A39: 材料名稱 | V39: 單位 | Y39: 設計數量 | AI39: 本日使用數量 | AS39: 累計使用數量 | BC39: 備註
AS40: =AI40+'1224'!AS40 -> 0
AS41: =AI41+'1224'!AS41 -> 0
...

Sheet 1226
A1: 公共工程施工日誌
A2: 表報編號： | H2: 12
A3: 本日天氣: | G3: 上午： | K3: 晴 | Q3: 下午: | U3: 晴 | AR3: 日期： | AW3: =SUM(R6+H2)-1 -> 45652 | BH3: =WEEKDAY(AW3) -> 5
A4: 工程名稱 | G4: 113年育英樓排水改善工程 | AN4: 承攬廠商名稱 | AV4: 齊全土木包工業
A5: 核定工期 | J5: 60 | O5: 天 | R5: 累計工期 | Z5: =H2-9 -> 3 | AE5: 天 | AH5: 剩餘工期 | AP5: =J5-Z5 -> 57 | AU5: 天 | AX5: 工期展廷天數 | BK5: 天
A6: 開 工 日 期 | R6: 45641 | AH6: 完 工 日 期 | AX6: =SUM(R6,J5)+31 -> 45732
A7: 本日預定進度(%) | R7: 0 | AH7: 本日實際進度(%) | AX7: =SUM(AR33/BO7) -> 0 | BO7: 891687
A8: 累計預定進度(%) | R8: =R7+'1225'!R8 -> 0.00903 | AH8: 累計實際進度(%) | AX8: =AX7+'1225'!AX8 -> 0.01579478
A9: 一、依施工計劃書執行按圖施工概況(含約定之重要施工項目及完成數量等)等：
A10: 項次 | D10: 施工項目 | AE10: 單位 | AI10: 契約數量 | AR10: 本日完成數量 | BA10: 累計完成數量 | BJ10: 備註 | BN10: 契約單價金額 | BO10: 本日完成金額 | BP10: 累計完成金額 | BR10: 契約總額
A11: 壹. | D11: 直接工程
A12: 1 | D12: 工程告示牌、職業安全衛生告示牌與交通管制設施(租用) | AE12: 式 | AI12: 1 | BA12: =AR12+'1225'!BA12 -> 1 | BN12: 5000 | BO12: =SUM(AR12*BN12) -> 0 | BP12: =BO12+'1225'!BP12 -> 5000 | BQ12: =BP12 -> 5000 | BR12: 5000
A13: 2 | D13: 施工圍籬(租用) | AE13: M | AI13: 74 | BA13: =AR13+'1225'!BA13 -> 15 | BN13: 400 | BO13: =SUM(AR13*BN13) -> 0 | BP13: =BO13+'1225'!BP13 -> 6000 | BQ13: =BP13 -> 6000 | BR13: 29600
A14: 3 | D14: 施工動線開闢及損壞復原 | AE14: 式 | AI14: 1 | BA14: =AR14+'1225'!BA14 -> 0 | BN14: 5000 | BO14: =SUM(AR14*BN14) -> 0 | BP14: =BO14+'1225'!BP14 -> 0 | BQ14: =BP14 -> 0 | BR14: 5000
A15: 4 | D15: 測量與放樣 | AE15: 式 | AI15: 1 | BA15: =AR15+'1225'!BA15 -> 0 | BN15: 5000 | BO15: =SUM(AR15*BN15) -> 0 | BP15: =BO15+'1225'!BP15 -> 0 | BQ15: =BP15 -> 0 | BR15: 5000
A16: 5 | D16: 既有水溝清淤(含移除水溝內樹木竄根)，破損處以樹脂水泥砂漿整平，外側溝壁以樹脂水泥砂漿打底至與鋪面齊平 | AE16: M | AI16: 81 | BA16: =AR16+'1225'!BA16 -> 0 | BN16: 1000 | BO16: =SUM(AR16*BN16) -> 0 | BP16: =BO16+'1225'!BP16 -> 0 | BQ16: =BP16 -> 0 | BR16: 81000
A17: 6 | D17: 既有水溝安裝鍍鋅鋼板 | AE17: M | AI17: 22 | BA17: =AR17+'1225'!BA17 -> 0 | BN17: 4650 | BO17: =SUM(AR17*BN17) -> 0 | BP17: =BO17+'1225'!BP17 -> 0 | BQ17: =BP17 -> 0 | BR17: 102300
A18: 7 | D18: 新設RC水溝 | AE18: M | AI18: 23 | BA18: =AR18+'1225'!BA18 -> 0 | BN18: 3500 | BO18: =SUM(AR18*BN18) -> 0 | BP18: =BO18+'1225'!BP18 -> 0 | BQ18: =BP18 -> 0 | BR18: 80500
A19: 8 | D19: 設置鍍鋅鋼材烤漆止滑細縫水溝蓋含框 | AE19: 組 | AI19: 8 | BA19: =AR19+'1225'!BA19 -> 0 | BN19: 6250 | BO19: =SUM(AR19*BN19) -> 0 | BP19: =BO19+'1225'!BP19 -> 0 | BQ19: =BP19 -> 0 | BR19: 50000
A20: 9 | D20: 切割打除既有地坪，整地，底土壓實 | AE20: M2 | AI20: 68 | BA20: =AR20+'1225'!BA20 -> 0 | BN20: 1200 | BO20: =SUM(AR20*BN20) -> 0 | BP20: =BO20+'1225'!BP20 -> 0 | BQ20: =BP20 -> 0 | BR20: 81600
A21: 10 | D21: 新設RC地坪與斜坡，面層抿石子 | AE21: M2 | AI21: 68 | BA21: =AR21+'1225'!BA21 -> 0 | BN21: 3000 | BO21: =SUM(AR21*BN21) -> 0 | BP21: =BO21+'1225'!BP21 -> 0 | BQ21: =BP21 -> 0 | BR21: 204000
A22: 11 | D22: 北側圍牆邊陰井新設不鏽鋼沉水馬達220V/110V 1HP以上(含工帶料，需配浮球開關)，抽水至圍牆外水溝 | AE22: 組 | AI22: 1 | BA22: =AR22+'1225'!BA22 -> 0 | BN22: 20000 | BO22: =SUM(AR22*BN22) -> 0 | BP22: =BO22+'1225'!BP22 -> 0 | BQ22: =BP22 -> 0 | BR22: 20000
A23: 12 | D23: 西側既有走廊上水溝格柵蓋板，設置化妝蓋板含框，周邊復原 | AE23: 式 | AI23: 1 | BA23: =AR23+'1225'!BA23 -> 0 | BN23: 68000 | BO23: =SUM(AR23*BN23) -> 0 | BP23: =BO23+'1225'!BP23 -> 0 | BQ23: =BP23 -> 0 | BR23: 68000
... A25: 14 | D25: 材料檢驗費用 | AE25: 式 | AI25: 1 | BA25: =AR25+'1225'!BA25 -> 0 | BN25: 1440 | BO25: =SUM(AR25*BN25) -> 0 | BP25: =BO25+'1225'!BP25 -> 0 | BQ25: =BP25 -> 0 | BR25: 1440
D26: 合計(壹) | BO26: =SUM(BO12:BO25) -> 0 | BP26: =SUM(BP12:BP25) -> 11000 | BQ26: =BP26 -> 11000 | BR26: =SUM(BR12:BR25) -> 776279
