Workbook

Sheet 基本資料
B1: 自行填寫 | C1: 有公式勿動
J2: 標價清單
B3: 工程名稱 | D3: 114年度修整建運動場地 | G3: 必填 | J3: 項 次 | K3: 項 目 及 說 明 | L3: 單位 | M3: 數量 | N3: 單價 | O3: 複價
B4: 契約工期 | D4: 30 | E4: 日曆天 | G4: 必填 | J4: 壹 | K4: 直接工程費
B5: 開工日期 | D5: 45880 | G5: 必填 | J5: 1 | K5: 工程告示牌與職安衛告示牌(租用) | L5: 式 | M5: 1 | N5: 8700 | O5: =M5*N5 -> 8700
B6: 預定完工日 | D6: =D5+D4-1 -> 45909 | G6: 必填 | J6: 2 | K6: 工區管制措施，施工環境保護與清潔 | L6: 式 | M6: 1 | N6: 15300 | O6: =M6*N6 -> 15300
B7: 契約編號 | D7: 11419 | G7: 必填 | J7: 3 | K7: 查修天花板所有天井燈具(30盞)與迴路 | L7: 式 | M7: 1 | N7: 95210 | O7: =M7*N7 -> 95210
B8: 契約金額 | C8: 原契約 | D8: 780000 | G8: 必填 | J8: 4 | K8: 拆除清運既有天井燈具，安裝LED天井燈具 (200W以上，含防眩鏡片與安全防墜配件)(含施工機具，連工帶料 | L8: 盞 | M8: 10 | N8: 19100 | O8: =M8*N8 -> 191000
C9: 變更後契約 | G9: (基本上不需填) | J9: 貳 | K9: 職業安全衛生管理費(壹*1%) | L9: 式 | M9: 1 | N9: 3102 | O9: =M9*N9 -> 3102
B10: 契約變更次數 | G10: (沒有就不要填) | J10: 參 | K10: 公共工程品質管制作業費(壹*1%) | L10: 式 | M10: 1 | N10: 3102 | O10: =M10*N10 -> 3102
B11: 工期展延天數 | G11: (沒有就不要填) | J11: 肆 | K11: 包商利潤及管理費(約壹*7%) | L11: 式 | M11: 1 | N11: 21715 | O11: =M11*N11 -> 21715
B12: 主辦機關 | D12: 嘉義縣立永慶高級中學 | G12: 封面資料 | J12: 伍 | K12: 營造綜合保險費 | L12: 式 | M12: 1 | N12: 2000 | O12: =M12*N12 -> 2000
B13: 監造單位 | D13: 大墩規劃設計顧問有限公司 | G13: 封面資料 | J13: 陸 | K13: 營業稅((壹~伍)*5%) | L13: 式 | M13: 1 | N13: 17006 | O13: =M13*N13 -> 17006
B14: 承攬廠商 | D14: 以勒綠能光電有限公司 | G14: 封面資料
B15: 封面日期 | G15: 封面資料 | P15: =SUM(O5:O13) -> 357135

Sheet 填寫
AE1: 施工取樣試驗記錄： | AF1: 出工數及機具: | AL1: 甲方通知辦理事項: | AM1: 重要事項紀錄: | AO1: 工地勞工安全衛生事項之督導 | AP1: 檢驗停留點及施工抽查等情形 | AU1: 查核材料規格及品質 | AV1: 其他約定監造事項 | AW1: 通知分包廠商辦理事項 | AX1: 監造-勞安部分
A2: 日期 | B2: 星期 | C2: 上午 | D2: 下午 | E2: 天數 | F2: 預定每日進度% | G2: 預計累計進度% | H2: 實際累計進度% | I2: 施作概述 | J2: 備註 | K2: 項目 | L2: =基本資料!K5 -> 工程告示牌與職安衛告示牌(租用) | M2: 累計數量 | N2: =基本資料!K6 -> 工區管制措施，施工環境保護與清潔 | O2: 累計數量 | P2: =基本資料!K7 -> 查修天花板所有天井燈具(30盞)與迴路 | Q2: 累計數量 | R2: =基本資料!K8 -> 拆除清運既有天井燈具，安裝LED天井燈具 (200W以上，含防眩鏡片與安全防墜配件)(含施工機具，連工帶料 | S2: 累計數量 | T2: =基本資料!K9 -> 職業安全衛生管理費(壹*1%) | U2: 累計數量 | V2: =基本資料!K10 -> 公共工程品質管制作業費(壹*1%) | W2: 累計數量 | X2: =基本資料!K11 -> 包商利潤及管理費(約壹*7%) | Y2: 累計數量 | Z2: =基本資料!K12 -> 營造綜合保險費 | AA2: 累計數量 | AB2: =基本資料!K13 -> 營業稅((壹~伍)*5%) | AC2: 累計數量 | AD2: 金額 | AF2: 水電工 | AG2: 累計數量 | AH2: 高空作業車 | AI2: 累計數量 | AJ2: 貨車 | AK2: 累計數量 | AO2: (ㄧ)施工前檢查事項： 1.實施勤前教育(含工地預防災變及危害告知)：█有 □無 2.確認新進勞工是否提報勞工保險(或其他商業保險)資料及安全衛生教育訓練紀錄：□有 □無 █無新進勞工 204.檢查勞工個人防護具：█有 □無
K3: 單位 | L3: =基本資料!L5 -> 式 | N3: =基本資料!L6 -> 式 | P3: =基本資料!L7 -> 式 | R3: =基本資料!L8 -> 盞 | T3: =基本資料!L9 -> 式 | V3: =基本資料!L10 -> 式 | X3: =基本資料!L11 -> 式 | Z3: =基本資料!L12 -> 式 | AB3: =基本資料!L13 -> 式
K4: 數量 | L4: =基本資料!M5 -> 1 | N4: =基本資料!M6 -> 1 | P4: =基本資料!M7 -> 1 | R4: =基本資料!M8 -> 10 | T4: =基本資料!M9 -> 1 | V4: =基本資料!M10 -> 1 | X4: =基本資料!M11 -> 1 | Z4: =基本資料!M12 -> 1 | AB4: =基本資料!M13 -> 1 | AD4: 契約金額
K5: 單價 | L5: =基本資料!N5 -> 8700 | N5: =基本資料!N6 -> 15300 | P5: =基本資料!N7 -> 95210 | R5: =基本資料!N8 -> 19100 | T5: =基本資料!N9 -> 3102 | V5: =基本資料!N10 -> 3102 | X5: =基本資料!N11 -> 21715 | Z5: =基本資料!N12 -> 2000 | AB5: =基本資料!N13 -> 17006 | AD5: =L4*L5+N4*N5+P4*P5+R4*R5+T4*T5+V4*V5+X4*X5+Z4*Z5+AB4*AB5 -> 357135
A6: =基本資料!D5 -> 45880 | B6: =A6 -> 45880 | C6: 雨 | D6: 雨 | E6: 1 | F6: 0.0333 | G6: 0.0333 | H6: 0.0338 | L6: 1 | M6: =L6 -> 1 | O6: =N6 -> 0 | Q6: =P6 -> 0 | S6: =R6 -> 0 | T6: 0.028 | U6: =T6 -> 0.028 | V6: 0.028 | W6: =V6 -> 0.028 | X6: 0.028 | Y6: =X6 -> 0.028 | Z6: 0.028 | AA6: =Z6 -> 0.028 | AB6: 0.028 | AC6: =AB6 -> 0.028 | AD6: =填寫!M6*基本資料!$N$5+填寫!O6*基本資料!$N$6+填寫!Q6*基本資料!$N$7+填寫!S6*基本資料!$N$8+填寫!U6*基本資料!$N$9+填寫!W6*基本資料!$N$10+填寫!Y6*基本資料!$N$11+填寫!AA6*基本資料!$N$12+填寫!AC6*基本資料!$N$13 -> 10013.9 | AG6: 0 | AI6: =AH6 -> 0 | AK6: =AJ6 -> 0 | AN6: =G6 -> 0.0333 | AO6: (ㄧ)施工前檢查事項： 1.實施勤前教育(含工地預防災變及危害告知)：█有 □無 2.確認新進勞工是否提報勞工保險(或其他商業保險)資料及安全衛生教育訓練紀錄：□有 □無 █無新進勞工 3.檢查勞工個人防護具：█有 □無 | AQ6: =B6 -> 45880 | AR6: =F6-0 -> 0.0333 | AS6: =G6-0 -> 0.0333 | AT6: =A6 -> 45880 | AU6: =K6 -> 0 | AX6: （一）施工廠商施工前檢查事項辦理情形：█完成 □未完成 （二）其他工地安全衛生督導事項：
A7: =A6+1 -> 45881 | B7: =A7 -> 45881 | C7: 雨 | D7: 雨 | E7: =E6+1 -> 2 | F7: 0.0333 | G7: =G6+F7 -> 0.0666 | H7: 0.0338 | M7: =M6+L7 -> 1 | O7: =O6+N7 -> 0 | Q7: =Q6+P7 -> 0 | S7: =S6+R7 -> 0 | U7: =U6+T7 -> 0.028 | W7: =W6+V7 -> 0.028 | Y7: =Y6+X7 -> 0.028 | AA7: =AA6+Z7 -> 0.028 | AC7: =AC6+AB7 -> 0.028 | AD7: =填寫!M7*基本資料!$N$5+填寫!O7*基本資料!$N$6+填寫!Q7*基本資料!$N$7+填寫!S7*基本資料!$N$8+填寫!U7*基本資料!$N$9+填寫!W7*基本資料!$N$10+填寫!Y7*基本資料!$N$11+填寫!AA7*基本資料!$N$12+填寫!AC7*基本資料!$N$13 -> 10013.9 | AG7: =AG6+AF7 -> 0 | AI7: =AI6+AH7 -> 0 | AK7: =AK6+AJ7 -> 0
A8: =A7+1 -> 45882 | B8: =A8 -> 45882 | C8: 雨 | D8: 雨 | E8: =E7+1 -> 3 | F8: 0.0333 | G8: =G7+F8 -> 0.0999 | H8: 0.0338 | M8: =M7+L8 -> 1 | O8: =O7+N8 -> 0 | Q8: =Q7+P8 -> 0 | S8: =S7+R8 -> 0 | U8: =U7+T8 -> 0.028 | W8: =W7+V8 -> 0.028 | Y8: =Y7+X8 -> 0.028 | AA8: =AA7+Z8 -> 0.028 | AC8: =AC7+AB8 -> 0.028 | AD8: =填寫!M8*基本資料!$N$5+填寫!O8*基本資料!$N$6+填寫!Q8*基本資料!$N$7+填寫!S8*基本資料!$N$8+填寫!U8*基本資料!$N$9+填寫!W8*基本資料!$N$10+填寫!Y8*基本資料!$N$11+填寫!AA8*基本資料!$N$12+填寫!AC8*基本資料!$N$13 -> 10013.9 | AG8: =AG7+AF8 -> 0 | AI8: =AI7+AH8 -> 0 | AK8: =AK7+AJ8 -> 0
A9: =A8+1 -> 45883 | B9: =A9 -> 45883 | C9: 雨 | D9: 雨 | E9: =E8+1 -> 4 | F9: 0.0333 | G9: =G8+F9 -> 0.1332 | H9: 0.0338 | M9: =M8+L9 -> 1 | O9: =O8+N9 -> 0 | Q9: =Q8+P9 -> 0 | S9: =S8+R9 -> 0 | U9: =U8+T9 -> 0.028 | W9: =W8+V9 -> 0.028 | Y9: =Y8+X9 -> 0.028 | AA9: =AA8+Z9 -> 0.028 | AC9: =AC8+AB9 -> 0.028 | AD9: =填寫!M9*基本資料!$N$5+填寫!O9*基本資料!$N$6+填寫!Q9*基本資料!$N$7+填寫!S9*基本資料!$N$8+填寫!U9*基本資料!$N$9+填寫!W9*基本資料!$N$10+填寫!Y9*基本資料!$N$11+填寫!AA9*基本資料!$N$12+填寫!AC9*基本資料!$N$13 -> 10013.9 | AG9: =AG8+AF9 -> 0 | AI9: =AI8+AH9 -> 0 | AK9: =AK8+AJ9 -> 0
A10: =A9+1 -> 45884 | B10: =A10 -> 45884 | C10: 雨 | D10: 雨 | E10: =E9+1 -> 5 | F10: 0.0333 | G10: =G9+F10 -> 0.1665 | H10: 0.0338 | M10: =M9+L10 -> 1 | O10: =O9+N10 -> 0 | Q10: =Q9+P10 -> 0 | S10: =S9+R10 -> 0 | U10: =U9+T10 -> 0.028 | W10: =W9+V10 -> 0.028 | Y10: =Y9+X10 -> 0.028 | AA10: =AA9+Z10 -> 0.028 | AC10: =AC9+AB10 -> 0.028 | AD10: =填寫!M10*基本資料!$N$5+填寫!O10*基本資料!$N$6+填寫!Q10*基本資料!$N$7+填寫!S10*基本資料!$N$8+填寫!U10*基本資料!$N$9+填寫!W10*基本資料!$N$10+填寫!Y10*基本資料!$N$11+填寫!AA10*基本資料!$N$12+填寫!AC10*基本資料!$N$13 -> 10013.9 | AG10: =AG9+AF10 -> 0 | AI10: =AI9+AH10 -> 0 | AK10: =AK9+AJ10 -> 0
A11: =A10+1 -> 45885 | B11: =A11 -> 45885 | C11: 雨 | D11: 雨 | E11: =E10+1 -> 6 | F11: 0.0333 | G11: =G10+F11 -> 0.1998 | H11: 0.0338 | M11: =M10+L11 -> 1 | O11: =O10+N11 -> 0 | Q11: =Q10+P11 -> 0 | S11: =S10+R11 -> 0 | U11: =U10+T11 -> 0.028 | W11: =W10+V11 -> 0.028 | Y11: =Y10+X11 -> 0.028 | AA11: =AA10+Z11 -> 0.028 | AC11: =AC10+AB11 -> 0.028 | AD11: =填寫!M11*基本資料!$N$5+填寫!O11*基本資料!$N$6+填寫!Q11*基本資料!$N$7+填寫!S11*基本資料!$N$8+填寫!U11*基本資料!$N$9+填寫!W11*基本資料!$N$10+填寫!Y11*基本資料!$N$11+填寫!AA11*基本資料!$N$12+填寫!AC11*基本資料!$N$13 -> 10013.9 | AG11: =AG10+AF11 -> 0 | AI11: =AI10+AH11 -> 0 | AK11: =AK10+AJ11 -> 0
A12: =A11+1 -> 45886 | B12: =A12 -> 45886 | C12: 雨 | D12: 雨 | E12: =E11+1 -> 7 | F12: 0.0333 | G12: =G11+F12 -> 0.2331 | H12: 0.0338 | M12: =M11+L12 -> 1 | O12: =O11+N12 -> 0 | Q12: =Q11+P12 -> 0 | S12: =S11+R12 -> 0 | U12: =U11+T12 -> 0.028 | W12: =W11+V12 -> 0.028 | Y12: =Y11+X12 -> 0.028 | AA12: =AA11+Z12 -> 0.028 | AC12: =AC11+AB12 -> 0.028 | AD12: =填寫!M12*基本資料!$N$5+填寫!O12*基本資料!$N$6+填寫!Q12*基本資料!$N$7+填寫!S12*基本資料!$N$8+填寫!U12*基本資料!$N$9+填寫!W12*基本資料!$N$10+填寫!Y12*基本資料!$N$11+填寫!AA12*基本資料!$N$12+填寫!AC12*基本資料!$N$13 -> 10013.9 | AG12: =AG11+AF12 -> 0 | AI12: =AI11+AH12 -> 0 | AK12: =AK11+AJ12 -> 0
A13: =A12+1 -> 45887 | B13: =A13 -> 45887 | C13: 晴 | D13: 雨 | E13: =E12+1 -> 8 | F13: 0.0333 | G13: =G12+F13 -> 0.2664 | H13: 0.0338 | M13: =M12+L13 -> 1 | O13: =O12+N13 -> 0 | Q13: =Q12+P13 -> 0 | S13: =S12+R13 -> 0 | U13: =U12+T13 -> 0.028 | W13: =W12+V13 -> 0.028 | Y13: =Y12+X13 -> 0.028 | AA13: =AA12+Z13 -> 0.028 | AC13: =AC12+AB13 -> 0.028 | AD13: =填寫!M13*基本資料!$N$5+填寫!O13*基本資料!$N$6+填寫!Q13*基本資料!$N$7+填寫!S13*基本資料!$N$8+填寫!U13*基本資料!$N$9+填寫!W13*基本資料!$N$10+填寫!Y13*基本資料!$N$11+填寫!AA13*基本資料!$N$12+填寫!AC13*基本資料!$N$13 -> 10013.9 | AG13: =AG12+AF13 -> 0 | AI13: =AI12+AH13 -> 0 | AK13: =AK12+AJ13 -> 0
A14: =A13+1 -> 45888 | B14: =A14 -> 45888 | C14: 晴 | D14: 雨 | E14: =E13+1 -> 9 | F14: 0.0333 | G14: =G13+F14 -> 0.2997 | H14: 0.0338 | M14: =M13+L14 -> 1 | O14: =O13+N14 -> 0 | Q14: =Q13+P14 -> 0 | S14: =S13+R14 -> 0 | U14: =U13+T14 -> 0.028 | W14: =W13+V14 -> 0.028 | Y14: =Y13+X14 -> 0.028 | AA14: =AA13+Z14 -> 0.028 | AC14: =AC13+AB14 -> 0.028 | AD14: =填寫!M14*基本資料!$N$5+填寫!O14*基本資料!$N$6+填寫!Q14*基本資料!$N$7+填寫!S14*基本資料!$N$8+填寫!U14*基本資料!$N$9+填寫!W14*基本資料!$N$10+填寫!Y14*基本資料!$N$11+填寫!AA14*基本資料!$N$12+填寫!AC14*基本資料!$N$13 -> 10013.9 | AG14: =AG13+AF14 -> 0 | AI14: =AI13+AH14 -> 0 | AK14: =AK13+AJ14 -> 0
A15: =A14+1 -> 45889 | B15: =A15 -> 45889 | C15: 晴 | D15: 晴 | E15: =E14+1 -> 10 | F15: 0.0333 | G15: =G14+F15 -> 0.333 | H15: 0.0338 | M15: =M14+L15 -> 1 | O15: =O14+N15 -> 0 | Q15: =Q14+P15 -> 0 | S15: =S14+R15 -> 0 | U15: =U14+T15 -> 0.028 | W15: =W14+V15 -> 0.028 | Y15: =Y14+X15 -> 0.028 | AA15: =AA14+Z15 -> 0.028 | AC15: =AC14+AB15 -> 0.028 | AD15: =填寫!M15*基本資料!$N$5+填寫!O15*基本資料!$N$6+填寫!Q15*基本資料!$N$7+填寫!S15*基本資料!$N$8+填寫!U15*基本資料!$N$9+填寫!W15*基本資料!$N$10+填寫!Y15*基本資料!$N$11+填寫!AA15*基本資料!$N$12+填寫!AC15*基本資料!$N$13 -> 10013.9 | AG15: =AG14+AF15 -> 0 | AI15: =AI14+AH15 -> 0 | AK15: =AK14+AJ15 -> 0
A16: =A15+1 -> 45890 | B16: =A16 -> 45890 | C16: 晴 | D16: 晴 | E16: =E15+1 -> 11 | F16: 0.0333 | G16: =G15+F16 -> 0.3663 | H16: =AD16/基本資料!P15 -> 0.54240406 | I16: 安裝燈具10pc | M16: =M15+L16 -> 1 | N16: 1 | O16: =O15+N16 -> 1 | P16: 0.5 | Q16: =Q15+P16 -> 0.5 | R16: 5 | S16: =S15+R16 -> 5 | T16: 0.539 | U16: =U15+T16 -> 0.567 | V16: 0.539 | W16: =W15+V16 -> 0.567 | X16: 0.539 | Y16: =Y15+X16 -> 0.567 | Z16: 0.539 | AA16: =AA15+Z16 -> 0.567 | AB16: 0.539 | AC16: =AC15+AB16 -> 0.567 | AD16: =填寫!M16*基本資料!$N$5+填寫!O16*基本資料!$N$6+填寫!Q16*基本資料!$N$7+填寫!S16*基本資料!$N$8+填寫!U16*基本資料!$N$9+填寫!W16*基本資料!$N$10+填寫!Y16*基本資料!$N$11+填寫!AA16*基本資料!$N$12+填寫!AC16*基本資料!$N$13 -> 193711.48 | AF16: 4 | AG16: =AG15+AF16 -> 4 | AH16: 2 | AI16: =AI15+AH16 -> 2 | AJ16: 2 | AK16: =AK15+AJ16 -> 2
A17: =A16+1 -> 45891 | B17: =A17 -> 45891 | C17: 晴 | D17: 晴 | E17: =E16+1 -> 12 | F17: 0.0333 | G17: =G16+F17 -> 0.3996 | H17: 1 | I17: 查修燈具 | M17: =M16+L17 -> 1 | O17: =O16+N17 -> 1 | P17: 0.5 | Q17: =Q16+P17 -> 1 | R17: 5 | S17: =S16+R17 -> 10 | T17: 0.461 | U17: =U16+T17 -> 1.028 | V17: 0.461 | W17: =W16+V17 -> 1.028 | X17: 0.461 | Y17: =Y16+X17 -> 1.028 | Z17: 0.461 | AA17: =AA16+Z17 -> 1.028 | AB17: 0.461 | AC17: =AC16+AB17 -> 1.028 | AD17: =填寫!M17*基本資料!$N$5+填寫!O17*基本資料!$N$6+填寫!Q17*基本資料!$N$7+填寫!S17*基本資料!$N$8+填寫!U17*基本資料!$N$9+填寫!W17*基本資料!$N$10+填寫!Y17*基本資料!$N$11+填寫!AA17*基本資料!$N$12+填寫!AC17*基本資料!$N$13 -> 358448.9 | AF17: 4 | AG17: =AG16+AF17 -> 8 | AH17: 2 | AI17: =AI16+AH17 -> 4 | AJ17: 2 | AK17: =AK16+AJ17 -> 4
A18: =A17+1 -> 45892 | B18: =A18 -> 45892 | F18: 0.0333 | G18: =G17+F18 -> 0.4329 | O18: =O17+N18 -> 1 | Q18: =Q17+P18 -> 1 | S18: =S17+R18 -> 10 | U18: =U17+T18 -> 1.028 | W18: =W17+V18 -> 1.028 | Y18: =Y17+X18 -> 1.028 | AA18: =AA17+Z18 -> 1.028 | AC18: =AC17+AB18 -> 1.028 | AD18: =填寫!M18*基本資料!N17+填寫!O18*基本資料!N18+填寫!Q18*基本資料!N19+填寫!S18*基本資料!N20+填寫!U18*基本資料!N21+填寫!W18*基本資料!N22+填寫!Y18*填寫!J16+填寫!AA18*填寫!J17+填寫!AC18*基本資料!N25 -> 0 | AG18: =AG17+AF18 -> 8 | AI18: =AI17+AH18 -> 4 | AK18: =AK17+AJ18 -> 4
A19: =A18+1 -> 45893 | B19: =A19 -> 45893 | F19: 0.0333 | G19: =G18+F19 -> 0.4662
A20: =A19+1 -> 45894 | B20: =A20 -> 45894 | F20: 0.0333 | G20: =G19+F20 -> 0.4995
A21: =A20+1 -> 45895 | B21: =A21 -> 45895 | F21: 0.0333 | G21: =G20+F21 -> 0.5328
A22: =A21+1 -> 45896 | B22: =A22 -> 45896 | F22: 0.0333 | G22: =G21+F22 -> 0.5661
A23: =A22+1 -> 45897 | B23: =A23 -> 45897 | F23: 0.0333 | G23: =G22+F23 -> 0.5994
A24: =A23+1 -> 45898 | B24: =A24 -> 45898 | F24: 0.0333 | G24: =G23+F24 -> 0.6327
A25: =A24+1 -> 45899 | B25: =A25 -> 45899 | F25: 0.0333 | G25: =G24+F25 -> 0.666
A26: =A25+1 -> 45900 | B26: =A26 -> 45900 | F26: 0.0333 | G26: =G25+F26 -> 0.6993
A27: =A26+1 -> 45901 | B27: =A27 -> 45901 | F27: 0.0333 | G27: =G26+F27 -> 0.7326
A28: =A27+1 -> 45902 | B28: =A28 -> 45902 | F28: 0.0333 | G28: =G27+F28 -> 0.7659
A29: =A28+1 -> 45903 | B29: =A29 -> 45903 | F29: 0.0333 | G29: =G28+F29 -> 0.7992
A30: =A29+1 -> 45904 | B30: =A30 -> 45904 | F30: 0.0333 | G30: =G29+F30 -> 0.8325
... A35: =A34+1 -> 45909 | B35: =A35 -> 45909 | F35: 0.0343 | G35: =G34+F35 -> 1

Sheet 0811
A1: 公共工程施工日誌
A2: 表報編號: | B2: =基本資料!D7 -> 11419 | C2: P001 | D2: =J2 -> 45880 | I2: 填報日期： | J2: =基本資料!D5 -> 45880 | L2: =J2 -> 45880
A3: 本日天氣: | B3: 上午： | C3: =_xlfn.XLOOKUP(J2,填寫!A:A,填寫!C:C) -> 雨 | D3: 下午： | E3: =_xlfn.XLOOKUP(J2,填寫!A:A,填寫!D:D) -> 雨
A4: 工程名稱 | C4: =基本資料!D3 -> 114年度修整建運動場地 | G4: 承攬廠商名稱 | I4: =基本資料!D14 -> 以勒綠能光電有限公司
A5: 核定工期 | C5: =基本資料!D4 -> 30 | D5: 累計工期 | F5: =填寫!E6 -> 1 | G5: 剩餘工期 | I5: =C5-F5 -> 29 | J5: 工期展延天數
A6: 開工日期 | D6: =基本資料!D5 -> 45880 | G6: 完工日期 | J6: =D6+C5-1 -> 45909
A7: 預定進度(%) | D7: =_xlfn.XLOOKUP(J2,填寫!A:A,填寫!G:G,) -> 0.0333 | G7: 實際進度(%) | J7: =_xlfn.XLOOKUP(J2,填寫!A:A,填寫!H:H) -> 0.0338
A8: 一、依施工計畫書執行按圖施工概況（含約定之重要施工項目及完成數量等）：
A9: 施工項目 | D9: 單位 | E9: 契約數量 | G9: 本日完成數量 | I9: 累計完成數量 | K9: 備註
A10: =基本資料!K5 -> 工程告示牌與職安衛告示牌(租用) | D10: =基本資料!L5 -> 式 | E10: =基本資料!M5 -> 1 | G10: =_xlfn.XLOOKUP(J2,填寫!A:A,填寫!L:L) -> 1 | I10: =_xlfn.XLOOKUP(J2,填寫!A:A,填寫!M:M) -> 1
A11: =基本資料!K6 -> 工區管制措施，施工環境保護與清潔 | D11: =基本資料!L6 -> 式 | E11: =基本資料!M6 -> 1 | G11: =_xlfn.XLOOKUP(J2,填寫!A:A,填寫!N:N) -> 0 | I11: =_xlfn.XLOOKUP(J2,填寫!A:A,填寫!O:O) -> 0
A12: =基本資料!K7 -> 查修天花板所有天井燈具(30盞)與迴路 | D12: =基本資料!L7 -> 式 | E12: =基本資料!M7 -> 1 | G12: =_xlfn.XLOOKUP(J2,填寫!A:A,填寫!P:P) -> 0 | I12: =_xlfn.XLOOKUP(J2,填寫!A:A,填寫!Q:Q) -> 0
A13: =基本資料!K8 -> 拆除清運既有天井燈具，安裝LED天井燈具 (200W以上，含防眩鏡片與安全防墜配件)(含施工機具，連工帶料 | D13: =基本資料!L8 -> 盞 | E13: =基本資料!M8 -> 10 | G13: =_xlfn.XLOOKUP(J2,填寫!A:A,填寫!R:R) -> 0 | I13: =_xlfn.XLOOKUP(J2,填寫!A:A,填寫!S:S) -> 0
A14: =基本資料!K9 -> 職業安全衛生管理費(壹*1%) | D14: =基本資料!L9 -> 式 | E14: =基本資料!M9 -> 1 | G14: =_xlfn.XLOOKUP(J2,填寫!A:A,填寫!T:T) -> 0.028 | I14: =_xlfn.XLOOKUP(J2,填寫!A:A,填寫!U:U) -> 0.028
A15: =基本資料!K10 -> 公共工程品質管制作業費(壹*1%) | D15: =基本資料!L10 -> 式 | E15: =基本資料!M10 -> 1 | G15: =_xlfn.XLOOKUP(J2,填寫!A:A,填寫!V:V) -> 0.028 | I15: =_xlfn.XLOOKUP(J2,填寫!A:A,填寫!W:W) -> 0.028
A16: =基本資料!K11 -> 包商利潤及管理費(約壹*7%) | D16: =基本資料!L11 -> 式 | E16: =基本資料!M11 -> 1 | G16: =_xlfn.XLOOKUP(J2,填寫!A:A,填寫!X:X) -> 0.028 | I16: =_xlfn.XLOOKUP(J2,填寫!A:A,填寫!Y:Y) -> 0.028
A17: =基本資料!K12 -> 營造綜合保險費 | D17: =基本資料!L12 -> 式 | E17: =基本資料!M12 -> 1 | G17: =_xlfn.XLOOKUP(J2,填寫!A:A,填寫!Z:Z) -> 0.028 | I17: =_xlfn.XLOOKUP(J2,填寫!A:A,填寫!AA:AA) -> 0.028
A18: =基本資料!K13 -> 營業稅((壹~伍)*5%) | D18: =基本資料!L13 -> 式 | E18: =基本資料!M13 -> 1 | G18: =_xlfn.XLOOKUP(J2,填寫!A:A,填寫!AB:AB) -> 0.028 | I18: =_xlfn.XLOOKUP(J2,填寫!A:A,填寫!AC:AC) -> 0.028
A21: 二、工地材料管理概況（含約定之重要材料使用狀況及數量等）：
A22: 材料名稱 | D22: 單位 | E22: 設計數量 | G22: 本日使用數量 | I22: 累計使用數量 | K22: 備註
A24: 三、工地人員及機具管理（含約定之出工人數及機具使用情形及數量）：
A25: 工別 | C25: 本日人數 | E25: 累計人數 | G25: 機具名稱 | I25: 本日使用量 | K25: 累計使用量
A26: =填寫!AF2 -> 水電工 | C26: =_xlfn.XLOOKUP(J2,填寫!A:A,填寫!AF:AF) -> 0 | E26: =_xlfn.XLOOKUP(J2,填寫!A:A,填寫!AG:AG) -> 0 | G26: =填寫!AH2 -> 高空作業車 | I26: =_xlfn.XLOOKUP(J2,填寫!A:A,填寫!AH:AH) -> 0 | K26: =_xlfn.XLOOKUP(J2,填寫!A:A,填寫!AI:AI) -> 0
G27: =填寫!AJ2 -> 貨車 | I27: =_xlfn.XLOOKUP(J2,填寫!A:A,填寫!AJ:AJ) -> 0 | K27: =_xlfn.XLOOKUP(J2,填寫!A:A,填寫!AK:AK) -> 0
A28: 四、本日施工項目是否有須依「營造業專業工程特定施工項目應置之技術士總類、比率或人數標準表」規定應設置技術士之專業工程：□有■無 (此項如勾選"有"，則應填寫後附｢公共工程施工日誌之技術士簽章表｣
A29: 五、工地勞工安全衛生事項之督導、公共環境與安全之維護及其他工地行政事務：
A30: =VLOOKUP(J2,'[1]2.總表'!$A$7:$GT$499,196) -> (ㄧ)施工前檢查事項： 1.實施勤前教育(含工地預防災變及危害告知)：█有 □無 2.確認新進勞工是否提報勞工保險(或其他商業保險)資料及安全衛生教育訓練紀錄：□有 □無 █無新進勞工 3.檢查勞工個人防護具：█有 □無
A31: 六、施工取樣試驗紀錄：
A35: 七、通知分包廠商辦理事項：
A36: =VLOOKUP(J2,'[1]2.總表'!$A$7:$GW$499,193) -> 0
A37: 八、重要事項紀錄:
A41: =VLOOKUP(J2,'[1]2.總表'!$A$7:$GY$499,194) -> 0
A42: 簽章：【工地負責人】(註3)
A44: 註：1.依據營造業法第32條第1項第2款規定，工地主任應按日填報施工日誌。
A45: 2.本施工日誌格式僅供參考，惟原則應包含上開欄位，各機關亦得依工程性質及契約約定事項自行增訂之。
A46: 3.本工程依營造業法第30條規定須置工地主任者，由工地主任簽章；依上開規定免置工地主任者，則由營造業法第32條第2項所定之人員簽章。廠商非屬營造業者，由工地負責人簽章。
A47: 4.契約工期如有修正，應填修正後之契約工期，含展延工期及不計工期天數；如有依契約變更設計，預定進度及實際進度應填變更設計後計算之進度。
A48: 5.上開重要事項紀錄包含(1)主辦機關及監造單位指示(2)工地遇緊急異常狀況之通報處理情形(3)本日是否由專任工程人員督察按圖施工、解決施工技術問題等。
A49: 6.公共工程屬建築物者，請依內政部99年2月5日台內營字第0990800804號令頒之「建築物施工日誌」填寫。

Sheet 0812
A1: 公共工程施工日誌
A2: 表報編號: | B2: =基本資料!D7 -> 11419 | C2: P001 | D2: =J2 -> 45881 | I2: 填報日期： | J2: 45881 | L2: =J2 -> 45881
A3: 本日天氣: | B3: 上午： | C3: =_xlfn.XLOOKUP(J2,填寫!A:A,填寫!C:C) -> 雨 | D3: 下午： | E3: =_xlfn.XLOOKUP(J2,填寫!A:A,填寫!D:D) -> 雨
A4: 工程名稱 | C4: =基本資料!D3 -> 114年度修整建運動場地 | G4: 承攬廠商名稱 | I4: =基本資料!D14 -> 以勒綠能光電有限公司
A5: 核定工期 | C5: =基本資料!D4 -> 30 | D5: 累計工期 | F5: =填寫!E7 -> 2 | G5: 剩餘工期 | I5: =C5-F5 -> 28 | J5: 工期展延天數
A6: 開工日期 | D6: =基本資料!D5 -> 45880 | G6: 完工日期 | J6: =D6+C5-1 -> 45909
A7: 預定進度(%) | D7: =_xlfn.XLOOKUP(J2,填寫!A:A,填寫!G:G,) -> 0.0666 | G7: 實際進度(%) | J7: =_xlfn.XLOOKUP(J2,填寫!A:A,填寫!H:H) -> 0.0338
A8: 一、依施工計畫書執行按圖施工概況（含約定之重要施工項目及完成數量等）：
A9: 施工項目 | D9: 單位 | E9: 契約數量 | G9: 本日完成數量 | I9: 累計完成數量 | K9: 備註
A10: =基本資料!K5 -> 工程告示牌與職安衛告示牌(租用) | D10: =基本資料!L5 -> 式 | E10: =基本資料!M5 -> 1 | G10: =_xlfn.XLOOKUP(J2,填寫!A:A,填寫!L:L) -> 0 | I10: =_xlfn.XLOOKUP(J2,填寫!A:A,填寫!M:M) -> 1
A11: =基本資料!K6 -> 工區管制措施，施工環境保護與清潔 | D11: =基本資料!L6 -> 式 | E11: =基本資料!M6 -> 1 | G11: =_xlfn.XLOOKUP(J2,填寫!A:A,填寫!N:N) -> 0 | I11: =_xlfn.XLOOKUP(J2,填寫!A:A,填寫!O:O) -> 0
A12: =基本資料!K7 -> 查修天花板所有天井燈具(30盞)與迴路 | D12: =基本資料!L7 -> 式 | E12: =基本資料!M7 -> 1 | G12: =_xlfn.XLOOKUP(J2,填寫!A:A,填寫!P:P) -> 0 | I12: =_xlfn.XLOOKUP(J2,填寫!A:A,填寫!Q:Q) -> 0
A13: =基本資料!K8 -> 拆除清運既有天井燈具，安裝LED天井燈具 (200W以上，含防眩鏡片與安全防墜配件)(含施工機具，連工帶料 | D13: =基本資料!L8 -> 盞 | E13: =基本資料!M8 -> 10 | G13: =_xlfn.XLOOKUP(J2,填寫!A:A,填寫!R:R) -> 0 | I13: =_xlfn.XLOOKUP(J2,填寫!A:A,填寫!S:S) -> 0
A14: =基本資料!K9 -> 職業安全衛生管理費(壹*1%) | D14: =基本資料!L9 -> 式 | E14: =基本資料!M9 -> 1 | G14: =_xlfn.XLOOKUP(J2,填寫!A:A,填寫!T:T) -> 0 | I14: =_xlfn.XLOOKUP(J2,填寫!A:A,填寫!U:U) -> 0.028
A15: =基本資料!K10 -> 公共工程品質管制作業費(壹*1%) | D15: =基本資料!L10 -> 式 | E15: =基本資料!M10 -> 1 | G15: =_xlfn.XLOOKUP(J2,填寫!A:A,填寫!V:V) -> 0 | I15: =_xlfn.XLOOKUP(J2,填寫!A:A,填寫!W:W) -> 0.028
A16: =基本資料!K11 -> 包商利潤及管理費(約壹*7%) | D16: =基本資料!L11 -> 式 | E16: =基本資料!M11 -> 1 | G16: =_xlfn.XLOOKUP(J2,填寫!A:A,填寫!X:X) -> 0 | I16: =_xlfn.XLOOKUP(J2,填寫!A:A,填寫!Y:Y) -> 0.028
A17: =基本資料!K12 -> 營造綜合保險費 | D17: =基本資料!L12 -> 式 | E17: =基本資料!M12 -> 1 | G17: =_xlfn.XLOOKUP(J2,填寫!A:A,填寫!Z:Z) -> 0 | I17: =_xlfn.XLOOKUP(J2,填寫!A:A,填寫!AA:AA) -> 0.028
A18: =基本資料!K13 -> 營業稅((壹~伍)*5%) | D18: =基本資料!L13 -> 式 | E18: =基本資料!M13 -> 1 | G18: =_xlfn.XLOOKUP(J2,填寫!A:A,填寫!AB:AB) -> 0 | I18: =_xlfn.XLOOKUP(J2,填寫!A:A,填寫!AC:AC) -> 0.028
A21: 二、工地材料管理概況（含約定之重要材料使用狀況及數量等）：
A22: 材料名稱 | D22: 單位 | E22: 設計數量 | G22: 本日使用數量 | I22: 累計使用數量 | K22: 備註
A24: 三、工地人員及機具管理（含約定之出工人數及機具使用情形及數量）：
A25: 工別 | C25: 本日人數 | E25: 累計人數 | G25: 機具名稱 | I25: 本日使用量 | K25: 累計使用量
A26: =填寫!AF2 -> 水電工 | C26: =_xlfn.XLOOKUP(J2,填寫!A:A,填寫!AF:AF) -> 0 | E26: =_xlfn.XLOOKUP(J2,填寫!A:A,填寫!AG:AG) -> 0 | G26: =填寫!AH2 -> 高空作業車 | I26: =_xlfn.XLOOKUP(J2,填寫!A:A,填寫!AH:AH) -> 0 | K26: =_xlfn.XLOOKUP(J2,填寫!A:A,填寫!AI:AI) -> 0
G27: =填寫!AJ2 -> 貨車 | I27: =_xlfn.XLOOKUP(J2,填寫!A:A,填寫!AJ:AJ) -> 0 | K27: =_xlfn.XLOOKUP(J2,填寫!A:A,填寫!AK:AK) -> 0
A28: 四、本日施工項目是否有須依「營造業專業工程特定施工項目應置之技術士總類、比率或人數標準表」規定應設置技術士之專業工程：□有■無 (此項如勾選"有"，則應填寫後附｢公共工程施工日誌之技術士簽章表｣
A29: 五、工地勞工安全衛生事項之督導、公共環境與安全之維護及其他工地行政事務：
A30: =VLOOKUP(J2,'[1]2.總表'!$A$7:$GT$499,196) -> (ㄧ)施工前檢查事項： 1.實施勤前教育(含工地預防災變及危害告知)：█有 □無 2.確認新進勞工是否提報勞工保險(或其他商業保險)資料及安全衛生教育訓練紀錄：□有 □無 █無新進勞工 3.檢查勞工個人防護具：█有 □無
A31: 六、施工取樣試驗紀錄：
A35: 七、通知分包廠商辦理事項：
A36: =VLOOKUP(J2,'[1]2.總表'!$A$7:$GW$499,193) -> 0
A37: 八、重要事項紀錄:
A41: =VLOOKUP(J2,'[1]2.總表'!$A$7:$GY$499,194) -> 0
A42: 簽章：【工地負責人】(註3)
A44: 註：1.依據營造業法第32條第1項第2款規定，工地主任應按日填報施工日誌。
A45: 2.本施工日誌格式僅供參考，惟原則應包含上開欄位，各機關亦得依工程性質及契約約定事項自行增訂之。
A46: 3.本工程依營造業法第30條規定須置工地主任者，由工地主任簽章；依上開規定免置工地主任者，則由營造業法第32條第2項所定之人員簽章。廠商非屬營造業者，由工地負責人簽章。
A47: 4.契約工期如有修正，應填修正後之契約工期，含展延工期及不計工期天數；如有依契約變更設計，預定進度及實際進度應填變更設計後計算之進度。
A48: 5.上開重要事項紀錄包含(1)主辦機關及監造單位指示(2)工地遇緊急異常狀況之通報處理情形(3)本日是否由專任工程人員督察按圖施工、解決施工技術問題等。
A49: 6.公共工程屬建築物者，請依內政部99年2月5日台內營字第0990800804號令頒之「建築物施工日誌」填寫。

Sheet 0813
A1: 公共工程施工日誌
A2: 表報編號: | B2: =基本資料!D7 -> 11419 | C2: P001 | D2: =J2 -> 45882 | I2: 填報日期： | J2: 45882 | L2: =J2 -> 45882
A3: 本日天氣: | B3: 上午： | C3: =_xlfn.XLOOKUP(J2,填寫!A:A,填寫!C:C) -> 雨 | D3: 下午： | E3: =_xlfn.XLOOKUP(J2,填寫!A:A,填寫!D:D) -> 雨
A4: 工程名稱 | C4: =基本資料!D3 -> 114年度修整建運動場地 | G4: 承攬廠商名稱 | I4: =基本資料!D14 -> 以勒綠能光電有限公司
A5: 核定工期 | C5: =基本資料!D4 -> 30 | D5: 累計工期 | F5: =填寫!E8 -> 3 | G5: 剩餘工期 | I5: =C5-F5 -> 27 | J5: 工期展延天數
A6: 開工日期 | D6: =基本資料!D5 -> 45880 | G6: 完工日期 | J6: =D6+C5-1 -> 45909
A7: 預定進度(%) | D7: =_xlfn.XLOOKUP(J2,填寫!A:A,填寫!G:G,) -> 0.0999 | G7: 實際進度(%) | J7: =_xlfn.XLOOKUP(J2,填寫!A:A,填寫!H:H) -> 0.0338
A8: 一、依施工計畫書執行按圖施工概況（含約定之重要施工項目及完成數量等）：
A9: 施工項目 | D9: 單位 | E9: 契約數量 | G9: 本日完成數量 | I9: 累計完成數量 | K9: 備註
A10: =基本資料!K5 -> 工程告示牌與職安衛告示牌(租用) | D10: =基本資料!L5 -> 式 | E10: =基本資料!M5 -> 1 | G10: =_xlfn.XLOOKUP(J2,填寫!A:A,填寫!L:L) -> 0 | I10: =_xlfn.XLOOKUP(J2,填寫!A:A,填寫!M:M) -> 1
A11: =基本資料!K6 -> 工區管制措施，施工環境保護與清潔 | D11: =基本資料!L6 -> 式 | E11: =基本資料!M6 -> 1 | G11: =_xlfn.XLOOKUP(J2,填寫!A:A,填寫!N:N) -> 0 | I11: =_xlfn.XLOOKUP(J2,填寫!A:A,填寫!O:O) -> 0
A12: =基本資料!K7 -> 查修天花板所有天井燈具(30盞)與迴路 | D12: =基本資料!L7 -> 式 | E12: =基本資料!M7 -> 1 | G12: =_xlfn.XLOOKUP(J2,填寫!A:A,填寫!P:P) -> 0 | I12: =_xlfn.XLOOKUP(J2,填寫!A:A,填寫!Q:Q) -> 0
A13: =基本資料!K8 -> 拆除清運既有天井燈具，安裝LED天井燈具 (200W以上，含防眩鏡片與安全防墜配件)(含施工機具，連工帶料 | D13: =基本資料!L8 -> 盞 | E13: =基本資料!M8 -> 10 | G13: =_xlfn.XLOOKUP(J2,填寫!A:A,填寫!R:R) -> 0 | I13: =_xlfn.XLOOKUP(J2,填寫!A:A,填寫!S:S) -> 0
A14: =基本資料!K9 -> 職業安全衛生管理費(壹*1%) | D14: =基本資料!L9 -> 式 | E14: =基本資料!M9 -> 1 | G14: =_xlfn.XLOOKUP(J2,填寫!A:A,填寫!T:T) -> 0 | I14: =_xlfn.XLOOKUP(J2,填寫!A:A,填寫!U:U) -> 0.028
A15: =基本資料!K10 -> 公共工程品質管制作業費(壹*1%) | D15: =基本資料!L10 -> 式 | E15: =基本資料!M10 -> 1 | G15: =_xlfn.XLOOKUP(J2,填寫!A:A,填寫!V:V) -> 0 | I15: =_xlfn.XLOOKUP(J2,填寫!A:A,填寫!W:W) -> 0.028
A16: =基本資料!K11 -> 包商利潤及管理費(約壹*7%) | D16: =基本資料!L11 -> 式 | E16: =基本資料!M11 -> 1 | G16: =_xlfn.XLOOKUP(J2,填寫!A:A,填寫!X:X) -> 0 | I16: =_xlfn.XLOOKUP(J2,填寫!A:A,填寫!Y:Y) -> 0.028
A17: =基本資料!K12 -> 營造綜合保險費 | D17: =基本資料!L12 -> 式 | E17: =基本資料!M12 -> 1 | G17: =_xlfn.XLOOKUP(J2,填寫!A:A,填寫!Z:Z) -> 0 | I17: =_xlfn.XLOOKUP(J2,填寫!A:A,填寫!AA:AA) -> 0.028
A18: =基本資料!K13 -> 營業稅((壹~伍)*5%) | D18: =基本資料!L13 -> 式 | E18: =基本資料!M13 -> 1 | G18: =_xlfn.XLOOKUP(J2,填寫!A:A,填寫!AB:AB) -> 0 | I18: =_xlfn.XLOOKUP(J2,填寫!A:A,填寫!AC:AC) -> 0.028
A21: 二、工地材料管理概況（含約定之重要材料使用狀況及數量等）：
A22: 材料名稱 | D22: 單位 | E22: 設計數量 | G22: 本日使用數量 | I22: 累計使用數量 | K22: 備註
A24: 三、工地人員及機具管理（含約定之出工人數及機具使用情形及數量）：
A25: 工別 | C25: 本日人數 | E25: 累計人數 | G25: 機具名稱 | I25: 本日使用量 | K25: 累計使用量
A26: =填寫!AF2 -> 水電工 | C26: =_xlfn.XLOOKUP(J2,填寫!A:A,填寫!AF:AF) -> 0 | E26: =_xlfn.XLOOKUP(J2,填寫!A:A,填寫!AG:AG) -> 0 | G26: =填寫!AH2 -> 高空作業車 | I26: =_xlfn.XLOOKUP(J2,填寫!A:A,填寫!AH:AH) -> 0 | K26: =_xlfn.XLOOKUP(J2,填寫!A:A,填寫!AI:AI) -> 0
G27: =填寫!AJ2 -> 貨車 | I27: =_xlfn.XLOOKUP(J2,填寫!A:A,填寫!AJ:AJ) -> 0 | K27: =_xlfn.XLOOKUP(J2,填寫!A:A,填寫!AK:AK) -> 0
A28: 四、本日施工項目是否有須依「營造業專業工程特定施工項目應置之技術士總類、比率或人數標準表」規定應設置技術士之專業工程：□有■無 (此項如勾選"有"，則應填寫後附｢公共工程施工日誌之技術士簽章表｣
A29: 五、工地勞工安全衛生事項之督導、公共環境與安全之維護及其他工地行政事務：
A30: =VLOOKUP(J2,'[1]2.總表'!$A$7:$GT$499,196) -> (ㄧ)施工前檢查事項： 1.實施勤前教育(含工地預防災變及危害告知)：█有 □無 2.確認新進勞工是否提報勞工保險(或其他商業保險)資料及安全衛生教育訓練紀錄：□有 □無 █無新進勞工 3.檢查勞工個人防護具：█有 □無
A31: 六、施工取樣試驗紀錄：
A35: 七、通知分包廠商辦理事項：
A36: =VLOOKUP(J2,'[1]2.總表'!$A$7:$GW$499,193) -> 0
A37: 八、重要事項紀錄:
A41: =VLOOKUP(J2,'[1]2.總表'!$A$7:$GY$499,194) -> 0
A42: 簽章：【工地負責人】(註3)
A44: 註：1.依據營造業法第32條第1項第2款規定，工地主任應按日填報施工日誌。
A45: 2.本施工日誌格式僅供參考，惟原則應包含上開欄位，各機關亦得依工程性質及契約約定事項自行增訂之。
A46: 3.本工程依營造業法第30條規定須置工地主任者，由工地主任簽章；依上開規定免置工地主任者，則由營造業法第32條第2項所定之人員簽章。廠商非屬營造業者，由工地負責人簽章。
A47: 4.契約工期如有修正，應填修正後之契約工期，含展延工期及不計工期天數；如有依契約變更設計，預定進度及實際進度應填變更設計後計算之進度。
A48: 5.上開重要事項紀錄包含(1)主辦機關及監造單位指示(2)工地遇緊急異常狀況之通報處理情形(3)本日是否由專任工程人員督察按圖施工、解決施工技術問題等。
A49: 6.公共工程屬建築物者，請依內政部99年2月5日台內營字第0990800804號令頒之「建築物施工日誌」填寫。

Sheet 0814
A1: 公共工程施工日誌
A2: 表報編號: | B2: =基本資料!D7 -> 11419 | C2: P001 | D2: =J2 -> 45883 | I2: 填報日期： | J2: 45883 | L2: =J2 -> 45883
A3: 本日天氣: | B3: 上午： | C3: =_xlfn.XLOOKUP(J2,填寫!A:A,填寫!C:C) -> 雨 | D3: 下午： | E3: =_xlfn.XLOOKUP(J2,填寫!A:A,填寫!D:D) -> 雨
A4: 工程名稱 | C4: =基本資料!D3 -> 114年度修整建運動場地 | G4: 承攬廠商名稱 | I4: =基本資料!D14 -> 以勒綠能光電有限公司
A5: 核定工期 | C5: =基本資料!D4 -> 30 | D5: 累計工期 | F5: =填寫!E9 -> 4 | G5: 剩餘工期 | I5: =C5-F5 -> 26 | J5: 工期展延天數
A6: 開工日期 | D6: =基本資料!D5 -> 45880 | G6: 完工日期 | J6: =D6+C5-1 -> 45909
A7: 預定進度(%) | D7: =_xlfn.XLOOKUP(J2,填寫!A:A,填寫!G:G,) -> 0.1332 | G7: 實際進度(%) | J7: =_xlfn.XLOOKUP(J2,填寫!A:A,填寫!H:H) -> 0.0338
A8: 一、依施工計畫書執行按圖施工概況（含約定之重要施工項目及完成數量等）：
A9: 施工項目 | D9: 單位 | E9: 契約數量 | G9: 本日完成數量 | I9: 累計完成數量 | K9: 備註
A10: =基本資料!K5 -> 工程告示牌與職安衛告示牌(租用) | D10: =基本資料!L5 -> 式 | E10: =基本資料!M5 -> 1 | G10: =_xlfn.XLOOKUP(J2,填寫!A:A,填寫!L:L) -> 0 | I10: =_xlfn.XLOOKUP(J2,填寫!A:A,填寫!M:M) -> 1
A11: =基本資料!K6 -> 工區管制措施，施工環境保護與清潔 | D11: =基本資料!L6 -> 式 | E11: =基本資料!M6 -> 1 | G11: =_xlfn.XLOOKUP(J2,填寫!A:A,填寫!N:N) -> 0 | I11: =_xlfn.XLOOKUP(J2,填寫!A:A,填寫!O:O) -> 0
A12: =基本資料!K7 -> 查修天花板所有天井燈具(30盞)與迴路 | D12: =基本資料!L7 -> 式 | E12: =基本資料!M7 -> 1 | G12: =_xlfn.XLOOKUP(J2,填寫!A:A,填寫!P:P) -> 0 | I12: =_xlfn.XLOOKUP(J2,填寫!A:A,填寫!Q:Q) -> 0
A13: =基本資料!K8 -> 拆除清運既有天井燈具，安裝LED天井燈具 (200W以上，含防眩鏡片與安全防墜配件)(含施工機具，連工帶料 | D13: =基本資料!L8 -> 盞 | E13: =基本資料!M8 -> 10 | G13: =_xlfn.XLOOKUP(J2,填寫!A:A,填寫!R:R) -> 0 | I13: =_xlfn.XLOOKUP(J2,填寫!A:A,填寫!S:S) -> 0
A14: =基本資料!K9 -> 職業安全衛生管理費(壹*1%) | D14: =基本資料!L9 -> 式 | E14: =基本資料!M9 -> 1 | G14: =_xlfn.XLOOKUP(J2,填寫!A:A,填寫!T:T) -> 0 | I14: =_xlfn.XLOOKUP(J2,填寫!A:A,填寫!U:U) -> 0.028
A15: =基本資料!K10 -> 公共工程品質管制作業費(壹*1%) | D15: =基本資料!L10 -> 式 | E15: =基本資料!M10 -> 1 | G15: =_xlfn.XLOOKUP(J2,填寫!A:A,填寫!V:V) -> 0 | I15: =_xlfn.XLOOKUP(J2,填寫!A:A,填寫!W:W) -> 0.028
A16: =基本資料!K11 -> 包商利潤及管理費(約壹*7%) | D16: =基本資料!L11 -> 式 | E16: =基本資料!M11 -> 1 | G16: =_xlfn.XLOOKUP(J2,填寫!A:A,填寫!X:X) -> 0 | I16: =_xlfn.XLOOKUP(J2,填寫!A:A,填寫!Y:Y) -> 0.028
A17: =基本資料!K12 -> 營造綜合保險費 | D17: =基本資料!L12 -> 式 | E17: =基本資料!M12 -> 1 | G17: =_xlfn.XLOOKUP(J2,填寫!A:A,填寫!Z:Z) -> 0 | I17: =_xlfn.XLOOKUP(J2,填寫!A:A,填寫!AA:AA) -> 0.028
A18: =基本資料!K13 -> 營業稅((壹~伍)*5%) | D18: =基本資料!L13 -> 式 | E18: =基本資料!M13 -> 1 | G18: =_xlfn.XLOOKUP(J2,填寫!A:A,填寫!AB:AB) -> 0 | I18: =_xlfn.XLOOKUP(J2,填寫!A:A,填寫!AC:AC) -> 0.028
A21: 二、工地材料管理概況（含約定之重要材料使用狀況及數量等）：
A22: 材料名稱 | D22: 單位 | E22: 設計數量 | G22: 本日使用數量 | I22: 累計使用數量 | K22: 備註
A24: 三、工地人員及機具管理（含約定之出工人數及機具使用情形及數量）：
A25: 工別 | C25: 本日人數 | E25: 累計人數 | G25: 機具名稱 | I25: 本日使用量 | K25: 累計使用量
A26: =填寫!AF2 -> 水電工 | C26: =_xlfn.XLOOKUP(J2,填寫!A:A,填寫!AF:AF) -> 0 | E26: =_xlfn.XLOOKUP(J2,填寫!A:A,填寫!AG:AG) -> 0 | G26: =填寫!AH2 -> 高空作業車 | I26: =_xlfn.XLOOKUP(J2,填寫!A:A,填寫!AH:AH) -> 0 | K26: =_xlfn.XLOOKUP(J2,填寫!A:A,填寫!AI:AI) -> 0
G27: =填寫!AJ2 -> 貨車 | I27: =_xlfn.XLOOKUP(J2,填寫!A:A,填寫!AJ:AJ) -> 0 | K27: =_xlfn.XLOOKUP(J2,填寫!A:A,填寫!AK:AK) -> 0
A28: 四、本日施工項目是否有須依「營造業專業工程特定施工項目應置之技術士總類、比率或人數標準表」規定應設置技術士之專業工程：□有■無 (此項如勾選"有"，則應填寫後附｢公共工程施工日誌之技術士簽章表｣
A29: 五、工地勞工安全衛生事項之督導、公共環境與安全之維護及其他工地行政事務：
A30: =VLOOKUP(J2,'[1]2.總表'!$A$7:$GT$499,196) -> (ㄧ)施工前檢查事項： 1.實施勤前教育(含工地預防災變及危害告知)：█有 □無 2.確認新進勞工是否提報勞工保險(或其他商業保險)資料及安全衛生教育訓練紀錄：□有 □無 █無新進勞工 3.檢查勞工個人防護具：█有 □無
A31: 六、施工取樣試驗紀錄：
A35: 七、通知分包廠商辦理事項：
A36: =VLOOKUP(J2,'[1]2.總表'!$A$7:$GW$499,193) -> 0
A37: 八、重要事項紀錄:
A41: =VLOOKUP(J2,'[1]2.總表'!$A$7:$GY$499,194) -> 0
A42: 簽章：【工地負責人】(註3)
A44: 註：1.依據營造業法第32條第1項第2款規定，工地主任應按日填報施工日誌。
A45: 2.本施工日誌格式僅供參考，惟原則應包含上開欄位，各機關亦得依工程性質及契約約定事項自行增訂之。
A46: 3.本工程依營造業法第30條規定須置工地主任者，由工地主任簽章；依上開規定免置工地主任者，則由營造業法第32條第2項所定之人員簽章。廠商非屬營造業者，由工地負責人簽章。
A47: 4.契約工期如有修正，應填修正後之契約工期，含展延工期及不計工期天數；如有依契約變更設計，預定進度及實際進度應填變更設計後計算之進度。
A48: 5.上開重要事項紀錄包含(1)主辦機關及監造單位指示(2)工地遇緊急異常狀況之通報處理情形(3)本日是否由專任工程人員督察按圖施工、解決施工技術問題等。
A49: 6.公共工程屬建築物者，請依內政部99年2月5日台內營字第0990800804號令頒之「建築物施工日誌」填寫。

Sheet 0815
A1: 公共工程施工日誌
A2: 表報編號: | B2: =基本資料!D7 -> 11419 | C2: P001 | D2: =J2 -> 45884 | I2: 填報日期： | J2: 45884 | L2: =J2 -> 45884
A3: 本日天氣: | B3: 上午： | C3: =_xlfn.XLOOKUP(J2,填寫!A:A,填寫!C:C) -> 雨 | D3: 下午： | E3: =_xlfn.XLOOKUP(J2,填寫!A:A,填寫!D:D) -> 雨
A4: 工程名稱 | C4: =基本資料!D3 -> 114年度修整建運動場地 | G4: 承攬廠商名稱 | I4: =基本資料!D14 -> 以勒綠能光電有限公司
A5: 核定工期 | C5: =基本資料!D4 -> 30 | D5: 累計工期 | F5: =填寫!E10 -> 5 | G5: 剩餘工期 | I5: =C5-F5 -> 25 | J5: 工期展延天數
A6: 開工日期 | D6: =基本資料!D5 -> 45880 | G6: 完工日期 | J6: =D6+C5-1 -> 45909
A7: 預定進度(%) | D7: =_xlfn.XLOOKUP(J2,填寫!A:A,填寫!G:G,) -> 0.1665 | G7: 實際進度(%) | J7: =_xlfn.XLOOKUP(J2,填寫!A:A,填寫!H:H) -> 0.0338
A8: 一、依施工計畫書執行按圖施工概況（含約定之重要施工項目及完成數量等）：
A9: 施工項目 | D9: 單位 | E9: 契約數量 | G9: 本日完成數量 | I9: 累計完成數量 | K9: 備註
A10: =基本資料!K5 -> 工程告示牌與職安衛告示牌(租用) | D10: =基本資料!L5 -> 式 | E10: =基本資料!M5 -> 1 | G10: =_xlfn.XLOOKUP(J2,填寫!A:A,填寫!L:L) -> 0 | I10: =_xlfn.XLOOKUP(J2,填寫!A:A,填寫!M:M) -> 1
A11: =基本資料!K6 -> 工區管制措施，施工環境保護與清潔 | D11: =基本資料!L6 -> 式 | E11: =基本資料!M6 -> 1 | G11: =_xlfn.XLOOKUP(J2,填寫!A:A,填寫!N:N) -> 0 | I11: =_xlfn.XLOOKUP(J2,填寫!A:A,填寫!O:O) -> 0
A12: =基本資料!K7 -> 查修天花板所有天井燈具(30盞)與迴路 | D12: =基本資料!L7 -> 式 | E12: =基本資料!M7 -> 1 | G12: =_xlfn.XLOOKUP(J2,填寫!A:A,填寫!P:P) -> 0 | I12: =_xlfn.XLOOKUP(J2,填寫!A:A,填寫!Q:Q) -> 0
A13: =基本資料!K8 -> 拆除清運既有天井燈具，安裝LED天井燈具 (200W以上，含防眩鏡片與安全防墜配件)(含施工機具，連工帶料 | D13: =基本資料!L8 -> 盞 | E13: =基本資料!M8 -> 10 | G13: =_xlfn.XLOOKUP(J2,填寫!A:A,填寫!R:R) -> 0 | I13: =_xlfn.XLOOKUP(J2,填寫!A:A,填寫!S:S) -> 0
A14: =基本資料!K9 -> 職業安全衛生管理費(壹*1%) | D14: =基本資料!L9 -> 式 | E14: =基本資料!M9 -> 1 | G14: =_xlfn.XLOOKUP(J2,填寫!A:A,填寫!T:T) -> 0 | I14: =_xlfn.XLOOKUP(J2,填寫!A:A,填寫!U:U) -> 0.028
A15: =基本資料!K10 -> 公共工程品質管制作業費(壹*1%) | D15: =基本資料!L10 -> 式 | E15: =基本資料!M10 -> 1 | G15: =_xlfn.XLOOKUP(J2,填寫!A:A,填寫!V:V) -> 0 | I15: =_xlfn.XLOOKUP(J2,填寫!A:A,填寫!W:W) -> 0.028
A16: =基本資料!K11 -> 包商利潤及管理費(約壹*7%) | D16: =基本資料!L11 -> 式 | E16: =基本資料!M11 -> 1 | G16: =_xlfn.XLOOKUP(J2,填寫!A:A,填寫!X:X) -> 0 | I16: =_xlfn.XLOOKUP(J2,填寫!A:A,填寫!Y:Y) -> 0.028
A17: =基本資料!K12 -> 營造綜合保險費 | D17: =基本資料!L12 -> 式 | E17: =基本資料!M12 -> 1 | G17: =_xlfn.XLOOKUP(J2,填寫!A:A,填寫!Z:Z) -> 0 | I17: =_xlfn.XLOOKUP(J2,填寫!A:A,填寫!AA:AA) -> 0.028
A18: =基本資料!K13 -> 營業稅((壹~伍)*5%) | D18: =基本資料!L13 -> 式 | E18: =基本資料!M13 -> 1 | G18: =_xlfn.XLOOKUP(J2,填寫!A:A,填寫!AB:AB) -> 0 | I18: =_xlfn.XLOOKUP(J2,填寫!A:A,填寫!AC:AC) -> 0.028
A21: 二、工地材料管理概況（含約定之重要材料使用狀況及數量等）：
A22: 材料名稱 | D22: 單位 | E22: 設計數量 | G22: 本日使用數量 | I22: 累計使用數量 | K22: 備註
A24: 三、工地人員及機具管理（含約定之出工人數及機具使用情形及數量）：
A25: 工別 | C25: 本日人數 | E25: 累計人數 | G25: 機具名稱 | I25: 本日使用量 | K25: 累計使用量
A26: =填寫!AF2 -> 水電工 | C26: =_xlfn.XLOOKUP(J2,填寫!A:A,填寫!AF:AF) -> 0 | E26: =_xlfn.XLOOKUP(J2,填寫!A:A,填寫!AG:AG) -> 0 | G26: =填寫!AH2 -> 高空作業車 | I26: =_xlfn.XLOOKUP(J2,填寫!A:A,填寫!AH:AH) -> 0 | K26: =_xlfn.XLOOKUP(J2,填寫!A:A,填寫!AI:AI) -> 0
G27: =填寫!AJ2 -> 貨車 | I27: =_xlfn.XLOOKUP(J2,填寫!A:A,填寫!AJ:AJ) -> 0 | K27: =_xlfn.XLOOKUP(J2,填寫!A:A,填寫!AK:AK) -> 0
A28: 四、本日施工項目是否有須依「營造業專業工程特定施工項目應置之技術士總類、比率或人數標準表」規定應設置技術士之專業工程：□有■無 (此項如勾選"有"，則應填寫後附｢公共工程施工日誌之技術士簽章表｣
A29: 五、工地勞工安全衛生事項之督導、公共環境與安全之維護及其他工地行政事務：
A30: =VLOOKUP(J2,'[1]2.總表'!$A$7:$GT$499,196) -> (ㄧ)施工前檢查事項： 1.實施勤前教育(含工地預防災變及危害告知)：█有 □無 2.確認新進勞工是否提報勞工保險(或其他商業保險)資料及安全衛生教育訓練紀錄：□有 □無 █無新進勞工 3.檢查勞工個人防護具：█有 □無
A31: 六、施工取樣試驗紀錄：
A35: 七、通知分包廠商辦理事項：
A36: =VLOOKUP(J2,'[1]2.總表'!$A$7:$GW$499,193) -> 0
A37: 八、重要事項紀錄:
A41: =VLOOKUP(J2,'[1]2.總表'!$A$7:$GY$499,194) -> 0
A42: 簽章：【工地負責人】(註3)
A44: 註：1.依據營造業法第32條第1項第2款規定，工地主任應按日填報施工日誌。
A45: 2.本施工日誌格式僅供參考，惟原則應包含上開欄位，各機關亦得依工程性質及契約約定事項自行增訂之。
A46: 3.本工程依營造業法第30條規定須置工地主任者，由工地主任簽章；依上開規定免置工地主任者，則由營造業法第32條第2項所定之人員簽章。廠商非屬營造業者，由工地負責人簽章。
A47: 4.契約工期如有修正，應填修正後之契約工期，含展延工期及不計工期天數；如有依契約變更設計，預定進度及實際進度應填變更設計後計算之進度。
A48: 5.上開重要事項紀錄包含(1)主辦機關及監造單位指示(2)工地遇緊急異常狀況之通報處理情形(3)本日是否由專任工程人員督察按圖施工、解決施工技術問題等。
A49: 6.公共工程屬建築物者，請依內政部99年2月5日台內營字第0990800804號令頒之「建築物施工日誌」填寫。

Sheet 0816
A1: 公共工程施工日誌
A2: 表報編號: | B2: =基本資料!D7 -> 11419 | C2: P001 | D2: =J2 -> 45885 | I2: 填報日期： | J2: 45885 | L2: =J2 -> 45885
A3: 本日天氣: | B3: 上午： | C3: =_xlfn.XLOOKUP(J2,填寫!A:A,填寫!C:C) -> 雨 | D3: 下午： | E3: =_xlfn.XLOOKUP(J2,填寫!A:A,填寫!D:D) -> 雨
A4: 工程名稱 | C4: =基本資料!D3 -> 114年度修整建運動場地 | G4: 承攬廠商名稱 | I4: =基本資料!D14 -> 以勒綠能光電有限公司
A5: 核定工期 | C5: =基本資料!D4 -> 30 | D5: 累計工期 | F5: =填寫!E11 -> 6 | G5: 剩餘工期 | I5: =C5-F5 -> 24 | J5: 工期展延天數
A6: 開工日期 | D6: =基本資料!D5 -> 45880 | G6: 完工日期 | J6: =D6+C5-1 -> 45909
A7: 預定進度(%) | D7: =_xlfn.XLOOKUP(J2,填寫!A:A,填寫!G:G,) -> 0.1998 | G7: 實際進度(%) | J7: =_xlfn.XLOOKUP(J2,填寫!A:A,填寫!H:H) -> 0.0338
A8: 一、依施工計畫書執行按圖施工概況（含約定之重要施工項目及完成數量等）：
A9: 施工項目 | D9: 單位 | E9: 契約數量 | G9: 本日完成數量 | I9: 累計完成數量 | K9: 備註
A10: =基本資料!K5 -> 工程告示牌與職安衛告示牌(租用) | D10: =基本資料!L5 -> 式 | E10: =基本資料!M5 -> 1 | G10: =_xlfn.XLOOKUP(J2,填寫!A:A,填寫!L:L) -> 0 | I10: =_xlfn.XLOOKUP(J2,填寫!A:A,填寫!M:M) -> 1
A11: =基本資料!K6 -> 工區管制措施，施工環境保護與清潔 | D11: =基本資料!L6 -> 式 | E11: =基本資料!M6 -> 1 | G11: =_xlfn.XLOOKUP(J2,填寫!A:A,填寫!N:N) -> 0 | I11: =_xlfn.XLOOKUP(J2,填寫!A:A,填寫!O:O) -> 0
A12: =基本資料!K7 -> 查修天花板所有天井燈具(30盞)與迴路 | D12: =基本資料!L7 -> 式 | E12: =基本資料!M7 -> 1 | G12: =_xlfn.XLOOKUP(J2,填寫!A:A,填寫!P:P) -> 0 | I12: =_xlfn.XLOOKUP(J2,填寫!A:A,填寫!Q:Q) -> 0
A13: =基本資料!K8 -> 拆除清運既有天井燈具，安裝LED天井燈具 (200W以上，含防眩鏡片與安全防墜配件)(含施工機具，連工帶料 | D13: =基本資料!L8 -> 盞 | E13: =基本資料!M8 -> 10 | G13: =_xlfn.XLOOKUP(J2,填寫!A:A,填寫!R:R) -> 0 | I13: =_xlfn.XLOOKUP(J2,填寫!A:A,填寫!S:S) -> 0
A14: =基本資料!K9 -> 職業安全衛生管理費(壹*1%) | D14: =基本資料!L9 -> 式 | E14: =基本資料!M9 -> 1 | G14: =_xlfn.XLOOKUP(J2,填寫!A:A,填寫!T:T) -> 0 | I14: =_xlfn.XLOOKUP(J2,填寫!A:A,填寫!U:U) -> 0.028
A15: =基本資料!K10 -> 公共工程品質管制作業費(壹*1%) | D15: =基本資料!L10 -> 式 | E15: =基本資料!M10 -> 1 | G15: =_xlfn.XLOOKUP(J2,填寫!A:A,填寫!V:V) -> 0 | I15: =_xlfn.XLOOKUP(J2,填寫!A:A,填寫!W:W) -> 0.028
A16: =基本資料!K11 -> 包商利潤及管理費(約壹*7%) | D16: =基本資料!L11 -> 式 | E16: =基本資料!M11 -> 1 | G16: =_xlfn.XLOOKUP(J2,填寫!A:A,填寫!X:X) -> 0 | I16: =_xlfn.XLOOKUP(J2,填寫!A:A,填寫!Y:Y) -> 0.028
A17: =基本資料!K12 -> 營造綜合保險費 | D17: =基本資料!L12 -> 式 | E17: =基本資料!M12 -> 1 | G17: =_xlfn.XLOOKUP(J2,填寫!A:A,填寫!Z:Z) -> 0 | I17: =_xlfn.XLOOKUP(J2,填寫!A:A,填寫!AA:AA) -> 0.028
A18: =基本資料!K13 -> 營業稅((壹~伍)*5%) | D18: =基本資料!L13 -> 式 | E18: =基本資料!M13 -> 1 | G18: =_xlfn.XLOOKUP(J2,填寫!A:A,填寫!AB:AB) -> 0 | I18: =_xlfn.XLOOKUP(J2,填寫!A:A,填寫!AC:AC) -> 0.028
A21: 二、工地材料管理概況（含約定之重要材料使用狀況及數量等）：
A22: 材料名稱 | D22: 單位 | E22: 設計數量 | G22: 本日使用數量 | I22: 累計使用數量 | K22: 備註
A24: 三、工地人員及機具管理（含約定之出工人數及機具使用情形及數量）：
A25: 工別 | C25: 本日人數 | E25: 累計人數 | G25: 機具名稱 | I25: 本日使用量 | K25: 累計使用量
A26: =填寫!AF2 -> 水電工 | C26: =_xlfn.XLOOKUP(J2,填寫!A:A,填寫!AF:AF) -> 0 | E26: =_xlfn.XLOOKUP(J2,填寫!A:A,填寫!AG:AG) -> 0 | G26: =填寫!AH2 -> 高空作業車 | I26: =_xlfn.XLOOKUP(J2,填寫!A:A,填寫!AH:AH) -> 0 | K26: =_xlfn.XLOOKUP(J2,填寫!A:A,填寫!AI:AI) -> 0
G27: =填寫!AJ2 -> 貨車 | I27: =_xlfn.XLOOKUP(J2,填寫!A:A,填寫!AJ:AJ) -> 0 | K27: =_xlfn.XLOOKUP(J2,填寫!A:A,填寫!AK:AK) -> 0
A28: 四、本日施工項目是否有須依「營造業專業工程特定施工項目應置之技術士總類、比率或人數標準表」規定應設置技術士之專業工程：□有■無 (此項如勾選"有"，則應填寫後附｢公共工程施工日誌之技術士簽章表｣
A29: 五、工地勞工安全衛生事項之督導、公共環境與安全之維護及其他工地行政事務：
A30: =VLOOKUP(J2,'[1]2.總表'!$A$7:$GT$499,196) -> (ㄧ)施工前檢查事項： 1.實施勤前教育(含工地預防災變及危害告知)：█有 □無 2.確認新進勞工是否提報勞工保險(或其他商業保險)資料及安全衛生教育訓練紀錄：□有 □無 █無新進勞工 3.檢查勞工個人防護具：█有 □無
A31: 六、施工取樣試驗紀錄：
A35: 七、通知分包廠商辦理事項：
A36: =VLOOKUP(J2,'[1]2.總表'!$A$7:$GW$499,193) -> 0
A37: 八、重要事項紀錄:
A41: =VLOOKUP(J2,'[1]2.總表'!$A$7:$GY$499,194) -> 0
A42: 簽章：【工地負責人】(註3)
A44: 註：1.依據營造業法第32條第1項第2款規定，工地主任應按日填報施工日誌。
A45: 2.本施工日誌格式僅供參考，惟原則應包含上開欄位，各機關亦得依工程性質及契約約定事項自行增訂之。
A46: 3.本工程依營造業法第30條規定須置工地主任者，由工地主任簽章；依上開規定免置工地主任者，則由營造業法第32條第2項所定之人員簽章。廠商非屬營造業者，由工地負責人簽章。
A47: 4.契約工期如有修正，應填修正後之契約工期，含展延工期及不計工期天數；如有依契約變更設計，預定進度及實際進度應填變更設計後計算之進度。
A48: 5.上開重要事項紀錄包含(1)主辦機關及監造單位指示(2)工地遇緊急異常狀況之通報處理情形(3)本日是否由專任工程人員督察按圖施工、解決施工技術問題等。
A49: 6.公共工程屬建築物者，請依內政部99年2月5日台內營字第0990800804號令頒之「建築物施工日誌」填寫。

Sheet 0817
A1: 公共工程施工日誌
A2: 表報編號: | B2: =基本資料!D7 -> 11419 | C2: P001 | D2: =J2 -> 45886 | I2: 填報日期： | J2: 45886 | L2: =J2 -> 45886
A3: 本日天氣: | B3: 上午： | C3: =_xlfn.XLOOKUP(J2,填寫!A:A,填寫!C:C) -> 雨 | D3: 下午： | E3: =_xlfn.XLOOKUP(J2,填寫!A:A,填寫!D:D) -> 雨
A4: 工程名稱 | C4: =基本資料!D3 -> 114年度修整建運動場地 | G4: 承攬廠商名稱 | I4: =基本資料!D14 -> 以勒綠能光電有限公司
A5: 核定工期 | C5: =基本資料!D4 -> 30 | D5: 累計工期 | F5: =填寫!E12 -> 7 | G5: 剩餘工期 | I5: =C5-F5 -> 23 | J5: 工期展延天數
A6: 開工日期 | D6: =基本資料!D5 -> 45880 | G6: 完工日期 | J6: =D6+C5-1 -> 45909
A7: 預定進度(%) | D7: =_xlfn.XLOOKUP(J2,填寫!A:A,填寫!G:G,) -> 0.2331 | G7: 實際進度(%) | J7: =_xlfn.XLOOKUP(J2,填寫!A:A,填寫!H:H) -> 0.0338
A8: 一、依施工計畫書執行按圖施工概況（含約定之重要施工項目及完成數量等）：
A9: 施工項目 | D9: 單位 | E9: 契約數量 | G9: 本日完成數量 | I9: 累計完成數量 | K9: 備註
A10: =基本資料!K5 -> 工程告示牌與職安衛告示牌(租用) | D10: =基本資料!L5 -> 式 | E10: =基本資料!M5 -> 1 | G10: =_xlfn.XLOOKUP(J2,填寫!A:A,填寫!L:L) -> 0 | I10: =_xlfn.XLOOKUP(J2,填寫!A:A,填寫!M:M) -> 1
A11: =基本資料!K6 -> 工區管制措施，施工環境保護與清潔 | D11: =基本資料!L6 -> 式 | E11: =基本資料!M6 -> 1 | G11: =_xlfn.XLOOKUP(J2,填寫!A:A,填寫!N:N) -> 0 | I11: =_xlfn.XLOOKUP(J2,填寫!A:A,填寫!O:O) -> 0
A12: =基本資料!K7 -> 查修天花板所有天井燈具(30盞)與迴路 | D12: =基本資料!L7 -> 式 | E12: =基本資料!M7 -> 1 | G12: =_xlfn.XLOOKUP(J2,填寫!A:A,填寫!P:P) -> 0 | I12: =_xlfn.XLOOKUP(J2,填寫!A:A,填寫!Q:Q) -> 0
A13: =基本資料!K8 -> 拆除清運既有天井燈具，安裝LED天井燈具 (200W以上，含防眩鏡片與安全防墜配件)(含施工機具，連工帶料 | D13: =基本資料!L8 -> 盞 | E13: =基本資料!M8 -> 10 | G13: =_xlfn.XLOOKUP(J2,填寫!A:A,填寫!R:R) -> 0 | I13: =_xlfn.XLOOKUP(J2,填寫!A:A,填寫!S:S) -> 0
A14: =基本資料!K9 -> 職業安全衛生管理費(壹*1%) | D14: =基本資料!L9 -> 式 | E14: =基本資料!M9 -> 1 | G14: =_xlfn.XLOOKUP(J2,填寫!A:A,填寫!T:T) -> 0 | I14: =_xlfn.XLOOKUP(J2,填寫!A:A,填寫!U:U) -> 0.028
A15: =基本資料!K10 -> 公共工程品質管制作業費(壹*1%) | D15: =基本資料!L10 -> 式 | E15: =基本資料!M10 -> 1 | G15: =_xlfn.XLOOKUP(J2,填寫!A:A,填寫!V:V) -> 0 | I15: =_xlfn.XLOOKUP(J2,填寫!A:A,填寫!W:W) -> 0.028
A16: =基本資料!K11 -> 包商利潤及管理費(約壹*7%) | D16: =基本資料!L11 -> 式 | E16: =基本資料!M11 -> 1 | G16: =_xlfn.XLOOKUP(J2,填寫!A:A,填寫!X:X) -> 0 | I16: =_xlfn.XLOOKUP(J2,填寫!A:A,填寫!Y:Y) -> 0.028
A17: =基本資料!K12 -> 營造綜合保險費 | D17: =基本資料!L12 -> 式 | E17: =基本資料!M12 -> 1 | G17: =_xlfn.XLOOKUP(J2,填寫!A:A,填寫!Z:Z) -> 0 | I17: =_xlfn.XLOOKUP(J2,填寫!A:A,填寫!AA:AA) -> 0.028
A18: =基本資料!K13 -> 營業稅((壹~伍)*5%) | D18: =基本資料!L13 -> 式 | E18: =基本資料!M13 -> 1 | G18: =_xlfn.XLOOKUP(J2,填寫!A:A,填寫!AB:AB) -> 0 | I18: =_xlfn.XLOOKUP(J2,填寫!A:A,填寫!AC:AC) -> 0.028
A21: 二、工地材料管理概況（含約定之重要材料使用狀況及數量等）：
A22: 材料名稱 | D22: 單位 | E22: 設計數量 | G22: 本日使用數量 | I22: 累計使用數量 | K22: 備註
A24: 三、工地人員及機具管理（含約定之出工人數及機具使用情形及數量）：
A25: 工別 | C25: 本日人數 | E25: 累計人數 | G25: 機具名稱 | I25: 本日使用量 | K25: 累計使用量
A26: =填寫!AF2 -> 水電工 | C26: =_xlfn.XLOOKUP(J2,填寫!A:A,填寫!AF:AF) -> 0 | E26: =_xlfn.XLOOKUP(J2,填寫!A:A,填寫!AG:AG) -> 0 | G26: =填寫!AH2 -> 高空作業車 | I26: =_xlfn.XLOOKUP(J2,填寫!A:A,填寫!AH:AH) -> 0 | K26: =_xlfn.XLOOKUP(J2,填寫!A:A,填寫!AI:AI) -> 0
G27: =填寫!AJ2 -> 貨車 | I27: =_xlfn.XLOOKUP(J2,填寫!A:A,填寫!AJ:AJ) -> 0 | K27: =_xlfn.XLOOKUP(J2,填寫!A:A,填寫!AK:AK) -> 0
A28: 四、本日施工項目是否有須依「營造業專業工程特定施工項目應置之技術士總類、比率或人數標準表」規定應設置技術士之專業工程：□有■無 (此項如勾選"有"，則應填寫後附｢公共工程施工日誌之技術士簽章表｣
A29: 五、工地勞工安全衛生事項之督導、公共環境與安全之維護及其他工地行政事務：
A30: =VLOOKUP(J2,'[1]2.總表'!$A$7:$GT$499,196) -> (ㄧ)施工前檢查事項： 1.實施勤前教育(含工地預防災變及危害告知)：█有 □無 2.確認新進勞工是否提報勞工保險(或其他商業保險)資料及安全衛生教育訓練紀錄：□有 □無 █無新進勞工 3.檢查勞工個人防護具：█有 □無
A31: 六、施工取樣試驗紀錄：
A35: 七、通知分包廠商辦理事項：
A36: =VLOOKUP(J2,'[1]2.總表'!$A$7:$GW$499,193) -> 0
A37: 八、重要事項紀錄:
A41: =VLOOKUP(J2,'[1]2.總表'!$A$7:$GY$499,194) -> 0
A42: 簽章：【工地負責人】(註3)
A44: 註：1.依據營造業法第32條第1項第2款規定，工地主任應按日填報施工日誌。
A45: 2.本施工日誌格式僅供參考，惟原則應包含上開欄位，各機關亦得依工程性質及契約約定事項自行增訂之。
A46: 3.本工程依營造業法第30條規定須置工地主任者，由工地主任簽章；依上開規定免置工地主任者，則由營造業法第32條第2項所定之人員簽章。廠商非屬營造業者，由工地負責人簽章。
A47: 4.契約工期如有修正，應填修正後之契約工期，含展延工期及不計工期天數；如有依契約變更設計，預定進度及實際進度應填變更設計後計算之進度。
A48: 5.上開重要事項紀錄包含(1)主辦機關及監造單位指示(2)工地遇緊急異常狀況之通報處理情形(3)本日是否由專任工程人員督察按圖施工、解決施工技術問題等。
A49: 6.公共工程屬建築物者，請依內政部99年2月5日台內營字第0990800804號令頒之「建築物施工日誌」填寫。

Sheet 0818
A1: 公共工程施工日誌
A2: 表報編號: | B2: =基本資料!D7 -> 11419 | C2: P001 | D2: =J2 -> 45887 | I2: 填報日期： | J2: 45887 | L2: =J2 -> 45887
A3: 本日天氣: | B3: 上午： | C3: =_xlfn.XLOOKUP(J2,填寫!A:A,填寫!C:C) -> 晴 | D3: 下午： | E3: =_xlfn.XLOOKUP(J2,填寫!A:A,填寫!D:D) -> 雨
A4: 工程名稱 | C4: =基本資料!D3 -> 114年度修整建運動場地 | G4: 承攬廠商名稱 | I4: =基本資料!D14 -> 以勒綠能光電有限公司
A5: 核定工期 | C5: =基本資料!D4 -> 30 | D5: 累計工期 | F5: =填寫!E13 -> 8 | G5: 剩餘工期 | I5: =C5-F5 -> 22 | J5: 工期展延天數
A6: 開工日期 | D6: =基本資料!D5 -> 45880 | G6: 完工日期 | J6: =D6+C5-1 -> 45909
A7: 預定進度(%) | D7: =_xlfn.XLOOKUP(J2,填寫!A:A,填寫!G:G,) -> 0.2664 | G7: 實際進度(%) | J7: =_xlfn.XLOOKUP(J2,填寫!A:A,填寫!H:H) -> 0.0338
A8: 一、依施工計畫書執行按圖施工概況（含約定之重要施工項目及完成數量等）：
A9: 施工項目 | D9: 單位 | E9: 契約數量 | G9: 本日完成數量 | I9: 累計完成數量 | K9: 備註
A10: =基本資料!K5 -> 工程告示牌與職安衛告示牌(租用) | D10: =基本資料!L5 -> 式 | E10: =基本資料!M5 -> 1 | G10: =_xlfn.XLOOKUP(J2,填寫!A:A,填寫!L:L) -> 0 | I10: =_xlfn.XLOOKUP(J2,填寫!A:A,填寫!M:M) -> 1
A11: =基本資料!K6 -> 工區管制措施，施工環境保護與清潔 | D11: =基本資料!L6 -> 式 | E11: =基本資料!M6 -> 1 | G11: =_xlfn.XLOOKUP(J2,填寫!A:A,填寫!N:N) -> 0 | I11: =_xlfn.XLOOKUP(J2,填寫!A:A,填寫!O:O) -> 0
A12: =基本資料!K7 -> 查修天花板所有天井燈具(30盞)與迴路 | D12: =基本資料!L7 -> 式 | E12: =基本資料!M7 -> 1 | G12: =_xlfn.XLOOKUP(J2,填寫!A:A,填寫!P:P) -> 0 | I12: =_xlfn.XLOOKUP(J2,填寫!A:A,填寫!Q:Q) -> 0
A13: =基本資料!K8 -> 拆除清運既有天井燈具，安裝LED天井燈具 (200W以上，含防眩鏡片與安全防墜配件)(含施工機具，連工帶料 | D13: =基本資料!L8 -> 盞 | E13: =基本資料!M8 -> 10 | G13: =_xlfn.XLOOKUP(J2,填寫!A:A,填寫!R:R) -> 0 | I13: =_xlfn.XLOOKUP(J2,填寫!A:A,填寫!S:S) -> 0
A14: =基本資料!K9 -> 職業安全衛生管理費(壹*1%) | D14: =基本資料!L9 -> 式 | E14: =基本資料!M9 -> 1 | G14: =_xlfn.XLOOKUP(J2,填寫!A:A,填寫!T:T) -> 0 | I14: =_xlfn.XLOOKUP(J2,填寫!A:A,填寫!U:U) -> 0.028
A15: =基本資料!K10 -> 公共工程品質管制作業費(壹*1%) | D15: =基本資料!L10 -> 式 | E15: =基本資料!M10 -> 1 | G15: =_xlfn.XLOOKUP(J2,填寫!A:A,填寫!V:V) -> 0 | I15: =_xlfn.XLOOKUP(J2,填寫!A:A,填寫!W:W) -> 0.028
A16: =基本資料!K11 -> 包商利潤及管理費(約壹*7%) | D16: =基本資料!L11 -> 式 | E16: =基本資料!M11 -> 1 | G16: =_xlfn.XLOOKUP(J2,填寫!A:A,填寫!X:X) -> 0 | I16: =_xlfn.XLOOKUP(J2,填寫!A:A,填寫!Y:Y) -> 0.028
A17: =基本資料!K12 -> 營造綜合保險費 | D17: =基本資料!L12 -> 式 | E17: =基本資料!M12 -> 1 | G17: =_xlfn.XLOOKUP(J2,填寫!A:A,填寫!Z:Z) -> 0 | I17: =_xlfn.XLOOKUP(J2,填寫!A:A,填寫!AA:AA) -> 0.028
A18: =基本資料!K13 -> 營業稅((壹~伍)*5%) | D18: =基本資料!L13 -> 式 | E18: =基本資料!M13 -> 1 | G18: =_xlfn.XLOOKUP(J2,填寫!A:A,填寫!AB:AB) -> 0 | I18: =_xlfn.XLOOKUP(J2,填寫!A:A,填寫!AC:AC) -> 0.028
A21: 二、工地材料管理概況（含約定之重要材料使用狀況及數量等）：
A22: 材料名稱 | D22: 單位 | E22: 設計數量 | G22: 本日使用數量 | I22: 累計使用數量 | K22: 備註
A24: 三、工地人員及機具管理（含約定之出工人數及機具使用情形及數量）：
A25: 工別 | C25: 本日人數 | E25: 累計人數 | G25: 機具名稱 | I25: 本日使用量 | K25: 累計使用量
A26: =填寫!AF2 -> 水電工 | C26: =_xlfn.XLOOKUP(J2,填寫!A:A,填寫!AF:AF) -> 0 | E26: =_xlfn.XLOOKUP(J2,填寫!A:A,填寫!AG:AG) -> 0 | G26: =填寫!AH2 -> 高空作業車 | I26: =_xlfn.XLOOKUP(J2,填寫!A:A,填寫!AH:AH) -> 0 | K26: =_xlfn.XLOOKUP(J2,填寫!A:A,填寫!AI:AI) -> 0
G27: =填寫!AJ2 -> 貨車 | I27: =_xlfn.XLOOKUP(J2,填寫!A:A,填寫!AJ:AJ) -> 0 | K27: =_xlfn.XLOOKUP(J2,填寫!A:A,填寫!AK:AK) -> 0
A28: 四、本日施工項目是否有須依「營造業專業工程特定施工項目應置之技術士總類、比率或人數標準表」規定應設置技術士之專業工程：□有■無 (此項如勾選"有"，則應填寫後附｢公共工程施工日誌之技術士簽章表｣
A29: 五、工地勞工安全衛生事項之督導、公共環境與安全之維護及其他工地行政事務：
A30: =VLOOKUP(J2,'[1]2.總表'!$A$7:$GT$499,196) -> (ㄧ)施工前檢查事項： 1.實施勤前教育(含工地預防災變及危害告知)：█有 □無 2.確認新進勞工是否提報勞工保險(或其他商業保險)資料及安全衛生教育訓練紀錄：□有 □無 █無新進勞工 3.檢查勞工個人防護具：█有 □無
A31: 六、施工取樣試驗紀錄：
A35: 七、通知分包廠商辦理事項：
A36: =VLOOKUP(J2,'[1]2.總表'!$A$7:$GW$499,193) -> 0
A37: 八、重要事項紀錄:
A41: =VLOOKUP(J2,'[1]2.總表'!$A$7:$GY$499,194) -> 0
A42: 簽章：【工地負責人】(註3)
A44: 註：1.依據營造業法第32條第1項第2款規定，工地主任應按日填報施工日誌。
A45: 2.本施工日誌格式僅供參考，惟原則應包含上開欄位，各機關亦得依工程性質及契約約定事項自行增訂之。
A46: 3.本工程依營造業法第30條規定須置工地主任者，由工地主任簽章；依上開規定免置工地主任者，則由營造業法第32條第2項所定之人員簽章。廠商非屬營造業者，由工地負責人簽章。
A47: 4.契約工期如有修正，應填修正後之契約工期，含展延工期及不計工期天數；如有依契約變更設計，預定進度及實際進度應填變更設計後計算之進度。
A48: 5.上開重要事項紀錄包含(1)主辦機關及監造單位指示(2)工地遇緊急異常狀況之通報處理情形(3)本日是否由專任工程人員督察按圖施工、解決施工技術問題等。
A49: 6.公共工程屬建築物者，請依內政部99年2月5日台內營字第0990800804號令頒之「建築物施工日誌」填寫。

Sheet 0819
A1: 公共工程施工日誌
A2: 表報編號: | B2: =基本資料!D7 -> 11419 | C2: P001 | D2: =J2 -> 45888 | I2: 填報日期： | J2: 45888 | L2: =J2 -> 45888
A3: 本日天氣: | B3: 上午： | C3: =_xlfn.XLOOKUP(J2,填寫!A:A,填寫!C:C) -> 晴 | D3: 下午： | E3: =_xlfn.XLOOKUP(J2,填寫!A:A,填寫!D:D) -> 雨
A4: 工程名稱 | C4: =基本資料!D3 -> 114年度修整建運動場地 | G4: 承攬廠商名稱 | I4: =基本資料!D14 -> 以勒綠能光電有限公司
A5: 核定工期 | C5: =基本資料!D4 -> 30 | D5: 累計工期 | F5: =填寫!E14 -> 9 | G5: 剩餘工期 | I5: =C5-F5 -> 21 | J5: 工期展延天數
A6: 開工日期 | D6: =基本資料!D5 -> 45880 | G6: 完工日期 | J6: =D6+C5-1 -> 45909
A7: 預定進度(%) | D7: =_xlfn.XLOOKUP(J2,填寫!A:A,填寫!G:G,) -> 0.2997 | G7: 實際進度(%) | J7: =_xlfn.XLOOKUP(J2,填寫!A:A,填寫!H:H) -> 0.0338
A8: 一、依施工計畫書執行按圖施工概況（含約定之重要施工項目及完成數量等）：
A9: 施工項目 | D9: 單位 | E9: 契約數量 | G9: 本日完成數量 | I9: 累計完成數量 | K9: 備註
A10: =基本資料!K5 -> 工程告示牌與職安衛告示牌(租用) | D10: =基本資料!L5 -> 式 | E10: =基本資料!M5 -> 1 | G10: =_xlfn.XLOOKUP(J2,填寫!A:A,填寫!L:L) -> 0 | I10: =_xlfn.XLOOKUP(J2,填寫!A:A,填寫!M:M) -> 1
A11: =基本資料!K6 -> 工區管制措施，施工環境保護與清潔 | D11: =基本資料!L6 -> 式 | E11: =基本資料!M6 -> 1 | G11: =_xlfn.XLOOKUP(J2,填寫!A:A,填寫!N:N) -> 0 | I11: =_xlfn.XLOOKUP(J2,填寫!A:A,填寫!O:O) -> 0
A12: =基本資料!K7 -> 查修天花板所有天井燈具(30盞)與迴路 | D12: =基本資料!L7 -> 式 | E12: =基本資料!M7 -> 1 | G12: =_xlfn.XLOOKUP(J2,填寫!A:A,填寫!P:P) -> 0 | I12: =_xlfn.XLOOKUP(J2,填寫!A:A,填寫!Q:Q) -> 0
A13: =基本資料!K8 -> 拆除清運既有天井燈具，安裝LED天井燈具 (200W以上，含防眩鏡片與安全防墜配件)(含施工機具，連工帶料 | D13: =基本資料!L8 -> 盞 | E13: =基本資料!M8 -> 10 | G13: =_xlfn.XLOOKUP(J2,填寫!A:A,填寫!R:R) -> 0 | I13: =_xlfn.XLOOKUP(J2,填寫!A:A,填寫!S:S) -> 0
A14: =基本資料!K9 -> 職業安全衛生管理費(壹*1%) | D14: =基本資料!L9 -> 式 | E14: =基本資料!M9 -> 1 | G14: =_xlfn.XLOOKUP(J2,填寫!A:A,填寫!T:T) -> 0 | I14: =_xlfn.XLOOKUP(J2,填寫!A:A,填寫!U:U) -> 0.028
A15: =基本資料!K10 -> 公共工程品質管制作業費(壹*1%) | D15: =基本資料!L10 -> 式 | E15: =基本資料!M10 -> 1 | G15: =_xlfn.XLOOKUP(J2,填寫!A:A,填寫!V:V) -> 0 | I15: =_xlfn.XLOOKUP(J2,填寫!A:A,填寫!W:W) -> 0.028
A16: =基本資料!K11 -> 包商利潤及管理費(約壹*7%) | D16: =基本資料!L11 -> 式 | E16: =基本資料!M11 -> 1 | G16: =_xlfn.XLOOKUP(J2,填寫!A:A,填寫!X:X) -> 0 | I16: =_xlfn.XLOOKUP(J2,填寫!A:A,填寫!Y:Y) -> 0.028
A17: =基本資料!K12 -> 營造綜合保險費 | D17: =基本資料!L12 -> 式 | E17: =基本資料!M12 -> 1 | G17: =_xlfn.XLOOKUP(J2,填寫!A:A,填寫!Z:Z) -> 0 | I17: =_xlfn.XLOOKUP(J2,填寫!A:A,填寫!AA:AA) -> 0.028
A18: =基本資料!K13 -> 營業稅((壹~伍)*5%) | D18: =基本資料!L13 -> 式 | E18: =基本資料!M13 -> 1 | G18: =_xlfn.XLOOKUP(J2,填寫!A:A,填寫!AB:AB) -> 0 | I18: =_xlfn.XLOOKUP(J2,填寫!A:A,填寫!AC:AC) -> 0.028
A21: 二、工地材料管理概況（含約定之重要材料使用狀況及數量等）：
A22: 材料名稱 | D22: 單位 | E22: 設計數量 | G22: 本日使用數量 | I22: 累計使用數量 | K22: 備註
A24: 三、工地人員及機具管理（含約定之出工人數及機具使用情形及數量）：
A25: 工別 | C25: 本日人數 | E25: 累計人數 | G25: 機具名稱 | I25: 本日使用量 | K25: 累計使用量
A26: =填寫!AF2 -> 水電工 | C26: =_xlfn.XLOOKUP(J2,填寫!A:A,填寫!AF:AF) -> 0 | E26: =_xlfn.XLOOKUP(J2,填寫!A:A,填寫!AG:AG) -> 0 | G26: =填寫!AH2 -> 高空作業車 | I26: =_xlfn.XLOOKUP(J2,填寫!A:A,填寫!AH:AH) -> 0 | K26: =_xlfn.XLOOKUP(J2,填寫!A:A,填寫!AI:AI) -> 0
G27: =填寫!AJ2 -> 貨車 | I27: =_xlfn.XLOOKUP(J2,填寫!A:A,填寫!AJ:AJ) -> 0 | K27: =_xlfn.XLOOKUP(J2,填寫!A:A,填寫!AK:AK) -> 0
A28: 四、本日施工項目是否有須依「營造業專業工程特定施工項目應置之技術士總類、比率或人數標準表」規定應設置技術士之專業工程：□有■無 (此項如勾選"有"，則應填寫後附｢公共工程施工日誌之技術士簽章表｣
A29: 五、工地勞工安全衛生事項之督導、公共環境與安全之維護及其他工地行政事務：
A30: =VLOOKUP(J2,'[1]2.總表'!$A$7:$GT$499,196) -> (ㄧ)施工前檢查事項： 1.實施勤前教育(含工地預防災變及危害告知)：█有 □無 2.確認新進勞工是否提報勞工保險(或其他商業保險)資料及安全衛生教育訓練紀錄：□有 □無 █無新進勞工 3.檢查勞工個人防護具：█有 □無
A31: 六、施工取樣試驗紀錄：
A35: 七、通知分包廠商辦理事項：
A36: =VLOOKUP(J2,'[1]2.總表'!$A$7:$GW$499,193) -> 0
A37: 八、重要事項紀錄:
A41: =VLOOKUP(J2,'[1]2.總表'!$A$7:$GY$499,194) -> 0
A42: 簽章：【工地負責人】(註3)
A44: 註：1.依據營造業法第32條第1項第2款規定，工地主任應按日填報施工日誌。
A45: 2.本施工日誌格式僅供參考，惟原則應包含上開欄位，各機關亦得依工程性質及契約約定事項自行增訂之。
A46: 3.本工程依營造業法第30條規定須置工地主任者，由工地主任簽章；依上開規定免置工地主任者，則由營造業法第32條第2項所定之人員簽章。廠商非屬營造業者，由工地負責人簽章。
A47: 4.契約工期如有修正，應填修正後之契約工期，含展延工期及不計工期天數；如有依契約變更設計，預定進度及實際進度應填變更設計後計算之進度。
A48: 5.上開重要事項紀錄包含(1)主辦機關及監造單位指示(2)工地遇緊急異常狀況之通報處理情形(3)本日是否由專任工程人員督察按圖施工、解決施工技術問題等。
A49: 6.公共工程屬建築物者，請依內政部99年2月5日台內營字第0990800804號令頒之「建築物施工日誌」填寫。

Sheet 0820
A1: 公共工程施工日誌
A2: 表報編號: | B2: =基本資料!D7 -> 11419 | C2: P001 | D2: =J2 -> 45889 | I2: 填報日期： | J2: 45889 | L2: =J2 -> 45889
A3: 本日天氣: | B3: 上午： | C3: =_xlfn.XLOOKUP(J2,填寫!A:A,填寫!C:C) -> 晴 | D3: 下午： | E3: =_xlfn.XLOOKUP(J2,填寫!A:A,填寫!D:D) -> 晴
A4: 工程名稱 | C4: =基本資料!D3 -> 114年度修整建運動場地 | G4: 承攬廠商名稱 | I4: =基本資料!D14 -> 以勒綠能光電有限公司
A5: 核定工期 | C5: =基本資料!D4 -> 30 | D5: 累計工期 | F5: =填寫!E15 -> 10 | G5: 剩餘工期 | I5: =C5-F5 -> 20 | J5: 工期展延天數
A6: 開工日期 | D6: =基本資料!D5 -> 45880 | G6: 完工日期 | J6: =D6+C5-1 -> 45909
A7: 預定進度(%) | D7: =_xlfn.XLOOKUP(J2,填寫!A:A,填寫!G:G,) -> 0.333 | G7: 實際進度(%) | J7: =_xlfn.XLOOKUP(J2,填寫!A:A,填寫!H:H) -> 0.0338
A8: 一、依施工計畫書執行按圖施工概況（含約定之重要施工項目及完成數量等）：
A9: 施工項目 | D9: 單位 | E9: 契約數量 | G9: 本日完成數量 | I9: 累計完成數量 | K9: 備註
A10: =基本資料!K5 -> 工程告示牌與職安衛告示牌(租用) | D10: =基本資料!L5 -> 式 | E10: =基本資料!M5 -> 1 | G10: =_xlfn.XLOOKUP(J2,填寫!A:A,填寫!L:L) -> 0 | I10: =_xlfn.XLOOKUP(J2,填寫!A:A,填寫!M:M) -> 1
A11: =基本資料!K6 -> 工區管制措施，施工環境保護與清潔 | D11: =基本資料!L6 -> 式 | E11: =基本資料!M6 -> 1 | G11: =_xlfn.XLOOKUP(J2,填寫!A:A,填寫!N:N) -> 0 | I11: =_xlfn.XLOOKUP(J2,填寫!A:A,填寫!O:O) -> 0
A12: =基本資料!K7 -> 查修天花板所有天井燈具(30盞)與迴路 | D12: =基本資料!L7 -> 式 | E12: =基本資料!M7 -> 1 | G12: =_xlfn.XLOOKUP(J2,填寫!A:A,填寫!P:P) -> 0 | I12: =_xlfn.XLOOKUP(J2,填寫!A:A,填寫!Q:Q) -> 0
A13: =基本資料!K8 -> 拆除清運既有天井燈具，安裝LED天井燈具 (200W以上，含防眩鏡片與安全防墜配件)(含施工機具，連工帶料 | D13: =基本資料!L8 -> 盞 | E13: =基本資料!M8 -> 10 | G13: =_xlfn.XLOOKUP(J2,填寫!A:A,填寫!R:R) -> 0 | I13: =_xlfn.XLOOKUP(J2,填寫!A:A,填寫!S:S) -> 0
A14: =基本資料!K9 -> 職業安全衛生管理費(壹*1%) | D14: =基本資料!L9 -> 式 | E14: =基本資料!M9 -> 1 | G14: =_xlfn.XLOOKUP(J2,填寫!A:A,填寫!T:T) -> 0 | I14: =_xlfn.XLOOKUP(J2,填寫!A:A,填寫!U:U) -> 0.028
A15: =基本資料!K10 -> 公共工程品質管制作業費(壹*1%) | D15: =基本資料!L10 -> 式 | E15: =基本資料!M10 -> 1 | G15: =_xlfn.XLOOKUP(J2,填寫!A:A,填寫!V:V) -> 0 | I15: =_xlfn.XLOOKUP(J2,填寫!A:A,填寫!W:W) -> 0.028
A16: =基本資料!K11 -> 包商利潤及管理費(約壹*7%) | D16: =基本資料!L11 -> 式 | E16: =基本資料!M11 -> 1 | G16: =_xlfn.XLOOKUP(J2,填寫!A:A,填寫!X:X) -> 0 | I16: =_xlfn.XLOOKUP(J2,填寫!A:A,填寫!Y:Y) -> 0.028
A17: =基本資料!K12 -> 營造綜合保險費 | D17: =基本資料!L12 -> 式 | E17: =基本資料!M12 -> 1 | G17: =_xlfn.XLOOKUP(J2,填寫!A:A,填寫!Z:Z) -> 0 | I17: =_xlfn.XLOOKUP(J2,填寫!A:A,填寫!AA:AA) -> 0.028
A18: =基本資料!K13 -> 營業稅((壹~伍)*5%) | D18: =基本資料!L13 -> 式 | E18: =基本資料!M13 -> 1 | G18: =_xlfn.XLOOKUP(J2,填寫!A:A,填寫!AB:AB) -> 0 | I18: =_xlfn.XLOOKUP(J2,填寫!A:A,填寫!AC:AC) -> 0.028
A21: 二、工地材料管理概況（含約定之重要材料使用狀況及數量等）：
A22: 材料名稱 | D22: 單位 | E22: 設計數量 | G22: 本日使用數量 | I22: 累計使用數量 | K22: 備註
A24: 三、工地人員及機具管理（含約定之出工人數及機具使用情形及數量）：
A25: 工別 | C25: 本日人數 | E25: 累計人數 | G25: 機具名稱 | I25: 本日使用量 | K25: 累計使用量
A26: =填寫!AF2 -> 水電工 | C26: =_xlfn.XLOOKUP(J2,填寫!A:A,填寫!AF:AF) -> 0 | E26: =_xlfn.XLOOKUP(J2,填寫!A:A,填寫!AG:AG) -> 0 | G26: =填寫!AH2 -> 高空作業車 | I26: =_xlfn.XLOOKUP(J2,填寫!A:A,填寫!AH:AH) -> 0 | K26: =_xlfn.XLOOKUP(J2,填寫!A:A,填寫!AI:AI) -> 0
G27: =填寫!AJ2 -> 貨車 | I27: =_xlfn.XLOOKUP(J2,填寫!A:A,填寫!AJ:AJ) -> 0 | K27: =_xlfn.XLOOKUP(J2,填寫!A:A,填寫!AK:AK) -> 0
A28: 四、本日施工項目是否有須依「營造業專業工程特定施工項目應置之技術士總類、比率或人數標準表」規定應設置技術士之專業工程：□有■無 (此項如勾選"有"，則應填寫後附｢公共工程施工日誌之技術士簽章表｣
A29: 五、工地勞工安全衛生事項之督導、公共環境與安全之維護及其他工地行政事務：
A30: =VLOOKUP(J2,'[1]2.總表'!$A$7:$GT$499,196) -> (ㄧ)施工前檢查事項： 1.實施勤前教育(含工地預防災變及危害告知)：█有 □無 2.確認新進勞工是否提報勞工保險(或其他商業保險)資料及安全衛生教育訓練紀錄：□有 □無 █無新進勞工 3.檢查勞工個人防護具：█有 □無
A31: 六、施工取樣試驗紀錄：
A35: 七、通知分包廠商辦理事項：
A36: =VLOOKUP(J2,'[1]2.總表'!$A$7:$GW$499,193) -> 0
A37: 八、重要事項紀錄:
A41: =VLOOKUP(J2,'[1]2.總表'!$A$7:$GY$499,194) -> 0
A42: 簽章：【工地負責人】(註3)
A44: 註：1.依據營造業法第32條第1項第2款規定，工地主任應按日填報施工日誌。
A45: 2.本施工日誌格式僅供參考，惟原則應包含上開欄位，各機關亦得依工程性質及契約約定事項自行增訂之。
A46: 3.本工程依營造業法第30條規定須置工地主任者，由工地主任簽章；依上開規定免置工地主任者，則由營造業法第32條第2項所定之人員簽章。廠商非屬營造業者，由工地負責人簽章。
A47: 4.契約工期如有修正，應填修正後之契約工期，含展延工期及不計工期天數；如有依契約變更設計，預定進度及實際進度應填變更設計後計算之進度。
A48: 5.上開重要事項紀錄包含(1)主辦機關及監造單位指示(2)工地遇緊急異常狀況之通報處理情形(3)本日是否由專任工程人員督察按圖施工、解決施工技術問題等。
A49: 6.公共工程屬建築物者，請依內政部99年2月5日台內營字第0990800804號令頒之「建築物施工日誌」填寫。

Sheet 0821
A1: 公共工程施工日誌
A2: 表報編號: | B2: =基本資料!D7 -> 11419 | C2: P001 | D2: =J2 -> 45890 | I2: 填報日期： | J2: 45890 | L2: =J2 -> 45890
A3: 本日天氣: | B3: 上午： | C3: =_xlfn.XLOOKUP(J2,填寫!A:A,填寫!C:C) -> 晴 | D3: 下午： | E3: =_xlfn.XLOOKUP(J2,填寫!A:A,填寫!D:D) -> 晴
A4: 工程名稱 | C4: =基本資料!D3 -> 114年度修整建運動場地 | G4: 承攬廠商名稱 | I4: =基本資料!D14 -> 以勒綠能光電有限公司
A5: 核定工期 | C5: =基本資料!D4 -> 30 | D5: 累計工期 | F5: =填寫!E16 -> 11 | G5: 剩餘工期 | I5: =C5-F5 -> 19 | J5: 工期展延天數
A6: 開工日期 | D6: =基本資料!D5 -> 45880 | G6: 完工日期 | J6: =D6+C5-1 -> 45909
A7: 預定進度(%) | D7: =_xlfn.XLOOKUP(J2,填寫!A:A,填寫!G:G,) -> 0.3663 | G7: 實際進度(%) | J7: =_xlfn.XLOOKUP(J2,填寫!A:A,填寫!H:H) -> 0.54240406
A8: 一、依施工計畫書執行按圖施工概況（含約定之重要施工項目及完成數量等）：
A9: 施工項目 | D9: 單位 | E9: 契約數量 | G9: 本日完成數量 | I9: 累計完成數量 | K9: 備註
A10: =基本資料!K5 -> 工程告示牌與職安衛告示牌(租用) | D10: =基本資料!L5 -> 式 | E10: =基本資料!M5 -> 1 | G10: =_xlfn.XLOOKUP(J2,填寫!A:A,填寫!L:L) -> 0 | I10: =_xlfn.XLOOKUP(J2,填寫!A:A,填寫!M:M) -> 1
A11: =基本資料!K6 -> 工區管制措施，施工環境保護與清潔 | D11: =基本資料!L6 -> 式 | E11: =基本資料!M6 -> 1 | G11: =_xlfn.XLOOKUP(J2,填寫!A:A,填寫!N:N) -> 1 | I11: =_xlfn.XLOOKUP(J2,填寫!A:A,填寫!O:O) -> 1
A12: =基本資料!K7 -> 查修天花板所有天井燈具(30盞)與迴路 | D12: =基本資料!L7 -> 式 | E12: =基本資料!M7 -> 1 | G12: =_xlfn.XLOOKUP(J2,填寫!A:A,填寫!P:P) -> 0.5 | I12: =_xlfn.XLOOKUP(J2,填寫!A:A,填寫!Q:Q) -> 0.5
A13: =基本資料!K8 -> 拆除清運既有天井燈具，安裝LED天井燈具 (200W以上，含防眩鏡片與安全防墜配件)(含施工機具，連工帶料 | D13: =基本資料!L8 -> 盞 | E13: =基本資料!M8 -> 10 | G13: =_xlfn.XLOOKUP(J2,填寫!A:A,填寫!R:R) -> 5 | I13: =_xlfn.XLOOKUP(J2,填寫!A:A,填寫!S:S) -> 5
A14: =基本資料!K9 -> 職業安全衛生管理費(壹*1%) | D14: =基本資料!L9 -> 式 | E14: =基本資料!M9 -> 1 | G14: =_xlfn.XLOOKUP(J2,填寫!A:A,填寫!T:T) -> 0.539 | I14: =_xlfn.XLOOKUP(J2,填寫!A:A,填寫!U:U) -> 0.567
A15: =基本資料!K10 -> 公共工程品質管制作業費(壹*1%) | D15: =基本資料!L10 -> 式 | E15: =基本資料!M10 -> 1 | G15: =_xlfn.XLOOKUP(J2,填寫!A:A,填寫!V:V) -> 0.539 | I15: =_xlfn.XLOOKUP(J2,填寫!A:A,填寫!W:W) -> 0.567
A16: =基本資料!K11 -> 包商利潤及管理費(約壹*7%) | D16: =基本資料!L11 -> 式 | E16: =基本資料!M11 -> 1 | G16: =_xlfn.XLOOKUP(J2,填寫!A:A,填寫!X:X) -> 0.539 | I16: =_xlfn.XLOOKUP(J2,填寫!A:A,填寫!Y:Y) -> 0.567
A17: =基本資料!K12 -> 營造綜合保險費 | D17: =基本資料!L12 -> 式 | E17: =基本資料!M12 -> 1 | G17: =_xlfn.XLOOKUP(J2,填寫!A:A,填寫!Z:Z) -> 0.539 | I17: =_xlfn.XLOOKUP(J2,填寫!A:A,填寫!AA:AA) -> 0.567
A18: =基本資料!K13 -> 營業稅((壹~伍)*5%) | D18: =基本資料!L13 -> 式 | E18: =基本資料!M13 -> 1 | G18: =_xlfn.XLOOKUP(J2,填寫!A:A,填寫!AB:AB) -> 0.539 | I18: =_xlfn.XLOOKUP(J2,填寫!A:A,填寫!AC:AC) -> 0.567
A21: 二、工地材料管理概況（含約定之重要材料使用狀況及數量等）：
A22: 材料名稱 | D22: 單位 | E22: 設計數量 | G22: 本日使用數量 | I22: 累計使用數量 | K22: 備註
A24: 三、工地人員及機具管理（含約定之出工人數及機具使用情形及數量）：
A25: 工別 | C25: 本日人數 | E25: 累計人數 | G25: 機具名稱 | I25: 本日使用量 | K25: 累計使用量
A26: =填寫!AF2 -> 水電工 | C26: =_xlfn.XLOOKUP(J2,填寫!A:A,填寫!AF:AF) -> 4 | E26: =_xlfn.XLOOKUP(J2,填寫!A:A,填寫!AG:AG) -> 4 | G26: =填寫!AH2 -> 高空作業車 | I26: =_xlfn.XLOOKUP(J2,填寫!A:A,填寫!AH:AH) -> 2 | K26: =_xlfn.XLOOKUP(J2,填寫!A:A,填寫!AI:AI) -> 2
G27: =填寫!AJ2 -> 貨車 | I27: =_xlfn.XLOOKUP(J2,填寫!A:A,填寫!AJ:AJ) -> 2 | K27: =_xlfn.XLOOKUP(J2,填寫!A:A,填寫!AK:AK) -> 2
A28: 四、本日施工項目是否有須依「營造業專業工程特定施工項目應置之技術士總類、比率或人數標準表」規定應設置技術士之專業工程：□有■無 (此項如勾選"有"，則應填寫後附｢公共工程施工日誌之技術士簽章表｣
A29: 五、工地勞工安全衛生事項之督導、公共環境與安全之維護及其他工地行政事務：
A30: =VLOOKUP(J2,'[1]2.總表'!$A$7:$GT$499,196) -> (ㄧ)施工前檢查事項： 1.實施勤前教育(含工地預防災變及危害告知)：█有 □無 2.確認新進勞工是否提報勞工保險(或其他商業保險)資料及安全衛生教育訓練紀錄：□有 □無 █無新進勞工 3.檢查勞工個人防護具：█有 □無
A31: 六、施工取樣試驗紀錄：
A35: 七、通知分包廠商辦理事項：
A36: =VLOOKUP(J2,'[1]2.總表'!$A$7:$GW$499,193) -> 0
A37: 八、重要事項紀錄:
A41: =VLOOKUP(J2,'[1]2.總表'!$A$7:$GY$499,194) -> 0
A42: 簽章：【工地負責人】(註3)
A44: 註：1.依據營造業法第32條第1項第2款規定，工地主任應按日填報施工日誌。
A45: 2.本施工日誌格式僅供參考，惟原則應包含上開欄位，各機關亦得依工程性質及契約約定事項自行增訂之。
A46: 3.本工程依營造業法第30條規定須置工地主任者，由工地主任簽章；依上開規定免置工地主任者，則由營造業法第32條第2項所定之人員簽章。廠商非屬營造業者，由工地負責人簽章。
A47: 4.契約工期如有修正，應填修正後之契約工期，含展延工期及不計工期天數；如有依契約變更設計，預定進度及實際進度應填變更設計後計算之進度。
A48: 5.上開重要事項紀錄包含(1)主辦機關及監造單位指示(2)工地遇緊急異常狀況之通報處理情形(3)本日是否由專任工程人員督察按圖施工、解決施工技術問題等。
A49: 6.公共工程屬建築物者，請依內政部99年2月5日台內營字第0990800804號令頒之「建築物施工日誌」填寫。

Sheet 0822
A1: 公共工程施工日誌
A2: 表報編號: | B2: =基本資料!D7 -> 11419 | C2: P001 | D2: =J2 -> 45891 | I2: 填報日期： | J2: 45891 | L2: =J2 -> 45891
A3: 本日天氣: | B3: 上午： | C3: =_xlfn.XLOOKUP(J2,填寫!A:A,填寫!C:C) -> 晴 | D3: 下午： | E3: =_xlfn.XLOOKUP(J2,填寫!A:A,填寫!D:D) -> 晴
A4: 工程名稱 | C4: =基本資料!D3 -> 114年度修整建運動場地 | G4: 承攬廠商名稱 | I4: =基本資料!D14 -> 以勒綠能光電有限公司
A5: 核定工期 | C5: =基本資料!D4 -> 30 | D5: 累計工期 | F5: =填寫!E17 -> 12 | G5: 剩餘工期 | I5: =C5-F5 -> 18 | J5: 工期展延天數
A6: 開工日期 | D6: =基本資料!D5 -> 45880 | G6: 完工日期 | J6: =D6+C5-1 -> 45909
A7: 預定進度(%) | D7: =_xlfn.XLOOKUP(J2,填寫!A:A,填寫!G:G,) -> 0.3996 | G7: 實際進度(%) | J7: =_xlfn.XLOOKUP(J2,填寫!A:A,填寫!H:H) -> 1
A8: 一、依施工計畫書執行按圖施工概況（含約定之重要施工項目及完成數量等）：
A9: 施工項目 | D9: 單位 | E9: 契約數量 | G9: 本日完成數量 | I9: 累計完成數量 | K9: 備註
A10: =基本資料!K5 -> 工程告示牌與職安衛告示牌(租用) | D10: =基本資料!L5 -> 式 | E10: =基本資料!M5 -> 1 | G10: =_xlfn.XLOOKUP(J2,填寫!A:A,填寫!L:L) -> 0 | I10: =_xlfn.XLOOKUP(J2,填寫!A:A,填寫!M:M) -> 1
A11: =基本資料!K6 -> 工區管制措施，施工環境保護與清潔 | D11: =基本資料!L6 -> 式 | E11: =基本資料!M6 -> 1 | G11: =_xlfn.XLOOKUP(J2,填寫!A:A,填寫!N:N) -> 0 | I11: =_xlfn.XLOOKUP(J2,填寫!A:A,填寫!O:O) -> 1
A12: =基本資料!K7 -> 查修天花板所有天井燈具(30盞)與迴路 | D12: =基本資料!L7 -> 式 | E12: =基本資料!M7 -> 1 | G12: =_xlfn.XLOOKUP(J2,填寫!A:A,填寫!P:P) -> 0.5 | I12: =_xlfn.XLOOKUP(J2,填寫!A:A,填寫!Q:Q) -> 1
A13: =基本資料!K8 -> 拆除清運既有天井燈具，安裝LED天井燈具 (200W以上，含防眩鏡片與安全防墜配件)(含施工機具，連工帶料 | D13: =基本資料!L8 -> 盞 | E13: =基本資料!M8 -> 10 | G13: =_xlfn.XLOOKUP(J2,填寫!A:A,填寫!R:R) -> 5 | I13: =_xlfn.XLOOKUP(J2,填寫!A:A,填寫!S:S) -> 10
A14: =基本資料!K9 -> 職業安全衛生管理費(壹*1%) | D14: =基本資料!L9 -> 式 | E14: =基本資料!M9 -> 1 | G14: =_xlfn.XLOOKUP(J2,填寫!A:A,填寫!T:T) -> 0.461 | I14: =_xlfn.XLOOKUP(J2,填寫!A:A,填寫!U:U) -> 1.028
A15: =基本資料!K10 -> 公共工程品質管制作業費(壹*1%) | D15: =基本資料!L10 -> 式 | E15: =基本資料!M10 -> 1 | G15: =_xlfn.XLOOKUP(J2,填寫!A:A,填寫!V:V) -> 0.461 | I15: =_xlfn.XLOOKUP(J2,填寫!A:A,填寫!W:W) -> 1.028
A16: =基本資料!K11 -> 包商利潤及管理費(約壹*7%) | D16: =基本資料!L11 -> 式 | E16: =基本資料!M11 -> 1 | G16: =_xlfn.XLOOKUP(J2,填寫!A:A,填寫!X:X) -> 0.461 | I16: =_xlfn.XLOOKUP(J2,填寫!A:A,填寫!Y:Y) -> 1.028
A17: =基本資料!K12 -> 營造綜合保險費 | D17: =基本資料!L12 -> 式 | E17: =基本資料!M12 -> 1 | G17: =_xlfn.XLOOKUP(J2,填寫!A:A,填寫!Z:Z) -> 0.461 | I17: =_xlfn.XLOOKUP(J2,填寫!A:A,填寫!AA:AA) -> 1.028
A18: =基本資料!K13 -> 營業稅((壹~伍)*5%) | D18: =基本資料!L13 -> 式 | E18: =基本資料!M13 -> 1 | G18: =_xlfn.XLOOKUP(J2,填寫!A:A,填寫!AB:AB) -> 0.461 | I18: =_xlfn.XLOOKUP(J2,填寫!A:A,填寫!AC:AC) -> 1.028
A21: 二、工地材料管理概況（含約定之重要材料使用狀況及數量等）：
A22: 材料名稱 | D22: 單位 | E22: 設計數量 | G22: 本日使用數量 | I22: 累計使用數量 | K22: 備註
A24: 三、工地人員及機具管理（含約定之出工人數及機具使用情形及數量）：
A25: 工別 | C25: 本日人數 | E25: 累計人數 | G25: 機具名稱 | I25: 本日使用量 | K25: 累計使用量
A26: =填寫!AF2 -> 水電工 | C26: =_xlfn.XLOOKUP(J2,填寫!A:A,填寫!AF:AF) -> 4 | E26: =_xlfn.XLOOKUP(J2,填寫!A:A,填寫!AG:AG) -> 8 | G26: =填寫!AH2 -> 高空作業車 | I26: =_xlfn.XLOOKUP(J2,填寫!A:A,填寫!AH:AH) -> 2 | K26: =_xlfn.XLOOKUP(J2,填寫!A:A,填寫!AI:AI) -> 4
G27: =填寫!AJ2 -> 貨車 | I27: =_xlfn.XLOOKUP(J2,填寫!A:A,填寫!AJ:AJ) -> 2 | K27: =_xlfn.XLOOKUP(J2,填寫!A:A,填寫!AK:AK) -> 4
A28: 四、本日施工項目是否有須依「營造業專業工程特定施工項目應置之技術士總類、比率或人數標準表」規定應設置技術士之專業工程：□有■無 (此項如勾選"有"，則應填寫後附｢公共工程施工日誌之技術士簽章表｣
A29: 五、工地勞工安全衛生事項之督導、公共環境與安全之維護及其他工地行政事務：
A30: =VLOOKUP(J2,'[1]2.總表'!$A$7:$GT$499,196) -> (ㄧ)施工前檢查事項： 1.實施勤前教育(含工地預防災變及危害告知)：█有 □無 2.確認新進勞工是否提報勞工保險(或其他商業保險)資料及安全衛生教育訓練紀錄：□有 □無 █無新進勞工 3.檢查勞工個人防護具：█有 □無
A31: 六、施工取樣試驗紀錄：
A35: 七、通知分包廠商辦理事項：
A36: =VLOOKUP(J2,'[1]2.總表'!$A$7:$GW$499,193) -> 0
A37: 八、重要事項紀錄:
A41: =VLOOKUP(J2,'[1]2.總表'!$A$7:$GY$499,194) -> 0
A42: 簽章：【工地負責人】(註3)
A44: 註：1.依據營造業法第32條第1項第2款規定，工地主任應按日填報施工日誌。
A45: 2.本施工日誌格式僅供參考，惟原則應包含上開欄位，各機關亦得依工程性質及契約約定事項自行增訂之。
A46: 3.本工程依營造業法第30條規定須置工地主任者，由工地主任簽章；依上開規定免置工地主任者，則由營造業法第32條第2項所定之人員簽章。廠商非屬營造業者，由工地負責人簽章。
A47: 4.契約工期如有修正，應填修正後之契約工期，含展延工期及不計工期天數；如有依契約變更設計，預定進度及實際進度應填變更設計後計算之進度。
A48: 5.上開重要事項紀錄包含(1)主辦機關及監造單位指示(2)工地遇緊急異常狀況之通報處理情形(3)本日是否由專任工程人員督察按圖施工、解決施工技術問題等。
A49: 6.公共工程屬建築物者，請依內政部99年2月5日台內營字第0990800804號令頒之「建築物施工日誌」填寫。

Sheet 可改
A1: 公共工程施工日誌
A2: 表報編號: | B2: =基本資料!D7 -> 11419 | C2: P001 | D2: =J2 -> 45891 | I2: 填報日期： | J2: 45891 | L2: =J2 -> 45891
A3: 本日天氣: | B3: 上午： | C3: =_xlfn.XLOOKUP(J2,填寫!A:A,填寫!C:C) -> 晴 | D3: 下午： | E3: =_xlfn.XLOOKUP(J2,填寫!A:A,填寫!D:D) -> 晴
A4: 工程名稱 | C4: =基本資料!D3 -> 114年度修整建運動場地 | G4: 承攬廠商名稱 | I4: =基本資料!D14 -> 以勒綠能光電有限公司
A5: 核定工期 | C5: =基本資料!D4 -> 30 | D5: 累計工期 | G5: 剩餘工期 | I5: =C5-F5 -> 30 | J5: 工期展延天數
A6: 開工日期 | D6: =基本資料!D5 -> 45880 | G6: 完工日期 | J6: =D6+C5-1 -> 45909
A7: 預定進度(%) | D7: =_xlfn.XLOOKUP(J2,填寫!A:A,填寫!G:G,) -> 0.3996 | G7: 實際進度(%) | J7: =_xlfn.XLOOKUP(J2,填寫!A:A,填寫!H:H) -> 1
A8: 一、依施工計畫書執行按圖施工概況（含約定之重要施工項目及完成數量等）：
A9: 施工項目 | D9: 單位 | E9: 契約數量 | G9: 本日完成數量 | I9: 累計完成數量 | K9: 備註
A10: =基本資料!K5 -> 工程告示牌與職安衛告示牌(租用) | D10: =基本資料!L5 -> 式 | E10: =基本資料!M5 -> 1 | G10: =_xlfn.XLOOKUP(J2,填寫!A:A,填寫!L:L) -> 0 | I10: =_xlfn.XLOOKUP(J2,填寫!A:A,填寫!M:M) -> 1
A11: =基本資料!K6 -> 工區管制措施，施工環境保護與清潔 | D11: =基本資料!L6 -> 式 | E11: =基本資料!M6 -> 1 | G11: =_xlfn.XLOOKUP(J2,填寫!A:A,填寫!N:N) -> 0 | I11: =_xlfn.XLOOKUP(J2,填寫!A:A,填寫!O:O) -> 1
A12: =基本資料!K7 -> 查修天花板所有天井燈具(30盞)與迴路 | D12: =基本資料!L7 -> 式 | E12: =基本資料!M7 -> 1 | G12: =_xlfn.XLOOKUP(J2,填寫!A:A,填寫!P:P) -> 0.5 | I12: =_xlfn.XLOOKUP(J2,填寫!A:A,填寫!Q:Q) -> 1
A13: =基本資料!K8 -> 拆除清運既有天井燈具，安裝LED天井燈具 (200W以上，含防眩鏡片與安全防墜配件)(含施工機具，連工帶料 | D13: =基本資料!L8 -> 盞 | E13: =基本資料!M8 -> 10 | G13: =_xlfn.XLOOKUP(J2,填寫!A:A,填寫!R:R) -> 5 | I13: =_xlfn.XLOOKUP(J2,填寫!A:A,填寫!S:S) -> 10
A14: =基本資料!K9 -> 職業安全衛生管理費(壹*1%) | D14: =基本資料!L9 -> 式 | E14: =基本資料!M9 -> 1 | G14: =_xlfn.XLOOKUP(J2,填寫!A:A,填寫!T:T) -> 0.461 | I14: =_xlfn.XLOOKUP(J2,填寫!A:A,填寫!U:U) -> 1.028
A15: =基本資料!K10 -> 公共工程品質管制作業費(壹*1%) | D15: =基本資料!L10 -> 式 | E15: =基本資料!M10 -> 1 | G15: =_xlfn.XLOOKUP(J2,填寫!A:A,填寫!V:V) -> 0.461 | I15: =_xlfn.XLOOKUP(J2,填寫!A:A,填寫!W:W) -> 1.028
A16: =基本資料!K11 -> 包商利潤及管理費(約壹*7%) | D16: =基本資料!L11 -> 式 | E16: =基本資料!M11 -> 1 | G16: =_xlfn.XLOOKUP(J2,填寫!A:A,填寫!X:X) -> 0.461 | I16: =_xlfn.XLOOKUP(J2,填寫!A:A,填寫!Y:Y) -> 1.028
A17: =基本資料!K12 -> 營造綜合保險費 | D17: =基本資料!L12 -> 式 | E17: =基本資料!M12 -> 1 | G17: =_xlfn.XLOOKUP(J2,填寫!A:A,填寫!Z:Z) -> 0.461 | I17: =_xlfn.XLOOKUP(J2,填寫!A:A,填寫!AA:AA) -> 1.028
A18: =基本資料!K13 -> 營業稅((壹~伍)*5%) | D18: =基本資料!L13 -> 式 | E18: =基本資料!M13 -> 1 | G18: =_xlfn.XLOOKUP(J2,填寫!A:A,填寫!AB:AB) -> 0.461 | I18: =_xlfn.XLOOKUP(J2,填寫!A:A,填寫!AC:AC) -> 1.028
A21: 二、工地材料管理概況（含約定之重要材料使用狀況及數量等）：
A22: 材料名稱 | D22: 單位 | E22: 設計數量 | G22: 本日使用數量 | I22: 累計使用數量 | K22: 備註
A24: 三、工地人員及機具管理（含約定之出工人數及機具使用情形及數量）：
A25: 工別 | C25: 本日人數 | E25: 累計人數 | G25: 機具名稱 | I25: 本日使用量 | K25: 累計使用量
A26: =填寫!AF2 -> 水電工 | C26: =_xlfn.XLOOKUP(J2,填寫!A:A,填寫!AF:AF) -> 4 | E26: =_xlfn.XLOOKUP(J2,填寫!A:A,填寫!AG:AG) -> 8 | G26: =填寫!AH2 -> 高空作業車 | I26: =_xlfn.XLOOKUP(J2,填寫!A:A,填寫!AH:AH) -> 2 | K26: =_xlfn.XLOOKUP(J2,填寫!A:A,填寫!AI:AI) -> 4
G27: =填寫!AJ2 -> 貨車 | I27: =_xlfn.XLOOKUP(J2,填寫!A:A,填寫!AJ:AJ) -> 2 | K27: =_xlfn.XLOOKUP(J2,填寫!A:A,填寫!AK:AK) -> 4
A28: 四、本日施工項目是否有須依「營造業專業工程特定施工項目應置之技術士總類、比率或人數標準表」規定應設置技術士之專業工程：□有■無 (此項如勾選"有"，則應填寫後附｢公共工程施工日誌之技術士簽章表｣
A29: 五、工地勞工安全衛生事項之督導、公共環境與安全之維護及其他工地行政事務：
