Workbook

Sheet 施工日誌1
A1: 公共工程施工日誌
A2: 表報編號： | B2: 1
A3: 本日天氣： | B3: 上午： | C3: 晴 | D3: 下午： | E3: 晴 | H3: 填報日期： | J3: 46212 | M3: =J3 -> 46212
A4: 工程名稱 | B4: 元長國小辦理114年度充實設施設備-校園鋪面改善工程 | H4: 承攬廠商名稱 | K4: 有謙營造有限公司
A5: 核定工期 | B5: 60 | C5: 日曆天 | D5: 累計工期 | F5: 1 | G5: 天 | H5: 剩餘工期 | I5: =B5-F5 -> 59 | J5: 天 | K5: 工期展延天數 | N5: 天
A6: 開工日期 | D6: 46212 | H6: 完工日期 | K6: =D6+59 -> 46271
A7: 預定進度（％） | D7: =0.0005/5 -> 0.0001 | H7: 實際進度（％） | K7: =R38 -> 0.0043738268
A9: 一、依施工計畫書執行按圖施工概況（含約定之重要施工項目及完成數量等）：
A10: 施 工 項 目 | F10: 單位 | G10: 契約數量 | I10: 本日完成數量 | L10: 累計完成數量 | N10: 備註 | P10: 單價 | Q10: 複價 | R10: 實做金額
A11: =[1]詳細價目表!B3 -> 工程告示牌與職安告示牌(租用) | F11: 式 | G11: =[1]詳細價目表!D3 -> 1 | I11: 1 | L11: =I11 -> 1 | P11: 6000 | Q11: =P11*G11 -> 6000 | R11: =L11*P11 -> 6000
A12: =[1]詳細價目表!B4 -> 施工管制措施(租用) | F12: 式 | G12: =[1]詳細價目表!D4 -> 1 | L12: =I12 -> 0 | P12: 193300 | Q12: =P12*G12 -> 193300 | R12: =L12*P12 -> 0
A13: =[1]詳細價目表!B5 -> 施工動線開闢，整備與復原工程 | F13: 式 | G13: =[1]詳細價目表!D5 -> 1 | L13: =I13 -> 0 | P13: 30000 | Q13: =P13*G13 -> 30000 | R13: =L13*P13 -> 0
A14: =[1]詳細價目表!B6 -> 施工測量，工地放樣 | F14: 式 | G14: =[1]詳細價目表!D6 -> 1 | L14: =I14 -> 0 | P14: 10000 | Q14: =P14*G14 -> 10000 | R14: =L14*P14 -> 0
A15: =[1]詳細價目表!B7 -> 移除清運大王椰子樹(含挖樹頭，混凝土打底) | F15: 棵 | G15: =[1]詳細價目表!D7 -> 9 | L15: =I15 -> 0 | P15: 21000 | Q15: =P15*G15 -> 189000 | R15: =L15*P15 -> 0
A16: =[1]詳細價目表!B8 -> 既有水溝陰井清淤，暢通西南側圍牆外陰井暗溝排水至通路排水溝(含試水);雜項工程 | F16: 式 | G16: =[1]詳細價目表!D8 -> 1 | L16: =I16 -> 0 | P16: 184468 | Q16: =P16*G16 -> 184468 | R16: =L16*P16 -> 0
A17: =[1]詳細價目表!B9 -> 埋設RC陰井(含鍍鋅鋼材止滑細縫陰井蓋含框) | F17: 座 | G17: =[1]詳細價目表!D9 -> 9 | L17: =I17 -> 0 | P17: 20000 | Q17: =P17*G17 -> 180000 | R17: =L17*P17 -> 0
A18: =[1]詳細價目表!B10 -> 埋設10吋排水管 | F18: M | G18: =[1]詳細價目表!D10 -> 52 | L18: =I18 -> 0 | P18: 2500 | Q18: =P18*G18 -> 130000 | R18: =L18*P18 -> 0
A19: =[1]詳細價目表!B11 -> 安裝專用不鏽鋼開關箱，接引既有電源附接地線，陰井內安裝不鏽鋼沉水抽水馬達，安裝排水管排水至排水溝 | F19: 組 | G19: =[1]詳細價目表!D11 -> 1 | L19: =I19 -> 0 | P19: 80000 | Q19: =P19*G19 -> 80000 | R19: =L19*P19 -> 0
A20: =[1]詳細價目表!B12 -> 挖除石板鋪面，廢棄物集中處理 | F20: M2 | G20: =[1]詳細價目表!D12 -> 31 | L20: =I20 -> 0 | P20: 400 | Q20: =P20*G20 -> 12400 | R20: =L20*P20 -> 0
A21: =[1]詳細價目表!B13 -> 切割打除既有地坪，廢棄物集中處理 | F21: M2 | G21: =[1]詳細價目表!D13 -> 100 | L21: =I21 -> 0 | P21: 350 | Q21: =P21*G21 -> 35000 | R21: =L21*P21 -> 0
A22: =[1]詳細價目表!B14 -> 場鑄RC緣石 | F22: M | G22: =[1]詳細價目表!D14 -> 35 | L22: =I22 -> 0 | P22: 1200 | Q22: =P22*G22 -> 42000 | R22: =L22*P22 -> 0
A23: =[1]詳細價目表!B15 -> 鋪設預鑄緣石 | F23: M | G23: =[1]詳細價目表!D15 -> 282 | L23: =I23 -> 0 | P23: 1400 | Q23: =P23*G23 -> 394800 | R23: =L23*P23 -> 0
... A31: =[1]詳細價目表!B23 -> 營建廢棄物清運(含清運證明) | F31: 式 | G31: =[1]詳細價目表!D23 -> 1 | L31: =I31 -> 0 | P31: 276970 | Q31: =P31*G31 -> 276970 | R31: =L31*P31 -> 0
A32: =[1]詳細價目表!B25 -> 職業安全衛生管理費（壹*1.6%） | F32: 式 | G32: 1 | L32: =I32 -> 0 | P32: 60873 | Q32: =P32*G32 -> 60873 | R32: =L32*P32 -> 0
A33: =[1]詳細價目表!B26 -> 公共工程品質管制作業費（壹*1.6%） | F33: 式 | G33: =[1]詳細價目表!D25 -> 1 | L33: =I33 -> 0 | P33: 60873 | Q33: =P33*G33 -> 60873 | R33: =L33*P33 -> 0
A34: =[1]詳細價目表!B27 -> 包商管理及利潤費（壹*7%） | F34: 式 | G34: =[1]詳細價目表!D26 -> 1 | L34: =I34 -> 0 | P34: 266321 | Q34: =P34*G34 -> 266321 | R34: =L34*P34 -> 0
A35: =[1]詳細價目表!B28 -> 保險費 | F35: 式 | G35: =[1]詳細價目表!D27 -> 1 | I35: 1 | L35: =I35 -> 1 | P35: 13316 | Q35: =P35*G35 -> 13316 | R35: =L35*P35 -> 13316
A36: =[1]詳細價目表!B29 -> 營業稅（(壹~伍)*5％） | F36: 式 | G36: =[1]詳細價目表!D28 -> 1 | L36: =I36 -> 0 | P36: 210299 | Q36: =P36*G36 -> 210299 | R36: =L36*P36 -> 0
Q37: =SUM(Q11:Q36) -> 4416270 | R37: =SUM(R11:R36) -> 19316
R38: =R37/Q37 -> 0.0043738268
A47: 二、工地材料管理概況（含約定之重要材料使用狀況及數量等）：
A48: 材料名稱 | F48: 單位 | G48: 契約數量 | I48: 本日使用數量 | L48: 累計使用數量 | N48: 備註
A50: 三、工地人員及機具管理（含約定之出工人數及機具使用情形及數量）：
A51: 工別 | C51: 本日人數 | E51: 累計人數 | G51: 機具名稱 | J51: 本日使用數量 | M51: 累計使用數量
A52: 大工 | C52: 1 | E52: =C52 -> 1 | G52: 挖土機 | M52: =J52 -> 0
A53: 小工 | E53: =C53 -> 0 | G53: 卡車 | M53: =J53 -> 0
A54: 小工 | C54: 1 | E54: =C54 -> 1 | G54: 山貓 | M54: =J54 -> 0
A55: 四、本日施工項目是否有須依「營造業專業工程特定施工項目應置之技術士總類、比率或人數標準表」
A56: 規定應設置技術士之專業工程：□有□無 （此項如勾選“有”，則應填寫後附「公共工程施工日誌之技
A57: 術士簽章表」）
...
