Workbook

Sheet 11月
A1: 表報編號： | C1: 1
A2: 本日天氣： | C2: 上午： | D2: 晴 | E2: 下午： | F2: 晴 | H2: 填表日期： | J2: 45988 | L2: =J2 -> 45988
A3: 工程名稱 | C3: 114年度沙灘排球場地整建 | H3: 廠商名稱
A4: 核定工期 | C4: 50 | D4: 天 | E4: 累計工期 | F4: 1 | G4: 天 | H4: 剩餘工期 | I4: =C4-F4+L4 -> 49 | J4: 天 | K4: 工期展延天數 | M4: 天
A5: 開工日期 | D5: 45988 | H5: 完工日期 | J5: =D5+50-1 -> 46037
A6: 本日預定進度(%) | D6: 0.216 | H6: 本日實際進度(%) | J6: =P22 -> 0
A7: 累計預定進度(%) | D7: =D6 -> 0.216 | H7: 累計實際進度(%) | J7: =J6 -> 0
A8: 一、依施工計畫書執行按圖施工概況(含約定之重要施工項目及完成數量等):
A9: 項次 | B9: 施工項目 | E9: 單位 | F9: 契約數量 | H9: 本日完成數量 | J9: 累計完成數量 | L9: 備註 | O9: 單價 | P9: 總價 | T9: 剩餘數量
A10: 壹 | B10: 直接工程
A11: 1 | B11: 工程告示牌與職安告示牌(租用) | C11: 工程告示牌與職安告示牌(租用) | D11: 工程告示牌與職安告示牌(租用) | E11: 式 | F11: 1 | J11: =H11 -> 0 | O11: 4000 | P11: =ROUND(H11*O11,0) -> 0 | S11: =ROUND(J11*O11,0) -> 0 | T11: =F11-J11 -> 1
A12: 2 | B12: 施工區管制措施(租用) | C12: 施工區管制措施(租用) | D12: 施工區管制措施(租用) | E12: 式 | F12: 1 | J12: =H12 -> 0 | O12: 14334 | P12: =ROUND(H12*O12,0) -> 0 | S12: =ROUND(J12*O12,0) -> 0 | T12: =F12-J12 -> 1
A13: 3 | B13: 施工動線開闢與復原;測量與放樣;環境保護與清潔費 | C13: 施工動線開闢與復原;測量與放樣;環境保護與清潔費 | D13: 施工動線開闢與復原;測量與放樣;環境保護與清潔費 | E13: 式 | F13: 1 | J13: =H13 -> 0 | O13: 7000 | P13: =ROUND(H13*O13,0) -> 0 | S13: =ROUND(J13*O13,0) -> 0 | T13: =F13-J13 -> 1
A14: 4 | B14: 球場施工範圍及周遭，移植喬木與遷移地磚至校方指定位置 | C14: 球場施工範圍及周遭，移植喬木與遷移地磚至校方指定位置 | D14: 球場施工範圍及周遭，移植喬木與遷移地磚至校方指定位置 | E14: 式 | F14: 1 | J14: =H14 -> 0 | O14: 74000 | P14: =ROUND(H14*O14,0) -> 0 | S14: =ROUND(J14*O14,0) -> 0 | T14: =F14-J14 -> 1
A15: 5 | B15: 開挖整地，挖除土方平鋪校園空地整平，整地，鋪設不織布 | C15: 開挖整地，挖除土方平鋪校園空地整平，整地，鋪設不織布 | D15: 開挖整地，挖除土方平鋪校園空地整平，整地，鋪設不織布 | E15: ㎡ | F15: 396 | J15: =H15 -> 0 | O15: 200 | P15: =ROUND(H15*O15,0) -> 0 | S15: =ROUND(J15*O15,0) -> 0 | T15: =F15-J15 -> 396
A16: 6 | B16: 設置L型RC緣石與埋設PVC排水管 | C16: 設置L型RC緣石與埋設PVC排水管 | D16: 設置L型RC緣石與埋設PVC排水管 | E16: M | F16: 80 | G16: 183.6 | J16: =H16 -> 0 | O16: 1463 | P16: =ROUND(H16*O16,0) -> 0 | S16: =ROUND(J16*O16,0) -> 0 | T16: =F16-J16 -> 80
A17: 7 | B17: 吊料鋪設#3白色矽砂整平 | C17: 吊料鋪設#3白色矽砂整平 | D17: 吊料鋪設#3白色矽砂整平 | E17: 噸 | F17: 126 | G17: 19 | J17: =H17 -> 0 | O17: 6350 | P17: =ROUND(H17*O17,0) -> 0 | S17: =ROUND(J17*O17,0) -> 0 | T17: =F17-J17 -> 126
A18: 8 | B18: 安裝RC基礎底板與套管組、金屬排球柱含捲揚機、排球網與球柱防撞墊 | C18: 安裝RC基礎底板與套管組、金屬排球柱含捲揚機、排球網與球柱防撞墊 | D18: 安裝RC基礎底板與套管組、金屬排球柱含捲揚機、排球網與球柱防撞墊 | E18: 組 | F18: 1 | G18: 1192 | J18: =H18 -> 0 | O18: 47600 | P18: =ROUND(H18*O18,0) -> 0 | S18: =ROUND(J18*O18,0) -> 0 | T18: =F18-J18 -> 1
A19: 9 | B19: 安裝沙灘排球場標準線 | C19: 安裝沙灘排球場標準線 | D19: 安裝沙灘排球場標準線 | E19: 場 | F19: 1 | G19: 1261 | J19: =H19 -> 0 | O19: 10000 | P19: =ROUND(H19*O19,0) -> 0 | S19: =ROUND(J19*O19,0) -> 0 | T19: =F19-J19 -> 1
P20: 合計 | Q20: =SUM(P11:P19) -> 0 | S20: =SUM(S11:S19) -> 0
O21: 總計： | P21: =Q20 -> 0
O22: 百分比 | P22: =ROUND(P21/1153274,4)*100 -> 0
B23: 本日合計 | L23: =P21 -> 0
B24: 累計合計金額 | L24: =L23 -> 0
B25: 營造業專業工程特定施工項目
B26: A.
B27: B.
A28: 二、工地材料管理概況(含約定之重要材料使用狀況及數量等)：
A29: 材料名稱 | E29: 單位 | F29: 契約數量 | H29: 本日使用數量 | J29: 累計使用數量 | L29: 備註
A30: 6 | B30: 設置L型RC緣石與埋設PVC排水管 | C30: RC水溝B設置重載型連續式止滑細縫水溝蓋板 | D30: RC水溝B設置重載型連續式止滑細縫水溝蓋板 | E30: M | F30: 80 | G30: 1261 | H30: =H16 -> 0 | J30: =H30 -> 0
A31: 7 | B31: 吊料鋪設#3白色矽砂整平 | C31: 吊料鋪設#3白色矽砂整平 | D31: 吊料鋪設#3白色矽砂整平 | E31: 噸 | F31: 126 | H31: =H17 -> 0 | J31: =H31 -> 0
A32: 8 | B32: 安裝RC基礎底板與套管組、金屬排球柱含捲揚機、排球網與球柱防撞墊 | C32: 安裝RC基礎底板與套管組、金屬排球柱含捲揚機、排球網與球柱防撞墊 | D32: 安裝RC基礎底板與套管組、金屬排球柱含捲揚機、排球網與球柱防撞墊 | E32: 組 | F32: 1 | H32: =H18 -> 0 | J32: =H32 -> 0
A33: 三、工地人員及機具管理(含約定之出工人數及機具使用情形及數量)：
A34: 工別 | E34: 本日人數 | F34: 累計人數 | H34: 機具名稱 | J34: 本日使用數量 | L34: 累計使用數量
A35: 技術工 | F35: =E35 -> 0 | H35: 貨車 | L35: =J35 -> 0
A36: 水泥工 | F36: =E36 -> 0 | H36: 吊卡車 | L36: =J36 -> 0
A37: 體力工 | F37: =E37 -> 0 | H37: 挖土機(怪手) | L37: =J37 -> 0
A38: 模板工 | F38: =E38 -> 0 | H38: 山貓(堆土機) | L38: =J38 -> 0
A39: 四、本日施工項目是否有須依「營造業專業工程特定施工項目應置之技術士總類、比率或人數標準表」規定應設置技術士之專業工程：□有 ■無 （此項如勾選“有”，則應填寫「公共工程施工日誌之技術士簽章表」)
A40: 五、工地職業安全衛生事項之督導、公共環境與安全之維護及其他工地行政事務：
...

Sheet 12月
A1: 表報編號： | C1: ='11月'!C175+1 -> 5
A2: 本日天氣： | C2: 上午： | D2: 晴 | E2: 下午： | F2: 晴 | H2: 填表日期： | J2: ='11月'!J176:K176+1 -> 45992 | L2: =J2 -> 45992
A3: 工程名稱 | C3: 114年度沙灘排球場地整建 | H3: 廠商名稱
A4: 核定工期 | C4: 50 | D4: 天 | E4: 累計工期 | F4: ='11月'!F178+1 -> 5 | G4: 天 | H4: 剩餘工期 | I4: =C4-F4+L4 -> 45 | J4: 天 | K4: 工期展延天數 | L4: ='11月'!L178 -> 0 | M4: 天
A5: 開工日期 | D5: ='11月'!D179:G179 -> 45988 | H5: 完工日期 | J5: ='11月'!J179:M179 -> 46037
A6: 本日預定進度(%) | D6: 0.454 | H6: 本日實際進度(%) | J6: =P22 -> 9.72
A7: 累計預定進度(%) | D7: =D6+'11月'!D181:G181 -> 1.794 | H7: 累計實際進度(%) | J7: =J6+'11月'!J181:M181 -> 13.04
A8: 一、依施工計畫書執行按圖施工概況(含約定之重要施工項目及完成數量等):
A9: 項次 | B9: 施工項目 | E9: 單位 | F9: 契約數量 | H9: 本日完成數量 | J9: 累計完成數量 | L9: 備註 | O9: 單價 | P9: 總價 | T9: 剩餘數量
A10: 壹 | B10: 直接工程
A11: 1 | B11: 工程告示牌與職安告示牌(租用) | C11: 工程告示牌與職安告示牌(租用) | D11: 工程告示牌與職安告示牌(租用) | E11: 式 | F11: 1 | J11: =H11+'11月'!J185:K185 -> 1 | O11: 4000 | P11: =ROUND(H11*O11,0) -> 0 | S11: =ROUND(J11*O11,0) -> 4000 | T11: =F11-J11 -> 0
A12: 2 | B12: 施工區管制措施(租用) | C12: 施工區管制措施(租用) | D12: 施工區管制措施(租用) | E12: 式 | F12: 1 | J12: =H12+'11月'!J186:K186 -> 1 | O12: 14334 | P12: =ROUND(H12*O12,0) -> 0 | S12: =ROUND(J12*O12,0) -> 14334 | T12: =F12-J12 -> 0
A13: 3 | B13: 施工動線開闢與復原;測量與放樣;環境保護與清潔費 | C13: 施工動線開闢與復原;測量與放樣;環境保護與清潔費 | D13: 施工動線開闢與復原;測量與放樣;環境保護與清潔費 | E13: 式 | F13: 1 | H13: 0.5 | J13: =H13+'11月'!J187:K187 -> 0.5 | O13: 7000 | P13: =ROUND(H13*O13,0) -> 3500 | S13: =ROUND(J13*O13,0) -> 3500 | T13: =F13-J13 -> 0.5
A14: 4 | B14: 球場施工範圍及周遭，移植喬木與遷移地磚至校方指定位置 | C14: 球場施工範圍及周遭，移植喬木與遷移地磚至校方指定位置 | D14: 球場施工範圍及周遭，移植喬木與遷移地磚至校方指定位置 | E14: 式 | F14: 1 | H14: 1 | J14: =H14+'11月'!J188:K188 -> 1 | O14: 74000 | P14: =ROUND(H14*O14,0) -> 74000 | S14: =ROUND(J14*O14,0) -> 74000 | T14: =F14-J14 -> 0
A15: 5 | B15: 開挖整地，挖除土方平鋪校園空地整平，整地，鋪設不織布 | C15: 開挖整地，挖除土方平鋪校園空地整平，整地，鋪設不織布 | D15: 開挖整地，挖除土方平鋪校園空地整平，整地，鋪設不織布 | E15: ㎡ | F15: 396 | H15: 100 | J15: =H15+'11月'!J189:K189 -> 200 | O15: 200 | P15: =ROUND(H15*O15,0) -> 20000 | S15: =ROUND(J15*O15,0) -> 40000 | T15: =F15-J15 -> 196
A16: 6 | B16: 設置L型RC緣石與埋設PVC排水管 | C16: 設置L型RC緣石與埋設PVC排水管 | D16: 設置L型RC緣石與埋設PVC排水管 | E16: M | F16: 80 | G16: 183.6 | H16: 10 | J16: =H16+'11月'!J190:K190 -> 10 | O16: 1463 | P16: =ROUND(H16*O16,0) -> 14630 | S16: =ROUND(J16*O16,0) -> 14630 | T16: =F16-J16 -> 70
A17: 7 | B17: 吊料鋪設#3白色矽砂整平 | C17: 吊料鋪設#3白色矽砂整平 | D17: 吊料鋪設#3白色矽砂整平 | E17: 噸 | F17: 126 | G17: 19 | J17: =H17+'11月'!J191:K191 -> 0 | O17: 6350 | P17: =ROUND(H17*O17,0) -> 0 | S17: =ROUND(J17*O17,0) -> 0 | T17: =F17-J17 -> 126
A18: 8 | B18: 安裝RC基礎底板與套管組、金屬排球柱含捲揚機、排球網與球柱防撞墊 | C18: 安裝RC基礎底板與套管組、金屬排球柱含捲揚機、排球網與球柱防撞墊 | D18: 安裝RC基礎底板與套管組、金屬排球柱含捲揚機、排球網與球柱防撞墊 | E18: 組 | F18: 1 | G18: 1192 | J18: =H18+'11月'!J192:K192 -> 0 | O18: 47600 | P18: =ROUND(H18*O18,0) -> 0 | S18: =ROUND(J18*O18,0) -> 0 | T18: =F18-J18 -> 1
A19: 9 | B19: 安裝沙灘排球場標準線 | C19: 安裝沙灘排球場標準線 | D19: 安裝沙灘排球場標準線 | E19: 場 | F19: 1 | G19: 1261 | J19: =H19+'11月'!J193:K193 -> 0 | O19: 10000 | P19: =ROUND(H19*O19,0) -> 0 | S19: =ROUND(J19*O19,0) -> 0 | T19: =F19-J19 -> 1
P20: 合計 | Q20: =SUM(P11:P19) -> 112130 | S20: =SUM(S11:S19) -> 150464
O21: 總計： | P21: =Q20 -> 112130
O22: 百分比 | P22: =ROUND(P21/1153274,4)*100 -> 9.72
B23: 本日合計 | L23: =P21 -> 112130
B24: 累計合計金額 | L24: =L23+'11月'!L198:M198 -> 150464
B25: 營造業專業工程特定施工項目
B26: A.
B27: B.
A28: 二、工地材料管理概況(含約定之重要材料使用狀況及數量等)：
A29: 材料名稱 | E29: 單位 | F29: 契約數量 | H29: 本日使用數量 | J29: 累計使用數量 | L29: 備註
A30: 6 | B30: 設置L型RC緣石與埋設PVC排水管 | C30: RC水溝B設置重載型連續式止滑細縫水溝蓋板 | D30: RC水溝B設置重載型連續式止滑細縫水溝蓋板 | E30: M | F30: 80 | G30: 1261 | H30: =H16 -> 10 | J30: =H30+'11月'!J204:K204 -> 10
A31: 7 | B31: 吊料鋪設#3白色矽砂整平 | C31: 吊料鋪設#3白色矽砂整平 | D31: 吊料鋪設#3白色矽砂整平 | E31: 噸 | F31: 126 | H31: =H17 -> 0 | J31: =H31+'11月'!J205:K205 -> 0
A32: 8 | B32: 安裝RC基礎底板與套管組、金屬排球柱含捲揚機、排球網與球柱防撞墊 | C32: 安裝RC基礎底板與套管組、金屬排球柱含捲揚機、排球網與球柱防撞墊 | D32: 安裝RC基礎底板與套管組、金屬排球柱含捲揚機、排球網與球柱防撞墊 | E32: 組 | F32: 1 | H32: =H18 -> 0 | J32: =H32+'11月'!J206:K206 -> 0
A33: 三、工地人員及機具管理(含約定之出工人數及機具使用情形及數量)：
A34: 工別 | E34: 本日人數 | F34: 累計人數 | H34: 機具名稱 | J34: 本日使用數量 | L34: 累計使用數量
A35: 技術工 | E35: 2 | F35: =E35+'11月'!F209:G209 -> 6 | H35: 貨車 | J35: 1 | L35: =J35+'11月'!L209:M209 -> 3
A36: 水泥工 | F36: =E36+'11月'!F210:G210 -> 0 | H36: 吊卡車 | L36: =J36+'11月'!L210:M210 -> 0
A37: 體力工 | F37: =E37+'11月'!F211:G211 -> 0 | H37: 挖土機(怪手) | J37: 1 | L37: =J37+'11月'!L211:M211 -> 2
A38: 模板工 | F38: =E38+'11月'!F212:G212 -> 0 | H38: 山貓(堆土機) | L38: =J38+'11月'!L212:M212 -> 0
A39: 四、本日施工項目是否有須依「營造業專業工程特定施工項目應置之技術士總類、比率或人數標準表」規定應設置技術士之專業工程：□有 ■無 （此項如勾選“有”，則應填寫「公共工程施工日誌之技術士簽章表」)
A40: 五、工地職業安全衛生事項之督導、公共環境與安全之維護及其他工地行政事務：
...

Sheet 115年1月
A1: 表報編號： | C1: ='12月'!C1741+1 -> 36
A2: 本日天氣： | C2: 上午： | E2: 下午： | H2: 填表日期： | J2: ='12月'!J1742:K1742+1 -> 46023 | L2: =J2 -> 46023
A3: 工程名稱 | C3: 114年度沙灘排球場地整建 | H3: 廠商名稱
A4: 核定工期 | C4: 50 | D4: 天 | E4: 累計工期 | F4: ='12月'!F1744+1 -> 36 | G4: 天 | H4: 剩餘工期 | I4: =C4-F4+L4 -> 14 | J4: 天 | K4: 工期展延天數 | L4: ='12月'!L1744 -> 0 | M4: 天
A5: 開工日期 | D5: ='12月'!D1745:G1745 -> 45988 | H5: 完工日期 | J5: ='12月'!J1745:M1745 -> 46037
A6: 本日預定進度(%) | D6: 0.826 | H6: 本日實際進度(%) | J6: =P22 -> 0
A7: 累計預定進度(%) | D7: =D6+'12月'!D1747:G1747 -> 26.265 | H7: 累計實際進度(%) | J7: =J6+'12月'!J1747:M1747 -> 25.47
A8: 一、依施工計畫書執行按圖施工概況(含約定之重要施工項目及完成數量等):
A9: 項次 | B9: 施工項目 | E9: 單位 | F9: 契約數量 | H9: 本日完成數量 | J9: 累計完成數量 | L9: 備註 | O9: 單價 | P9: 總價 | T9: 剩餘數量
A10: 壹 | B10: 直接工程
A11: 1 | B11: 工程告示牌與職安告示牌(租用) | C11: 工程告示牌與職安告示牌(租用) | D11: 工程告示牌與職安告示牌(租用) | E11: 式 | F11: 1 | J11: =H11+'12月'!J1751:K1751 -> 1 | O11: 4000 | P11: =ROUND(H11*O11,0) -> 0 | S11: =ROUND(J11*O11,0) -> 4000 | T11: =F11-J11 -> 0
A12: 2 | B12: 施工區管制措施(租用) | C12: 施工區管制措施(租用) | D12: 施工區管制措施(租用) | E12: 式 | F12: 1 | J12: =H12+'12月'!J1752:K1752 -> 1 | O12: 14334 | P12: =ROUND(H12*O12,0) -> 0 | S12: =ROUND(J12*O12,0) -> 14334 | T12: =F12-J12 -> 0
A13: 3 | B13: 施工動線開闢與復原;測量與放樣;環境保護與清潔費 | C13: 施工動線開闢與復原;測量與放樣;環境保護與清潔費 | D13: 施工動線開闢與復原;測量與放樣;環境保護與清潔費 | E13: 式 | F13: 1 | J13: =H13+'12月'!J1753:K1753 -> 0.5 | O13: 7000 | P13: =ROUND(H13*O13,0) -> 0 | S13: =ROUND(J13*O13,0) -> 3500 | T13: =F13-J13 -> 0.5
A14: 4 | B14: 球場施工範圍及周遭，移植喬木與遷移地磚至校方指定位置 | C14: 球場施工範圍及周遭，移植喬木與遷移地磚至校方指定位置 | D14: 球場施工範圍及周遭，移植喬木與遷移地磚至校方指定位置 | E14: 式 | F14: 1 | J14: =H14+'12月'!J1754:K1754 -> 1 | O14: 74000 | P14: =ROUND(H14*O14,0) -> 0 | S14: =ROUND(J14*O14,0) -> 74000 | T14: =F14-J14 -> 0
A15: 5 | B15: 開挖整地，挖除土方平鋪校園空地整平，整地，鋪設不織布 | C15: 開挖整地，挖除土方平鋪校園空地整平，整地，鋪設不織布 | D15: 開挖整地，挖除土方平鋪校園空地整平，整地，鋪設不織布 | E15: ㎡ | F15: 396 | J15: =H15+'12月'!J1755:K1755 -> 350 | O15: 200 | P15: =ROUND(H15*O15,0) -> 0 | S15: =ROUND(J15*O15,0) -> 70000 | T15: =F15-J15 -> 46
A16: 6 | B16: 設置L型RC緣石與埋設PVC排水管 | C16: 設置L型RC緣石與埋設PVC排水管 | D16: 設置L型RC緣石與埋設PVC排水管 | E16: M | F16: 80 | G16: 183.6 | J16: =H16+'12月'!J1756:K1756 -> 78 | O16: 1463 | P16: =ROUND(H16*O16,0) -> 0 | S16: =ROUND(J16*O16,0) -> 114114 | T16: =F16-J16 -> 2
A17: 7 | B17: 吊料鋪設#3白色矽砂整平 | C17: 吊料鋪設#3白色矽砂整平 | D17: 吊料鋪設#3白色矽砂整平 | E17: 噸 | F17: 126 | G17: 19 | J17: =H17+'12月'!J1757:K1757 -> 0 | O17: 6350 | P17: =ROUND(H17*O17,0) -> 0 | S17: =ROUND(J17*O17,0) -> 0 | T17: =F17-J17 -> 126
A18: 8 | B18: 安裝RC基礎底板與套管組、金屬排球柱含捲揚機、排球網與球柱防撞墊 | C18: 安裝RC基礎底板與套管組、金屬排球柱含捲揚機、排球網與球柱防撞墊 | D18: 安裝RC基礎底板與套管組、金屬排球柱含捲揚機、排球網與球柱防撞墊 | E18: 組 | F18: 1 | G18: 1192 | J18: =H18+'12月'!J1758:K1758 -> 0.3 | O18: 47600 | P18: =ROUND(H18*O18,0) -> 0 | S18: =ROUND(J18*O18,0) -> 14280 | T18: =F18-J18 -> 0.7
A19: 9 | B19: 安裝沙灘排球場標準線 | C19: 安裝沙灘排球場標準線 | D19: 安裝沙灘排球場標準線 | E19: 場 | F19: 1 | G19: 1261 | J19: =H19+'12月'!J1759:K1759 -> 0 | O19: 10000 | P19: =ROUND(H19*O19,0) -> 0 | S19: =ROUND(J19*O19,0) -> 0 | T19: =F19-J19 -> 1
P20: 合計 | Q20: =SUM(P11:P19) -> 0 | S20: =SUM(S11:S19) -> 294228
O21: 總計： | P21: =Q20 -> 0
O22: 百分比 | P22: =ROUND(P21/1153274,4)*100 -> 0
B23: 本日合計 | L23: =P21 -> 0
B24: 累計合計金額 | L24: =L23+'12月'!L1764:M1764 -> 294228
B25: 營造業專業工程特定施工項目
B26: A.
B27: B.
A28: 二、工地材料管理概況(含約定之重要材料使用狀況及數量等)：
A29: 材料名稱 | E29: 單位 | F29: 契約數量 | H29: 本日使用數量 | J29: 累計使用數量 | L29: 備註
A30: 6 | B30: 設置L型RC緣石與埋設PVC排水管 | C30: RC水溝B設置重載型連續式止滑細縫水溝蓋板 | D30: RC水溝B設置重載型連續式止滑細縫水溝蓋板 | E30: M | F30: 80 | G30: 1261 | H30: =H16 -> 0 | J30: =H30+'12月'!J1770:K1770 -> 78
A31: 7 | B31: 吊料鋪設#3白色矽砂整平 | C31: 吊料鋪設#3白色矽砂整平 | D31: 吊料鋪設#3白色矽砂整平 | E31: 噸 | F31: 126 | H31: =H17 -> 0 | J31: =H31+'12月'!J1771:K1771 -> 0
A32: 8 | B32: 安裝RC基礎底板與套管組、金屬排球柱含捲揚機、排球網與球柱防撞墊 | C32: 安裝RC基礎底板與套管組、金屬排球柱含捲揚機、排球網與球柱防撞墊 | D32: 安裝RC基礎底板與套管組、金屬排球柱含捲揚機、排球網與球柱防撞墊 | E32: 組 | F32: 1 | H32: =H18 -> 0 | J32: =H32+'12月'!J1772:K1772 -> 0.3
A33: 三、工地人員及機具管理(含約定之出工人數及機具使用情形及數量)：
A34: 工別 | E34: 本日人數 | F34: 累計人數 | H34: 機具名稱 | J34: 本日使用數量 | L34: 累計使用數量
A35: 技術工 | F35: =E35+'12月'!F1775:G1775 -> 28 | H35: 貨車 | L35: =J35+'12月'!L1775:M1775 -> 15
A36: 水泥工 | F36: =E36+'12月'!F1776:G1776 -> 0 | H36: 吊卡車 | L36: =J36+'12月'!L1776:M1776 -> 0
A37: 體力工 | F37: =E37+'12月'!F1777:G1777 -> 2 | H37: 挖土機(怪手) | L37: =J37+'12月'!L1777:M1777 -> 5
A38: 模板工 | F38: =E38+'12月'!F1778:G1778 -> 4 | H38: 山貓(堆土機) | L38: =J38+'12月'!L1778:M1778 -> 1
A39: 四、本日施工項目是否有須依「營造業專業工程特定施工項目應置之技術士總類、比率或人數標準表」規定應設置技術士之專業工程：□有 ■無 （此項如勾選“有”，則應填寫「公共工程施工日誌之技術士簽章表」)
A40: 五、工地職業安全衛生事項之督導、公共環境與安全之維護及其他工地行政事務：
...
